<?xml version="1.0" ?>
<!-- =================================================================================== -->
<!-- |    This document was autogenerated by xacro from ../robots/curi.urdf.xacro      | -->
<!-- |    EDITING THIS FILE BY HAND IS NOT RECOMMENDED                                 | -->
<!-- =================================================================================== -->
<robot name="curi">
  <!-- in kg-->
  <!-- =============================================================== -->
  <!-- || This file does not contain official inertial properties   || -->
  <!-- || of panda robot. The values are from the identification    || -->
  <!-- || results published in: Identification of the Franka Emika  || -->
  <!-- || PandaRobot With Retrieval of Feasible Parameters Using    || -->
  <!-- || Penalty-Based Optimization                                || -->
  <!-- || by: Claudio Gaz, Marco Cognetti, Alexander Oliva,         || -->
  <!-- || Paolo Robuffo Giordano, Alessandro de Luca                || -->
  <!-- =============================================================== -->
  <link name="world"/>
  <joint name="reference" type="floating">
    <parent link="world"/>
    <child link="summit_xls_base_footprint"/>
  </joint>
  <link name="summit_xls_base_footprint">
    <visual>
      <origin rpy="0 0 0" xyz="0 0 0"/>
      <geometry>
        <box size="0.001 0.001 0.001"/>
      </geometry>
    </visual>
  </link>
  <joint name="summit_xls_base_footprint_joint" type="fixed">
    <origin rpy="0 0 0" xyz="0 0 0.127"/>
    <parent link="summit_xls_base_footprint"/>
    <child link="summit_xls_base_link"/>
  </joint>
  <!-- BASE_LINK -->
  <link name="summit_xls_base_link">
    <inertial>
      <mass value="125.0"/>
      <origin xyz="0 0 0"/>
      <inertia ixx="1.391" ixy="0.004" ixz="0.0" iyy="6.853" iyz="0.0" izz="6.125"/>
    </inertial>
    <visual>
      <origin rpy="0 0 0" xyz="0 0 0"/>
      <geometry>
        <mesh filename="../meshes/robotnik/bases/summit_xls_chassis.dae"/>
      </geometry>
      <material name="black">
        <color rgba="0.0 0.0 0.0 1"/>
      </material>
    </visual>
    <collision>
      <origin rpy="0 0 0 " xyz="0 0 0"/>
      <geometry>
        <mesh filename="../meshes/robotnik/bases/summit_xls_chassis.stl"/>
      </geometry>
    </collision>
  </link>
  <joint name="summit_xls_front_right_wheel_joint" type="continuous">
    <parent link="summit_xls_base_link"/>
    <child link="summit_xls_front_right_wheel_link"/>
    <origin rpy="0 0 0" xyz="0.2225 -0.2045 0.0"/>
    <axis rpy="0 0 0" xyz="0 1 0"/>
    <limit effort="100" velocity="100"/>
    <joint_properties damping="0.0" friction="0.0"/>
  </joint>
  <link name="summit_xls_front_right_wheel_link">
    <visual>
      <origin rpy="0 0 0" xyz="0 0 0"/>
      <geometry>
        <mesh filename="../meshes/robotnik/wheels/omni_wheel_2.dae"/>
      </geometry>
      <material name="darkgrey">
        <color rgba="0.2 0.2 0.2 1"/>
      </material>
    </visual>
    <collision>
      <origin rpy="1.5707963267948966 0 0" xyz="0 0 0"/>
      <geometry>
        <cylinder length="0.087" radius="0.127"/>
      </geometry>
    </collision>
    <inertial>
      <mass value="6.5"/>
      <origin xyz="0 0 0"/>
      <inertia ixx="0.0303095" ixy="0" ixz="0" iyy="0.05241925" iyz="0" izz="0.0303095"/>
    </inertial>
  </link>
  <joint name="summit_xls_front_left_wheel_joint" type="continuous">
    <parent link="summit_xls_base_link"/>
    <child link="summit_xls_front_left_wheel_link"/>
    <origin rpy="0 0 0" xyz="0.2225 0.2045 0.0"/>
    <axis rpy="0 0 0" xyz="0 1 0"/>
    <limit effort="100" velocity="100"/>
    <joint_properties damping="0.0" friction="0.0"/>
  </joint>
  <link name="summit_xls_front_left_wheel_link">
    <visual>
      <origin rpy="0 0 0" xyz="0 0 0"/>
      <geometry>
        <mesh filename="../meshes/robotnik/wheels/omni_wheel_1.dae"/>
      </geometry>
      <material name="darkgrey">
        <color rgba="0.2 0.2 0.2 1"/>
      </material>
    </visual>
    <collision>
      <origin rpy="1.5707963267948966 0 0" xyz="0 0 0"/>
      <geometry>
        <cylinder length="0.087" radius="0.127"/>
      </geometry>
    </collision>
    <inertial>
      <mass value="6.5"/>
      <origin xyz="0 0 0"/>
      <inertia ixx="0.0303095" ixy="0" ixz="0" iyy="0.05241925" iyz="0" izz="0.0303095"/>
    </inertial>
  </link>
  <joint name="summit_xls_back_left_wheel_joint" type="continuous">
    <parent link="summit_xls_base_link"/>
    <child link="summit_xls_back_left_wheel_link"/>
    <origin rpy="0 0 0" xyz="-0.2225 0.2045 0.0"/>
    <axis rpy="0 0 0" xyz="0 1 0"/>
    <limit effort="100" velocity="100"/>
    <joint_properties damping="0.0" friction="0.0"/>
  </joint>
  <link name="summit_xls_back_left_wheel_link">
    <visual>
      <origin rpy="0 0 0" xyz="0 0 0"/>
      <geometry>
        <mesh filename="../meshes/robotnik/wheels/omni_wheel_1.dae"/>
      </geometry>
      <material name="darkgrey">
        <color rgba="0.2 0.2 0.2 1"/>
      </material>
    </visual>
    <collision>
      <origin rpy="1.5707963267948966 0 0" xyz="0 0 0"/>
      <geometry>
        <cylinder length="0.087" radius="0.127"/>
      </geometry>
    </collision>
    <inertial>
      <mass value="6.5"/>
      <origin xyz="0 0 0"/>
      <inertia ixx="0.0303095" ixy="0" ixz="0" iyy="0.05241925" iyz="0" izz="0.0303095"/>
    </inertial>
  </link>
  <joint name="summit_xls_back_right_wheel_joint" type="continuous">
    <parent link="summit_xls_base_link"/>
    <child link="summit_xls_back_right_wheel_link"/>
    <origin rpy="0 0 0" xyz="-0.2225 -0.2045 0.0"/>
    <axis rpy="0 0 0" xyz="0 1 0"/>
    <limit effort="100" velocity="100"/>
    <joint_properties damping="0.0" friction="0.0"/>
  </joint>
  <link name="summit_xls_back_right_wheel_link">
    <visual>
      <origin rpy="0 0 0" xyz="0 0 0"/>
      <geometry>
        <mesh filename="../meshes/robotnik/wheels/omni_wheel_2.dae"/>
      </geometry>
      <material name="darkgrey">
        <color rgba="0.2 0.2 0.2 1"/>
      </material>
    </visual>
    <collision>
      <origin rpy="1.5707963267948966 0 0" xyz="0 0 0"/>
      <geometry>
        <cylinder length="0.087" radius="0.127"/>
      </geometry>
    </collision>
    <inertial>
      <mass value="6.5"/>
      <origin xyz="0 0 0"/>
      <inertia ixx="0.0303095" ixy="0" ixz="0" iyy="0.05241925" iyz="0" izz="0.0303095"/>
    </inertial>
  </link>
  <joint name="torso_joint_summit_xls_base_footprint" type="fixed">
    <parent link="summit_xls_base_footprint"/>
    <child link="control_box"/>
    <origin rpy="0 0 0" xyz="0 0 0.52262"/>
  </joint>
  <link name="control_box">
    <visual>
      <origin rpy="0 0 0" xyz="0 0 0"/>
      <geometry>
        <mesh filename="../meshes/clover/visual/control_box.dae"/>
      </geometry>
    </visual>
    <collision>
      <origin rpy="0 0 0" xyz="0 0 0"/>
      <geometry>
        <mesh filename="../meshes/clover/collision/control_box.stl"/>
      </geometry>
    </collision>
    <inertial>
      <!-- Estimated guesses from CAD -->
      <origin rpy="0 0 0" xyz="-0.221652 1.4173e-02 0.165597"/>
      <mass value="37.813"/>
      <inertia ixx="1.672305973" ixy="-0.023504956" ixz="-0.565170381" iyy="2.616747309" iyz="0.046623093" izz="2.524344244"/>
    </inertial>
  </link>
  <link name="torso_base1">
    <visual>
      <origin rpy="0 0 0" xyz="0 0 0"/>
      <geometry>
        <mesh filename="../meshes/clover/visual/torso_base1.dae"/>
      </geometry>
    </visual>
    <collision>
      <origin rpy="0 0 0" xyz="0 0 0"/>
      <geometry>
        <mesh filename="../meshes/clover/collision/torso_base1.stl"/>
      </geometry>
    </collision>
    <inertial>
      <origin rpy="0 0 0" xyz="0 0 0.02555"/>
      <mass value="1.18"/>
      <inertia ixx="0.00241116" ixy="0" ixz="0" iyy="0.00241116" iyz="0" izz="0.00362611"/>
    </inertial>
  </link>
  <joint name="torso_joint1" type="fixed">
    <origin rpy="0 0 0" xyz="0.2375 0 0.015"/>
    <parent link="control_box"/>
    <child link="torso_base1"/>
  </joint>
  <link name="torso_base2">
    <visual>
      <origin rpy="0 0 0" xyz="0 0 0"/>
      <geometry>
        <mesh filename="../meshes/clover/visual/torso_base2.dae"/>
      </geometry>
    </visual>
    <collision>
      <origin rpy="0 0 0" xyz="0 0 0"/>
      <geometry>
        <mesh filename="../meshes/clover/collision/torso_base2.stl"/>
      </geometry>
    </collision>
    <inertial>
      <origin rpy="0 0 0" xyz="-0.05478 0.03332 -0.07616"/>
      <mass value="35.66"/>
      <inertia ixx="0.87275935" ixy="-0.06173772" ixz="0.01895727" iyy="0.57302356" iyz="0.11888755" izz="1.06212354"/>
    </inertial>
  </link>
  <joint name="torso_actuated_joint1" type="revolute">
    <safety_controller k_position="100.0" k_velocity="40.0" soft_lower_limit="-1.5" soft_upper_limit="1.5"/>
    <origin rpy="0 0 0" xyz="0 0 0.215"/>
    <parent link="torso_base1"/>
    <child link="torso_base2"/>
    <axis xyz="0 0 1"/>
    <limit acceleration="0.6" effort="300" lower="-1.57" upper="1.57" velocity="0.3"/>
    <dynamics D="1" K="7000" damping="0.003" friction="0.0" mu_coulomb="0" mu_viscous="16"/>
  </joint>
  <link name="torso_link_b2">
    <visual>
      <origin rpy="0 0 0" xyz="0 0 0"/>
      <geometry>
        <mesh filename="../meshes/clover/visual/torso_link_b2.dae"/>
      </geometry>
    </visual>
    <collision>
      <origin rpy="0 0 0" xyz="0 0 0"/>
      <geometry>
        <mesh filename="../meshes/clover/collision/torso_link_b2.stl"/>
      </geometry>
    </collision>
    <inertial>
      <origin rpy="0 0 0" xyz="2.066e-03 2.4036e-02 8.3361e-02"/>
      <mass value="2.698"/>
      <inertia ixx="0.035907338" ixy="-0.000134319" ixz="0.000037769" iyy="0.023944853" iyz="-0.005304362" izz="0.014484777"/>
    </inertial>
  </link>
  <joint name="torso_actuated_joint2" type="revolute">
    <safety_controller k_position="100.0" k_velocity="40.0" soft_lower_limit="-1.2" soft_upper_limit="0.5"/>
    <origin rpy="0 0 0" xyz="0 0 0"/>
    <parent link="torso_base2"/>
    <child link="torso_link_b2"/>
    <axis xyz="0 1 0"/>
    <limit acceleration="0.6" effort="300" lower="-1.2" upper="0.5" velocity="0.3"/>
    <dynamics D="1" K="7000" damping="0.003" friction="0.0" mu_coulomb="0" mu_viscous="16"/>
  </joint>
  <link name="torso_middle">
    <visual>
      <origin rpy="0 0 0" xyz="0 0 0"/>
      <geometry>
        <mesh filename="../meshes/clover/visual/torso_middle.dae"/>
      </geometry>
    </visual>
    <collision>
      <origin rpy="0 0 0" xyz="0 0 0"/>
      <geometry>
        <mesh filename="../meshes/clover/collision/torso_middle.stl"/>
      </geometry>
    </collision>
    <inertial>
      <origin rpy="0 0 0" xyz="3.2089e-02 0 4.789e-02"/>
      <mass value="2.688"/>
      <inertia ixx="0.00744652" ixy="-0.00003495" ixz="0.000230038" iyy="0.006884728" iyz="0.000041279" izz="0.008084049"/>
    </inertial>
  </link>
  <joint name="torso_joint5" type="revolute">
    <safety_controller k_position="100.0" k_velocity="40.0" soft_lower_limit="-0.5" soft_upper_limit="1.2"/>
    <origin rpy="0 0 0" xyz="0 0 0.25"/>
    <parent link="torso_link_b2"/>
    <child link="torso_middle"/>
    <axis xyz="0 1 0"/>
    <limit acceleration="0.6" effort="300" lower="-0.5" upper="1.2" velocity="0.3"/>
    <dynamics D="1" K="7000" damping="0.003" friction="0.0" mu_coulomb="0" mu_viscous="16"/>
    <mimic joint="torso_actuated_joint2" multiplier="-1"/>
  </joint>
  <link name="torso_link_c1">
    <visual>
      <origin rpy="0 0 0" xyz="0 0 0"/>
      <geometry>
        <mesh filename="../meshes/clover/visual/torso_link_c1.dae"/>
      </geometry>
    </visual>
    <collision>
      <origin rpy="0 0 0" xyz="0 0 0"/>
      <geometry>
        <mesh filename="../meshes/clover/collision/torso_link_c1.stl"/>
      </geometry>
    </collision>
    <inertial>
      <origin rpy="0 0 0" xyz="0.10533 1.503e-03 9.863e-03"/>
      <mass value="2.4"/>
      <inertia ixx="0.014986407" ixy="-1.7102e-05" ixz="-4.53321e-04" iyy="0.027549549" iyz="-3.557e-05" izz="0.041344611"/>
    </inertial>
  </link>
  <joint name="torso_actuated_joint3" type="revolute">
    <safety_controller k_position="100.0" k_velocity="40.0" soft_lower_limit="-0.9" soft_upper_limit="0.9"/>
    <origin rpy="0 0 0" xyz="0 0 0"/>
    <parent link="torso_middle"/>
    <child link="torso_link_c1"/>
    <axis xyz="0 1 0"/>
    <limit acceleration="0.6" effort="300" lower="-0.9" upper="0.9" velocity="0.3"/>
    <dynamics D="1" K="7000" damping="0.003" friction="0.0" mu_coulomb="0" mu_viscous="16"/>
  </joint>
  <link name="torso_end">
    <visual>
      <origin rpy="0 0 0" xyz="0 0 0"/>
      <geometry>
        <mesh filename="../meshes/clover/visual/torso_end.dae"/>
      </geometry>
    </visual>
    <collision>
      <origin rpy="0 0 0" xyz="0 0 0"/>
      <geometry>
        <mesh filename="../meshes/clover/collision/torso_end.stl"/>
      </geometry>
    </collision>
    <inertial>
      <origin rpy="0 0 0" xyz="1.3086e-02 0.132e-03 0.184066"/>
      <mass value="12.083"/>
      <inertia ixx="0.146638956" ixy="-2.2432e-05" ixz="-0.012989506" iyy="0.097685785" iyz="-2.19304e-04" izz="0.100449047"/>
    </inertial>
  </link>
  <joint name="torso_joint8" type="revolute">
    <safety_controller k_position="100.0" k_velocity="40.0" soft_lower_limit="-0.9" soft_upper_limit="0.9"/>
    <origin rpy="0 0 0" xyz="0.25 0 0"/>
    <parent link="torso_link_c1"/>
    <child link="torso_end"/>
    <axis xyz="0 1 0"/>
    <limit acceleration="0.6" effort="300" lower="-0.9" upper="0.9" velocity="0.3"/>
    <dynamics D="1" K="7000" damping="0.003" friction="0.0" mu_coulomb="0" mu_viscous="16"/>
    <mimic joint="torso_actuated_joint3" multiplier="-1"/>
  </joint>
  <link name="torso_link_b1">
    <visual>
      <origin rpy="0 0 0" xyz="0 0 0"/>
      <geometry>
        <mesh filename="../meshes/clover/visual/torso_link_b1.dae"/>
      </geometry>
    </visual>
    <collision>
      <origin rpy="0 0 0" xyz="0 0 0"/>
      <geometry>
        <mesh filename="../meshes/clover/collision/torso_link_b1.stl"/>
      </geometry>
    </collision>
    <inertial>
      <origin rpy="0 0 0" xyz="0 -0.362e-03 0.12405"/>
      <mass value="1.319"/>
      <inertia ixx="0.01417626" ixy="0" ixz="0" iyy="0.01069895" iyz="0.00005678" izz="0.0039678"/>
    </inertial>
  </link>
  <joint name="torso_joint4" type="revolute">
    <safety_controller k_position="100.0" k_velocity="40.0" soft_lower_limit="-1.2" soft_upper_limit="0.5"/>
    <origin rpy="0 0 0" xyz="0.0866 0 0.05"/>
    <parent link="torso_base2"/>
    <child link="torso_link_b1"/>
    <axis xyz="0 1 0"/>
    <limit acceleration="0.6" effort="300" lower="-1.2" upper="0.5" velocity="0.3"/>
    <dynamics D="1" K="7000" damping="0.003" friction="0.0" mu_coulomb="0" mu_viscous="16"/>
    <mimic joint="torso_actuated_joint2" multiplier="1"/>
  </joint>
  <link name="torso_link_c2">
    <visual>
      <origin rpy="0 0 0" xyz="0 0 0"/>
      <geometry>
        <mesh filename="../meshes/clover/visual/torso_link_c2.dae"/>
      </geometry>
    </visual>
    <collision>
      <origin rpy="0 0 0" xyz="0 0 0"/>
      <geometry>
        <mesh filename="../meshes/clover/collision/torso_link_c2.stl"/>
      </geometry>
    </collision>
    <inertial>
      <origin rpy="0 0 0" xyz="0.120384 0.569e-03 6.703e-03"/>
      <mass value="2.148"/>
      <inertia ixx="0.010693997" ixy="5.645e-06" ixz="-9.4779e-04" iyy="0.026717753" iyz="-8.196e-06" izz="0.036543169"/>
    </inertial>
  </link>
  <joint name="torso_joint7" type="revolute">
    <safety_controller k_position="100.0" k_velocity="40.0" soft_lower_limit="-0.9" soft_upper_limit="0.9"/>
    <origin rpy="0 0 0" xyz="0 0 0.1"/>
    <parent link="torso_middle"/>
    <child link="torso_link_c2"/>
    <axis xyz="0 1 0"/>
    <limit acceleration="0.6" effort="300" lower="-0.9" upper="0.9" velocity="0.3"/>
    <dynamics D="1" K="7000" damping="0.003" friction="0.0" mu_coulomb="0" mu_viscous="16"/>
    <mimic joint="torso_actuated_joint3" multiplier="1"/>
  </joint>
  <joint name="head_joint_torso_end" type="fixed">
    <parent link="torso_end"/>
    <child link="head_base"/>
    <origin rpy="0 0 0" xyz="0.01466 0 0.2775"/>
  </joint>
  <link name="head_base">
    <visual>
      <origin rpy="0 0 0" xyz="0 0 0"/>
      <geometry>
        <mesh filename="../meshes/clover/visual/head_base.dae"/>
      </geometry>
    </visual>
    <collision>
      <origin rpy="0 0 0" xyz="0 0 0"/>
      <geometry>
        <mesh filename="../meshes/clover/collision/head_base.stl"/>
      </geometry>
    </collision>
    <inertial>
      <!-- Estimated guesses from CAD -->
      <origin rpy="0 0 0" xyz="-1.9726e-02 1.281e-03 2.2693e-02"/>
      <mass value="0.803"/>
      <inertia ixx="6.56432e-04" ixy="-3.4976e-05" ixz="0.652e-6" iyy="6.42664e-04" iyz="-1.577e-06" izz="1.046862e-03"/>
    </inertial>
  </link>
  <joint name="head_actuated_joint1" type="revolute">
    <safety_controller k_position="100.0" k_velocity="40.0" soft_lower_limit="-1.5" soft_upper_limit="1.5"/>
    <origin rpy="0 0 0" xyz="0 0 0.045"/>
    <parent link="head_base"/>
    <child link="head_link1"/>
    <axis xyz="0 0 1"/>
    <limit effort="30" lower="-1.57" upper="1.57" velocity="1.0"/>
    <dynamics D="1" K="7000" damping="0.003" friction="0.0" mu_coulomb="0" mu_viscous="16"/>
  </joint>
  <link name="head_link1">
    <visual>
      <origin rpy="0 0 0" xyz="0 0 0"/>
      <geometry>
        <mesh filename="../meshes/clover/visual/head_link1.dae"/>
      </geometry>
    </visual>
    <collision>
      <origin rpy="0 0 0" xyz="0 0 0"/>
      <geometry>
        <mesh filename="../meshes/clover/collision/head_link1.stl"/>
      </geometry>
    </collision>
    <inertial>
      <!-- Estimated guesses from CAD -->
      <origin rpy="0 0 0" xyz="-1.8392e-02 -0.4e-03 2.8338e-02"/>
      <mass value="0.534"/>
      <inertia ixx="2.34142e-04" ixy="-3.129e-06" ixz="6.321e-05" iyy="5.09246e-04" iyz="1.49e-06" izz="4.3777e-04"/>
    </inertial>
  </link>
  <joint name="head_actuated_joint2" type="revolute">
    <safety_controller k_position="100.0" k_velocity="40.0" soft_lower_limit="-0.8" soft_upper_limit="0.5"/>
    <origin rpy="0 0 0" xyz="0 0 0.043"/>
    <parent link="head_link1"/>
    <child link="head_link2"/>
    <axis xyz="0 1 0"/>
    <limit effort="30" lower="-0.82" upper="0.52" velocity="1.0"/>
    <dynamics D="1" K="7000" damping="0.003" friction="0.0" mu_coulomb="0" mu_viscous="16"/>
  </joint>
  <link name="head_link2">
    <visual>
      <origin rpy="0 0 0" xyz="0 0 0"/>
      <geometry>
        <mesh filename="../meshes/clover/visual/head_link2.dae"/>
      </geometry>
    </visual>
    <collision>
      <origin rpy="0 0 0" xyz="0 0 0"/>
      <geometry>
        <mesh filename="../meshes/clover/collision/head_link2.stl"/>
      </geometry>
    </collision>
    <inertial>
      <!-- Estimated guesses from CAD -->
      <origin rpy="0 0 0" xyz="3.8624e-02 0 0.143829"/>
      <mass value="1.346"/>
      <inertia ixx="0.010306864" ixy="-5.953e-06" ixz="6.74795e-04" iyy="0.011632066" iyz="-1.125e-06" izz="0.009582498"/>
    </inertial>
  </link>
  <joint name="panda_left_joint_torso_end" type="fixed">
    <parent link="torso_end"/>
    <child link="panda_left_link0"/>
    <origin rpy="-1.5004311592913677 0.8772798703277918 -0.2038499389018784" xyz="0.02842 0.11216 0.19004"/>
  </joint>
  <link name="panda_left_link0">
    <visual>
      <origin rpy="0 0 0" xyz="0 0 0"/>
      <geometry>
        <mesh filename="../meshes/franka/visual/link0.dae"/>
      </geometry>
    </visual>
    <collision>
      <origin rpy="0 0 0" xyz="0 0 0"/>
      <geometry>
        <mesh filename="../meshes/franka/collision/link0.stl"/>
      </geometry>
    </collision>
    <inertial>
      <!-- Estimated guesses from CAD -->
      <origin rpy="0 0 0" xyz="-0.041018 -0.00014 0.049974"/>
      <mass value="0.629769"/>
      <inertia ixx="0.00315" ixy="8.2904E-07" ixz="0.00015" iyy="0.00388" iyz="8.2299E-06" izz="0.004285"/>
    </inertial>
  </link>
  <link name="panda_left_link1">
    <visual>
      <origin rpy="0 0 0" xyz="0 0 0"/>
      <geometry>
        <mesh filename="../meshes/franka/visual/link1.dae"/>
      </geometry>
    </visual>
    <collision>
      <origin rpy="0 0 0" xyz="0 0 0"/>
      <geometry>
        <mesh filename="../meshes/franka/collision/link1.stl"/>
      </geometry>
    </collision>
    <inertial>
      <origin rpy="0 0 0" xyz="0.003875 0.002081 -0.04762"/>
      <mass value="4.970684"/>
      <inertia ixx="0.70337" ixy="-0.00013900" ixz="0.0067720" iyy="0.70661" iyz="0.019169" izz="0.0091170"/>
    </inertial>
  </link>
  <joint name="panda_left_joint1" type="revolute">
    <safety_controller k_position="100.0" k_velocity="40.0" soft_lower_limit="-2.8973" soft_upper_limit="2.8973"/>
    <origin rpy="0 0 0" xyz="0 0 0.333"/>
    <parent link="panda_left_link0"/>
    <child link="panda_left_link1"/>
    <axis xyz="0 0 1"/>
    <limit acceleration="15" effort="87" lower="-2.8973" upper="2.8973" velocity="2.1750"/>
    <dynamics D="1" K="7000" damping="0.003" friction="0.0" mu_coulomb="0" mu_viscous="16"/>
  </joint>
  <link name="panda_left_link2">
    <visual>
      <origin rpy="0 0 0" xyz="0 0 0"/>
      <geometry>
        <mesh filename="../meshes/franka/visual/link2.dae"/>
      </geometry>
    </visual>
    <collision>
      <origin rpy="0 0 0" xyz="0 0 0"/>
      <geometry>
        <mesh filename="../meshes/franka/collision/link2.stl"/>
      </geometry>
    </collision>
    <inertial>
      <origin rpy="0 0 0" xyz=" -0.003141 -0.02872  0.003495"/>
      <mass value="0.646926"/>
      <inertia ixx="0.0079620" ixy="-3.9250e-3" ixz="1.0254e-02" iyy="2.8110e-02" iyz="7.0400e-04" izz="2.5995e-02"/>
    </inertial>
  </link>
  <joint name="panda_left_joint2" type="revolute">
    <safety_controller k_position="100.0" k_velocity="40.0" soft_lower_limit="-1.7628" soft_upper_limit="1.7628"/>
    <origin rpy="-1.5707963267948966 0 0" xyz="0 0 0"/>
    <parent link="panda_left_link1"/>
    <child link="panda_left_link2"/>
    <axis xyz="0 0 1"/>
    <limit acceleration="7.5" effort="87" lower="-1.7628" upper="1.7628" velocity="2.1750"/>
    <dynamics D="1" K="7000" damping="0.003" friction="0.0" mu_coulomb="0" mu_viscous="16"/>
  </joint>
  <link name="panda_left_link3">
    <visual>
      <origin rpy="0 0 0" xyz="0 0 0"/>
      <geometry>
        <mesh filename="../meshes/franka/visual/link3.dae"/>
      </geometry>
    </visual>
    <collision>
      <origin rpy="0 0 0" xyz="0 0 0"/>
      <geometry>
        <mesh filename="../meshes/franka/collision/link3.stl"/>
      </geometry>
    </collision>
    <inertial>
      <origin rpy="0 0 0" xyz="2.7518e-02 3.9252e-02 -6.6502e-02"/>
      <mass value="3.228604"/>
      <inertia ixx="3.7242e-02" ixy="-4.7610e-03" ixz="-1.1396e-02" iyy="3.6155e-02" iyz="-1.2805e-02" izz="1.0830e-02"/>
    </inertial>
  </link>
  <joint name="panda_left_joint3" type="revolute">
    <safety_controller k_position="100.0" k_velocity="40.0" soft_lower_limit="-2.8973" soft_upper_limit="2.8973"/>
    <origin rpy="1.5707963267948966 0 0" xyz="0 -0.316 0"/>
    <parent link="panda_left_link2"/>
    <child link="panda_left_link3"/>
    <axis xyz="0 0 1"/>
    <limit acceleration="12.5" effort="87" lower="-2.8973" upper="2.8973" velocity="2.1750"/>
    <dynamics D="1" K="7000" damping="0.003" friction="0.0" mu_coulomb="0" mu_viscous="16"/>
  </joint>
  <link name="panda_left_link4">
    <visual>
      <origin rpy="0 0 0" xyz="0 0 0"/>
      <geometry>
        <mesh filename="../meshes/franka/visual/link4.dae"/>
      </geometry>
    </visual>
    <collision>
      <origin rpy="0 0 0" xyz="0 0 0"/>
      <geometry>
        <mesh filename="../meshes/franka/collision/link4.stl"/>
      </geometry>
    </collision>
    <inertial>
      <origin rpy="0 0 0" xyz="-5.317e-02 1.04419e-01 2.7454e-02"/>
      <mass value="3.587895"/>
      <inertia ixx="2.5853e-02" ixy="7.7960e-03" ixz="-1.3320e-03" iyy="1.9552e-02" iyz="8.6410e-03" izz="2.8323e-02"/>
    </inertial>
  </link>
  <joint name="panda_left_joint4" type="revolute">
    <safety_controller k_position="100.0" k_velocity="40.0" soft_lower_limit="-3.0718" soft_upper_limit="-0.0698"/>
    <origin rpy="1.5707963267948966 0 0" xyz="0.0825 0 0"/>
    <parent link="panda_left_link3"/>
    <child link="panda_left_link4"/>
    <axis xyz="0 0 1"/>
    <limit acceleration="12.5" effort="87" lower="-3.0718" upper="-0.0698" velocity="2.1750"/>
    <dynamics D="1" K="7000" damping="0.003" friction="0.0" mu_coulomb="0" mu_viscous="16"/>
  </joint>
  <link name="panda_left_link5">
    <visual>
      <origin rpy="0 0 0" xyz="0 0 0"/>
      <geometry>
        <mesh filename="../meshes/franka/visual/link5.dae"/>
      </geometry>
    </visual>
    <collision>
      <origin rpy="0 0 0" xyz="0 0 0"/>
      <geometry>
        <mesh filename="../meshes/franka/collision/link5.stl"/>
      </geometry>
    </collision>
    <inertial>
      <origin rpy="0 0 0" xyz="-1.1953e-02 4.1065e-02 -3.8437e-02"/>
      <mass value="1.225946"/>
      <inertia ixx="3.5549e-02" ixy="-2.1170e-03" ixz="-4.0370e-03" iyy="2.9474e-02" iyz="2.2900e-04" izz="8.6270e-03"/>
    </inertial>
  </link>
  <joint name="panda_left_joint5" type="revolute">
    <safety_controller k_position="100.0" k_velocity="40.0" soft_lower_limit="-2.8973" soft_upper_limit="2.8973"/>
    <origin rpy="-1.5707963267948966 0 0" xyz="-0.0825 0.384 0"/>
    <parent link="panda_left_link4"/>
    <child link="panda_left_link5"/>
    <axis xyz="0 0 1"/>
    <limit acceleration="15" effort="12" lower="-2.8973" upper="2.8973" velocity="2.6100"/>
    <dynamics D="1" K="7000" damping="0.003" friction="0.0" mu_coulomb="0" mu_viscous="16"/>
  </joint>
  <link name="panda_left_link6">
    <visual>
      <origin rpy="0 0 0" xyz="0 0 0"/>
      <geometry>
        <mesh filename="../meshes/franka/visual/link6.dae"/>
      </geometry>
    </visual>
    <collision>
      <origin rpy="0 0 0" xyz="0 0 0"/>
      <geometry>
        <mesh filename="../meshes/franka/collision/link6.stl"/>
      </geometry>
    </collision>
    <inertial>
      <origin rpy="0 0 0" xyz="6.0149e-02 -1.4117e-02 -1.0517e-02"/>
      <mass value="1.666555"/>
      <inertia ixx="1.9640e-03" ixy="1.0900e-04" ixz="-1.1580e-03" iyy="4.3540e-03" iyz="3.4100e-04" izz="5.4330e-03"/>
    </inertial>
  </link>
  <joint name="panda_left_joint6" type="revolute">
    <safety_controller k_position="100.0" k_velocity="40.0" soft_lower_limit="-0.0175" soft_upper_limit="3.7525"/>
    <origin rpy="1.5707963267948966 0 0" xyz="0 0 0"/>
    <parent link="panda_left_link5"/>
    <child link="panda_left_link6"/>
    <axis xyz="0 0 1"/>
    <limit acceleration="20" effort="12" lower="-0.0175" upper="3.7525" velocity="2.6100"/>
    <dynamics D="1" K="7000" damping="0.003" friction="0.0" mu_coulomb="0" mu_viscous="16"/>
  </joint>
  <link name="panda_left_link7">
    <visual>
      <origin rpy="0 0 0" xyz="0 0 0"/>
      <geometry>
        <mesh filename="../meshes/franka/visual/link7.dae"/>
      </geometry>
    </visual>
    <collision>
      <origin rpy="0 0 0" xyz="0 0 0"/>
      <geometry>
        <mesh filename="../meshes/franka/collision/link7.stl"/>
      </geometry>
    </collision>
    <inertial>
      <origin rpy="0 0 0" xyz="1.0517e-02 -4.252e-03 6.1597e-02"/>
      <mass value="7.35522e-01"/>
      <inertia ixx="1.2516e-02" ixy="-4.2800e-04" ixz="-1.1960e-03" iyy="1.0027e-02" iyz="-7.4100e-04" izz="4.8150e-03"/>
    </inertial>
  </link>
  <joint name="panda_left_joint7" type="revolute">
    <safety_controller k_position="100.0" k_velocity="40.0" soft_lower_limit="-2.8973" soft_upper_limit="2.8973"/>
    <origin rpy="1.5707963267948966 0 0" xyz="0.088 0 0"/>
    <parent link="panda_left_link6"/>
    <child link="panda_left_link7"/>
    <axis xyz="0 0 1"/>
    <limit acceleration="20" effort="12" lower="-2.8973" upper="2.8973" velocity="2.6100"/>
    <dynamics D="1" K="7000" damping="0.003" friction="0.0" mu_coulomb="0" mu_viscous="16"/>
  </joint>
  <joint name="panda_right_joint_torso_end" type="fixed">
    <parent link="torso_end"/>
    <child link="panda_right_link0"/>
    <origin rpy="1.5004311592913677 0.8772798703277918 0.2038499389018784" xyz="0.02842 -0.11216 0.19004"/>
  </joint>
  <link name="panda_right_link0">
    <visual>
      <origin rpy="0 0 0" xyz="0 0 0"/>
      <geometry>
        <mesh filename="../meshes/franka/visual/link0.dae"/>
      </geometry>
    </visual>
    <collision>
      <origin rpy="0 0 0" xyz="0 0 0"/>
      <geometry>
        <mesh filename="../meshes/franka/collision/link0.stl"/>
      </geometry>
    </collision>
    <inertial>
      <!-- Estimated guesses from CAD -->
      <origin rpy="0 0 0" xyz="-0.041018 -0.00014 0.049974"/>
      <mass value="0.629769"/>
      <inertia ixx="0.00315" ixy="8.2904E-07" ixz="0.00015" iyy="0.00388" iyz="8.2299E-06" izz="0.004285"/>
    </inertial>
  </link>
  <link name="panda_right_link1">
    <visual>
      <origin rpy="0 0 0" xyz="0 0 0"/>
      <geometry>
        <mesh filename="../meshes/franka/visual/link1.dae"/>
      </geometry>
    </visual>
    <collision>
      <origin rpy="0 0 0" xyz="0 0 0"/>
      <geometry>
        <mesh filename="../meshes/franka/collision/link1.stl"/>
      </geometry>
    </collision>
    <inertial>
      <origin rpy="0 0 0" xyz="0.003875 0.002081 -0.04762"/>
      <mass value="4.970684"/>
      <inertia ixx="0.70337" ixy="-0.00013900" ixz="0.0067720" iyy="0.70661" iyz="0.019169" izz="0.0091170"/>
    </inertial>
  </link>
  <joint name="panda_right_joint1" type="revolute">
    <safety_controller k_position="100.0" k_velocity="40.0" soft_lower_limit="-2.8973" soft_upper_limit="2.8973"/>
    <origin rpy="0 0 0" xyz="0 0 0.333"/>
    <parent link="panda_right_link0"/>
    <child link="panda_right_link1"/>
    <axis xyz="0 0 1"/>
    <limit acceleration="15" effort="87" lower="-2.8973" upper="2.8973" velocity="2.1750"/>
    <dynamics D="1" K="7000" damping="0.003" friction="0.0" mu_coulomb="0" mu_viscous="16"/>
  </joint>
  <link name="panda_right_link2">
    <visual>
      <origin rpy="0 0 0" xyz="0 0 0"/>
      <geometry>
        <mesh filename="../meshes/franka/visual/link2.dae"/>
      </geometry>
    </visual>
    <collision>
      <origin rpy="0 0 0" xyz="0 0 0"/>
      <geometry>
        <mesh filename="../meshes/franka/collision/link2.stl"/>
      </geometry>
    </collision>
    <inertial>
      <origin rpy="0 0 0" xyz=" -0.003141 -0.02872  0.003495"/>
      <mass value="0.646926"/>
      <inertia ixx="0.0079620" ixy="-3.9250e-3" ixz="1.0254e-02" iyy="2.8110e-02" iyz="7.0400e-04" izz="2.5995e-02"/>
    </inertial>
  </link>
  <joint name="panda_right_joint2" type="revolute">
    <safety_controller k_position="100.0" k_velocity="40.0" soft_lower_limit="-1.7628" soft_upper_limit="1.7628"/>
    <origin rpy="-1.5707963267948966 0 0" xyz="0 0 0"/>
    <parent link="panda_right_link1"/>
    <child link="panda_right_link2"/>
    <axis xyz="0 0 1"/>
    <limit acceleration="7.5" effort="87" lower="-1.7628" upper="1.7628" velocity="2.1750"/>
    <dynamics D="1" K="7000" damping="0.003" friction="0.0" mu_coulomb="0" mu_viscous="16"/>
  </joint>
  <link name="panda_right_link3">
    <visual>
      <origin rpy="0 0 0" xyz="0 0 0"/>
      <geometry>
        <mesh filename="../meshes/franka/visual/link3.dae"/>
      </geometry>
    </visual>
    <collision>
      <origin rpy="0 0 0" xyz="0 0 0"/>
      <geometry>
        <mesh filename="../meshes/franka/collision/link3.stl"/>
      </geometry>
    </collision>
    <inertial>
      <origin rpy="0 0 0" xyz="2.7518e-02 3.9252e-02 -6.6502e-02"/>
      <mass value="3.228604"/>
      <inertia ixx="3.7242e-02" ixy="-4.7610e-03" ixz="-1.1396e-02" iyy="3.6155e-02" iyz="-1.2805e-02" izz="1.0830e-02"/>
    </inertial>
  </link>
  <joint name="panda_right_joint3" type="revolute">
    <safety_controller k_position="100.0" k_velocity="40.0" soft_lower_limit="-2.8973" soft_upper_limit="2.8973"/>
    <origin rpy="1.5707963267948966 0 0" xyz="0 -0.316 0"/>
    <parent link="panda_right_link2"/>
    <child link="panda_right_link3"/>
    <axis xyz="0 0 1"/>
    <limit acceleration="12.5" effort="87" lower="-2.8973" upper="2.8973" velocity="2.1750"/>
    <dynamics D="1" K="7000" damping="0.003" friction="0.0" mu_coulomb="0" mu_viscous="16"/>
  </joint>
  <link name="panda_right_link4">
    <visual>
      <origin rpy="0 0 0" xyz="0 0 0"/>
      <geometry>
        <mesh filename="../meshes/franka/visual/link4.dae"/>
      </geometry>
    </visual>
    <collision>
      <origin rpy="0 0 0" xyz="0 0 0"/>
      <geometry>
        <mesh filename="../meshes/franka/collision/link4.stl"/>
      </geometry>
    </collision>
    <inertial>
      <origin rpy="0 0 0" xyz="-5.317e-02 1.04419e-01 2.7454e-02"/>
      <mass value="3.587895"/>
      <inertia ixx="2.5853e-02" ixy="7.7960e-03" ixz="-1.3320e-03" iyy="1.9552e-02" iyz="8.6410e-03" izz="2.8323e-02"/>
    </inertial>
  </link>
  <joint name="panda_right_joint4" type="revolute">
    <safety_controller k_position="100.0" k_velocity="40.0" soft_lower_limit="-3.0718" soft_upper_limit="-0.0698"/>
    <origin rpy="1.5707963267948966 0 0" xyz="0.0825 0 0"/>
    <parent link="panda_right_link3"/>
    <child link="panda_right_link4"/>
    <axis xyz="0 0 1"/>
    <limit acceleration="12.5" effort="87" lower="-3.0718" upper="-0.0698" velocity="2.1750"/>
    <dynamics D="1" K="7000" damping="0.003" friction="0.0" mu_coulomb="0" mu_viscous="16"/>
  </joint>
  <link name="panda_right_link5">
    <visual>
      <origin rpy="0 0 0" xyz="0 0 0"/>
      <geometry>
        <mesh filename="../meshes/franka/visual/link5.dae"/>
      </geometry>
    </visual>
    <collision>
      <origin rpy="0 0 0" xyz="0 0 0"/>
      <geometry>
        <mesh filename="../meshes/franka/collision/link5.stl"/>
      </geometry>
    </collision>
    <inertial>
      <origin rpy="0 0 0" xyz="-1.1953e-02 4.1065e-02 -3.8437e-02"/>
      <mass value="1.225946"/>
      <inertia ixx="3.5549e-02" ixy="-2.1170e-03" ixz="-4.0370e-03" iyy="2.9474e-02" iyz="2.2900e-04" izz="8.6270e-03"/>
    </inertial>
  </link>
  <joint name="panda_right_joint5" type="revolute">
    <safety_controller k_position="100.0" k_velocity="40.0" soft_lower_limit="-2.8973" soft_upper_limit="2.8973"/>
    <origin rpy="-1.5707963267948966 0 0" xyz="-0.0825 0.384 0"/>
    <parent link="panda_right_link4"/>
    <child link="panda_right_link5"/>
    <axis xyz="0 0 1"/>
    <limit acceleration="15" effort="12" lower="-2.8973" upper="2.8973" velocity="2.6100"/>
    <dynamics D="1" K="7000" damping="0.003" friction="0.0" mu_coulomb="0" mu_viscous="16"/>
  </joint>
  <link name="panda_right_link6">
    <visual>
      <origin rpy="0 0 0" xyz="0 0 0"/>
      <geometry>
        <mesh filename="../meshes/franka/visual/link6.dae"/>
      </geometry>
    </visual>
    <collision>
      <origin rpy="0 0 0" xyz="0 0 0"/>
      <geometry>
        <mesh filename="../meshes/franka/collision/link6.stl"/>
      </geometry>
    </collision>
    <inertial>
      <origin rpy="0 0 0" xyz="6.0149e-02 -1.4117e-02 -1.0517e-02"/>
      <mass value="1.666555"/>
      <inertia ixx="1.9640e-03" ixy="1.0900e-04" ixz="-1.1580e-03" iyy="4.3540e-03" iyz="3.4100e-04" izz="5.4330e-03"/>
    </inertial>
  </link>
  <joint name="panda_right_joint6" type="revolute">
    <safety_controller k_position="100.0" k_velocity="40.0" soft_lower_limit="-0.0175" soft_upper_limit="3.7525"/>
    <origin rpy="1.5707963267948966 0 0" xyz="0 0 0"/>
    <parent link="panda_right_link5"/>
    <child link="panda_right_link6"/>
    <axis xyz="0 0 1"/>
    <limit acceleration="20" effort="12" lower="-0.0175" upper="3.7525" velocity="2.6100"/>
    <dynamics D="1" K="7000" damping="0.003" friction="0.0" mu_coulomb="0" mu_viscous="16"/>
  </joint>
  <link name="panda_right_link7">
    <visual>
      <origin rpy="0 0 0" xyz="0 0 0"/>
      <geometry>
        <mesh filename="../meshes/franka/visual/link7.dae"/>
      </geometry>
    </visual>
    <collision>
      <origin rpy="0 0 0" xyz="0 0 0"/>
      <geometry>
        <mesh filename="../meshes/franka/collision/link7.stl"/>
      </geometry>
    </collision>
    <inertial>
      <origin rpy="0 0 0" xyz="1.0517e-02 -4.252e-03 6.1597e-02"/>
      <mass value="7.35522e-01"/>
      <inertia ixx="1.2516e-02" ixy="-4.2800e-04" ixz="-1.1960e-03" iyy="1.0027e-02" iyz="-7.4100e-04" izz="4.8150e-03"/>
    </inertial>
  </link>
  <joint name="panda_right_joint7" type="revolute">
    <safety_controller k_position="100.0" k_velocity="40.0" soft_lower_limit="-2.8973" soft_upper_limit="2.8973"/>
    <origin rpy="1.5707963267948966 0 0" xyz="0.088 0 0"/>
    <parent link="panda_right_link6"/>
    <child link="panda_right_link7"/>
    <axis xyz="0 0 1"/>
    <limit acceleration="20" effort="12" lower="-2.8973" upper="2.8973" velocity="2.6100"/>
    <dynamics D="1" K="7000" damping="0.003" friction="0.0" mu_coulomb="0" mu_viscous="16"/>
  </joint>
  <joint name="panda_left_hand_joint" type="fixed">
    <parent link="panda_left_link7"/>
    <child link="panda_left_hand"/>
    <origin rpy="0 0 -0.7853981633974483" xyz="0 0 0.107"/>
  </joint>
  <link name="panda_left_hand">
    <visual>
      <geometry>
        <mesh filename="../meshes/franka/visual/hand.dae"/>
      </geometry>
    </visual>
    <collision>
      <geometry>
        <mesh filename="../meshes/franka/collision/hand.stl"/>
      </geometry>
    </collision>
    <inertial>
      <mass value="0.73"/>
      <origin xyz="-0.01 0 0.03"/>
      <inertia ixx="0.001" ixy="0" ixz="0" iyy="0.0025" iyz="0" izz="0.0017"/>
    </inertial>
  </link>
  <link name="panda_left_leftfinger">
    <inertial>
      <mass value="0.015"/>
      <inertia ixx="2.3749999999999997e-06" ixy="0" ixz="0" iyy="2.3749999999999997e-06" iyz="0" izz="7.5e-07"/>
    </inertial>
    <visual>
      <geometry>
        <mesh filename="../meshes/franka/visual/finger.dae"/>
      </geometry>
    </visual>
    <!-- screw mount -->
    <collision>
      <origin rpy="0 0 0" xyz="0 +18.5e-3 11e-3"/>
      <geometry>
        <box size="22e-3 15e-3 20e-3"/>
      </geometry>
    </collision>
    <!-- cartriage sledge -->
    <collision>
      <origin rpy="0 0 0" xyz="0 +6.8e-3 2.2e-3"/>
      <geometry>
        <box size="22e-3 8.8e-3 3.8e-3"/>
      </geometry>
    </collision>
    <!-- diagonal finger -->
    <collision>
      <origin rpy="+0.5235987755982988 0 0" xyz="0 +15.9e-3 28.35e-3"/>
      <geometry>
        <box size="17.5e-3 7e-3 23.5e-3"/>
      </geometry>
    </collision>
    <!-- rubber tip with which to grasp -->
    <collision>
      <origin rpy="0 0 0" xyz="0 +7.58e-3 45.25e-3"/>
      <geometry>
        <box size="17.5e-3 15.2e-3 18.5e-3"/>
      </geometry>
    </collision>
  </link>
  <link name="panda_left_rightfinger">
    <inertial>
      <mass value="0.015"/>
      <inertia ixx="2.3749999999999997e-06" ixy="0" ixz="0" iyy="2.3749999999999997e-06" iyz="0" izz="7.5e-07"/>
    </inertial>
    <visual>
      <origin rpy="0 0 3.141592653589793" xyz="0 0 0"/>
      <geometry>
        <mesh filename="../meshes/franka/visual/finger.dae"/>
      </geometry>
    </visual>
    <!-- screw mount -->
    <collision>
      <origin rpy="0 0 0" xyz="0 -18.5e-3 11e-3"/>
      <geometry>
        <box size="22e-3 15e-3 20e-3"/>
      </geometry>
    </collision>
    <!-- cartriage sledge -->
    <collision>
      <origin rpy="0 0 0" xyz="0 -6.8e-3 2.2e-3"/>
      <geometry>
        <box size="22e-3 8.8e-3 3.8e-3"/>
      </geometry>
    </collision>
    <!-- diagonal finger -->
    <collision>
      <origin rpy="-0.5235987755982988 0 0" xyz="0 -15.9e-3 28.35e-3"/>
      <geometry>
        <box size="17.5e-3 7e-3 23.5e-3"/>
      </geometry>
    </collision>
    <!-- rubber tip with which to grasp -->
    <collision>
      <origin rpy="0 0 0" xyz="0 -7.58e-3 45.25e-3"/>
      <geometry>
        <box size="17.5e-3 15.2e-3 18.5e-3"/>
      </geometry>
    </collision>
  </link>
  <joint name="panda_left_finger_joint1" type="prismatic">
    <parent link="panda_left_hand"/>
    <child link="panda_left_leftfinger"/>
    <origin rpy="0 0 0" xyz="0 0 0.0584"/>
    <axis xyz="0 1 0"/>
    <limit effort="100" lower="0.0" upper="0.04" velocity="0.2"/>
    <dynamics damping="0.03" friction="0.0"/>
  </joint>
  <joint name="panda_left_finger_joint2" type="prismatic">
    <parent link="panda_left_hand"/>
    <child link="panda_left_rightfinger"/>
    <origin rpy="0 0 0" xyz="0 0 0.0584"/>
    <axis xyz="0 -1 0"/>
    <limit effort="100" lower="0.0" upper="0.04" velocity="0.2"/>
    <dynamics damping="0.03" friction="0.0"/>
    <mimic joint="panda_left_finger_joint1"/>
  </joint>
  <joint name="panda_right_hand_joint" type="fixed">
    <parent link="panda_right_link7"/>
    <child link="panda_right_hand"/>
    <origin rpy="0 0 -0.7853981633974483" xyz="0 0 0.107"/>
  </joint>
  <link name="panda_right_hand">
    <visual>
      <geometry>
        <mesh filename="../meshes/franka/visual/hand.dae"/>
      </geometry>
    </visual>
    <collision>
      <geometry>
        <mesh filename="../meshes/franka/collision/hand.stl"/>
      </geometry>
    </collision>
    <inertial>
      <mass value="0.73"/>
      <origin xyz="-0.01 0 0.03"/>
      <inertia ixx="0.001" ixy="0" ixz="0" iyy="0.0025" iyz="0" izz="0.0017"/>
    </inertial>
  </link>
  <link name="panda_right_leftfinger">
    <inertial>
      <mass value="0.015"/>
      <inertia ixx="2.3749999999999997e-06" ixy="0" ixz="0" iyy="2.3749999999999997e-06" iyz="0" izz="7.5e-07"/>
    </inertial>
    <visual>
      <geometry>
        <mesh filename="../meshes/franka/visual/finger.dae"/>
      </geometry>
    </visual>
    <!-- screw mount -->
    <collision>
      <origin rpy="0 0 0" xyz="0 +18.5e-3 11e-3"/>
      <geometry>
        <box size="22e-3 15e-3 20e-3"/>
      </geometry>
    </collision>
    <!-- cartriage sledge -->
    <collision>
      <origin rpy="0 0 0" xyz="0 +6.8e-3 2.2e-3"/>
      <geometry>
        <box size="22e-3 8.8e-3 3.8e-3"/>
      </geometry>
    </collision>
    <!-- diagonal finger -->
    <collision>
      <origin rpy="+0.5235987755982988 0 0" xyz="0 +15.9e-3 28.35e-3"/>
      <geometry>
        <box size="17.5e-3 7e-3 23.5e-3"/>
      </geometry>
    </collision>
    <!-- rubber tip with which to grasp -->
    <collision>
      <origin rpy="0 0 0" xyz="0 +7.58e-3 45.25e-3"/>
      <geometry>
        <box size="17.5e-3 15.2e-3 18.5e-3"/>
      </geometry>
    </collision>
  </link>
  <link name="panda_right_rightfinger">
    <inertial>
      <mass value="0.015"/>
      <inertia ixx="2.3749999999999997e-06" ixy="0" ixz="0" iyy="2.3749999999999997e-06" iyz="0" izz="7.5e-07"/>
    </inertial>
    <visual>
      <origin rpy="0 0 3.141592653589793" xyz="0 0 0"/>
      <geometry>
        <mesh filename="../meshes/franka/visual/finger.dae"/>
      </geometry>
    </visual>
    <!-- screw mount -->
    <collision>
      <origin rpy="0 0 0" xyz="0 -18.5e-3 11e-3"/>
      <geometry>
        <box size="22e-3 15e-3 20e-3"/>
      </geometry>
    </collision>
    <!-- cartriage sledge -->
    <collision>
      <origin rpy="0 0 0" xyz="0 -6.8e-3 2.2e-3"/>
      <geometry>
        <box size="22e-3 8.8e-3 3.8e-3"/>
      </geometry>
    </collision>
    <!-- diagonal finger -->
    <collision>
      <origin rpy="-0.5235987755982988 0 0" xyz="0 -15.9e-3 28.35e-3"/>
      <geometry>
        <box size="17.5e-3 7e-3 23.5e-3"/>
      </geometry>
    </collision>
    <!-- rubber tip with which to grasp -->
    <collision>
      <origin rpy="0 0 0" xyz="0 -7.58e-3 45.25e-3"/>
      <geometry>
        <box size="17.5e-3 15.2e-3 18.5e-3"/>
      </geometry>
    </collision>
  </link>
  <joint name="panda_right_finger_joint1" type="prismatic">
    <parent link="panda_right_hand"/>
    <child link="panda_right_leftfinger"/>
    <origin rpy="0 0 0" xyz="0 0 0.0584"/>
    <axis xyz="0 1 0"/>
    <limit effort="100" lower="0.0" upper="0.04" velocity="0.2"/>
    <dynamics damping="0.03" friction="0.0"/>
  </joint>
  <joint name="panda_right_finger_joint2" type="prismatic">
    <parent link="panda_right_hand"/>
    <child link="panda_right_rightfinger"/>
    <origin rpy="0 0 0" xyz="0 0 0.0584"/>
    <axis xyz="0 -1 0"/>
    <limit effort="100" lower="0.0" upper="0.04" velocity="0.2"/>
    <dynamics damping="0.03" friction="0.0"/>
    <mimic joint="panda_right_finger_joint1"/>
  </joint>
</robot>

