<?xml version="1.0" ?>
<!-- =================================================================================== -->
<!-- |    This document was autogenerated by xacro from qbhand.urdf.xacro              | -->
<!-- |    EDITING THIS FILE BY HAND IS NOT RECOMMENDED                                 | -->
<!-- =================================================================================== -->
<robot name="qbhand">
   <mujoco>
        <compiler
        meshdir="../meshes/qbhand"
        balanceinertia="true"
        discardvisual="false" />
   </mujoco>
  <material name="qbhand/optional">
    <color rgba="0.0 0.5 0.8 1.0"/>
  </material>
  <material name="qbhand/base">
    <color rgba="0.35 0.35 0.35 1.0"/>
  </material>
  <material name="qbhand/palm">
    <color rgba="0.35 0.35 0.35 1.0"/>
  </material>
  <material name="qbhand/knuckle">
    <color rgba="0.35 0.35 0.35 1.0"/>
  </material>
  <material name="qbhand/proximal">
    <color rgba="0.35 0.35 0.35 1.0"/>
  </material>
  <material name="qbhand/middle">
    <color rgba="0.35 0.35 0.35 1.0"/>
  </material>
  <material name="qbhand/distal">
    <color rgba="0.35 0.35 0.35 1.0"/>
  </material>
  <material name="qbhand/default">
    <color rgba="0.35 0.35 0.35 1.0"/>
  </material>
  <link name="root_link"/>
  <joint name="qbhand_base_fixed_joint" type="fixed">
    <origin rpy="0 0 0" xyz="0 0 0"/>
    <parent link="root_link"/>
    <child link="qbhand_base_link"/>
  </joint>
  <link name="qbhand_base_link">
    <inertial>
      <mass value="0.205"/>
      <origin rpy="0 0 0" xyz="0.0 7.8738498e-04 1.5878899e-02"/>
      <inertia ixx="0.00012506929" ixy="0.0" ixz="0.0" iyy="0.0001338779" iyz="0.0" izz="0.00019218394"/>
    </inertial>
    <visual>
      <origin rpy="0 0 0" xyz="0 0 0"/>
      <geometry>
        <mesh filename="../meshes/qbhand/flange_iso_04.stl" scale="0.001 0.001 0.001"/>
      </geometry>
      <material name="qbhand/base"/>
    </visual>
    <collision>
      <origin rpy="0 0 0" xyz="0 0 0"/>
      <geometry>
        <mesh filename="../meshes/qbhand/flange_iso_04.stl" scale="0.001 0.001 0.001"/>
      </geometry>
    </collision>
  </link>
  <gazebo reference="qbhand_base_link">
    <self_collide>1</self_collide>
    <!-- TODO: add other Gazebo Link properties (http://sdformat.org/spec?elem=link) -->
    <!--      <collision>-->
    <!--        <surface>-->
    <!--          <contact>-->
    <!--            <ode>-->
    <!--              <kp>1.0</kp>-->
    <!--              <kd>0.01</kd>-->
    <!--              <max_vel>0.0</max_vel>-->
    <!--              <min_depth>0.001</min_depth>-->
    <!--            </ode>-->
    <!--          </contact>-->
    <!--          <friction>-->
    <!--            <ode>-->
    <!--              <mu>0.9</mu>-->
    <!--              <mu2>0.9</mu2>-->
    <!--            </ode>-->
    <!--          </friction>-->
    <!--        </surface>-->
    <!--      </collision>-->
  </gazebo>
  <joint name="qbhand_palm_fixed_joint" type="fixed">
    <origin rpy="1.57 0 3.14" xyz="0.0045 0.0145 0.144"/>
    <parent link="qbhand_base_link"/>
    <child link="qbhand_palm_link"/>
  </joint>
  <link name="qbhand_palm_link">
    <inertial>
      <mass value="0.45"/>
      <origin rpy="0 0 0" xyz="0.0030 -0.0449 -0.0135"/>
      <inertia ixx="0.00045" ixy="0.0" ixz="0.0" iyy="0.0006" iyz="0.0" izz="0.00025"/>
    </inertial>
    <visual>
      <origin rpy="0 0 0" xyz="0 0 0"/>
      <geometry>
        <mesh filename="../meshes/qbhand/palm_pinch_l.stl" scale="0.001 0.001 0.001"/>
      </geometry>
      <material name="qbhand/palm"/>
    </visual>
    <collision>
      <origin rpy="0 0 0" xyz="0 0 0"/>
      <geometry>
        <mesh filename="../meshes/qbhand/palm_pinch_l.stl" scale="0.001 0.001 0.001"/>
      </geometry>
    </collision>
  </link>
  <gazebo reference="qbhand_palm_link">
    <self_collide>1</self_collide>
    <!-- TODO: add other Gazebo Link properties (http://sdformat.org/spec?elem=link) -->
    <!--      <collision>-->
    <!--        <surface>-->
    <!--          <contact>-->
    <!--            <ode>-->
    <!--              <kp>1.0</kp>-->
    <!--              <kd>0.01</kd>-->
    <!--              <max_vel>0.0</max_vel>-->
    <!--              <min_depth>0.001</min_depth>-->
    <!--            </ode>-->
    <!--          </contact>-->
    <!--          <friction>-->
    <!--            <ode>-->
    <!--              <mu>0.9</mu>-->
    <!--              <mu2>0.9</mu2>-->
    <!--            </ode>-->
    <!--          </friction>-->
    <!--        </surface>-->
    <!--      </collision>-->
  </gazebo>
  <joint name="qbhand_synergy_joint" type="revolute">
    <origin rpy="0 0 0" xyz="0 0 0"/>
    <parent link="qbhand_palm_link"/>
    <child link="qbhand_synergy_tendon_virtual_link"/>
    <axis xyz="0 0 1"/>
    <dynamics damping="0.0" friction="0.0"/>
    <limit effort="100" lower="0.0" upper="1.0" velocity="100"/>
  </joint>
  <transmission name="qbhand_synergy_transmission">
    <type>transmission_interface/qbMoveTransmission</type>
    <joint name="qbhand_synergy_joint">
      <hardwareInterface>hardware_interface/EffortJointInterface</hardwareInterface>
    </joint>
    <actuator name="qbhand_synergy_joint">
      <hardwareInterface>hardware_interface/EffortJointInterface</hardwareInterface>
    </actuator>
  </transmission>
  <link name="qbhand_synergy_tendon_virtual_link">
    <inertial>
      <origin rpy="0 0 0" xyz="0 0 0"/>
      <mass value="1e-4"/>
      <inertia ixx="1e-9" ixy="0.0" ixz="0.0" iyy="1e-9" iyz="0.0" izz="1e-9"/>
    </inertial>
  </link>
  <joint name="qbhand_thumb_knuckle_joint" type="revolute">
    <origin rpy="-1.57 3.14 0.0" xyz="-0.044 -0.0465 0.002"/>
    <parent link="qbhand_palm_link"/>
    <child link="qbhand_thumb_knuckle_link"/>
    <axis xyz="0 0 -1"/>
    <dynamics damping="0.0" friction="0.0"/>
    <limit effort="100" lower="0.0" upper="1.571" velocity="100"/>
    <mimic joint="qbhand_synergy_joint" multiplier="2.542"/>
  </joint>
  <transmission name="qbhand_transmission">
    <type>transmission_interface/qbMoveTransmission</type>
    <joint name="qbhand_thumb_knuckle_joint">
      <hardwareInterface>hardware_interface/EffortJointInterface</hardwareInterface>
    </joint>
    <actuator name="qbhand_thumb_knuckle_joint">
      <hardwareInterface>hardware_interface/EffortJointInterface</hardwareInterface>
    </actuator>
  </transmission>
  <gazebo reference="qbhand_thumb_knuckle_joint">
    <!-- TODO: add other Gazebo Joint properties (http://sdformat.org/spec?elem=joint) -->
  </gazebo>
  <link name="qbhand_thumb_knuckle_link">
    <inertial>
      <mass value="0.01"/>
      <origin rpy="0 0 0" xyz="1.3071561e-02 2.7346340e-03 6.4090487e-04"/>
      <inertia ixx="3.5827953e-07" ixy="-2.0934657e-07" ixz="-6.8435459e-08" iyy="1.3882698e-06" iyz="-3.2001578e-08" izz="1.3570267e-06"/>
    </inertial>
    <visual>
      <origin rpy="0 0 0" xyz="0 0 0"/>
      <geometry>
        <mesh filename="../meshes/qbhand/ph_thumb_l.stl" scale="0.001 0.001 0.001"/>
      </geometry>
      <material name="qbhand/knuckle"/>
    </visual>
    <collision>
      <origin rpy="0 0 0" xyz="0 0 0"/>
      <geometry>
        <mesh filename="../meshes/qbhand/ph_thumb_l_collision.stl" scale="0.001 0.001 0.001"/>
      </geometry>
    </collision>
  </link>
  <gazebo reference="qbhand_thumb_knuckle_link">
    <self_collide>1</self_collide>
    <!-- TODO: add other Gazebo Link properties (http://sdformat.org/spec?elem=link) -->
    <!--      <collision>-->
    <!--        <surface>-->
    <!--          <contact>-->
    <!--            <ode>-->
    <!--              <kp>1.0</kp>-->
    <!--              <kd>0.01</kd>-->
    <!--              <max_vel>0.0</max_vel>-->
    <!--              <min_depth>0.001</min_depth>-->
    <!--            </ode>-->
    <!--          </contact>-->
    <!--          <friction>-->
    <!--            <ode>-->
    <!--              <mu>0.9</mu>-->
    <!--              <mu2>0.9</mu2>-->
    <!--            </ode>-->
    <!--          </friction>-->
    <!--        </surface>-->
    <!--      </collision>-->
  </gazebo>
  <joint name="qbhand_thumb_proximal_joint" type="revolute">
    <origin rpy="-2.0 0.0 0.0" xyz="0.0255 0.0038 -0.00012"/>
    <parent link="qbhand_thumb_knuckle_link"/>
    <child link="qbhand_thumb_proximal_virtual_link"/>
    <axis xyz="0 0 -1"/>
    <dynamics damping="0.0" friction="0.0"/>
    <limit effort="100" lower="0.0" upper="0.785" velocity="100"/>
    <mimic joint="qbhand_synergy_joint" multiplier="0.785"/>
  </joint>
  <transmission name="qbhand_transmission">
    <type>transmission_interface/qbMoveTransmission</type>
    <joint name="qbhand_thumb_proximal_joint">
      <hardwareInterface>hardware_interface/EffortJointInterface</hardwareInterface>
    </joint>
    <actuator name="qbhand_thumb_proximal_joint">
      <hardwareInterface>hardware_interface/EffortJointInterface</hardwareInterface>
    </actuator>
  </transmission>
  <gazebo reference="qbhand_thumb_proximal_joint">
    <!-- TODO: add other Gazebo Joint properties (http://sdformat.org/spec?elem=joint) -->
  </gazebo>
  <link name="qbhand_thumb_proximal_virtual_link">
    <inertial>
      <origin rpy="0 0 0" xyz="0 0 0"/>
      <mass value="1e-4"/>
      <inertia ixx="1e-9" ixy="0.0" ixz="0.0" iyy="1e-9" iyz="0.0" izz="1e-9"/>
    </inertial>
  </link>
  <joint name="qbhand_thumb_proximal_virtual_joint" type="revolute">
    <origin rpy="0 0 0" xyz="0.013 0 0"/>
    <parent link="qbhand_thumb_proximal_virtual_link"/>
    <child link="qbhand_thumb_proximal_link"/>
    <axis xyz="0 0 -1"/>
    <dynamics damping="0.0" friction="0.0"/>
    <limit effort="100" lower="0.0" upper="0.785" velocity="100"/>
    <mimic joint="qbhand_thumb_proximal_joint" multiplier="1.0"/>
  </joint>
  <transmission name="qbhand_transmission">
    <type>transmission_interface/qbMoveTransmission</type>
    <joint name="qbhand_thumb_proximal_virtual_joint">
      <hardwareInterface>hardware_interface/EffortJointInterface</hardwareInterface>
    </joint>
    <actuator name="qbhand_thumb_proximal_virtual_joint">
      <hardwareInterface>hardware_interface/EffortJointInterface</hardwareInterface>
    </actuator>
  </transmission>
  <gazebo reference="qbhand_thumb_proximal_virtual_joint">
    <!-- TODO: add other Gazebo Joint properties (http://sdformat.org/spec?elem=joint) -->
  </gazebo>
  <link name="qbhand_thumb_proximal_link">
    <inertial>
      <mass value="0.0063"/>
      <origin rpy="0 0 0" xyz="4.7601567e-03 -1.3786947e-03 0.0"/>
      <inertia ixx="1.8024201e-07" ixy="5.756798e-09" ixz="0.0" iyy="2.3516266e-07" iyz="0.0" izz="2.691504e-07"/>
    </inertial>
    <visual>
      <origin rpy="0 0 0" xyz="0 0 0"/>
      <geometry>
        <mesh filename="../meshes/qbhand/ph_short.stl" scale="0.001 0.001 0.001"/>
      </geometry>
      <material name="qbhand/proximal"/>
    </visual>
    <collision>
      <origin rpy="0 0 0" xyz="0 0 0"/>
      <geometry>
        <mesh filename="../meshes/qbhand/ph_short_collision.stl" scale="0.001 0.001 0.001"/>
      </geometry>
    </collision>
  </link>
  <gazebo reference="qbhand_thumb_proximal_link">
    <self_collide>1</self_collide>
    <!-- TODO: add other Gazebo Link properties (http://sdformat.org/spec?elem=link) -->
    <!--      <collision>-->
    <!--        <surface>-->
    <!--          <contact>-->
    <!--            <ode>-->
    <!--              <kp>1.0</kp>-->
    <!--              <kd>0.01</kd>-->
    <!--              <max_vel>0.0</max_vel>-->
    <!--              <min_depth>0.001</min_depth>-->
    <!--            </ode>-->
    <!--          </contact>-->
    <!--          <friction>-->
    <!--            <ode>-->
    <!--              <mu>0.9</mu>-->
    <!--              <mu2>0.9</mu2>-->
    <!--            </ode>-->
    <!--          </friction>-->
    <!--        </surface>-->
    <!--      </collision>-->
  </gazebo>
  <joint name="qbhand_thumb_distal_joint" type="revolute">
    <origin rpy="0 0 0" xyz="0.009 0 0"/>
    <parent link="qbhand_thumb_proximal_link"/>
    <child link="qbhand_thumb_distal_virtual_link"/>
    <axis xyz="0 0 -1"/>
    <dynamics damping="0.0" friction="0.0"/>
    <limit effort="100" lower="0.0" upper="0.785" velocity="100"/>
    <mimic joint="qbhand_synergy_joint" multiplier="0.785"/>
  </joint>
  <transmission name="qbhand_transmission">
    <type>transmission_interface/qbMoveTransmission</type>
    <joint name="qbhand_thumb_distal_joint">
      <hardwareInterface>hardware_interface/EffortJointInterface</hardwareInterface>
    </joint>
    <actuator name="qbhand_thumb_distal_joint">
      <hardwareInterface>hardware_interface/EffortJointInterface</hardwareInterface>
    </actuator>
  </transmission>
  <gazebo reference="qbhand_thumb_distal_joint">
    <!-- TODO: add other Gazebo Joint properties (http://sdformat.org/spec?elem=joint) -->
  </gazebo>
  <link name="qbhand_thumb_distal_virtual_link">
    <inertial>
      <origin rpy="0 0 0" xyz="0 0 0"/>
      <mass value="1e-4"/>
      <inertia ixx="1e-9" ixy="0.0" ixz="0.0" iyy="1e-9" iyz="0.0" izz="1e-9"/>
    </inertial>
  </link>
  <joint name="qbhand_thumb_distal_virtual_joint" type="revolute">
    <origin rpy="0 0 0" xyz="0.013 0 0"/>
    <parent link="qbhand_thumb_distal_virtual_link"/>
    <child link="qbhand_thumb_distal_link"/>
    <axis xyz="0 0 -1"/>
    <dynamics damping="0.0" friction="0.0"/>
    <limit effort="100" lower="0.0" upper="0.785" velocity="100"/>
    <mimic joint="qbhand_thumb_distal_joint" multiplier="1.0"/>
  </joint>
  <transmission name="qbhand_transmission">
    <type>transmission_interface/qbMoveTransmission</type>
    <joint name="qbhand_thumb_distal_virtual_joint">
      <hardwareInterface>hardware_interface/EffortJointInterface</hardwareInterface>
    </joint>
    <actuator name="qbhand_thumb_distal_virtual_joint">
      <hardwareInterface>hardware_interface/EffortJointInterface</hardwareInterface>
    </actuator>
  </transmission>
  <gazebo reference="qbhand_thumb_distal_virtual_joint">
    <!-- TODO: add other Gazebo Joint properties (http://sdformat.org/spec?elem=joint) -->
  </gazebo>
  <link name="qbhand_thumb_distal_link">
    <inertial>
      <mass value="0.009"/>
      <origin rpy="0 0 0" xyz="8.8025467e-03 -1.7219289e-03 0.0"/>
      <inertia ixx="2.6586142e-07" ixy="1.2416847e-08" ixz="0.0" iyy="5.9935767e-07" iyz="0.0" izz="6.6781963e-07"/>
    </inertial>
    <visual>
      <origin rpy="0 0 0" xyz="0 0 0"/>
      <geometry>
        <mesh filename="../meshes/qbhand/ph_distal.stl" scale="0.001 0.001 0.001"/>
      </geometry>
      <material name="qbhand/distal"/>
    </visual>
    <collision>
      <origin rpy="0 0 0" xyz="0 0 0"/>
      <geometry>
        <mesh filename="../meshes/qbhand/ph_distal_collision.stl" scale="0.001 0.001 0.001"/>
      </geometry>
    </collision>
  </link>
  <gazebo reference="qbhand_thumb_distal_link">
    <self_collide>1</self_collide>
    <!-- TODO: add other Gazebo Link properties (http://sdformat.org/spec?elem=link) -->
    <!--      <collision>-->
    <!--        <surface>-->
    <!--          <contact>-->
    <!--            <ode>-->
    <!--              <kp>1.0</kp>-->
    <!--              <kd>0.01</kd>-->
    <!--              <max_vel>0.0</max_vel>-->
    <!--              <min_depth>0.001</min_depth>-->
    <!--            </ode>-->
    <!--          </contact>-->
    <!--          <friction>-->
    <!--            <ode>-->
    <!--              <mu>0.9</mu>-->
    <!--              <mu2>0.9</mu2>-->
    <!--            </ode>-->
    <!--          </friction>-->
    <!--        </surface>-->
    <!--      </collision>-->
  </gazebo>
  <joint name="qbhand_index_knuckle_joint" type="revolute">
    <origin rpy="0 3.14 -1.57" xyz="-0.02 -0.007 -0.014"/>
    <parent link="qbhand_palm_link"/>
    <child link="qbhand_index_knuckle_link"/>
    <axis xyz="0 0 -1"/>
    <dynamics damping="0.0" friction="0.0"/>
    <limit effort="100" lower="-0.524" upper="0.524" velocity="100"/>
    <mimic joint="qbhand_synergy_joint" multiplier="0.2"/>
  </joint>
  <transmission name="qbhand_transmission">
    <type>transmission_interface/qbMoveTransmission</type>
    <joint name="qbhand_index_knuckle_joint">
      <hardwareInterface>hardware_interface/EffortJointInterface</hardwareInterface>
    </joint>
    <actuator name="qbhand_index_knuckle_joint">
      <hardwareInterface>hardware_interface/EffortJointInterface</hardwareInterface>
    </actuator>
  </transmission>
  <gazebo reference="qbhand_index_knuckle_joint">
    <!-- TODO: add other Gazebo Joint properties (http://sdformat.org/spec?elem=joint) -->
  </gazebo>
  <link name="qbhand_index_knuckle_link">
    <inertial>
      <mass value="0.0095"/>
      <origin rpy="0 0 0" xyz="4.2753603e-04  0.0 -1.4321738e-03"/>
      <inertia ixx="6.4337303e-07" ixy="0.0" ixz="-3.9373913e-08" iyy="1.1253771e-06" iyz="0.0" izz="7.2336948e-07"/>
    </inertial>
    <visual>
      <origin rpy="0 0 0" xyz="0 0 0"/>
      <geometry>
        <mesh filename="../meshes/qbhand/ph_knuckle.stl" scale="0.001 0.001 0.001"/>
      </geometry>
      <material name="qbhand/knuckle"/>
    </visual>
    <collision>
      <origin rpy="0 0 0" xyz="0 0 0"/>
      <geometry>
        <mesh filename="../meshes/qbhand/ph_knuckle_collision.stl" scale="0.001 0.001 0.001"/>
      </geometry>
    </collision>
  </link>
  <gazebo reference="qbhand_index_knuckle_link">
    <self_collide>1</self_collide>
    <!-- TODO: add other Gazebo Link properties (http://sdformat.org/spec?elem=link) -->
    <!--      <collision>-->
    <!--        <surface>-->
    <!--          <contact>-->
    <!--            <ode>-->
    <!--              <kp>1.0</kp>-->
    <!--              <kd>0.01</kd>-->
    <!--              <max_vel>0.0</max_vel>-->
    <!--              <min_depth>0.001</min_depth>-->
    <!--            </ode>-->
    <!--          </contact>-->
    <!--          <friction>-->
    <!--            <ode>-->
    <!--              <mu>0.9</mu>-->
    <!--              <mu2>0.9</mu2>-->
    <!--            </ode>-->
    <!--          </friction>-->
    <!--        </surface>-->
    <!--      </collision>-->
  </gazebo>
  <joint name="qbhand_index_proximal_joint" type="revolute">
    <origin rpy="1.57 0 0" xyz="0.009 0 0"/>
    <parent link="qbhand_index_knuckle_link"/>
    <child link="qbhand_index_proximal_virtual_link"/>
    <axis xyz="0 0 -1"/>
    <dynamics damping="0.0" friction="0.0"/>
    <limit effort="100" lower="0.0" upper="0.785" velocity="100"/>
    <mimic joint="qbhand_synergy_joint" multiplier="0.785"/>
  </joint>
  <transmission name="qbhand_transmission">
    <type>transmission_interface/qbMoveTransmission</type>
    <joint name="qbhand_index_proximal_joint">
      <hardwareInterface>hardware_interface/EffortJointInterface</hardwareInterface>
    </joint>
    <actuator name="qbhand_index_proximal_joint">
      <hardwareInterface>hardware_interface/EffortJointInterface</hardwareInterface>
    </actuator>
  </transmission>
  <gazebo reference="qbhand_index_proximal_joint">
    <!-- TODO: add other Gazebo Joint properties (http://sdformat.org/spec?elem=joint) -->
  </gazebo>
  <link name="qbhand_index_proximal_virtual_link">
    <inertial>
      <origin rpy="0 0 0" xyz="0 0 0"/>
      <mass value="1e-4"/>
      <inertia ixx="1e-9" ixy="0.0" ixz="0.0" iyy="1e-9" iyz="0.0" izz="1e-9"/>
    </inertial>
  </link>
  <joint name="qbhand_index_proximal_virtual_joint" type="revolute">
    <origin rpy="0 0 0" xyz="0.013 0 0"/>
    <parent link="qbhand_index_proximal_virtual_link"/>
    <child link="qbhand_index_proximal_link"/>
    <axis xyz="0 0 -1"/>
    <dynamics damping="0.0" friction="0.0"/>
    <limit effort="100" lower="0.0" upper="0.785" velocity="100"/>
    <mimic joint="qbhand_index_proximal_joint" multiplier="1.0"/>
  </joint>
  <transmission name="qbhand_transmission">
    <type>transmission_interface/qbMoveTransmission</type>
    <joint name="qbhand_index_proximal_virtual_joint">
      <hardwareInterface>hardware_interface/EffortJointInterface</hardwareInterface>
    </joint>
    <actuator name="qbhand_index_proximal_virtual_joint">
      <hardwareInterface>hardware_interface/EffortJointInterface</hardwareInterface>
    </actuator>
  </transmission>
  <gazebo reference="qbhand_index_proximal_virtual_joint">
    <!-- TODO: add other Gazebo Joint properties (http://sdformat.org/spec?elem=joint) -->
  </gazebo>
  <link name="qbhand_index_proximal_link">
    <inertial>
      <mass value="0.0082"/>
      <origin rpy="0 0 0" xyz="8.7707437e-03 -1.7863138e-03 0.0"/>
      <inertia ixx="2.2722068e-07" ixy="1.1586053e-08" ixz="0.0" iyy="5.5947233e-07" iyz="0.0" izz="5.9562195e-07"/>
    </inertial>
    <visual>
      <origin rpy="0 0 0" xyz="0 0 0"/>
      <geometry>
        <mesh filename="../meshes/qbhand/ph_medium.stl" scale="0.001 0.001 0.001"/>
      </geometry>
      <material name="qbhand/proximal"/>
    </visual>
    <collision>
      <origin rpy="0 0 0" xyz="0 0 0"/>
      <geometry>
        <mesh filename="../meshes/qbhand/ph_medium_collision.stl" scale="0.001 0.001 0.001"/>
      </geometry>
    </collision>
  </link>
  <gazebo reference="qbhand_index_proximal_link">
    <self_collide>1</self_collide>
    <!-- TODO: add other Gazebo Link properties (http://sdformat.org/spec?elem=link) -->
    <!--      <collision>-->
    <!--        <surface>-->
    <!--          <contact>-->
    <!--            <ode>-->
    <!--              <kp>1.0</kp>-->
    <!--              <kd>0.01</kd>-->
    <!--              <max_vel>0.0</max_vel>-->
    <!--              <min_depth>0.001</min_depth>-->
    <!--            </ode>-->
    <!--          </contact>-->
    <!--          <friction>-->
    <!--            <ode>-->
    <!--              <mu>0.9</mu>-->
    <!--              <mu2>0.9</mu2>-->
    <!--            </ode>-->
    <!--          </friction>-->
    <!--        </surface>-->
    <!--      </collision>-->
  </gazebo>
  <joint name="qbhand_index_middle_joint" type="revolute">
    <origin rpy="0 0 0" xyz="0.017 0 0"/>
    <parent link="qbhand_index_proximal_link"/>
    <child link="qbhand_index_middle_virtual_link"/>
    <axis xyz="0 0 -1"/>
    <dynamics damping="0.0" friction="0.0"/>
    <limit effort="100" lower="0.0" upper="0.785" velocity="100"/>
    <mimic joint="qbhand_synergy_joint" multiplier="0.785"/>
  </joint>
  <transmission name="qbhand_transmission">
    <type>transmission_interface/qbMoveTransmission</type>
    <joint name="qbhand_index_middle_joint">
      <hardwareInterface>hardware_interface/EffortJointInterface</hardwareInterface>
    </joint>
    <actuator name="qbhand_index_middle_joint">
      <hardwareInterface>hardware_interface/EffortJointInterface</hardwareInterface>
    </actuator>
  </transmission>
  <gazebo reference="qbhand_index_middle_joint">
    <!-- TODO: add other Gazebo Joint properties (http://sdformat.org/spec?elem=joint) -->
  </gazebo>
  <link name="qbhand_index_middle_virtual_link">
    <inertial>
      <origin rpy="0 0 0" xyz="0 0 0"/>
      <mass value="1e-4"/>
      <inertia ixx="1e-9" ixy="0.0" ixz="0.0" iyy="1e-9" iyz="0.0" izz="1e-9"/>
    </inertial>
  </link>
  <joint name="qbhand_index_middle_virtual_joint" type="revolute">
    <origin rpy="0 0 0" xyz="0.013 0 0"/>
    <parent link="qbhand_index_middle_virtual_link"/>
    <child link="qbhand_index_middle_link"/>
    <axis xyz="0 0 -1"/>
    <dynamics damping="0.0" friction="0.0"/>
    <limit effort="100" lower="0.0" upper="0.785" velocity="100"/>
    <mimic joint="qbhand_index_middle_joint" multiplier="1.0"/>
  </joint>
  <transmission name="qbhand_transmission">
    <type>transmission_interface/qbMoveTransmission</type>
    <joint name="qbhand_index_middle_virtual_joint">
      <hardwareInterface>hardware_interface/EffortJointInterface</hardwareInterface>
    </joint>
    <actuator name="qbhand_index_middle_virtual_joint">
      <hardwareInterface>hardware_interface/EffortJointInterface</hardwareInterface>
    </actuator>
  </transmission>
  <gazebo reference="qbhand_index_middle_virtual_joint">
    <!-- TODO: add other Gazebo Joint properties (http://sdformat.org/spec?elem=joint) -->
  </gazebo>
  <link name="qbhand_index_middle_link">
    <inertial>
      <mass value="0.0063"/>
      <origin rpy="0 0 0" xyz="4.7601567e-03 -1.3786947e-03 0.0"/>
      <inertia ixx="1.8024201e-07" ixy="5.756798e-09" ixz="0.0" iyy="2.3516266e-07" iyz="0.0" izz="2.691504e-07"/>
    </inertial>
    <visual>
      <origin rpy="0 0 0" xyz="0 0 0"/>
      <geometry>
        <mesh filename="../meshes/qbhand/ph_short.stl" scale="0.001 0.001 0.001"/>
      </geometry>
      <material name="qbhand/middle"/>
    </visual>
    <collision>
      <origin rpy="0 0 0" xyz="0 0 0"/>
      <geometry>
        <mesh filename="../meshes/qbhand/ph_short_collision.stl" scale="0.001 0.001 0.001"/>
      </geometry>
    </collision>
  </link>
  <gazebo reference="qbhand_index_middle_link">
    <self_collide>1</self_collide>
    <!-- TODO: add other Gazebo Link properties (http://sdformat.org/spec?elem=link) -->
    <!--      <collision>-->
    <!--        <surface>-->
    <!--          <contact>-->
    <!--            <ode>-->
    <!--              <kp>1.0</kp>-->
    <!--              <kd>0.01</kd>-->
    <!--              <max_vel>0.0</max_vel>-->
    <!--              <min_depth>0.001</min_depth>-->
    <!--            </ode>-->
    <!--          </contact>-->
    <!--          <friction>-->
    <!--            <ode>-->
    <!--              <mu>0.9</mu>-->
    <!--              <mu2>0.9</mu2>-->
    <!--            </ode>-->
    <!--          </friction>-->
    <!--        </surface>-->
    <!--      </collision>-->
  </gazebo>
  <joint name="qbhand_index_distal_joint" type="revolute">
    <origin rpy="0 0 0" xyz="0.009 0 0"/>
    <parent link="qbhand_index_middle_link"/>
    <child link="qbhand_index_distal_virtual_link"/>
    <axis xyz="0 0 -1"/>
    <dynamics damping="0.0" friction="0.0"/>
    <limit effort="100" lower="0.0" upper="0.785" velocity="100"/>
    <mimic joint="qbhand_synergy_joint" multiplier="0.785"/>
  </joint>
  <transmission name="qbhand_transmission">
    <type>transmission_interface/qbMoveTransmission</type>
    <joint name="qbhand_index_distal_joint">
      <hardwareInterface>hardware_interface/EffortJointInterface</hardwareInterface>
    </joint>
    <actuator name="qbhand_index_distal_joint">
      <hardwareInterface>hardware_interface/EffortJointInterface</hardwareInterface>
    </actuator>
  </transmission>
  <gazebo reference="qbhand_index_distal_joint">
    <!-- TODO: add other Gazebo Joint properties (http://sdformat.org/spec?elem=joint) -->
  </gazebo>
  <link name="qbhand_index_distal_virtual_link">
    <inertial>
      <origin rpy="0 0 0" xyz="0 0 0"/>
      <mass value="1e-4"/>
      <inertia ixx="1e-9" ixy="0.0" ixz="0.0" iyy="1e-9" iyz="0.0" izz="1e-9"/>
    </inertial>
  </link>
  <joint name="qbhand_index_distal_virtual_joint" type="revolute">
    <origin rpy="0 0 0" xyz="0.013 0 0"/>
    <parent link="qbhand_index_distal_virtual_link"/>
    <child link="qbhand_index_distal_link"/>
    <axis xyz="0 0 -1"/>
    <dynamics damping="0.0" friction="0.0"/>
    <limit effort="100" lower="0.0" upper="0.785" velocity="100"/>
    <mimic joint="qbhand_index_distal_joint" multiplier="1.0"/>
  </joint>
  <transmission name="qbhand_transmission">
    <type>transmission_interface/qbMoveTransmission</type>
    <joint name="qbhand_index_distal_virtual_joint">
      <hardwareInterface>hardware_interface/EffortJointInterface</hardwareInterface>
    </joint>
    <actuator name="qbhand_index_distal_virtual_joint">
      <hardwareInterface>hardware_interface/EffortJointInterface</hardwareInterface>
    </actuator>
  </transmission>
  <gazebo reference="qbhand_index_distal_virtual_joint">
    <!-- TODO: add other Gazebo Joint properties (http://sdformat.org/spec?elem=joint) -->
  </gazebo>
  <link name="qbhand_index_distal_link">
    <inertial>
      <mass value="0.009"/>
      <origin rpy="0 0 0" xyz="8.8025467e-03 -1.7219289e-03 0.0"/>
      <inertia ixx="2.6586142e-07" ixy="1.2416847e-08" ixz="0.0" iyy="5.9935767e-07" iyz="0.0" izz="6.6781963e-07"/>
    </inertial>
    <visual>
      <origin rpy="0 0 0" xyz="0 0 0"/>
      <geometry>
        <mesh filename="../meshes/qbhand/ph_distal.stl" scale="0.001 0.001 0.001"/>
      </geometry>
      <material name="qbhand/distal"/>
    </visual>
    <collision>
      <origin rpy="0 0 0" xyz="0 0 0"/>
      <geometry>
        <mesh filename="../meshes/qbhand/ph_distal_collision.stl" scale="0.001 0.001 0.001"/>
      </geometry>
    </collision>
  </link>
  <gazebo reference="qbhand_index_distal_link">
    <self_collide>1</self_collide>
    <!-- TODO: add other Gazebo Link properties (http://sdformat.org/spec?elem=link) -->
    <!--      <collision>-->
    <!--        <surface>-->
    <!--          <contact>-->
    <!--            <ode>-->
    <!--              <kp>1.0</kp>-->
    <!--              <kd>0.01</kd>-->
    <!--              <max_vel>0.0</max_vel>-->
    <!--              <min_depth>0.001</min_depth>-->
    <!--            </ode>-->
    <!--          </contact>-->
    <!--          <friction>-->
    <!--            <ode>-->
    <!--              <mu>0.9</mu>-->
    <!--              <mu2>0.9</mu2>-->
    <!--            </ode>-->
    <!--          </friction>-->
    <!--        </surface>-->
    <!--      </collision>-->
  </gazebo>
  <joint name="qbhand_middle_knuckle_joint" type="revolute">
    <origin rpy="0 3.14 -1.57" xyz="0 0 -0.014"/>
    <parent link="qbhand_palm_link"/>
    <child link="qbhand_middle_knuckle_link"/>
    <axis xyz="0 0 -1"/>
    <dynamics damping="0.0" friction="0.0"/>
    <limit effort="100" lower="-0.524" upper="0.524" velocity="100"/>
    <mimic joint="qbhand_synergy_joint" multiplier="0.0"/>
  </joint>
  <transmission name="qbhand_transmission">
    <type>transmission_interface/qbMoveTransmission</type>
    <joint name="qbhand_middle_knuckle_joint">
      <hardwareInterface>hardware_interface/EffortJointInterface</hardwareInterface>
    </joint>
    <actuator name="qbhand_middle_knuckle_joint">
      <hardwareInterface>hardware_interface/EffortJointInterface</hardwareInterface>
    </actuator>
  </transmission>
  <gazebo reference="qbhand_middle_knuckle_joint">
    <!-- TODO: add other Gazebo Joint properties (http://sdformat.org/spec?elem=joint) -->
  </gazebo>
  <link name="qbhand_middle_knuckle_link">
    <inertial>
      <mass value="0.0095"/>
      <origin rpy="0 0 0" xyz="4.2753603e-04  0.0 -1.4321738e-03"/>
      <inertia ixx="6.4337303e-07" ixy="0.0" ixz="-3.9373913e-08" iyy="1.1253771e-06" iyz="0.0" izz="7.2336948e-07"/>
    </inertial>
    <visual>
      <origin rpy="0 0 0" xyz="0 0 0"/>
      <geometry>
        <mesh filename="../meshes/qbhand/ph_knuckle.stl" scale="0.001 0.001 0.001"/>
      </geometry>
      <material name="qbhand/knuckle"/>
    </visual>
    <collision>
      <origin rpy="0 0 0" xyz="0 0 0"/>
      <geometry>
        <mesh filename="../meshes/qbhand/ph_knuckle_collision.stl" scale="0.001 0.001 0.001"/>
      </geometry>
    </collision>
  </link>
  <gazebo reference="qbhand_middle_knuckle_link">
    <self_collide>1</self_collide>
    <!-- TODO: add other Gazebo Link properties (http://sdformat.org/spec?elem=link) -->
    <!--      <collision>-->
    <!--        <surface>-->
    <!--          <contact>-->
    <!--            <ode>-->
    <!--              <kp>1.0</kp>-->
    <!--              <kd>0.01</kd>-->
    <!--              <max_vel>0.0</max_vel>-->
    <!--              <min_depth>0.001</min_depth>-->
    <!--            </ode>-->
    <!--          </contact>-->
    <!--          <friction>-->
    <!--            <ode>-->
    <!--              <mu>0.9</mu>-->
    <!--              <mu2>0.9</mu2>-->
    <!--            </ode>-->
    <!--          </friction>-->
    <!--        </surface>-->
    <!--      </collision>-->
  </gazebo>
  <joint name="qbhand_middle_proximal_joint" type="revolute">
    <origin rpy="1.57 0 0" xyz="0.009 0 0"/>
    <parent link="qbhand_middle_knuckle_link"/>
    <child link="qbhand_middle_proximal_virtual_link"/>
    <axis xyz="0 0 -1"/>
    <dynamics damping="0.0" friction="0.0"/>
    <limit effort="100" lower="0.0" upper="0.785" velocity="100"/>
    <mimic joint="qbhand_synergy_joint" multiplier="0.785"/>
  </joint>
  <transmission name="qbhand_transmission">
    <type>transmission_interface/qbMoveTransmission</type>
    <joint name="qbhand_middle_proximal_joint">
      <hardwareInterface>hardware_interface/EffortJointInterface</hardwareInterface>
    </joint>
    <actuator name="qbhand_middle_proximal_joint">
      <hardwareInterface>hardware_interface/EffortJointInterface</hardwareInterface>
    </actuator>
  </transmission>
  <gazebo reference="qbhand_middle_proximal_joint">
    <!-- TODO: add other Gazebo Joint properties (http://sdformat.org/spec?elem=joint) -->
  </gazebo>
  <link name="qbhand_middle_proximal_virtual_link">
    <inertial>
      <origin rpy="0 0 0" xyz="0 0 0"/>
      <mass value="1e-4"/>
      <inertia ixx="1e-9" ixy="0.0" ixz="0.0" iyy="1e-9" iyz="0.0" izz="1e-9"/>
    </inertial>
  </link>
  <joint name="qbhand_middle_proximal_virtual_joint" type="revolute">
    <origin rpy="0 0 0" xyz="0.013 0 0"/>
    <parent link="qbhand_middle_proximal_virtual_link"/>
    <child link="qbhand_middle_proximal_link"/>
    <axis xyz="0 0 -1"/>
    <dynamics damping="0.0" friction="0.0"/>
    <limit effort="100" lower="0.0" upper="0.785" velocity="100"/>
    <mimic joint="qbhand_middle_proximal_joint" multiplier="1.0"/>
  </joint>
  <transmission name="qbhand_transmission">
    <type>transmission_interface/qbMoveTransmission</type>
    <joint name="qbhand_middle_proximal_virtual_joint">
      <hardwareInterface>hardware_interface/EffortJointInterface</hardwareInterface>
    </joint>
    <actuator name="qbhand_middle_proximal_virtual_joint">
      <hardwareInterface>hardware_interface/EffortJointInterface</hardwareInterface>
    </actuator>
  </transmission>
  <gazebo reference="qbhand_middle_proximal_virtual_joint">
    <!-- TODO: add other Gazebo Joint properties (http://sdformat.org/spec?elem=joint) -->
  </gazebo>
  <link name="qbhand_middle_proximal_link">
    <inertial>
      <mass value="0.0082"/>
      <origin rpy="0 0 0" xyz="8.7707437e-03 -1.7863138e-03 0.0"/>
      <inertia ixx="2.2722068e-07" ixy="1.1586053e-08" ixz="0.0" iyy="5.5947233e-07" iyz="0.0" izz="5.9562195e-07"/>
    </inertial>
    <visual>
      <origin rpy="0 0 0" xyz="0 0 0"/>
      <geometry>
        <mesh filename="../meshes/qbhand/ph_medium.stl" scale="0.001 0.001 0.001"/>
      </geometry>
      <material name="qbhand/proximal"/>
    </visual>
    <collision>
      <origin rpy="0 0 0" xyz="0 0 0"/>
      <geometry>
        <mesh filename="../meshes/qbhand/ph_medium_collision.stl" scale="0.001 0.001 0.001"/>
      </geometry>
    </collision>
  </link>
  <gazebo reference="qbhand_middle_proximal_link">
    <self_collide>1</self_collide>
    <!-- TODO: add other Gazebo Link properties (http://sdformat.org/spec?elem=link) -->
    <!--      <collision>-->
    <!--        <surface>-->
    <!--          <contact>-->
    <!--            <ode>-->
    <!--              <kp>1.0</kp>-->
    <!--              <kd>0.01</kd>-->
    <!--              <max_vel>0.0</max_vel>-->
    <!--              <min_depth>0.001</min_depth>-->
    <!--            </ode>-->
    <!--          </contact>-->
    <!--          <friction>-->
    <!--            <ode>-->
    <!--              <mu>0.9</mu>-->
    <!--              <mu2>0.9</mu2>-->
    <!--            </ode>-->
    <!--          </friction>-->
    <!--        </surface>-->
    <!--      </collision>-->
  </gazebo>
  <joint name="qbhand_middle_middle_joint" type="revolute">
    <origin rpy="0 0 0" xyz="0.017 0 0"/>
    <parent link="qbhand_middle_proximal_link"/>
    <child link="qbhand_middle_middle_virtual_link"/>
    <axis xyz="0 0 -1"/>
    <dynamics damping="0.0" friction="0.0"/>
    <limit effort="100" lower="0.0" upper="0.785" velocity="100"/>
    <mimic joint="qbhand_synergy_joint" multiplier="0.785"/>
  </joint>
  <transmission name="qbhand_transmission">
    <type>transmission_interface/qbMoveTransmission</type>
    <joint name="qbhand_middle_middle_joint">
      <hardwareInterface>hardware_interface/EffortJointInterface</hardwareInterface>
    </joint>
    <actuator name="qbhand_middle_middle_joint">
      <hardwareInterface>hardware_interface/EffortJointInterface</hardwareInterface>
    </actuator>
  </transmission>
  <gazebo reference="qbhand_middle_middle_joint">
    <!-- TODO: add other Gazebo Joint properties (http://sdformat.org/spec?elem=joint) -->
  </gazebo>
  <link name="qbhand_middle_middle_virtual_link">
    <inertial>
      <origin rpy="0 0 0" xyz="0 0 0"/>
      <mass value="1e-4"/>
      <inertia ixx="1e-9" ixy="0.0" ixz="0.0" iyy="1e-9" iyz="0.0" izz="1e-9"/>
    </inertial>
  </link>
  <joint name="qbhand_middle_middle_virtual_joint" type="revolute">
    <origin rpy="0 0 0" xyz="0.013 0 0"/>
    <parent link="qbhand_middle_middle_virtual_link"/>
    <child link="qbhand_middle_middle_link"/>
    <axis xyz="0 0 -1"/>
    <dynamics damping="0.0" friction="0.0"/>
    <limit effort="100" lower="0.0" upper="0.785" velocity="100"/>
    <mimic joint="qbhand_middle_middle_joint" multiplier="1.0"/>
  </joint>
  <transmission name="qbhand_transmission">
    <type>transmission_interface/qbMoveTransmission</type>
    <joint name="qbhand_middle_middle_virtual_joint">
      <hardwareInterface>hardware_interface/EffortJointInterface</hardwareInterface>
    </joint>
    <actuator name="qbhand_middle_middle_virtual_joint">
      <hardwareInterface>hardware_interface/EffortJointInterface</hardwareInterface>
    </actuator>
  </transmission>
  <gazebo reference="qbhand_middle_middle_virtual_joint">
    <!-- TODO: add other Gazebo Joint properties (http://sdformat.org/spec?elem=joint) -->
  </gazebo>
  <link name="qbhand_middle_middle_link">
    <inertial>
      <mass value="0.0063"/>
      <origin rpy="0 0 0" xyz="4.7601567e-03 -1.3786947e-03 0.0"/>
      <inertia ixx="1.8024201e-07" ixy="5.756798e-09" ixz="0.0" iyy="2.3516266e-07" iyz="0.0" izz="2.691504e-07"/>
    </inertial>
    <visual>
      <origin rpy="0 0 0" xyz="0 0 0"/>
      <geometry>
        <mesh filename="../meshes/qbhand/ph_short.stl" scale="0.001 0.001 0.001"/>
      </geometry>
      <material name="qbhand/middle"/>
    </visual>
    <collision>
      <origin rpy="0 0 0" xyz="0 0 0"/>
      <geometry>
        <mesh filename="../meshes/qbhand/ph_short_collision.stl" scale="0.001 0.001 0.001"/>
      </geometry>
    </collision>
  </link>
  <gazebo reference="qbhand_middle_middle_link">
    <self_collide>1</self_collide>
    <!-- TODO: add other Gazebo Link properties (http://sdformat.org/spec?elem=link) -->
    <!--      <collision>-->
    <!--        <surface>-->
    <!--          <contact>-->
    <!--            <ode>-->
    <!--              <kp>1.0</kp>-->
    <!--              <kd>0.01</kd>-->
    <!--              <max_vel>0.0</max_vel>-->
    <!--              <min_depth>0.001</min_depth>-->
    <!--            </ode>-->
    <!--          </contact>-->
    <!--          <friction>-->
    <!--            <ode>-->
    <!--              <mu>0.9</mu>-->
    <!--              <mu2>0.9</mu2>-->
    <!--            </ode>-->
    <!--          </friction>-->
    <!--        </surface>-->
    <!--      </collision>-->
  </gazebo>
  <joint name="qbhand_middle_distal_joint" type="revolute">
    <origin rpy="0 0 0" xyz="0.009 0 0"/>
    <parent link="qbhand_middle_middle_link"/>
    <child link="qbhand_middle_distal_virtual_link"/>
    <axis xyz="0 0 -1"/>
    <dynamics damping="0.0" friction="0.0"/>
    <limit effort="100" lower="0.0" upper="0.785" velocity="100"/>
    <mimic joint="qbhand_synergy_joint" multiplier="0.785"/>
  </joint>
  <transmission name="qbhand_transmission">
    <type>transmission_interface/qbMoveTransmission</type>
    <joint name="qbhand_middle_distal_joint">
      <hardwareInterface>hardware_interface/EffortJointInterface</hardwareInterface>
    </joint>
    <actuator name="qbhand_middle_distal_joint">
      <hardwareInterface>hardware_interface/EffortJointInterface</hardwareInterface>
    </actuator>
  </transmission>
  <gazebo reference="qbhand_middle_distal_joint">
    <!-- TODO: add other Gazebo Joint properties (http://sdformat.org/spec?elem=joint) -->
  </gazebo>
  <link name="qbhand_middle_distal_virtual_link">
    <inertial>
      <origin rpy="0 0 0" xyz="0 0 0"/>
      <mass value="1e-4"/>
      <inertia ixx="1e-9" ixy="0.0" ixz="0.0" iyy="1e-9" iyz="0.0" izz="1e-9"/>
    </inertial>
  </link>
  <joint name="qbhand_middle_distal_virtual_joint" type="revolute">
    <origin rpy="0 0 0" xyz="0.013 0 0"/>
    <parent link="qbhand_middle_distal_virtual_link"/>
    <child link="qbhand_middle_distal_link"/>
    <axis xyz="0 0 -1"/>
    <dynamics damping="0.0" friction="0.0"/>
    <limit effort="100" lower="0.0" upper="0.785" velocity="100"/>
    <mimic joint="qbhand_middle_distal_joint" multiplier="1.0"/>
  </joint>
  <transmission name="qbhand_transmission">
    <type>transmission_interface/qbMoveTransmission</type>
    <joint name="qbhand_middle_distal_virtual_joint">
      <hardwareInterface>hardware_interface/EffortJointInterface</hardwareInterface>
    </joint>
    <actuator name="qbhand_middle_distal_virtual_joint">
      <hardwareInterface>hardware_interface/EffortJointInterface</hardwareInterface>
    </actuator>
  </transmission>
  <gazebo reference="qbhand_middle_distal_virtual_joint">
    <!-- TODO: add other Gazebo Joint properties (http://sdformat.org/spec?elem=joint) -->
  </gazebo>
  <link name="qbhand_middle_distal_link">
    <inertial>
      <mass value="0.009"/>
      <origin rpy="0 0 0" xyz="8.8025467e-03 -1.7219289e-03 0.0"/>
      <inertia ixx="2.6586142e-07" ixy="1.2416847e-08" ixz="0.0" iyy="5.9935767e-07" iyz="0.0" izz="6.6781963e-07"/>
    </inertial>
    <visual>
      <origin rpy="0 0 0" xyz="0 0 0"/>
      <geometry>
        <mesh filename="../meshes/qbhand/ph_distal.stl" scale="0.001 0.001 0.001"/>
      </geometry>
      <material name="qbhand/distal"/>
    </visual>
    <collision>
      <origin rpy="0 0 0" xyz="0 0 0"/>
      <geometry>
        <mesh filename="../meshes/qbhand/ph_distal_collision.stl" scale="0.001 0.001 0.001"/>
      </geometry>
    </collision>
  </link>
  <gazebo reference="qbhand_middle_distal_link">
    <self_collide>1</self_collide>
    <!-- TODO: add other Gazebo Link properties (http://sdformat.org/spec?elem=link) -->
    <!--      <collision>-->
    <!--        <surface>-->
    <!--          <contact>-->
    <!--            <ode>-->
    <!--              <kp>1.0</kp>-->
    <!--              <kd>0.01</kd>-->
    <!--              <max_vel>0.0</max_vel>-->
    <!--              <min_depth>0.001</min_depth>-->
    <!--            </ode>-->
    <!--          </contact>-->
    <!--          <friction>-->
    <!--            <ode>-->
    <!--              <mu>0.9</mu>-->
    <!--              <mu2>0.9</mu2>-->
    <!--            </ode>-->
    <!--          </friction>-->
    <!--        </surface>-->
    <!--      </collision>-->
  </gazebo>
  <joint name="qbhand_ring_knuckle_joint" type="revolute">
    <origin rpy="0 3.14 -1.57" xyz="0.02 -0.007 -0.014"/>
    <parent link="qbhand_palm_link"/>
    <child link="qbhand_ring_knuckle_link"/>
    <axis xyz="0 0 -1"/>
    <dynamics damping="0.0" friction="0.0"/>
    <limit effort="100" lower="-0.524" upper="0.524" velocity="100"/>
    <mimic joint="qbhand_synergy_joint" multiplier="-0.2"/>
  </joint>
  <transmission name="qbhand_transmission">
    <type>transmission_interface/qbMoveTransmission</type>
    <joint name="qbhand_ring_knuckle_joint">
      <hardwareInterface>hardware_interface/EffortJointInterface</hardwareInterface>
    </joint>
    <actuator name="qbhand_ring_knuckle_joint">
      <hardwareInterface>hardware_interface/EffortJointInterface</hardwareInterface>
    </actuator>
  </transmission>
  <gazebo reference="qbhand_ring_knuckle_joint">
    <!-- TODO: add other Gazebo Joint properties (http://sdformat.org/spec?elem=joint) -->
  </gazebo>
  <link name="qbhand_ring_knuckle_link">
    <inertial>
      <mass value="0.0095"/>
      <origin rpy="0 0 0" xyz="4.2753603e-04  0.0 -1.4321738e-03"/>
      <inertia ixx="6.4337303e-07" ixy="0.0" ixz="-3.9373913e-08" iyy="1.1253771e-06" iyz="0.0" izz="7.2336948e-07"/>
    </inertial>
    <visual>
      <origin rpy="0 0 0" xyz="0 0 0"/>
      <geometry>
        <mesh filename="../meshes/qbhand/ph_knuckle.stl" scale="0.001 0.001 0.001"/>
      </geometry>
      <material name="qbhand/knuckle"/>
    </visual>
    <collision>
      <origin rpy="0 0 0" xyz="0 0 0"/>
      <geometry>
        <mesh filename="../meshes/qbhand/ph_knuckle_collision.stl" scale="0.001 0.001 0.001"/>
      </geometry>
    </collision>
  </link>
  <gazebo reference="qbhand_ring_knuckle_link">
    <self_collide>1</self_collide>
    <!-- TODO: add other Gazebo Link properties (http://sdformat.org/spec?elem=link) -->
    <!--      <collision>-->
    <!--        <surface>-->
    <!--          <contact>-->
    <!--            <ode>-->
    <!--              <kp>1.0</kp>-->
    <!--              <kd>0.01</kd>-->
    <!--              <max_vel>0.0</max_vel>-->
    <!--              <min_depth>0.001</min_depth>-->
    <!--            </ode>-->
    <!--          </contact>-->
    <!--          <friction>-->
    <!--            <ode>-->
    <!--              <mu>0.9</mu>-->
    <!--              <mu2>0.9</mu2>-->
    <!--            </ode>-->
    <!--          </friction>-->
    <!--        </surface>-->
    <!--      </collision>-->
  </gazebo>
  <joint name="qbhand_ring_proximal_joint" type="revolute">
    <origin rpy="1.57 0 0" xyz="0.009 0 0"/>
    <parent link="qbhand_ring_knuckle_link"/>
    <child link="qbhand_ring_proximal_virtual_link"/>
    <axis xyz="0 0 -1"/>
    <dynamics damping="0.0" friction="0.0"/>
    <limit effort="100" lower="0.0" upper="0.785" velocity="100"/>
    <mimic joint="qbhand_synergy_joint" multiplier="0.785"/>
  </joint>
  <transmission name="qbhand_transmission">
    <type>transmission_interface/qbMoveTransmission</type>
    <joint name="qbhand_ring_proximal_joint">
      <hardwareInterface>hardware_interface/EffortJointInterface</hardwareInterface>
    </joint>
    <actuator name="qbhand_ring_proximal_joint">
      <hardwareInterface>hardware_interface/EffortJointInterface</hardwareInterface>
    </actuator>
  </transmission>
  <gazebo reference="qbhand_ring_proximal_joint">
    <!-- TODO: add other Gazebo Joint properties (http://sdformat.org/spec?elem=joint) -->
  </gazebo>
  <link name="qbhand_ring_proximal_virtual_link">
    <inertial>
      <origin rpy="0 0 0" xyz="0 0 0"/>
      <mass value="1e-4"/>
      <inertia ixx="1e-9" ixy="0.0" ixz="0.0" iyy="1e-9" iyz="0.0" izz="1e-9"/>
    </inertial>
  </link>
  <joint name="qbhand_ring_proximal_virtual_joint" type="revolute">
    <origin rpy="0 0 0" xyz="0.013 0 0"/>
    <parent link="qbhand_ring_proximal_virtual_link"/>
    <child link="qbhand_ring_proximal_link"/>
    <axis xyz="0 0 -1"/>
    <dynamics damping="0.0" friction="0.0"/>
    <limit effort="100" lower="0.0" upper="0.785" velocity="100"/>
    <mimic joint="qbhand_ring_proximal_joint" multiplier="1.0"/>
  </joint>
  <transmission name="qbhand_transmission">
    <type>transmission_interface/qbMoveTransmission</type>
    <joint name="qbhand_ring_proximal_virtual_joint">
      <hardwareInterface>hardware_interface/EffortJointInterface</hardwareInterface>
    </joint>
    <actuator name="qbhand_ring_proximal_virtual_joint">
      <hardwareInterface>hardware_interface/EffortJointInterface</hardwareInterface>
    </actuator>
  </transmission>
  <gazebo reference="qbhand_ring_proximal_virtual_joint">
    <!-- TODO: add other Gazebo Joint properties (http://sdformat.org/spec?elem=joint) -->
  </gazebo>
  <link name="qbhand_ring_proximal_link">
    <inertial>
      <mass value="0.0082"/>
      <origin rpy="0 0 0" xyz="8.7707437e-03 -1.7863138e-03 0.0"/>
      <inertia ixx="2.2722068e-07" ixy="1.1586053e-08" ixz="0.0" iyy="5.5947233e-07" iyz="0.0" izz="5.9562195e-07"/>
    </inertial>
    <visual>
      <origin rpy="0 0 0" xyz="0 0 0"/>
      <geometry>
        <mesh filename="../meshes/qbhand/ph_medium.stl" scale="0.001 0.001 0.001"/>
      </geometry>
      <material name="qbhand/proximal"/>
    </visual>
    <collision>
      <origin rpy="0 0 0" xyz="0 0 0"/>
      <geometry>
        <mesh filename="../meshes/qbhand/ph_medium_collision.stl" scale="0.001 0.001 0.001"/>
      </geometry>
    </collision>
  </link>
  <gazebo reference="qbhand_ring_proximal_link">
    <self_collide>1</self_collide>
    <!-- TODO: add other Gazebo Link properties (http://sdformat.org/spec?elem=link) -->
    <!--      <collision>-->
    <!--        <surface>-->
    <!--          <contact>-->
    <!--            <ode>-->
    <!--              <kp>1.0</kp>-->
    <!--              <kd>0.01</kd>-->
    <!--              <max_vel>0.0</max_vel>-->
    <!--              <min_depth>0.001</min_depth>-->
    <!--            </ode>-->
    <!--          </contact>-->
    <!--          <friction>-->
    <!--            <ode>-->
    <!--              <mu>0.9</mu>-->
    <!--              <mu2>0.9</mu2>-->
    <!--            </ode>-->
    <!--          </friction>-->
    <!--        </surface>-->
    <!--      </collision>-->
  </gazebo>
  <joint name="qbhand_ring_middle_joint" type="revolute">
    <origin rpy="0 0 0" xyz="0.017 0 0"/>
    <parent link="qbhand_ring_proximal_link"/>
    <child link="qbhand_ring_middle_virtual_link"/>
    <axis xyz="0 0 -1"/>
    <dynamics damping="0.0" friction="0.0"/>
    <limit effort="100" lower="0.0" upper="0.785" velocity="100"/>
    <mimic joint="qbhand_synergy_joint" multiplier="0.785"/>
  </joint>
  <transmission name="qbhand_transmission">
    <type>transmission_interface/qbMoveTransmission</type>
    <joint name="qbhand_ring_middle_joint">
      <hardwareInterface>hardware_interface/EffortJointInterface</hardwareInterface>
    </joint>
    <actuator name="qbhand_ring_middle_joint">
      <hardwareInterface>hardware_interface/EffortJointInterface</hardwareInterface>
    </actuator>
  </transmission>
  <gazebo reference="qbhand_ring_middle_joint">
    <!-- TODO: add other Gazebo Joint properties (http://sdformat.org/spec?elem=joint) -->
  </gazebo>
  <link name="qbhand_ring_middle_virtual_link">
    <inertial>
      <origin rpy="0 0 0" xyz="0 0 0"/>
      <mass value="1e-4"/>
      <inertia ixx="1e-9" ixy="0.0" ixz="0.0" iyy="1e-9" iyz="0.0" izz="1e-9"/>
    </inertial>
  </link>
  <joint name="qbhand_ring_middle_virtual_joint" type="revolute">
    <origin rpy="0 0 0" xyz="0.013 0 0"/>
    <parent link="qbhand_ring_middle_virtual_link"/>
    <child link="qbhand_ring_middle_link"/>
    <axis xyz="0 0 -1"/>
    <dynamics damping="0.0" friction="0.0"/>
    <limit effort="100" lower="0.0" upper="0.785" velocity="100"/>
    <mimic joint="qbhand_ring_middle_joint" multiplier="1.0"/>
  </joint>
  <transmission name="qbhand_transmission">
    <type>transmission_interface/qbMoveTransmission</type>
    <joint name="qbhand_ring_middle_virtual_joint">
      <hardwareInterface>hardware_interface/EffortJointInterface</hardwareInterface>
    </joint>
    <actuator name="qbhand_ring_middle_virtual_joint">
      <hardwareInterface>hardware_interface/EffortJointInterface</hardwareInterface>
    </actuator>
  </transmission>
  <gazebo reference="qbhand_ring_middle_virtual_joint">
    <!-- TODO: add other Gazebo Joint properties (http://sdformat.org/spec?elem=joint) -->
  </gazebo>
  <link name="qbhand_ring_middle_link">
    <inertial>
      <mass value="0.0063"/>
      <origin rpy="0 0 0" xyz="4.7601567e-03 -1.3786947e-03 0.0"/>
      <inertia ixx="1.8024201e-07" ixy="5.756798e-09" ixz="0.0" iyy="2.3516266e-07" iyz="0.0" izz="2.691504e-07"/>
    </inertial>
    <visual>
      <origin rpy="0 0 0" xyz="0 0 0"/>
      <geometry>
        <mesh filename="../meshes/qbhand/ph_short.stl" scale="0.001 0.001 0.001"/>
      </geometry>
      <material name="qbhand/middle"/>
    </visual>
    <collision>
      <origin rpy="0 0 0" xyz="0 0 0"/>
      <geometry>
        <mesh filename="../meshes/qbhand/ph_short_collision.stl" scale="0.001 0.001 0.001"/>
      </geometry>
    </collision>
  </link>
  <gazebo reference="qbhand_ring_middle_link">
    <self_collide>1</self_collide>
    <!-- TODO: add other Gazebo Link properties (http://sdformat.org/spec?elem=link) -->
    <!--      <collision>-->
    <!--        <surface>-->
    <!--          <contact>-->
    <!--            <ode>-->
    <!--              <kp>1.0</kp>-->
    <!--              <kd>0.01</kd>-->
    <!--              <max_vel>0.0</max_vel>-->
    <!--              <min_depth>0.001</min_depth>-->
    <!--            </ode>-->
    <!--          </contact>-->
    <!--          <friction>-->
    <!--            <ode>-->
    <!--              <mu>0.9</mu>-->
    <!--              <mu2>0.9</mu2>-->
    <!--            </ode>-->
    <!--          </friction>-->
    <!--        </surface>-->
    <!--      </collision>-->
  </gazebo>
  <joint name="qbhand_ring_distal_joint" type="revolute">
    <origin rpy="0 0 0" xyz="0.009 0 0"/>
    <parent link="qbhand_ring_middle_link"/>
    <child link="qbhand_ring_distal_virtual_link"/>
    <axis xyz="0 0 -1"/>
    <dynamics damping="0.0" friction="0.0"/>
    <limit effort="100" lower="0.0" upper="0.785" velocity="100"/>
    <mimic joint="qbhand_synergy_joint" multiplier="0.785"/>
  </joint>
  <transmission name="qbhand_transmission">
    <type>transmission_interface/qbMoveTransmission</type>
    <joint name="qbhand_ring_distal_joint">
      <hardwareInterface>hardware_interface/EffortJointInterface</hardwareInterface>
    </joint>
    <actuator name="qbhand_ring_distal_joint">
      <hardwareInterface>hardware_interface/EffortJointInterface</hardwareInterface>
    </actuator>
  </transmission>
  <gazebo reference="qbhand_ring_distal_joint">
    <!-- TODO: add other Gazebo Joint properties (http://sdformat.org/spec?elem=joint) -->
  </gazebo>
  <link name="qbhand_ring_distal_virtual_link">
    <inertial>
      <origin rpy="0 0 0" xyz="0 0 0"/>
      <mass value="1e-4"/>
      <inertia ixx="1e-9" ixy="0.0" ixz="0.0" iyy="1e-9" iyz="0.0" izz="1e-9"/>
    </inertial>
  </link>
  <joint name="qbhand_ring_distal_virtual_joint" type="revolute">
    <origin rpy="0 0 0" xyz="0.013 0 0"/>
    <parent link="qbhand_ring_distal_virtual_link"/>
    <child link="qbhand_ring_distal_link"/>
    <axis xyz="0 0 -1"/>
    <dynamics damping="0.0" friction="0.0"/>
    <limit effort="100" lower="0.0" upper="0.785" velocity="100"/>
    <mimic joint="qbhand_ring_distal_joint" multiplier="1.0"/>
  </joint>
  <transmission name="qbhand_transmission">
    <type>transmission_interface/qbMoveTransmission</type>
    <joint name="qbhand_ring_distal_virtual_joint">
      <hardwareInterface>hardware_interface/EffortJointInterface</hardwareInterface>
    </joint>
    <actuator name="qbhand_ring_distal_virtual_joint">
      <hardwareInterface>hardware_interface/EffortJointInterface</hardwareInterface>
    </actuator>
  </transmission>
  <gazebo reference="qbhand_ring_distal_virtual_joint">
    <!-- TODO: add other Gazebo Joint properties (http://sdformat.org/spec?elem=joint) -->
  </gazebo>
  <link name="qbhand_ring_distal_link">
    <inertial>
      <mass value="0.009"/>
      <origin rpy="0 0 0" xyz="8.8025467e-03 -1.7219289e-03 0.0"/>
      <inertia ixx="2.6586142e-07" ixy="1.2416847e-08" ixz="0.0" iyy="5.9935767e-07" iyz="0.0" izz="6.6781963e-07"/>
    </inertial>
    <visual>
      <origin rpy="0 0 0" xyz="0 0 0"/>
      <geometry>
        <mesh filename="../meshes/qbhand/ph_distal.stl" scale="0.001 0.001 0.001"/>
      </geometry>
      <material name="qbhand/distal"/>
    </visual>
    <collision>
      <origin rpy="0 0 0" xyz="0 0 0"/>
      <geometry>
        <mesh filename="../meshes/qbhand/ph_distal_collision.stl" scale="0.001 0.001 0.001"/>
      </geometry>
    </collision>
  </link>
  <gazebo reference="qbhand_ring_distal_link">
    <self_collide>1</self_collide>
    <!-- TODO: add other Gazebo Link properties (http://sdformat.org/spec?elem=link) -->
    <!--      <collision>-->
    <!--        <surface>-->
    <!--          <contact>-->
    <!--            <ode>-->
    <!--              <kp>1.0</kp>-->
    <!--              <kd>0.01</kd>-->
    <!--              <max_vel>0.0</max_vel>-->
    <!--              <min_depth>0.001</min_depth>-->
    <!--            </ode>-->
    <!--          </contact>-->
    <!--          <friction>-->
    <!--            <ode>-->
    <!--              <mu>0.9</mu>-->
    <!--              <mu2>0.9</mu2>-->
    <!--            </ode>-->
    <!--          </friction>-->
    <!--        </surface>-->
    <!--      </collision>-->
  </gazebo>
  <joint name="qbhand_little_knuckle_joint" type="revolute">
    <origin rpy="0 3.14 -1.57" xyz="0.04 -0.012 -0.014"/>
    <parent link="qbhand_palm_link"/>
    <child link="qbhand_little_knuckle_link"/>
    <axis xyz="0 0 -1"/>
    <dynamics damping="0.0" friction="0.0"/>
    <limit effort="100" lower="-0.524" upper="0.524" velocity="100"/>
    <mimic joint="qbhand_synergy_joint" multiplier="-0.4"/>
  </joint>
  <transmission name="qbhand_transmission">
    <type>transmission_interface/qbMoveTransmission</type>
    <joint name="qbhand_little_knuckle_joint">
      <hardwareInterface>hardware_interface/EffortJointInterface</hardwareInterface>
    </joint>
    <actuator name="qbhand_little_knuckle_joint">
      <hardwareInterface>hardware_interface/EffortJointInterface</hardwareInterface>
    </actuator>
  </transmission>
  <gazebo reference="qbhand_little_knuckle_joint">
    <!-- TODO: add other Gazebo Joint properties (http://sdformat.org/spec?elem=joint) -->
  </gazebo>
  <link name="qbhand_little_knuckle_link">
    <inertial>
      <mass value="0.0095"/>
      <origin rpy="0 0 0" xyz="4.2753603e-04  0.0 -1.4321738e-03"/>
      <inertia ixx="6.4337303e-07" ixy="0.0" ixz="-3.9373913e-08" iyy="1.1253771e-06" iyz="0.0" izz="7.2336948e-07"/>
    </inertial>
    <visual>
      <origin rpy="0 0 0" xyz="0 0 0"/>
      <geometry>
        <mesh filename="../meshes/qbhand/ph_knuckle.stl" scale="0.001 0.001 0.001"/>
      </geometry>
      <material name="qbhand/knuckle"/>
    </visual>
    <collision>
      <origin rpy="0 0 0" xyz="0 0 0"/>
      <geometry>
        <mesh filename="../meshes/qbhand/ph_knuckle_collision.stl" scale="0.001 0.001 0.001"/>
      </geometry>
    </collision>
  </link>
  <gazebo reference="qbhand_little_knuckle_link">
    <self_collide>1</self_collide>
    <!-- TODO: add other Gazebo Link properties (http://sdformat.org/spec?elem=link) -->
    <!--      <collision>-->
    <!--        <surface>-->
    <!--          <contact>-->
    <!--            <ode>-->
    <!--              <kp>1.0</kp>-->
    <!--              <kd>0.01</kd>-->
    <!--              <max_vel>0.0</max_vel>-->
    <!--              <min_depth>0.001</min_depth>-->
    <!--            </ode>-->
    <!--          </contact>-->
    <!--          <friction>-->
    <!--            <ode>-->
    <!--              <mu>0.9</mu>-->
    <!--              <mu2>0.9</mu2>-->
    <!--            </ode>-->
    <!--          </friction>-->
    <!--        </surface>-->
    <!--      </collision>-->
  </gazebo>
  <joint name="qbhand_little_proximal_joint" type="revolute">
    <origin rpy="1.57 0 0" xyz="0.009 0 0"/>
    <parent link="qbhand_little_knuckle_link"/>
    <child link="qbhand_little_proximal_virtual_link"/>
    <axis xyz="0 0 -1"/>
    <dynamics damping="0.0" friction="0.0"/>
    <limit effort="100" lower="0.0" upper="0.785" velocity="100"/>
    <mimic joint="qbhand_synergy_joint" multiplier="0.785"/>
  </joint>
  <transmission name="qbhand_transmission">
    <type>transmission_interface/qbMoveTransmission</type>
    <joint name="qbhand_little_proximal_joint">
      <hardwareInterface>hardware_interface/EffortJointInterface</hardwareInterface>
    </joint>
    <actuator name="qbhand_little_proximal_joint">
      <hardwareInterface>hardware_interface/EffortJointInterface</hardwareInterface>
    </actuator>
  </transmission>
  <gazebo reference="qbhand_little_proximal_joint">
    <!-- TODO: add other Gazebo Joint properties (http://sdformat.org/spec?elem=joint) -->
  </gazebo>
  <link name="qbhand_little_proximal_virtual_link">
    <inertial>
      <origin rpy="0 0 0" xyz="0 0 0"/>
      <mass value="1e-4"/>
      <inertia ixx="1e-9" ixy="0.0" ixz="0.0" iyy="1e-9" iyz="0.0" izz="1e-9"/>
    </inertial>
  </link>
  <joint name="qbhand_little_proximal_virtual_joint" type="revolute">
    <origin rpy="0 0 0" xyz="0.013 0 0"/>
    <parent link="qbhand_little_proximal_virtual_link"/>
    <child link="qbhand_little_proximal_link"/>
    <axis xyz="0 0 -1"/>
    <dynamics damping="0.0" friction="0.0"/>
    <limit effort="100" lower="0.0" upper="0.785" velocity="100"/>
    <mimic joint="qbhand_little_proximal_joint" multiplier="1.0"/>
  </joint>
  <transmission name="qbhand_transmission">
    <type>transmission_interface/qbMoveTransmission</type>
    <joint name="qbhand_little_proximal_virtual_joint">
      <hardwareInterface>hardware_interface/EffortJointInterface</hardwareInterface>
    </joint>
    <actuator name="qbhand_little_proximal_virtual_joint">
      <hardwareInterface>hardware_interface/EffortJointInterface</hardwareInterface>
    </actuator>
  </transmission>
  <gazebo reference="qbhand_little_proximal_virtual_joint">
    <!-- TODO: add other Gazebo Joint properties (http://sdformat.org/spec?elem=joint) -->
  </gazebo>
  <link name="qbhand_little_proximal_link">
    <inertial>
      <mass value="0.0063"/>
      <origin rpy="0 0 0" xyz="4.7601567e-03 -1.3786947e-03 0.0"/>
      <inertia ixx="1.8024201e-07" ixy="5.756798e-09" ixz="0.0" iyy="2.3516266e-07" iyz="0.0" izz="2.691504e-07"/>
    </inertial>
    <visual>
      <origin rpy="0 0 0" xyz="0 0 0"/>
      <geometry>
        <mesh filename="../meshes/qbhand/ph_short.stl" scale="0.001 0.001 0.001"/>
      </geometry>
      <material name="qbhand/proximal"/>
    </visual>
    <collision>
      <origin rpy="0 0 0" xyz="0 0 0"/>
      <geometry>
        <mesh filename="../meshes/qbhand/ph_short_collision.stl" scale="0.001 0.001 0.001"/>
      </geometry>
    </collision>
  </link>
  <gazebo reference="qbhand_little_proximal_link">
    <self_collide>1</self_collide>
    <!-- TODO: add other Gazebo Link properties (http://sdformat.org/spec?elem=link) -->
    <!--      <collision>-->
    <!--        <surface>-->
    <!--          <contact>-->
    <!--            <ode>-->
    <!--              <kp>1.0</kp>-->
    <!--              <kd>0.01</kd>-->
    <!--              <max_vel>0.0</max_vel>-->
    <!--              <min_depth>0.001</min_depth>-->
    <!--            </ode>-->
    <!--          </contact>-->
    <!--          <friction>-->
    <!--            <ode>-->
    <!--              <mu>0.9</mu>-->
    <!--              <mu2>0.9</mu2>-->
    <!--            </ode>-->
    <!--          </friction>-->
    <!--        </surface>-->
    <!--      </collision>-->
  </gazebo>
  <joint name="qbhand_little_middle_joint" type="revolute">
    <origin rpy="0 0 0" xyz="0.009 0 0"/>
    <parent link="qbhand_little_proximal_link"/>
    <child link="qbhand_little_middle_virtual_link"/>
    <axis xyz="0 0 -1"/>
    <dynamics damping="0.0" friction="0.0"/>
    <limit effort="100" lower="0.0" upper="0.785" velocity="100"/>
    <mimic joint="qbhand_synergy_joint" multiplier="0.785"/>
  </joint>
  <transmission name="qbhand_transmission">
    <type>transmission_interface/qbMoveTransmission</type>
    <joint name="qbhand_little_middle_joint">
      <hardwareInterface>hardware_interface/EffortJointInterface</hardwareInterface>
    </joint>
    <actuator name="qbhand_little_middle_joint">
      <hardwareInterface>hardware_interface/EffortJointInterface</hardwareInterface>
    </actuator>
  </transmission>
  <gazebo reference="qbhand_little_middle_joint">
    <!-- TODO: add other Gazebo Joint properties (http://sdformat.org/spec?elem=joint) -->
  </gazebo>
  <link name="qbhand_little_middle_virtual_link">
    <inertial>
      <origin rpy="0 0 0" xyz="0 0 0"/>
      <mass value="1e-4"/>
      <inertia ixx="1e-9" ixy="0.0" ixz="0.0" iyy="1e-9" iyz="0.0" izz="1e-9"/>
    </inertial>
  </link>
  <joint name="qbhand_little_middle_virtual_joint" type="revolute">
    <origin rpy="0 0 0" xyz="0.013 0 0"/>
    <parent link="qbhand_little_middle_virtual_link"/>
    <child link="qbhand_little_middle_link"/>
    <axis xyz="0 0 -1"/>
    <dynamics damping="0.0" friction="0.0"/>
    <limit effort="100" lower="0.0" upper="0.785" velocity="100"/>
    <mimic joint="qbhand_little_middle_joint" multiplier="1.0"/>
  </joint>
  <transmission name="qbhand_transmission">
    <type>transmission_interface/qbMoveTransmission</type>
    <joint name="qbhand_little_middle_virtual_joint">
      <hardwareInterface>hardware_interface/EffortJointInterface</hardwareInterface>
    </joint>
    <actuator name="qbhand_little_middle_virtual_joint">
      <hardwareInterface>hardware_interface/EffortJointInterface</hardwareInterface>
    </actuator>
  </transmission>
  <gazebo reference="qbhand_little_middle_virtual_joint">
    <!-- TODO: add other Gazebo Joint properties (http://sdformat.org/spec?elem=joint) -->
  </gazebo>
  <link name="qbhand_little_middle_link">
    <inertial>
      <mass value="0.0063"/>
      <origin rpy="0 0 0" xyz="4.7601567e-03 -1.3786947e-03 0.0"/>
      <inertia ixx="1.8024201e-07" ixy="5.756798e-09" ixz="0.0" iyy="2.3516266e-07" iyz="0.0" izz="2.691504e-07"/>
    </inertial>
    <visual>
      <origin rpy="0 0 0" xyz="0 0 0"/>
      <geometry>
        <mesh filename="../meshes/qbhand/ph_short.stl" scale="0.001 0.001 0.001"/>
      </geometry>
      <material name="qbhand/middle"/>
    </visual>
    <collision>
      <origin rpy="0 0 0" xyz="0 0 0"/>
      <geometry>
        <mesh filename="../meshes/qbhand/ph_short_collision.stl" scale="0.001 0.001 0.001"/>
      </geometry>
    </collision>
  </link>
  <gazebo reference="qbhand_little_middle_link">
    <self_collide>1</self_collide>
    <!-- TODO: add other Gazebo Link properties (http://sdformat.org/spec?elem=link) -->
    <!--      <collision>-->
    <!--        <surface>-->
    <!--          <contact>-->
    <!--            <ode>-->
    <!--              <kp>1.0</kp>-->
    <!--              <kd>0.01</kd>-->
    <!--              <max_vel>0.0</max_vel>-->
    <!--              <min_depth>0.001</min_depth>-->
    <!--            </ode>-->
    <!--          </contact>-->
    <!--          <friction>-->
    <!--            <ode>-->
    <!--              <mu>0.9</mu>-->
    <!--              <mu2>0.9</mu2>-->
    <!--            </ode>-->
    <!--          </friction>-->
    <!--        </surface>-->
    <!--      </collision>-->
  </gazebo>
  <joint name="qbhand_little_distal_joint" type="revolute">
    <origin rpy="0 0 0" xyz="0.009 0 0"/>
    <parent link="qbhand_little_middle_link"/>
    <child link="qbhand_little_distal_virtual_link"/>
    <axis xyz="0 0 -1"/>
    <dynamics damping="0.0" friction="0.0"/>
    <limit effort="100" lower="0.0" upper="0.785" velocity="100"/>
    <mimic joint="qbhand_synergy_joint" multiplier="0.785"/>
  </joint>
  <transmission name="qbhand_transmission">
    <type>transmission_interface/qbMoveTransmission</type>
    <joint name="qbhand_little_distal_joint">
      <hardwareInterface>hardware_interface/EffortJointInterface</hardwareInterface>
    </joint>
    <actuator name="qbhand_little_distal_joint">
      <hardwareInterface>hardware_interface/EffortJointInterface</hardwareInterface>
    </actuator>
  </transmission>
  <gazebo reference="qbhand_little_distal_joint">
    <!-- TODO: add other Gazebo Joint properties (http://sdformat.org/spec?elem=joint) -->
  </gazebo>
  <link name="qbhand_little_distal_virtual_link">
    <inertial>
      <origin rpy="0 0 0" xyz="0 0 0"/>
      <mass value="1e-4"/>
      <inertia ixx="1e-9" ixy="0.0" ixz="0.0" iyy="1e-9" iyz="0.0" izz="1e-9"/>
    </inertial>
  </link>
  <joint name="qbhand_little_distal_virtual_joint" type="revolute">
    <origin rpy="0 0 0" xyz="0.013 0 0"/>
    <parent link="qbhand_little_distal_virtual_link"/>
    <child link="qbhand_little_distal_link"/>
    <axis xyz="0 0 -1"/>
    <dynamics damping="0.0" friction="0.0"/>
    <limit effort="100" lower="0.0" upper="0.785" velocity="100"/>
    <mimic joint="qbhand_little_distal_joint" multiplier="1.0"/>
  </joint>
  <transmission name="qbhand_transmission">
    <type>transmission_interface/qbMoveTransmission</type>
    <joint name="qbhand_little_distal_virtual_joint">
      <hardwareInterface>hardware_interface/EffortJointInterface</hardwareInterface>
    </joint>
    <actuator name="qbhand_little_distal_virtual_joint">
      <hardwareInterface>hardware_interface/EffortJointInterface</hardwareInterface>
    </actuator>
  </transmission>
  <gazebo reference="qbhand_little_distal_virtual_joint">
    <!-- TODO: add other Gazebo Joint properties (http://sdformat.org/spec?elem=joint) -->
  </gazebo>
  <link name="qbhand_little_distal_link">
    <inertial>
      <mass value="0.009"/>
      <origin rpy="0 0 0" xyz="8.8025467e-03 -1.7219289e-03 0.0"/>
      <inertia ixx="2.6586142e-07" ixy="1.2416847e-08" ixz="0.0" iyy="5.9935767e-07" iyz="0.0" izz="6.6781963e-07"/>
    </inertial>
    <visual>
      <origin rpy="0 0 0" xyz="0 0 0"/>
      <geometry>
        <mesh filename="../meshes/qbhand/ph_distal.stl" scale="0.001 0.001 0.001"/>
      </geometry>
      <material name="qbhand/distal"/>
    </visual>
    <collision>
      <origin rpy="0 0 0" xyz="0 0 0"/>
      <geometry>
        <mesh filename="../meshes/qbhand/ph_distal_collision.stl" scale="0.001 0.001 0.001"/>
      </geometry>
    </collision>
  </link>
  <gazebo reference="qbhand_little_distal_link">
    <self_collide>1</self_collide>
    <!-- TODO: add other Gazebo Link properties (http://sdformat.org/spec?elem=link) -->
    <!--      <collision>-->
    <!--        <surface>-->
    <!--          <contact>-->
    <!--            <ode>-->
    <!--              <kp>1.0</kp>-->
    <!--              <kd>0.01</kd>-->
    <!--              <max_vel>0.0</max_vel>-->
    <!--              <min_depth>0.001</min_depth>-->
    <!--            </ode>-->
    <!--          </contact>-->
    <!--          <friction>-->
    <!--            <ode>-->
    <!--              <mu>0.9</mu>-->
    <!--              <mu2>0.9</mu2>-->
    <!--            </ode>-->
    <!--          </friction>-->
    <!--        </surface>-->
    <!--      </collision>-->
  </gazebo>
  <joint name="qbhand_end_effector_fixed_joint" type="fixed">
    <origin rpy="-1.57 0 0" xyz="-0.03 0.060 0.142"/>
    <parent link="qbhand_base_link"/>
    <child link="qbhand_end_effector_link"/>
  </joint>
  <link name="qbhand_end_effector_link"/>
  <gazebo>
    <plugin filename="libqb_hand_gazebo_plugin.so" name="qb_hand_gazebo_plugin"/>
  </gazebo>
</robot>

