<?xml version="1.0" ?>
<!-- =================================================================================== -->
<!-- |    This document was autogenerated by xacro from /home/ubuntu/Github/Knowledge-Universe/Robotics/Roadmap-for-robot-science/rofunc/simulator/assets/urdf/curi_mini/urdf/diablo_simulation.xacro | -->
<!-- |    EDITING THIS FILE BY HAND IS NOT RECOMMENDED                                 | -->
<!-- =================================================================================== -->
<robot xmlns:xacro="http://www.ros.org/wiki/xacro" name="diablo_simulation">
  <material name="silver">
    <color rgba="0.700 0.700 0.700 1.000"/>
  </material>
  <transmission name="Rev1_tran">
    <type>transmission_interface/SimpleTransmission</type>
    <joint name="Rev1">
      <hardwareInterface>hardware_interface/EffortJointInterface</hardwareInterface>
    </joint>
    <actuator name="Rev1_actr">
      <hardwareInterface>hardware_interface/EffortJointInterface</hardwareInterface>
      <mechanicalReduction>1</mechanicalReduction>
    </actuator>
  </transmission>
  <transmission name="Rev2_tran">
    <type>transmission_interface/SimpleTransmission</type>
    <joint name="Rev2">
      <hardwareInterface>hardware_interface/EffortJointInterface</hardwareInterface>
    </joint>
    <actuator name="Rev2_actr">
      <hardwareInterface>hardware_interface/EffortJointInterface</hardwareInterface>
      <mechanicalReduction>1</mechanicalReduction>
    </actuator>
  </transmission>
  <transmission name="Rev3_tran">
    <type>transmission_interface/SimpleTransmission</type>
    <joint name="Rev3">
      <hardwareInterface>hardware_interface/EffortJointInterface</hardwareInterface>
    </joint>
    <actuator name="Rev3_actr">
      <hardwareInterface>hardware_interface/EffortJointInterface</hardwareInterface>
      <mechanicalReduction>1</mechanicalReduction>
    </actuator>
  </transmission>
  <transmission name="Rev4_tran">
    <type>transmission_interface/SimpleTransmission</type>
    <joint name="Rev4">
      <hardwareInterface>hardware_interface/EffortJointInterface</hardwareInterface>
    </joint>
    <actuator name="Rev4_actr">
      <hardwareInterface>hardware_interface/EffortJointInterface</hardwareInterface>
      <mechanicalReduction>1</mechanicalReduction>
    </actuator>
  </transmission>
  <transmission name="Rev5_tran">
    <type>transmission_interface/SimpleTransmission</type>
    <joint name="Rev5">
      <hardwareInterface>hardware_interface/EffortJointInterface</hardwareInterface>
    </joint>
    <actuator name="Rev5_actr">
      <hardwareInterface>hardware_interface/EffortJointInterface</hardwareInterface>
      <mechanicalReduction>1</mechanicalReduction>
    </actuator>
  </transmission>
  <transmission name="Rev6_tran">
    <type>transmission_interface/SimpleTransmission</type>
    <joint name="Rev6">
      <hardwareInterface>hardware_interface/EffortJointInterface</hardwareInterface>
    </joint>
    <actuator name="Rev6_actr">
      <hardwareInterface>hardware_interface/EffortJointInterface</hardwareInterface>
      <mechanicalReduction>1</mechanicalReduction>
    </actuator>
  </transmission>
  <transmission name="Rev7_tran">
    <type>transmission_interface/SimpleTransmission</type>
    <joint name="Rev7">
      <hardwareInterface>hardware_interface/EffortJointInterface</hardwareInterface>
    </joint>
    <actuator name="Rev7_actr">
      <hardwareInterface>hardware_interface/EffortJointInterface</hardwareInterface>
      <mechanicalReduction>1</mechanicalReduction>
    </actuator>
  </transmission>
  <transmission name="Rev8_tran">
    <type>transmission_interface/SimpleTransmission</type>
    <joint name="Rev8">
      <hardwareInterface>hardware_interface/EffortJointInterface</hardwareInterface>
    </joint>
    <actuator name="Rev8_actr">
      <hardwareInterface>hardware_interface/EffortJointInterface</hardwareInterface>
      <mechanicalReduction>1</mechanicalReduction>
    </actuator>
  </transmission>
  <gazebo>
    <plugin name="control" filename="libgazebo_ros_control.so"/>
  </gazebo>
  <gazebo reference="base_link">
    <material>Gazebo/Silver</material>
    <mu1>0.2</mu1>
    <mu2>0.2</mu2>
    <self_collide>true</self_collide>
    <gravity>true</gravity>
  </gazebo>
  <gazebo reference="motor_right_link_1">
    <material>Gazebo/Silver</material>
    <mu1>0.2</mu1>
    <mu2>0.2</mu2>
    <self_collide>true</self_collide>
  </gazebo>
  <gazebo reference="motor_left_link_1">
    <material>Gazebo/Silver</material>
    <mu1>0.2</mu1>
    <mu2>0.2</mu2>
    <self_collide>true</self_collide>
  </gazebo>
  <gazebo reference="leg_left_link_1">
    <material>Gazebo/Silver</material>
    <mu1>0.2</mu1>
    <mu2>0.2</mu2>
    <self_collide>true</self_collide>
  </gazebo>
  <gazebo reference="leg2_left_link_1">
    <material>Gazebo/Silver</material>
    <mu1>0.2</mu1>
    <mu2>0.2</mu2>
    <self_collide>true</self_collide>
  </gazebo>
  <gazebo reference="wheel_right_link_1">
    <material>Gazebo/Silver</material>
    <mu1>0.2</mu1>
    <mu2>0.2</mu2>
    <self_collide>true</self_collide>
  </gazebo>
  <gazebo reference="leg_right_link_1">
    <material>Gazebo/Silver</material>
    <mu1>0.2</mu1>
    <mu2>0.2</mu2>
    <self_collide>true</self_collide>
  </gazebo>
  <gazebo reference="leg2_right_link_1">
    <material>Gazebo/Silver</material>
    <mu1>0.2</mu1>
    <mu2>0.2</mu2>
    <self_collide>true</self_collide>
  </gazebo>
  <gazebo reference="wheel_left_link_1">
    <material>Gazebo/Silver</material>
    <mu1>0.2</mu1>
    <mu2>0.2</mu2>
    <self_collide>true</self_collide>
  </gazebo>
  <link name="base_link">
    <inertial>
      <origin xyz="0.017543382143852662 0.00010346167746144669 0.38740254039099875" rpy="0 0 0"/>
      <mass value="89.72018430112014"/>
      <inertia ixx="0.553912" iyy="1.227224" izz="1.101448" ixy="-0.0" iyz="-0.0" ixz="0.005005"/>
    </inertial>
    <visual>
      <origin xyz="0 0 0" rpy="0 0 0"/>
      <geometry>
        <mesh filename="/home/ubuntu/Github/Knowledge-Universe/Robotics/Roadmap-for-robot-science/rofunc/simulator/assets/urdf/curi_mini/meshes/base_link.stl" scale="0.001 0.001 0.001"/>
      </geometry>
      <material name="silver"/>
    </visual>
    <collision>
      <origin xyz="0 0 0" rpy="0 0 0"/>
      <geometry>
        <mesh filename="/home/ubuntu/Github/Knowledge-Universe/Robotics/Roadmap-for-robot-science/rofunc/simulator/assets/urdf/curi_mini/meshes/base_link.stl" scale="0.001 0.001 0.001"/>
      </geometry>
    </collision>
  </link>
  <link name="motor_right_link_1">
    <inertial>
      <origin xyz="3.497073235617207e-07 -0.06735037400671914 -0.0012035359325800465" rpy="0 0 0"/>
      <mass value="10.862390811322886"/>
      <inertia ixx="0.027399" iyy="0.027359" izz="0.026313" ixy="-0.0" iyz="-0.000518" ixz="0.0"/>
    </inertial>
    <visual>
      <origin xyz="-0.00036 0.053347 -0.379" rpy="0 0 0"/>
      <geometry>
        <mesh filename="/home/ubuntu/Github/Knowledge-Universe/Robotics/Roadmap-for-robot-science/rofunc/simulator/assets/urdf/curi_mini/meshes/motor_right_link_1.stl" scale="0.001 0.001 0.001"/>
      </geometry>
      <material name="silver"/>
    </visual>
    <collision>
      <origin xyz="-0.00036 0.053347 -0.379" rpy="0 0 0"/>
      <geometry>
        <mesh filename="/home/ubuntu/Github/Knowledge-Universe/Robotics/Roadmap-for-robot-science/rofunc/simulator/assets/urdf/curi_mini/meshes/motor_right_link_1.stl" scale="0.001 0.001 0.001"/>
      </geometry>
    </collision>
  </link>
  <link name="motor_left_link_1">
    <inertial>
      <origin xyz="4.148993296440801e-07 0.06735128629132996 -0.0012035359325800465" rpy="0 0 0"/>
      <mass value="10.862390811322886"/>
      <inertia ixx="0.027399" iyy="0.027359" izz="0.026313" ixy="0.0" iyz="0.000518" ixz="0.0"/>
    </inertial>
    <visual>
      <origin xyz="-0.00036 -0.053553 -0.379" rpy="0 0 0"/>
      <geometry>
        <mesh filename="/home/ubuntu/Github/Knowledge-Universe/Robotics/Roadmap-for-robot-science/rofunc/simulator/assets/urdf/curi_mini/meshes/motor_left_link_1.stl" scale="0.001 0.001 0.001"/>
      </geometry>
      <material name="silver"/>
    </visual>
    <collision>
      <origin xyz="-0.00036 -0.053553 -0.379" rpy="0 0 0"/>
      <geometry>
        <mesh filename="/home/ubuntu/Github/Knowledge-Universe/Robotics/Roadmap-for-robot-science/rofunc/simulator/assets/urdf/curi_mini/meshes/motor_left_link_1.stl" scale="0.001 0.001 0.001"/>
      </geometry>
    </collision>
  </link>
  <link name="leg_left_link_1">
    <inertial>
      <origin xyz="0.014639618926214636 0.008000749919275602 -0.05662661365304966" rpy="0 0 0"/>
      <mass value="0.8157102862557681"/>
      <inertia ixx="0.002301" iyy="0.002556" izz="0.00029" ixy="0.0" iyz="-0.0" ixz="0.000189"/>
    </inertial>
    <visual>
      <origin xyz="-0.00036 -0.171653 -0.379" rpy="0 0 0"/>
      <geometry>
        <mesh filename="/home/ubuntu/Github/Knowledge-Universe/Robotics/Roadmap-for-robot-science/rofunc/simulator/assets/urdf/curi_mini/meshes/leg_left_link_1.stl" scale="0.001 0.001 0.001"/>
      </geometry>
      <material name="silver"/>
    </visual>
    <collision>
      <origin xyz="-0.00036 -0.171653 -0.379" rpy="0 0 0"/>
      <geometry>
        <mesh filename="/home/ubuntu/Github/Knowledge-Universe/Robotics/Roadmap-for-robot-science/rofunc/simulator/assets/urdf/curi_mini/meshes/leg_left_link_1.stl" scale="0.001 0.001 0.001"/>
      </geometry>
    </collision>
  </link>
  <link name="leg2_left_link_1">
    <inertial>
      <origin xyz="2.0745030798655474e-06 0.012347872885931949 -0.0923637086931004" rpy="0 0 0"/>
      <mass value="1.431011292925293"/>
      <inertia ixx="0.003787" iyy="0.003963" izz="0.000327" ixy="-0.0" iyz="5.8e-05" ixz="-0.0"/>
    </inertial>
    <visual>
      <origin xyz="-0.00036 -0.187653 -0.239" rpy="0 0 0"/>
      <geometry>
        <mesh filename="/home/ubuntu/Github/Knowledge-Universe/Robotics/Roadmap-for-robot-science/rofunc/simulator/assets/urdf/curi_mini/meshes/leg2_left_link_1.stl" scale="0.001 0.001 0.001"/>
      </geometry>
      <material name="silver"/>
    </visual>
    <collision>
      <origin xyz="-0.00036 -0.187653 -0.239" rpy="0 0 0"/>
      <geometry>
        <mesh filename="/home/ubuntu/Github/Knowledge-Universe/Robotics/Roadmap-for-robot-science/rofunc/simulator/assets/urdf/curi_mini/meshes/leg2_left_link_1.stl" scale="0.001 0.001 0.001"/>
      </geometry>
    </collision>
  </link>
  <link name="wheel_right_link_1">
    <inertial>
      <origin xyz="3.4736125019505654e-07 0.026000451876437153 -9.328030758926076e-08" rpy="0 0 0"/>
      <mass value="10.92207848434664"/>
      <inertia ixx="0.025678" iyy="0.046537" izz="0.025678" ixy="-0.0" iyz="0.0" ixz="0.0"/>
    </inertial>
    <visual>
      <origin xyz="-0.00036 -0.215353 -0.099" rpy="0 0 0"/>
      <geometry>
        <mesh filename="/home/ubuntu/Github/Knowledge-Universe/Robotics/Roadmap-for-robot-science/rofunc/simulator/assets/urdf/curi_mini/meshes/wheel_right_link_1.stl" scale="0.001 0.001 0.001"/>
      </geometry>
      <material name="silver"/>
    </visual>
    <collision>
      <origin xyz="-0.00036 -0.215353 -0.099" rpy="0 0 0"/>
      <geometry>
        <mesh filename="/home/ubuntu/Github/Knowledge-Universe/Robotics/Roadmap-for-robot-science/rofunc/simulator/assets/urdf/curi_mini/meshes/wheel_right_link_1.stl" scale="0.001 0.001 0.001"/>
      </geometry>
    </collision>
  </link>
  <link name="leg_right_link_1">
    <inertial>
      <origin xyz="0.014639616641252011 -0.007999847806308108 -0.0566266115993988" rpy="0 0 0"/>
      <mass value="0.8157102710156714"/>
      <inertia ixx="0.002301" iyy="0.002556" izz="0.00029" ixy="-0.0" iyz="0.0" ixz="0.000189"/>
    </inertial>
    <visual>
      <origin xyz="-0.00036 0.171447 -0.379" rpy="0 0 0"/>
      <geometry>
        <mesh filename="/home/ubuntu/Github/Knowledge-Universe/Robotics/Roadmap-for-robot-science/rofunc/simulator/assets/urdf/curi_mini/meshes/leg_right_link_1.stl" scale="0.001 0.001 0.001"/>
      </geometry>
      <material name="silver"/>
    </visual>
    <collision>
      <origin xyz="-0.00036 0.171447 -0.379" rpy="0 0 0"/>
      <geometry>
        <mesh filename="/home/ubuntu/Github/Knowledge-Universe/Robotics/Roadmap-for-robot-science/rofunc/simulator/assets/urdf/curi_mini/meshes/leg_right_link_1.stl" scale="0.001 0.001 0.001"/>
      </geometry>
    </collision>
  </link>
  <link name="leg2_right_link_1">
    <inertial>
      <origin xyz="2.166854021847008e-06 -0.012347127307788974 -0.09236370869313185" rpy="0 0 0"/>
      <mass value="1.4310112929252925"/>
      <inertia ixx="0.003787" iyy="0.003963" izz="0.000327" ixy="0.0" iyz="-5.8e-05" ixz="-0.0"/>
    </inertial>
    <visual>
      <origin xyz="-0.00036 0.187447 -0.239" rpy="0 0 0"/>
      <geometry>
        <mesh filename="/home/ubuntu/Github/Knowledge-Universe/Robotics/Roadmap-for-robot-science/rofunc/simulator/assets/urdf/curi_mini/meshes/leg2_right_link_1.stl" scale="0.001 0.001 0.001"/>
      </geometry>
      <material name="silver"/>
    </visual>
    <collision>
      <origin xyz="-0.00036 0.187447 -0.239" rpy="0 0 0"/>
      <geometry>
        <mesh filename="/home/ubuntu/Github/Knowledge-Universe/Robotics/Roadmap-for-robot-science/rofunc/simulator/assets/urdf/curi_mini/meshes/leg2_right_link_1.stl" scale="0.001 0.001 0.001"/>
      </geometry>
    </collision>
  </link>
  <link name="wheel_left_link_1">
    <inertial>
      <origin xyz="3.4736125110096166e-07 -0.025999550959093704 -9.328040287415185e-08" rpy="0 0 0"/>
      <mass value="10.922078484346637"/>
      <inertia ixx="0.025678" iyy="0.046537" izz="0.025678" ixy="0.0" iyz="0.0" ixz="0.0"/>
    </inertial>
    <visual>
      <origin xyz="-0.00036 0.215147 -0.099" rpy="0 0 0"/>
      <geometry>
        <mesh filename="/home/ubuntu/Github/Knowledge-Universe/Robotics/Roadmap-for-robot-science/rofunc/simulator/assets/urdf/curi_mini/meshes/wheel_left_link_1.stl" scale="0.001 0.001 0.001"/>
      </geometry>
      <material name="silver"/>
    </visual>
    <collision>
      <origin xyz="-0.00036 0.215147 -0.099" rpy="0 0 0"/>
      <geometry>
        <mesh filename="/home/ubuntu/Github/Knowledge-Universe/Robotics/Roadmap-for-robot-science/rofunc/simulator/assets/urdf/curi_mini/meshes/wheel_left_link_1.stl" scale="0.001 0.001 0.001"/>
      </geometry>
    </collision>
  </link>
  <joint name="Rev1" type="continuous">
    <origin xyz="0.00036 -0.053347 0.379" rpy="0 0 0"/>
    <parent link="base_link"/>
    <child link="motor_right_link_1"/>
    <axis xyz="0.0 -1.0 0.0"/>
  </joint>
  <joint name="Rev2" type="continuous">
    <origin xyz="0.00036 0.053553 0.379" rpy="0 0 0"/>
    <parent link="base_link"/>
    <child link="motor_left_link_1"/>
    <axis xyz="0.0 1.0 0.0"/>
  </joint>
  <joint name="Rev3" type="continuous">
    <origin xyz="0.0 0.1181 0.0" rpy="0 0 0"/>
    <parent link="motor_left_link_1"/>
    <child link="leg_left_link_1"/>
    <axis xyz="0.0 1.0 0.0"/>
  </joint>
  <joint name="Rev4" type="continuous">
    <origin xyz="0.0 0.016 -0.14" rpy="0 0 0"/>
    <parent link="leg_left_link_1"/>
    <child link="leg2_left_link_1"/>
    <axis xyz="0.0 1.0 -0.0"/>
  </joint>
  <joint name="Rev5" type="continuous">
    <origin xyz="0.0 0.0277 -0.14" rpy="0 0 0"/>
    <parent link="leg2_left_link_1"/>
    <child link="wheel_right_link_1"/>
    <axis xyz="0.0 1.0 0.0"/>
  </joint>
  <joint name="Rev6" type="continuous">
    <origin xyz="0.0 -0.1181 0.0" rpy="0 0 0"/>
    <parent link="motor_right_link_1"/>
    <child link="leg_right_link_1"/>
    <axis xyz="0.0 -1.0 0.0"/>
  </joint>
  <joint name="Rev7" type="continuous">
    <origin xyz="0.0 -0.016 -0.14" rpy="0 0 0"/>
    <parent link="leg_right_link_1"/>
    <child link="leg2_right_link_1"/>
    <axis xyz="0.0 -1.0 -0.0"/>
  </joint>
  <joint name="Rev8" type="continuous">
    <origin xyz="0.0 -0.0277 -0.14" rpy="0 0 0"/>
    <parent link="leg2_right_link_1"/>
    <child link="wheel_left_link_1"/>
    <axis xyz="0.0 -1.0 -0.0"/>
  </joint>
</robot>
