<robot name="walker">
  <link name="world"/>
  <joint name="reference" type="floating">
    <parent link="world"/>
    <child link="base_link"/>
  </joint>
  <link name="base_link"/>
  <link name="torso">
    <inertial>
      <origin
          xyz="-0.00124874653232382 0.000246598785695634 -0.111598785207968"
          rpy="0 0 0"/>
      <mass
          value="20.773"/>
      <inertia
          ixx="0.0504230367553516"
          ixy="9.48207899309819E-06"
          ixz="0.000402652939677054"
          iyy="0.0425230890142075"
          iyz="3.19033530756639E-05"
          izz="0.0360972564220647"/>
    </inertial>
    <visual>
      <origin
          xyz="0 0 0"
          rpy="0 0 0"/>
      <geometry>
        <mesh
            filename="../meshes/base_link.STL"/>
      </geometry>
      <material
          name="">
        <color
            rgba="1 1 1 1"/>
      </material>
    </visual>
    <collision>
      <origin
          xyz="0 0 0"
          rpy="0 0 0"/>
      <geometry>
        <mesh
            filename="../meshes/base_link.STL"/>
      </geometry>
    </collision>
  </link>
  <joint
      name="torso_joint"
      type="fixed">
    <origin xyz="0 0 0" rpy="0 0 0"/>
    <parent link="base_link"/>
    <child link="torso"/>
  </joint>
  <link
      name="right_limb_l1">
    <inertial>
      <origin
          xyz="-0.00722075380474052 0.000182063550966449 -0.0361420965458128"
          rpy="0 0 0"/>
      <mass
          value="0.373"/>
      <inertia
          ixx="0.000311522358740572"
          ixy="9.35574756778796E-08"
          ixz="9.36994646655716E-06"
          iyy="0.000215286397239846"
          iyz="1.95199653306617E-07"
          izz="0.000396295467948814"/>
    </inertial>
    <visual>
      <origin
          xyz="0 0 0"
          rpy="0 0 0"/>
      <geometry>
        <mesh
            filename="../meshes/right_limb_l1.STL"/>
      </geometry>
      <material
          name="">
        <color
            rgba="0.752941176470588 0.752941176470588 0.752941176470588 1"/>
      </material>
    </visual>
    <collision>
      <origin
          xyz="0 0 0"
          rpy="0 0 0"/>
      <geometry>
        <mesh
            filename="../meshes/right_limb_l1.STL"/>
      </geometry>
    </collision>
  </link>
  <joint
      name="right_limb_j1"
      type="revolute">
    <origin
        xyz="0 -0.24142 0.018386"
        rpy="-1.9576E-06 1.3107 -1.5708"/>
    <parent
        link="torso"/>
    <child
        link="right_limb_l1"/>
    <axis
        xyz="0 0 -1"/>
    <limit
        lower="-3.1416"
        upper="0.7854"
        effort="30"
        velocity="2.0944"/>
  </joint>
  <link
      name="right_limb_l2">
    <inertial>
      <origin
          xyz="-0.00196280070849963 0.0273168501674689 -0.000134287637530872"
          rpy="0 0 0"/>
      <mass
          value="1.059"/>
      <inertia
          ixx="0.000358148474769472"
          ixy="4.04459296835339E-06"
          ixz="-1.32587419890355E-07"
          iyy="0.000288726351260568"
          iyz="-2.60810750383314E-07"
          izz="0.000390106430816898"/>
    </inertial>
    <visual>
      <origin
          xyz="0 0 0"
          rpy="0 0 0"/>
      <geometry>
        <mesh
            filename="../meshes/right_limb_l2.STL"/>
      </geometry>
      <material
          name="">
        <color
            rgba="0.752941176470588 0.752941176470588 0.752941176470588 1"/>
      </material>
    </visual>
    <collision>
      <origin
          xyz="0 0 0"
          rpy="0 0 0"/>
      <geometry>
        <mesh
            filename="../meshes/right_limb_l2.STL"/>
      </geometry>
    </collision>
  </link>
  <joint
      name="right_limb_j2"
      type="revolute">
    <origin
        xyz="0 0 0"
        rpy="2.5133 1.5708 0.94251"/>
    <parent
        link="right_limb_l1"/>
    <child
        link="right_limb_l2"/>
    <axis
        xyz="0 0 -1"/>
    <limit
        lower="-1.5708"
        upper="0.0175"
        effort="25"
        velocity="3.1416"/>
  </joint>
  <link
      name="right_limb_l3">
    <inertial>
      <origin
          xyz="0.00629656239509119 -0.000210202146791738 -0.0621806056819393"
          rpy="0 0 0"/>
      <mass
          value="1.311"/>
      <inertia
          ixx="0.000578598259089344"
          ixy="1.06936365158182E-06"
          ixz="-2.64856345206635E-05"
          iyy="0.00055597686018737"
          iyz="-3.95057844818449E-07"
          izz="0.000447021332772511"/>
    </inertial>
    <visual>
      <origin
          xyz="0 0 0"
          rpy="0 0 0"/>
      <geometry>
        <mesh
            filename="../meshes/right_limb_l3.STL"/>
      </geometry>
      <material
          name="">
        <color
            rgba="0.752941176470588 0.752941176470588 0.752941176470588 1"/>
      </material>
    </visual>
    <collision>
      <origin
          xyz="0 0 0"
          rpy="0 0 0"/>
      <geometry>
        <mesh
            filename="../meshes/right_limb_l3.STL"/>
      </geometry>
    </collision>
  </link>
  <joint
      name="right_limb_j3"
      type="revolute">
    <origin
        xyz="-0.00064368 0.22946 0"
        rpy="-1.5708 -5.382E-07 1.8518E-13"/>
    <parent
        link="right_limb_l2"/>
    <child
        link="right_limb_l3"/>
    <axis
        xyz="0 0 1"/>
    <limit
        lower="-1.9199"
        upper="1.9199"
        effort="15"
        velocity="3.1416"/>
  </joint>
  <link
      name="right_limb_l4">
    <inertial>
      <origin
          xyz="0.0187332468499471 0.0270289413426349 -0.000700111734367959"
          rpy="0 0 0"/>
      <mass
          value="1.025"/>
      <inertia
          ixx="0.000288414802228566"
          ixy="-3.8255971416539E-05"
          ixz="-1.37491897701913E-06"
          iyy="0.000238322279447384"
          iyz="-1.45890833294397E-06"
          izz="0.00032269764599304"/>
    </inertial>
    <visual>
      <origin
          xyz="0 0 0"
          rpy="0 0 0"/>
      <geometry>
        <mesh
            filename="../meshes/right_limb_l4.STL"/>
      </geometry>
      <material
          name="">
        <color
            rgba="0.752941176470588 0.752941176470588 0.752941176470588 1"/>
      </material>
    </visual>
    <collision>
      <origin
          xyz="0 0 0"
          rpy="0 0 0"/>
      <geometry>
        <mesh
            filename="../meshes/right_limb_l4.STL"/>
      </geometry>
    </collision>
  </link>
  <joint
      name="right_limb_j4"
      type="revolute">
    <origin
        xyz="0.02546 0 0"
        rpy="1.5708 -0.050009 -3.1416"/>
    <parent
        link="right_limb_l3"/>
    <child
        link="right_limb_l4"/>
    <axis
        xyz="0 0 -1"/>
    <limit
        lower="-2.234"
        upper="0"
        effort="15"
        velocity="3.1416"/>
  </joint>
  <link name="right_elbow"/>
  <joint name="right_elbow_joint" type="fixed">
    <origin
        xyz="0 0 0"
        rpy="0 -1.5708 -3.1416"/>
    <parent
        link="right_limb_l4"/>
    <child
        link="right_elbow"/>
    <axis
        xyz="0 0 1"/>
  </joint>
  <link
      name="right_limb_l5">
    <inertial>
      <origin
          xyz="-0.000596823513585643 0.000121710879949472 -0.0604708516266729"
          rpy="0 0 0"/>
      <mass
          value="0.523"/>
      <inertia
          ixx="0.000317212358011218"
          ixy="8.88268591235818E-08"
          ixz="-1.43322638083362E-06"
          iyy="0.000310459779022516"
          iyz="-1.31927102955734E-06"
          izz="0.00020181632910904"/>
    </inertial>
    <visual>
      <origin
          xyz="0 0 0"
          rpy="0 0 0"/>
      <geometry>
        <mesh
            filename="../meshes/right_limb_l5.STL"/>
      </geometry>
      <material
          name="">
        <color
            rgba="0.752941176470588 0.752941176470588 0.752941176470588 1"/>
      </material>
    </visual>
    <collision>
      <origin
          xyz="0 0 0"
          rpy="0 0 0"/>
      <geometry>
        <mesh
            filename="../meshes/right_limb_l5.STL"/>
      </geometry>
    </collision>
  </link>
  <joint
      name="right_limb_j5"
      type="revolute">
    <origin
        xyz="0.024799 0.20964 0"
        rpy="-0.26632 -1.5708 -1.3045"/>
    <parent
        link="right_limb_l4"/>
    <child
        link="right_limb_l5"/>
    <axis
        xyz="0 0 1"/>
    <limit
        lower="-2.3562"
        upper="2.3562"
        effort="2.5"
        velocity="4.8869"/>
  </joint>
  <link
      name="right_limb_l6">
    <inertial>
      <origin
          xyz="0.0128445139242113 0.000377301016695641 -0.000161615308550689"
          rpy="0 0 0"/>
      <mass
          value="0.167"/>
      <inertia
          ixx="2.98997054662723E-05"
          ixy="-1.80995710652571E-07"
          ixz="1.11151156519791E-08"
          iyy="1.83543369800577E-05"
          iyz="4.01989443243718E-09"
          izz="1.79177399902685E-05"/>
    </inertial>
    <visual>
      <origin
          xyz="0 0 0"
          rpy="0 0 0"/>
      <geometry>
        <mesh
            filename="../meshes/right_limb_l6.STL"/>
      </geometry>
      <material
          name="">
        <color
            rgba="0.752941176470588 0.752941176470588 0.752941176470588 1"/>
      </material>
    </visual>
    <collision>
      <origin
          xyz="0 0 0"
          rpy="0 0 0"/>
      <geometry>
        <mesh
            filename="../meshes/right_limb_l6.STL"/>
      </geometry>
    </collision>
  </link>
  <joint
      name="right_limb_j6"
      type="revolute">
    <origin
        xyz="0 0 0"
        rpy="-1.5708 -1.5708 3.1416"/>
    <parent
        link="right_limb_l5"/>
    <child
        link="right_limb_l6"/>
    <axis
        xyz="0 0 1"/>
    <limit
        lower="-0.3508"
        upper="0.3508"
        effort="2.5"
        velocity="3.1416"/>
  </joint>
  <link
      name="right_limb_l7">
    <inertial>
      <origin
          xyz="0.0128445139242113 -0.000161615367552381 -0.000377300991422524"
          rpy="0 0 0"/>
      <mass
          value="0.056"/>
      <inertia
          ixx="2.98997054662723E-05"
          ixy="1.11151439557976E-08"
          ixz="1.80995708914405E-07"
          iyy="1.79177399890113E-05"
          iyz="-4.01982615810442E-09"
          izz="1.83543369813149E-05"/>
    </inertial>
    <visual>
      <origin
          xyz="0 0 0"
          rpy="0 0 0"/>
      <geometry>
        <mesh
            filename="../meshes/right_limb_l7.STL"/>
      </geometry>
      <material
          name="">
        <color
            rgba="0.752941176470588 0.752941176470588 0.752941176470588 1"/>
      </material>
    </visual>
    <collision>
      <origin
          xyz="0 0 0"
          rpy="0 0 0"/>
      <geometry>
        <mesh
            filename="../meshes/right_limb_l7.STL"/>
      </geometry>
    </collision>
  </link>
  <joint
      name="right_limb_j7"
      type="revolute">
    <origin
        xyz="0 0 0"
        rpy="1.5708 -5.9686E-17 -1.3235E-23"/>
    <parent
        link="right_limb_l6"/>
    <child
        link="right_limb_l7"/>
    <axis
        xyz="0 0 1"/>
  </joint>
  <link
      name="right_palm_link">
    <inertial>
      <origin
          xyz="-0.0144809215118954 -0.0132347085538364 0.022306335464008"
          rpy="0 0 0"/>
      <mass
          value="0.0852752510078387"/>
      <inertia
          ixx="0.000154775131402232"
          ixy="1.85109602266807E-05"
          ixz="7.47252049170957E-06"
          iyy="0.000107981762301999"
          iyz="-1.08345230717271E-06"
          izz="0.000125562926987643"/>
    </inertial>
    <visual>
      <origin
          xyz="0 0 0"
          rpy="0 0 0"/>
      <geometry>
        <mesh
            filename="../meshes/right_hand.STL"/>
      </geometry>
      <material
          name="">
        <color
            rgba="0.752941176470588 0.752941176470588 0.752941176470588 1"/>
      </material>
    </visual>
    <collision>
      <origin
          xyz="0 0 0"
          rpy="0 0 0"/>
      <geometry>
        <mesh
            filename="../meshes/right_hand.STL"/>
      </geometry>
    </collision>
  </link>
  <joint
      name="right_palm_joint"
      type="fixed">
    <origin
        xyz="0.074796 0.011942 -0.02228"
        rpy="-1.0945E-07 -1.947E-07 1.7826"/>
    <parent
        link="right_limb_l7"/>
    <child
        link="right_palm_link"/>
    <axis
        xyz="0 0 0"/>
  </joint>

  <joint name="right_spoon_joint" type="fixed">
    <origin rpy="1 -0.3 1.5" xyz="0 0 0"/>
    <parent link="right_palm_link"/>
    <child link="spoon_link"/>
    <axis xyz="0 0 1"/>
    <dynamics damping="0.0" friction="0.0"/>
    <limit effort="100" lower="0.0" upper="1.571" velocity="100"/>
  </joint>
  <link name="spoon_link">
    <inertial>
      <mass value="0.01"/>
      <origin rpy="0 0 0" xyz="1.3071561e-02 2.7346340e-03 6.4090487e-04"/>
      <inertia ixx="3.5827953e-07" ixy="-2.0934657e-07" ixz="-6.8435459e-08" iyy="1.3882698e-06" iyz="-3.2001578e-08" izz="1.3570267e-06"/>
    </inertial>
    <visual>
      <origin rpy="1.3787 0.3490 0.3839" xyz="0 0 0"/>
      <geometry>
        <mesh filename="../../objects/pan_spoon/spoon.obj" scale="-1 1 1"/>
      </geometry>
      <material name="qbhand/spoon">
        <color rgba="0.35 0.35 0.35 1.0"/>
      </material>
    </visual>
    <collision>
      <origin rpy="1.3787 0.3490 0.3839" xyz="0 0 0"/>
      <geometry>
        <mesh filename="../../objects/pan_spoon/spoon.obj" scale="-1 1 1"/>
      </geometry>
    </collision>
  </link>


  <link name="right_tcp">
  </link>
  <joint name="right_tcp_joint" type="fixed">
    <origin
        xyz="0.02 -0.05 0.015"
        rpy="0.12217304763960307 -1.5707963267948966 0.0"/>
    <parent link="right_palm_link"/>
    <child link="right_tcp"/>
    <axis xyz="0 0 0"/>
  </joint>
  <link name="right_palm_tcp"/>
  <joint name="right_palm_tcp_joint" type="fixed">
    <origin
        xyz="0.08 -0.03 0.015"
        rpy="0.12217304763960307 -1.5707963267948966 -0.8"/>
    <parent link="right_palm_link"/>
    <child link="right_palm_tcp"/>
    <axis xyz="0 0 0"/>
  </joint>
  <link
      name="left_limb_l1">
    <inertial>
      <origin
          xyz="-0.00723118478663559 -0.00017669295908318 -0.0361510146492087"
          rpy="0 0 0"/>
      <mass
          value="0.373"/>
      <inertia
          ixx="0.000311546571609671"
          ixy="1.46233470422137E-07"
          ixz="9.38915560600786E-06"
          iyy="0.000215270106429758"
          iyz="-1.74887531239602E-07"
          izz="0.000396323890766572"/>
    </inertial>
    <visual>
      <origin
          xyz="0 0 0"
          rpy="0 0 0"/>
      <geometry>
        <mesh
            filename="../meshes/left_limb_l1.STL"/>
      </geometry>
      <material
          name="">
        <color
            rgba="0.752941176470588 0.752941176470588 0.752941176470588 1"/>
      </material>
    </visual>
    <collision>
      <origin
          xyz="0 0 0"
          rpy="0 0 0"/>
      <geometry>
        <mesh
            filename="../meshes/left_limb_l1.STL"/>
      </geometry>
    </collision>
  </link>
  <joint
      name="left_limb_j1"
      type="revolute">
    <origin
        xyz="0 0.24142 0.018386"
        rpy="-1.931E-07 1.3073 1.5708"/>
    <parent
        link="torso"/>
    <child
        link="left_limb_l1"/>
    <axis
        xyz="0 0 -1"/>
    <limit
        lower="-0.7854"
        upper="3.1416"
        effort="30"
        velocity="2.0944"/>
  </joint>
  <link
      name="left_limb_l2">
    <inertial>
      <origin
          xyz="-0.000955809738594438 -0.0269333403261617 -0.000117719319276233"
          rpy="0 0 0"/>
      <mass
          value="1.059"/>
      <inertia
          ixx="0.000356827361185567"
          ixy="-1.12533439596274E-06"
          ixz="-2.65449628458879E-07"
          iyy="0.000282975717348096"
          iyz="3.29216684248277E-07"
          izz="0.000383024214388443"/>
    </inertial>
    <visual>
      <origin
          xyz="0 0 0"
          rpy="0 0 0"/>
      <geometry>
        <mesh
            filename="../meshes/left_limb_l2.STL"/>
      </geometry>
      <material
          name="">
        <color
            rgba="0.752941176470588 0.752941176470588 0.752941176470588 1"/>
      </material>
    </visual>
    <collision>
      <origin
          xyz="0 0 0"
          rpy="0 0 0"/>
      <geometry>
        <mesh
            filename="../meshes/left_limb_l2.STL"/>
      </geometry>
    </collision>
  </link>
  <joint
      name="left_limb_j2"
      type="revolute">
    <origin
        xyz="0 0 0"
        rpy="-1.5708 1.5708 0"/>
    <parent
        link="left_limb_l1"/>
    <child
        link="left_limb_l2"/>
    <axis
        xyz="0 0 1"/>
    <limit
        lower="-1.5708"
        upper="0.0175"
        effort="25"
        velocity="3.1416"/>
  </joint>
  <link
      name="left_limb_l3">
    <inertial>
      <origin
          xyz="0.00627269966291388 0.000194319566014622 -0.0621535107459377"
          rpy="0 0 0"/>
      <mass
          value="1.311"/>
      <inertia
          ixx="0.000578159440804691"
          ixy="-1.08669345396034E-06"
          ixz="-2.63187856402938E-05"
          iyy="0.000555746273124769"
          iyz="2.4274818506786E-07"
          izz="0.00044678193897698"/>
    </inertial>
    <visual>
      <origin
          xyz="0 0 0"
          rpy="0 0 0"/>
      <geometry>
        <mesh
            filename="../meshes/left_limb_l3.STL"/>
      </geometry>
      <material
          name="">
        <color
            rgba="0.752941176470588 0.752941176470588 0.752941176470588 1"/>
      </material>
    </visual>
    <collision>
      <origin
          xyz="0 0 0"
          rpy="0 0 0"/>
      <geometry>
        <mesh
            filename="../meshes/left_limb_l3.STL"/>
      </geometry>
    </collision>
  </link>
  <joint
      name="left_limb_j3"
      type="revolute">
    <origin
        xyz="-0.00064368 -0.2285 0"
        rpy="1.5708 6.1653E-11 -2.7756E-17"/>
    <parent
        link="left_limb_l2"/>
    <child
        link="left_limb_l3"/>
    <axis
        xyz="0 0 1"/>
    <limit
        lower="-1.9199"
        upper="1.9199"
        effort="15"
        velocity="3.1416"/>
  </joint>
  <link
      name="left_limb_l4">
    <inertial>
      <origin
          xyz="0.0187474263134242 -0.0269365900000591 -0.000697445026925148"
          rpy="0 0 0"/>
      <mass
          value="1.025"/>
      <inertia
          ixx="0.00028845420774769"
          ixy="3.8269969495632E-05"
          ixz="-1.3877529241391E-06"
          iyy="0.000238329463729006"
          iyz="1.48262510934952E-06"
          izz="0.000322652845197085"/>
    </inertial>
    <visual>
      <origin
          xyz="0 0 0"
          rpy="0 0 0"/>
      <geometry>
        <mesh
            filename="../meshes/left_limb_l4.STL"/>
      </geometry>
      <material
          name="">
        <color
            rgba="0.752941176470588 0.752941176470588 0.752941176470588 1"/>
      </material>
    </visual>
    <collision>
      <origin
          xyz="0 0 0"
          rpy="0 0 0"/>
      <geometry>
        <mesh
            filename="../meshes/left_limb_l4.STL"/>
      </geometry>
    </collision>
  </link>
  <joint
      name="left_limb_j4"
      type="revolute">
    <origin
        xyz="0.025422 0 0"
        rpy="-1.5708 -0.046339 3.1416"/>
    <parent
        link="left_limb_l3"/>
    <child
        link="left_limb_l4"/>
    <axis
        xyz="0 0 1"/>
    <limit
        lower="-2.234"
        upper="0"
        effort="15"
        velocity="3.1416"/>
  </joint>
  <link name="left_elbow"/>
  <joint name="left_elbow_joint" type="fixed">
    <origin
        xyz="0 0 0"
        rpy="0 -1.5708 -3.1416"/>
    <parent
        link="left_limb_l4"/>
    <child
        link="left_elbow"/>
    <axis
        xyz="0 0 1"/>
  </joint>
  <link
      name="left_limb_l5">
    <inertial>
      <origin
          xyz="0.000547047098985953 -0.000122519646229002 -0.0604686375411661"
          rpy="0 0 0"/>
      <mass
          value="0.523"/>
      <inertia
          ixx="0.000317253893378651"
          ixy="9.52809865357166E-09"
          ixz="1.23465056753509E-06"
          iyy="0.000310424822694839"
          iyz="1.30897117817618E-06"
          izz="0.000201818691915647"/>
    </inertial>
    <visual>
      <origin
          xyz="0 0 0"
          rpy="0 0 0"/>
      <geometry>
        <mesh
            filename="../meshes/left_limb_l5.STL"/>
      </geometry>
      <material
          name="">
        <color
            rgba="0.752941176470588 0.752941176470588 0.752941176470588 1"/>
      </material>
    </visual>
    <collision>
      <origin
          xyz="0 0 0"
          rpy="0 0 0"/>
      <geometry>
        <mesh
            filename="../meshes/left_limb_l5.STL"/>
      </geometry>
    </collision>
  </link>
  <joint
      name="left_limb_j5"
      type="revolute">
    <origin
        xyz="0.024818 -0.22241 0"
        rpy="-1.5708 -1.5708 -3.1416"/>
    <parent
        link="left_limb_l4"/>
    <child
        link="left_limb_l5"/>
    <axis
        xyz="0 0 1"/>
    <limit
        lower="-2.3562"
        upper="2.3562"
        effort="2.5"
        velocity="4.8869"/>
  </joint>
  <link
      name="left_limb_l6">
    <inertial>
      <origin
          xyz="0.0125425664529848 0.000622049029732841 0.00052226894134122"
          rpy="0 0 0"/>
      <mass
          value="0.167"/>
      <inertia
          ixx="2.99031109754486E-05"
          ixy="1.80107466242642E-07"
          ixz="1.2083547861946E-08"
          iyy="1.83549287965366E-05"
          iyz="-3.56041365932579E-09"
          izz="1.7918623567772E-05"/>
    </inertial>
    <visual>
      <origin
          xyz="0 0 0"
          rpy="0 0 0"/>
      <geometry>
        <mesh
            filename="../meshes/left_limb_l6.STL"/>
      </geometry>
      <material
          name="">
        <color
            rgba="0.752941176470588 0.752941176470588 0.752941176470588 1"/>
      </material>
    </visual>
    <collision>
      <origin
          xyz="0 0 0"
          rpy="0 0 0"/>
      <geometry>
        <mesh
            filename="../meshes/left_limb_l6.STL"/>
      </geometry>
    </collision>
  </link>
  <joint
      name="left_limb_j6"
      type="revolute">
    <origin
        xyz="0 0 0"
        rpy="1.5708 -1.5708 0"/>
    <parent
        link="left_limb_l5"/>
    <child
        link="left_limb_l6"/>
    <axis
        xyz="0 0 -1"/>
    <limit
        lower="-0.3508"
        upper="0.3508"
        effort="2.5"
        velocity="3.1416"/>
  </joint>
  <link
      name="left_limb_l7">
    <inertial>
      <origin
          xyz="0.0125425664529848 0.00052226894134122 -0.000622049029732841"
          rpy="0 0 0"/>
      <mass
          value="0.056"/>
      <inertia
          ixx="2.99031109754486E-05"
          ixy="1.2083547861945E-08"
          ixz="-1.80107466242643E-07"
          iyy="1.7918623567772E-05"
          iyz="3.56041365932608E-09"
          izz="1.83549287965366E-05"/>
    </inertial>
    <visual>
      <origin
          xyz="0 0 0"
          rpy="0 0 0"/>
      <geometry>
        <mesh
            filename="../meshes/left_limb_l7.STL"/>
      </geometry>
      <material
          name="">
        <color
            rgba="0.752941176470588 0.752941176470588 0.752941176470588 1"/>
      </material>
    </visual>
    <collision>
      <origin
          xyz="0 0 0"
          rpy="0 0 0"/>
      <geometry>
        <mesh
            filename="../meshes/left_limb_l7.STL"/>
      </geometry>
    </collision>
  </link>
  <joint
      name="left_limb_j7"
      type="revolute">
    <origin
        xyz="0 0 0"
        rpy="1.5708 3.0389E-17 6.4236E-24"/>
    <parent
        link="left_limb_l6"/>
    <child
        link="left_limb_l7"/>
    <axis
        xyz="0 0 -1"/>
  </joint>
  <link
      name="left_palm_link">
    <inertial>
      <origin
          xyz="0.015922919736204 -0.0138313214453597 0.0219045185061652"
          rpy="0 0 0"/>
      <mass
          value="0.0819372257156439"/>
      <inertia
          ixx="0.000153363835173176"
          ixy="1.67361413147736E-05"
          ixz="6.26037102347951E-06"
          iyy="0.000103099876290357"
          iyz="-5.28417728738961E-07"
          izz="0.000120087679020098"/>
    </inertial>
    <visual>
      <origin
          xyz="0 0 0"
          rpy="0 0 0"/>
      <geometry>
        <mesh
            filename="../meshes/left_hand.STL"/>
      </geometry>
      <material
          name="">
        <color
            rgba="0.752941176470588 0.752941176470588 0.752941176470588 1"/>
      </material>
    </visual>
    <collision>
      <origin
          xyz="0 0 0"
          rpy="0 0 0"/>
      <geometry>
        <mesh
            filename="../meshes/left_hand.STL"/>
      </geometry>
    </collision>
  </link>
  <joint
      name="left_palm_joint"
      type="fixed">
    <origin
        xyz="0.073849 -0.0065547 -0.01588"
        rpy="-3.1478E-08 1.4374E-07 1.3553"/>
    <parent
        link="left_limb_l7"/>
    <child
        link="left_palm_link"/>
    <axis
        xyz="0 0 0"/>
  </joint>

  <joint name="left_pan_joint" type="fixed">
    <origin rpy="0 -0.8 -1.9" xyz="0 0 0"/>
    <parent link="left_palm_link"/>
    <child link="pan_link"/>
    <axis xyz="0 0 1"/>
    <dynamics damping="0.0" friction="0.0"/>
    <limit effort="100" lower="0.0" upper="1.571" velocity="100"/>
  </joint>
  <link name="pan_link">
    <inertial>
      <mass value="0.01"/>
      <origin rpy="0 0 0" xyz="1.3071561e-02 2.7346340e-03 6.4090487e-04"/>
      <inertia ixx="3.5827953e-07" ixy="-2.0934657e-07" ixz="-6.8435459e-08" iyy="1.3882698e-06" iyz="-3.2001578e-08" izz="1.3570267e-06"/>
    </inertial>
    <visual>
      <origin rpy="0 0 0" xyz="0 0 0"/>
      <geometry>
        <mesh filename="../../objects/pan_spoon/pan.obj" scale="1 1 -1"/>
      </geometry>
      <material name="qbhand/pan">
        <color rgba="0.35 0.35 0.35 1.0"/>
      </material>
    </visual>
    <collision>
      <origin rpy="0 0 0" xyz="0 0 0"/>
      <geometry>
        <mesh filename="../../objects/pan_spoon/pan.obj" scale="1 1 -1"/>
      </geometry>
    </collision>
  </link>



  <link name="left_tcp">
  </link>
  <joint name="left_tcp_joint" type="fixed">
    <origin
        xyz="-0.02 -0.05 0.015"
        rpy="3.01941960595019 -1.5707963267948966 0.0"/>
    <parent link="left_palm_link"/>
    <child link="left_tcp"/>
    <axis xyz="0 0 0"/>
  </joint>
  <link name="left_palm_tcp"/>
  <joint name="left_palm_tcp_joint" type="fixed">
    <origin
        xyz="-0.08 -0.03 0.015"
        rpy="3.01941960595019 -1.5707963267948966 0.4"/>
    <parent link="left_palm_link"/>
    <child link="left_palm_tcp"/>
    <axis xyz="0 0 0"/>
  </joint>
  <link
      name="head_l1">
    <inertial>
      <origin
          xyz="-0.00101176466106917 2.14927259107045E-05 2.40864327796242E-05"
          rpy="0 0 0"/>
      <mass
          value="0.11"/>
      <inertia
          ixx="4.47378645859373E-05"
          ixy="2.81915971144153E-10"
          ixz="-2.73721904719924E-10"
          iyy="4.50204226321243E-05"
          iyz="9.47033251933937E-08"
          izz="8.09468687396382E-05"/>
    </inertial>
    <visual>
      <origin
          xyz="0 0 0"
          rpy="0 0 0"/>
      <geometry>
        <mesh
            filename="../meshes/head_l1.STL"/>
      </geometry>
      <material
          name="">
        <color
            rgba="0.752941176470588 0.752941176470588 0.752941176470588 1"/>
      </material>
    </visual>
    <collision>
      <origin
          xyz="0 0 0"
          rpy="0 0 0"/>
      <geometry>
        <mesh
            filename="../meshes/head_l1.STL"/>
      </geometry>
    </collision>
  </link>
  <joint
      name="head_j1"
      type="revolute">
    <origin
        xyz="0 -0.00016327 0.098503"
        rpy="0.0016575 -7.7846E-07 -1.2903E-09"/>
    <parent
        link="torso"/>
    <child
        link="head_l1"/>
    <axis
        xyz="0 0 1"/>
    <limit
        lower="-1.5708"
        upper="1.5708"
        effort="10.0"
        velocity="1.8"/>
    <dynamics damping="5" friction="0.0"/>
  </joint>
  <link
      name="head_l2">
    <inertial>
      <origin
          xyz="-0.00101176466106923 2.40864327795132E-05 -2.14927259107323E-05"
          rpy="0 0 0"/>
      <mass
          value="2.003"/>
      <inertia
          ixx="4.47378645859373E-05"
          ixy="-2.73721904719871E-10"
          ixz="-2.81915971158962E-10"
          iyy="8.09468687396382E-05"
          iyz="-9.47033251933937E-08"
          izz="4.50204226321243E-05"/>
    </inertial>
    <visual>
      <origin
          xyz="0 0 0"
          rpy="0 0 0"/>
      <geometry>
        <mesh
            filename="../meshes/head_l2.STL"/>
      </geometry>
      <material
          name="">
        <color
            rgba="0.752941176470588 0.752941176470588 0.752941176470588 1"/>
      </material>
    </visual>
    <collision>
      <origin
          xyz="0 0 0"
          rpy="0 0 0"/>
      <geometry>
        <mesh
            filename="../meshes/head_l2.STL"/>
      </geometry>
    </collision>
  </link>
  <joint
      name="head_j2"
      type="revolute">
    <origin
        xyz="0 0 0"
        rpy="1.5708 0 0"/>
    <parent
        link="head_l1"/>
    <child
        link="head_l2"/>
    <axis
        xyz="0 0 -1"/>
    <limit
        lower="-0.2"
        upper="0.2"
        effort="10.0"
        velocity="1.8"/>
    <dynamics damping="5" friction="0.0"/>
  </joint>
  <link
      name="head_l3">
    <inertial>
      <origin
          xyz="3.54592869765136E-05 0.0428621473767309 -0.0791185735185245"
          rpy="0 0 0"/>
      <mass
          value="1.20773190668416"/>
      <inertia
          ixx="0.00745100600669459"
          ixy="-8.626335157939E-07"
          ixz="4.68776412376162E-06"
          iyy="0.00893488331919254"
          iyz="0.00039432451273699"
          izz="0.0106759110882988"/>
    </inertial>
    <visual>
      <origin
          xyz="0 0 0"
          rpy="0 0 0"/>
      <geometry>
        <mesh
            filename="../meshes/head_l3.STL"/>
      </geometry>
      <material
          name="">
        <color
            rgba="0.752941176470588 0.752941176470588 0.752941176470588 1"/>
      </material>
    </visual>
    <collision>
      <origin
          xyz="0 0 0"
          rpy="0 0 0"/>
      <geometry>
        <mesh
            filename="../meshes/head_l3.STL"/>
      </geometry>
    </collision>
  </link>
  <joint
      name="head_j3"
      type="fixed">
    <origin
        xyz="0.084415 0.093313 0.00013289"
        rpy="7.2818E-07 1.5708 0"/>
    <parent
        link="head_l2"/>
    <child
        link="head_l3"/>
    <axis
        xyz="0 0 0"/>
  </joint>
  <link
      name="right_leg_l1">
    <inertial>
      <origin
          xyz="5.11129158979606E-06 -0.00936418225303892 -0.0512174036838659"
          rpy="0 0 0"/>
      <mass
          value="0.988"/>
      <inertia
          ixx="0.00254235658315077"
          ixy="1.57337755179475E-07"
          ixz="-6.66232939731805E-08"
          iyy="0.00094385758061583"
          iyz="4.82425859167379E-05"
          izz="0.0019715721917557"/>
    </inertial>
    <visual>
      <origin
          xyz="0 0 0"
          rpy="0 0 0"/>
      <geometry>
        <mesh
            filename="../meshes/right_leg_l1.STL"/>
      </geometry>
      <material
          name="">
        <color
            rgba="0.752941176470588 0.752941176470588 0.752941176470588 1"/>
      </material>
    </visual>
    <collision>
      <origin
          xyz="0 0 0"
          rpy="0 0 0"/>
      <geometry>
        <mesh
            filename="../meshes/right_leg_l1.STL"/>
      </geometry>
    </collision>
  </link>
  <joint
      name="right_leg_j1"
      type="revolute">
    <origin
        xyz="0 -0.110 -0.43709"
        rpy="-3.1416 0.0016575 -1.5708"/>
    <parent
        link="torso"/>
    <child
        link="right_leg_l1"/>
    <axis
        xyz="0 0 -1"/>
    <limit
        lower="-1.0472"
        upper="1.0472"
        effort="30.0"
        velocity="2.0944"/>
    <dynamics damping="15" friction="0.0"/>
  </joint>
  <link
      name="right_leg_l2">
    <inertial>
      <origin
          xyz="-6.5633908391538E-06 -5.57679072622636E-05 -0.00164948244371405"
          rpy="0 0 0"/>
      <mass
          value="3.392"/>
      <inertia
          ixx="0.0012488527525295"
          ixy="-1.5318639928393E-07"
          ixz="1.42446025939976E-08"
          iyy="0.00186097534915346"
          iyz="1.09072987197785E-06"
          izz="0.00155483228726037"/>
    </inertial>
    <visual>
      <origin
          xyz="0 0 0"
          rpy="0 0 0"/>
      <geometry>
        <mesh
            filename="../meshes/right_leg_l2.STL"/>
      </geometry>
      <material
          name="">
        <color
            rgba="0.752941176470588 0.752941176470588 0.752941176470588 1"/>
      </material>
    </visual>
    <collision>
      <origin
          xyz="0 0 0"
          rpy="0 0 0"/>
      <geometry>
        <mesh
            filename="../meshes/right_leg_l2.STL"/>
      </geometry>
    </collision>
  </link>
  <joint
      name="right_leg_j2"
      type="revolute">
    <origin
        xyz="0 0 0"
        rpy="1.5708 -1.5708 0"/>
    <parent
        link="right_leg_l1"/>
    <child
        link="right_leg_l2"/>
    <axis
        xyz="0 0 1"/>
    <limit
        lower="-0.5236"
        upper="0.5236"
        effort="25.0"
        velocity="3.1416"/>
    <dynamics damping="8.0" friction="0.0"/>
  </joint>
  <link
      name="right_leg_l3">
    <inertial>
      <origin
          xyz="-6.5633908391538E-06 -0.00164948244371405 5.57679072622636E-05"
          rpy="0 0 0"/>
      <mass
          value="4.637"/>
      <inertia
          ixx="0.0012488527525295"
          ixy="1.42446025940514E-08"
          ixz="1.5318639928393E-07"
          iyy="0.00155483228726037"
          iyz="-1.09072987197784E-06"
          izz="0.00186097534915346"/>
    </inertial>
    <visual>
      <origin
          xyz="0 0 0"
          rpy="0 0 0"/>
      <geometry>
        <mesh
            filename="../meshes/right_leg_l3.STL"/>
      </geometry>
      <material
          name="">
        <color
            rgba="0.752941176470588 0.752941176470588 0.752941176470588 1"/>
      </material>
    </visual>
    <collision>
      <origin
          xyz="0 0 0"
          rpy="0 0 0"/>
      <geometry>
        <mesh
            filename="../meshes/right_leg_l3.STL"/>
      </geometry>
    </collision>
  </link>
  <joint
      name="right_leg_j3"
      type="revolute">
    <origin
        xyz="0 0 0"
        rpy="1.5708 0 -3.6455E-33"/>
    <parent
        link="right_leg_l2"/>
    <child
        link="right_leg_l3"/>
    <axis
        xyz="0 0 -1"/>
    <limit
        lower="-1.3963"
        upper="0.5236"
        effort="15.0"
        velocity="3.1416"/>
    <dynamics damping="5.0" friction="0.0"/>
  </joint>
  <link
      name="right_leg_link1">
    <inertial>
      <origin
          xyz="-0.00142087955151146 0.0169322449435227 0.0018595931132096"
          rpy="0 0 0"/>
      <mass
          value="6.606"/>
      <inertia
          ixx="0.00954952360792742"
          ixy="-4.80368528637106E-05"
          ixz="-1.16597038259326E-05"
          iyy="0.00492713857542187"
          iyz="0.000202093537905228"
          izz="0.0117254451783956"/>
    </inertial>
    <visual>
      <origin
          xyz="0 0 0"
          rpy="0 0 0"/>
      <geometry>
        <mesh
            filename="../meshes/right_leg_link1.STL"/>
      </geometry>
      <material
          name="">
        <color
            rgba="0.752941176470588 0.752941176470588 0.752941176470588 1"/>
      </material>
    </visual>
    <collision>
      <origin
          xyz="0 0 0"
          rpy="0 0 0"/>
      <geometry>
        <mesh
            filename="../meshes/right_leg_link1.STL"/>
      </geometry>
    </collision>
  </link>
  <joint
      name="right_leg_joint1"
      type="fixed">
    <origin
        xyz="0.109108017985617 0.0115828770565157 -0.000478265954605414"
        rpy="1.57079632667051 1.5707963267949 0"/>
    <parent
        link="right_leg_l3"/>
    <child
        link="right_leg_link1"/>
    <axis
        xyz="0 0 0"/>
  </joint>
  <link
      name="right_leg_l4">
    <inertial>
      <origin
          xyz="0.144364908610918 0.00102666849127708 -0.0602126138281597"
          rpy="0 0 0"/>
      <mass
          value="2.852"/>
      <inertia
          ixx="0.00349428616791082"
          ixy="6.68850844345398E-05"
          ixz="-2.3461690047968E-05"
          iyy="0.00919226857078176"
          iyz="-6.35361998636887E-06"
          izz="0.00803458705956712"/>
    </inertial>
    <visual>
      <origin
          xyz="0 0 0"
          rpy="0 0 0"/>
      <geometry>
        <mesh
            filename="../meshes/right_leg_l4.STL"/>
      </geometry>
      <material
          name="">
        <color
            rgba="0.752941176470588 0.752941176470588 0.752941176470588 1"/>
      </material>
    </visual>
    <collision>
      <origin
          xyz="0 0 0"
          rpy="0 0 0"/>
      <geometry>
        <mesh
            filename="../meshes/right_leg_l4.STL"/>
      </geometry>
    </collision>
  </link>
  <joint
      name="right_leg_j4"
      type="revolute">
    <origin
        xyz="-0.062478 0.18089 0.011583"
        rpy="-1.5708 -1.2439E-10 1.5708"/>
    <parent
        link="right_leg_link1"/>
    <child
        link="right_leg_l4"/>
    <axis
        xyz="0 0 -1"/>
    <limit
        lower="-0.1745"
        upper="2.1817"
        effort="15.0"
        velocity="3.1416"/>
    <dynamics damping="5.0" friction="0.0"/>
  </joint>
  <link
      name="right_leg_l5">
    <inertial>
      <origin
          xyz="7.96335833541661E-06 0.000381749364422312 0.000653555695878161"
          rpy="0 0 0"/>
      <mass
          value="0.684"/>
      <inertia
          ixx="0.00109931070401539"
          ixy="-2.12453559703151E-07"
          ixz="9.96056672112188E-08"
          iyy="0.00122880276053965"
          iyz="7.33600925422275E-07"
          izz="0.00151564864910183"/>
    </inertial>
    <visual>
      <origin
          xyz="0 0 0"
          rpy="0 0 0"/>
      <geometry>
        <mesh
            filename="../meshes/right_leg_l5.STL"/>
      </geometry>
      <material
          name="">
        <color
            rgba="0.752941176470588 0.752941176470588 0.752941176470588 1"/>
      </material>
    </visual>
    <collision>
      <origin
          xyz="0 0 0"
          rpy="0 0 0"/>
      <geometry>
        <mesh
            filename="../meshes/right_leg_l5.STL"/>
      </geometry>
    </collision>
  </link>
  <joint
      name="right_leg_j5"
      type="revolute">
    <origin
        xyz="0.275 0 -0.0622"
        rpy="-2.4228E-16 -7.0505E-30 -2.4021E-16"/>
    <parent
        link="right_leg_l4"/>
    <child
        link="right_leg_l5"/>
    <axis
        xyz="0 0 -1"/>
    <limit
        lower="-1.3963"
        upper="0.5236"
        effort="10.0"
        velocity="3.1416"/>
    <dynamics damping="5.0" friction="0.5"/>
  </joint>
  <link
      name="right_leg_l6">
    <inertial>
      <origin
          xyz="7.96335833530559E-06 -0.000653555695878175 0.000381749364422368"
          rpy="0 0 0"/>
      <mass
          value="0.879"/>
      <inertia
          ixx="0.00109931070401539"
          ixy="-9.96056672111714E-08"
          ixz="-2.12453559703205E-07"
          iyy="0.00151564864910183"
          iyz="-7.33600925422326E-07"
          izz="0.00122880276053965"/>
    </inertial>
    <visual>
      <origin
          xyz="0 0 0"
          rpy="0 0 0"/>
      <geometry>
        <mesh
            filename="../meshes/right_leg_l6.STL"/>
      </geometry>
      <material
          name="">
        <color
            rgba="0.752941176470588 0.752941176470588 0.752941176470588 1"/>
      </material>
    </visual>
    <collision>
      <origin
          xyz="0 0 0"
          rpy="0 0 0"/>
      <geometry>
        <mesh
            filename="../meshes/right_leg_l6.STL"/>
      </geometry>
    </collision>
  </link>
  <joint
      name="right_leg_j6"
      type="revolute">
    <origin
        xyz="0 0 0"
        rpy="-1.5708 2.1861E-32 0"/>
    <parent
        link="right_leg_l5"/>
    <child
        link="right_leg_l6"/>
    <axis
        xyz="0 0 1"/>
    <limit
        lower="-0.5236"
        upper="0.5236"
        effort="10.0"
        velocity="3.1416"/>
    <dynamics damping="5.0" friction="0.5"/>
  </joint>
  <link
      name="right_leg_link2">
    <inertial>
      <origin
          xyz="5.34466089641278E-05 -0.0271413448383173 0.0158898181923479"
          rpy="0 0 0"/>
      <mass
          value="0.477"/>
      <inertia
          ixx="0.00616159172023952"
          ixy="1.09312906490756E-06"
          ixz="-1.69420307973724E-06"
          iyy="0.00563302608024886"
          iyz="0.000157121150126078"
          izz="0.0028391224604733"/>
    </inertial>
    <visual>
      <origin
          xyz="0 0 0"
          rpy="0 0 0"/>
      <geometry>
        <mesh
            filename="../meshes/right_leg_link2.STL"/>
      </geometry>
      <material
          name="">
        <color
            rgba="0.752941176470588 0.752941176470588 0.752941176470588 1"/>
      </material>
    </visual>
    <collision>
      <origin
          xyz="0 0 0"
          rpy="0 0 0"/>
      <geometry>
        <mesh
            filename="../meshes/right_leg_link2.STL"/>
      </geometry>
    </collision>
  </link>
  <joint
      name="right_leg_joint2"
      type="fixed">
    <origin
        xyz="0.0757484988059719 0 0"
        rpy="-1.24388213768849E-10 -1.32978657476726E-16 1.5707963267949"/>
    <parent
        link="right_leg_l6"/>
    <child
        link="right_leg_link2"/>
    <axis
        xyz="0 0 0"/>
  </joint>
  <link name="right_sole"/>
  <joint
      name="right_sole"
      type="fixed">
    <origin
        xyz="0 -0.064652 0"
        rpy="0 -1.5707 -1.5707"/>
    <parent
        link="right_leg_link2"/>
    <child
        link="right_sole"/>
    <axis
        xyz="0 0 0"/>
  </joint>
  <link
      name="left_leg_l1">
    <inertial>
      <origin
          xyz="-5.11729121482896E-06 0.00936420392659232 -0.0512174071313175"
          rpy="0 0 0"/>
      <mass
          value="0.988"/>
      <inertia
          ixx="0.00254235702064034"
          ixy="1.57444035565841E-07"
          ixz="6.65716426297285E-08"
          iyy="0.000943857844567228"
          iyz="-4.82425522581393E-05"
          izz="0.00197157321730625"/>
    </inertial>
    <visual>
      <origin
          xyz="0 0 0"
          rpy="0 0 0"/>
      <geometry>
        <mesh
            filename="../meshes/left_leg_l1.STL"/>
      </geometry>
      <material
          name="">
        <color
            rgba="0.752941176470588 0.752941176470588 0.752941176470588 1"/>
      </material>
    </visual>
    <collision>
      <origin
          xyz="0 0 0"
          rpy="0 0 0"/>
      <geometry>
        <mesh
            filename="../meshes/left_leg_l1.STL"/>
      </geometry>
    </collision>
  </link>
  <joint
      name="left_leg_j1"
      type="revolute">
    <origin
        xyz="0 0.110 -0.43677"
        rpy="3.1416 -0.0016575 1.5708"/>
    <parent
        link="torso"/>
    <child
        link="left_leg_l1"/>
    <axis
        xyz="0 0 -1"/>
    <limit
        lower="-1.0472"
        upper="1.0472"
        effort="30.0"
        velocity="2.0944"/>
    <dynamics damping="15" friction="0.0"/>
  </joint>
  <link
      name="left_leg_l2">
    <inertial>
      <origin
          xyz="-2.80791043860348E-06 -5.52021585495388E-05 -0.00165084747917321"
          rpy="0 0 0"/>
      <mass
          value="3.392"/>
      <inertia
          ixx="0.00124886157714483"
          ixy="-1.26116836235839E-07"
          ixz="-5.58754914566251E-08"
          iyy="0.00186090476591848"
          iyz="1.08419803614329E-06"
          izz="0.00155478511176639"/>
    </inertial>
    <visual>
      <origin
          xyz="0 0 0"
          rpy="0 0 0"/>
      <geometry>
        <mesh
            filename="../meshes/left_leg_l2.STL"/>
      </geometry>
      <material
          name="">
        <color
            rgba="0.752941176470588 0.752941176470588 0.752941176470588 1"/>
      </material>
    </visual>
    <collision>
      <origin
          xyz="0 0 0"
          rpy="0 0 0"/>
      <geometry>
        <mesh
            filename="../meshes/left_leg_l2.STL"/>
      </geometry>
    </collision>
  </link>
  <joint
      name="left_leg_j2"
      type="revolute">
    <origin
        xyz="0 0 0"
        rpy="1.5708 -1.5708 0"/>
    <parent
        link="left_leg_l1"/>
    <child
        link="left_leg_l2"/>
    <axis
        xyz="0 0 -1"/>
    <limit
        lower="-0.5236"
        upper="0.5236"
        effort="25.0"
        velocity="3.1416"/>
    <dynamics damping="8.0" friction="0.0"/>
  </joint>
  <link
      name="left_leg_l3">
    <inertial>
      <origin
          xyz="-2.80791043856185E-06 0.00165084747917332 -5.52021585495388E-05"
          rpy="0 0 0"/>
      <mass
          value="4.637"/>
      <inertia
          ixx="0.00124886157714483"
          ixy="5.58754914573585E-08"
          ixz="-1.26116836235851E-07"
          iyy="0.00155478511176639"
          iyz="-1.08419803614329E-06"
          izz="0.00186090476591849"/>
    </inertial>
    <visual>
      <origin
          xyz="0 0 0"
          rpy="0 0 0"/>
      <geometry>
        <mesh
            filename="../meshes/left_leg_l3.STL"/>
      </geometry>
      <material
          name="">
        <color
            rgba="0.752941176470588 0.752941176470588 0.752941176470588 1"/>
      </material>
    </visual>
    <collision>
      <origin
          xyz="0 0 0"
          rpy="0 0 0"/>
      <geometry>
        <mesh
            filename="../meshes/left_leg_l3.STL"/>
      </geometry>
    </collision>
  </link>
  <joint
      name="left_leg_j3"
      type="revolute">
    <origin
        xyz="0 0 0"
        rpy="1.5708 0 1.5647E-33"/>
    <parent
        link="left_leg_l2"/>
    <child
        link="left_leg_l3"/>
    <axis
        xyz="0 0 1"/>
    <limit
        lower="-1.3963"
        upper="0.5236"
        effort="15.0"
        velocity="3.1416"/>
    <dynamics damping="5.0" friction="0.0"/>
  </joint>
  <link
      name="left_leg_link1">
    <inertial>
      <origin
          xyz="0.00144392186031067 -0.0169601633210853 -0.00169801629659933"
          rpy="0 0 0"/>
      <mass
          value="6.606"/>
      <inertia
          ixx="0.00956077848823135"
          ixy="-4.83564083228461E-05"
          ixz="-1.12762450536798E-05"
          iyy="0.00493338150806551"
          iyz="0.000203803662618588"
          izz="0.0117303046260317"/>
    </inertial>
    <visual>
      <origin
          xyz="0 0 0"
          rpy="0 0 0"/>
      <geometry>
        <mesh
            filename="../meshes/left_leg_link1.STL"/>
      </geometry>
      <material
          name="">
        <color
            rgba="0.752941176470588 0.752941176470588 0.752941176470588 1"/>
      </material>
    </visual>
    <collision>
      <origin
          xyz="0 0 0"
          rpy="0 0 0"/>
      <geometry>
        <mesh
            filename="../meshes/left_leg_link1.STL"/>
      </geometry>
    </collision>
  </link>
  <joint
      name="left_leg_joint1"
      type="fixed">
    <origin
        xyz="0.10911 -0.011583 -0.00049937"
        rpy="1.5708 -1.5708 0"/>
    <parent
        link="left_leg_l3"/>
    <child
        link="left_leg_link1"/>
    <axis
        xyz="0 0 0"/>
  </joint>
  <link
      name="left_leg_l4">
    <inertial>
      <origin
          xyz="0.144283841094366 -0.00102279547401057 -0.0603084014166758"
          rpy="0 0 0"/>
      <mass
          value="2.852"/>
      <inertia
          ixx="0.00348790903629806"
          ixy="-6.72197320848782E-05"
          ixz="-2.20660425922093E-05"
          iyy="0.00918390431395075"
          iyz="5.28347099368274E-06"
          izz="0.00803159482751147"/>
    </inertial>
    <visual>
      <origin
          xyz="0 0 0"
          rpy="0 0 0"/>
      <geometry>
        <mesh
            filename="../meshes/left_leg_l4.STL"/>
      </geometry>
      <material
          name="">
        <color
            rgba="0.752941176470588 0.752941176470588 0.752941176470588 1"/>
      </material>
    </visual>
    <collision>
      <origin
          xyz="0 0 0"
          rpy="0 0 0"/>
      <geometry>
        <mesh
            filename="../meshes/left_leg_l4.STL"/>
      </geometry>
    </collision>
  </link>
  <joint
      name="left_leg_j4"
      type="revolute">
    <origin
        xyz="0.062499 -0.18089 -0.011583"
        rpy="-1.5708 1.2439E-10 -1.5708"/>
    <parent
        link="left_leg_link1"/>
    <child
        link="left_leg_l4"/>
    <axis
        xyz="0 0 1"/>
    <limit
        lower="-0.1745"
        upper="2.1817"
        effort="15.0"
        velocity="3.1416"/>
    <dynamics damping="5.0" friction="0.0"/>
  </joint>
  <link
      name="left_leg_l5">
    <inertial>
      <origin
          xyz="-8.2197777209192E-06 -0.000384779884713304 -0.000653186499701697"
          rpy="0 0 0"/>
      <mass
          value="0.684"/>
      <inertia
          ixx="0.00109932649823027"
          ixy="-3.62028115995048E-07"
          ixz="8.85639972401551E-08"
          iyy="0.00122863403306236"
          iyz="7.05340902749059E-07"
          izz="0.00151550242399035"/>
    </inertial>
    <visual>
      <origin
          xyz="0 0 0"
          rpy="0 0 0"/>
      <geometry>
        <mesh
            filename="../meshes/left_leg_l5.STL"/>
      </geometry>
      <material
          name="">
        <color
            rgba="0.752941176470588 0.752941176470588 0.752941176470588 1"/>
      </material>
    </visual>
    <collision>
      <origin
          xyz="0 0 0"
          rpy="0 0 0"/>
      <geometry>
        <mesh
            filename="../meshes/left_leg_l5.STL"/>
      </geometry>
    </collision>
  </link>
  <joint
      name="left_leg_j5"
      type="revolute">
    <origin
        xyz="0.275 0 -0.0622"
        rpy="-1.0408E-16 -3.8765E-15 -1.2439E-10"/>
    <parent
        link="left_leg_l4"/>
    <child
        link="left_leg_l5"/>
    <axis
        xyz="0 0 1"/>
    <limit
        lower="-1.3963"
        upper="0.5236"
        effort="10.0"
        velocity="3.1416"/>
    <dynamics damping="5.0" friction="0.5"/>
  </joint>
  <link
      name="left_leg_l6">
    <inertial>
      <origin
          xyz="-8.21977772069715E-06 -0.000653186499701752 0.00038477988471336"
          rpy="0 0 0"/>
      <mass
          value="0.879"/>
      <inertia
          ixx="0.00109932649823027"
          ixy="8.85639972402085E-08"
          ixz="3.62028115994795E-07"
          iyy="0.00151550242399035"
          iyz="-7.05340902749067E-07"
          izz="0.00122863403306236"/>
    </inertial>
    <visual>
      <origin
          xyz="0 0 0"
          rpy="0 0 0"/>
      <geometry>
        <mesh
            filename="../meshes/left_leg_l6.STL"/>
      </geometry>
      <material
          name="">
        <color
            rgba="0.752941176470588 0.752941176470588 0.752941176470588 1"/>
      </material>
    </visual>
    <collision>
      <origin
          xyz="0 0 0"
          rpy="0 0 0"/>
      <geometry>
        <mesh
            filename="../meshes/left_leg_l6.STL"/>
      </geometry>
    </collision>
  </link>
  <joint
      name="left_leg_j6"
      type="revolute">
    <origin
        xyz="0 0 0"
        rpy="1.5708 -1.0785E-32 0"/>
    <parent
        link="left_leg_l5"/>
    <child
        link="left_leg_l6"/>
    <axis
        xyz="0 0 1"/>
    <limit
        lower="-0.5236"
        upper="0.5236"
        effort="10.0"
        velocity="3.1416"/>
    <dynamics damping="5.0" friction="0.5"/>
  </joint>
  <link
      name="left_leg_link2">
    <inertial>
      <origin
          xyz="5.34681040891272E-05 -0.0269451313812346 0.0158898260414049"
          rpy="0 0 0"/>
      <mass
          value="0.477"/>
      <inertia
          ixx="0.00616225237983881"
          ixy="1.08684830545396E-06"
          ixz="-1.69375185248199E-06"
          iyy="0.005633025666212"
          iyz="0.000156811758916287"
          izz="0.00283978255808244"/>
    </inertial>
    <visual>
      <origin
          xyz="0 0 0"
          rpy="0 0 0"/>
      <geometry>
        <mesh
            filename="../meshes/left_leg_link2.STL"/>
      </geometry>
      <material
          name="">
        <color
            rgba="0.752941176470588 0.752941176470588 0.752941176470588 1"/>
      </material>
    </visual>
    <collision>
      <origin
          xyz="0 0 0"
          rpy="0 0 0"/>
      <geometry>
        <mesh
            filename="../meshes/left_leg_link2.STL"/>
      </geometry>
    </collision>
  </link>
  <joint
      name="left_leg_joint2"
      type="fixed">
    <origin
        xyz="0.075748 0 0"
        rpy="-5.5511E-17 -2.918E-16 1.5708"/>
    <parent
        link="left_leg_l6"/>
    <child
        link="left_leg_link2"/>
    <axis
        xyz="0 0 0"/>
  </joint>
  <link name="left_sole"/>
  <joint
      name="left_sole"
      type="fixed">
    <origin
        xyz="0 -0.064652 0"
        rpy="0 -1.5707 -1.5707"/>
    <parent
        link="left_leg_link2"/>
    <child
        link="left_sole"/>
    <axis
        xyz="0 0 0"/>
  </joint>
</robot>
