<mujoco model="bruce">
    <compiler angle="radian" meshdir="../../urdf/bruce/meshes/"/>
    <statistic meansize="0.0946615" extent="0.788322" center="0.0304631 0 -0.123623"/>
    <default>
        <motor ctrlrange="-1 1" ctrllimited="true"/>
        <default class="body">
            <geom type="capsule" condim="1" friction="1.0 0.05 0.05" solimp=".9 .99 .003" solref=".015 1"/>
            <joint type="hinge" damping="0.1" stiffness="5" armature=".007" limited="true" solimplimit="0 .99 .01"/>
            <site size=".04" group="3"/>
            <default class="force-torque">
                <site type="box" size=".01 .01 .02" rgba="1 0 0 1"/>
            </default>
            <default class="touch">
                <site type="capsule" rgba="0 0 1 .3"/>
            </default>
        </default>
    </default>
    <asset>
        <mesh name="base_link" file="base_link.STL"/>
        <mesh name="hip_yaw_link_r" file="hip_yaw_link_r.STL"/>
        <mesh name="hip_roll_link_r" file="hip_roll_link_r.STL"/>
        <mesh name="hip_pitch_link_r" file="hip_pitch_link_r.STL"/>
        <mesh name="knee_pitch_link_r" file="knee_pitch_link_r.STL"/>
        <mesh name="ankle_pitch_link_r" file="ankle_pitch_link_r.STL"/>
        <mesh name="hip_yaw_link_l" file="hip_yaw_link_l.STL"/>
        <mesh name="hip_roll_link_l" file="hip_roll_link_l.STL"/>
        <mesh name="hip_pitch_link_l" file="hip_pitch_link_l.STL"/>
        <mesh name="knee_pitch_link_l" file="knee_pitch_link_l.STL"/>
        <mesh name="ankle_pitch_link_l" file="ankle_pitch_link_l.STL"/>
        <mesh name="shoulder_pitch_link_r" file="shoulder_pitch_link_r.STL"/>
        <mesh name="shoulder_roll_link_r" file="shoulder_roll_link_r.STL"/>
        <mesh name="elbow_pitch_link_r" file="elbow_pitch_link_r.STL"/>
        <mesh name="shoulder_pitch_link_l" file="shoulder_pitch_link_l.STL"/>
        <mesh name="shoulder_roll_link_l" file="shoulder_roll_link_l.STL"/>
        <mesh name="elbow_pitch_link_l" file="elbow_pitch_link_l.STL"/>
    </asset>
    <worldbody>
        <light directional="true" pos="-0.5 0.5 3" dir="0 0 -1"/>
<!--        <geom name="floor" type="plane" conaffinity="1" size="100 100 .2"/>-->
        <body name="pelvis" pos="0 0 0.5" childclass="body">
            <geom type="mesh" contype="0" conaffinity="0" group="1" density="0" rgba="0.752941 0.752941 0.752941 1"
                  mesh="base_link"/>
            <geom type="mesh" rgba="0.752941 0.752941 0.752941 1" mesh="base_link"/>
            <body name="hip_yaw_link_r" pos="0.029216 -0.0758557 -0.039765" quat="0.707107 0 0 -0.707107">
                <inertial pos="2.71e-06 -0.00024824 0.00522427" quat="0.517691 0.482114 0.518083 0.480784"
                          mass="0.637563"
                          diaginertia="0.0016174 0.00152078 0.000485406"/>
                <joint name="hip_yaw_r" pos="0 0 0" axis="0 0 1" range="-3.1415 3.1415"/>
                <geom type="mesh" contype="0" conaffinity="0" group="1" density="0" rgba="0.752941 0.752941 0.752941 1"
                      mesh="hip_yaw_link_r"/>
                <geom type="mesh" rgba="0.752941 0.752941 0.752941 1" mesh="hip_yaw_link_r"/>
                <body name="hip_roll_link_r" pos="0 0 0" quat="0.5 -0.5 0.5 0.5">
                    <inertial pos="-1.51e-07 0 6.88e-06" mass="0.05" diaginertia="1e-05 1e-05 1e-05"/>
                    <joint name="hip_roll_r" pos="0 0 0" axis="0 0 1" range="-3.1415 3.1415"/>
                    <geom type="mesh" contype="0" conaffinity="0" group="1" density="0"
                          rgba="0.752941 0.752941 0.752941 1"
                          mesh="hip_roll_link_r"/>
                    <geom type="mesh" rgba="0.752941 0.752941 0.752941 1" mesh="hip_roll_link_r"/>
                    <body name="hip_pitch_link_r" pos="0 0 0" quat="0.707107 0.707107 0 0">
                        <inertial pos="0.140714 -0.0086817 0.00167429" quat="-0.0210718 0.710934 0.00543456 0.702922"
                                  mass="0.72849" diaginertia="0.0181996 0.0179488 0.000479326"/>
                        <joint name="hip_pitch_r" pos="0 0 0" axis="0 0 1" range="-3.1415 3.1415"/>
                        <geom type="mesh" contype="0" conaffinity="0" group="1" density="0"
                              rgba="0.752941 0.752941 0.752941 1" mesh="hip_pitch_link_r"/>
                        <geom type="mesh" rgba="0.752941 0.752941 0.752941 1" mesh="hip_pitch_link_r"/>
                        <body name="knee_pitch_link_r" pos="0.204949 0 0">
                            <inertial pos="0.0729308 0.0174645 0.00216432" quat="-0.0124752 0.71085 -0.0538621 0.701167"
                                      mass="0.0956654" diaginertia="0.00108397 0.00102192 0.000106307"/>
                            <joint name="knee_pitch_r" pos="0 0 0" axis="0 0 1" range="-3.1415 3.1415"/>
                            <geom type="mesh" contype="0" conaffinity="0" group="1" density="0"
                                  rgba="0.752941 0.752941 0.752941 1" mesh="knee_pitch_link_r"/>
                            <geom type="mesh" rgba="0.752941 0.752941 0.752941 1" mesh="knee_pitch_link_r"/>
                            <body name="ankle_pitch_link_r" pos="0.199881 0 0">
                                <inertial pos="0.0120775 0.0019746 0.00029511"
                                          quat="0.443128 0.545146 -0.456612 0.545855"
                                          mass="0.0276265" diaginertia="2.58838e-05 2.09859e-05 5.64035e-06"/>
                                <joint name="ankle_pitch_r" pos="0 0 0" axis="0 0 1" range="-3.1415 3.1415"/>
                                <geom type="mesh" contype="0" conaffinity="0" group="1" density="0"
                                      rgba="0.792157 0.819608 0.933333 1" mesh="ankle_pitch_link_r"/>
                                <geom type="mesh" rgba="0.792157 0.819608 0.933333 1" mesh="ankle_pitch_link_r"/>
                            </body>
                        </body>
                    </body>
                </body>
            </body>
            <body name="hip_yaw_link_l" pos="0.029216 0.0758557 -0.039765" quat="0.707107 0 0 -0.707107">
                <inertial pos="0 -0.00020849 0.00528032" quat="0.518836 0.480432 0.518756 0.480506" mass="0.637386"
                          diaginertia="0.00161868 0.00152047 0.0004852"/>
                <joint name="hip_yaw_l" pos="0 0 0" axis="0 0 1" range="-3.1415 3.1415"/>
                <geom type="mesh" contype="0" conaffinity="0" group="1" density="0" rgba="0.752941 0.752941 0.752941 1"
                      mesh="hip_yaw_link_l"/>
                <geom type="mesh" rgba="0.752941 0.752941 0.752941 1" mesh="hip_yaw_link_l"/>
                <body name="hip_roll_link_l" pos="0 0 0" quat="0.500001 -0.499999 0.500001 0.499999">
                    <inertial pos="-1.51e-07 0 6.88e-06" mass="0.05" diaginertia="1e-05 1e-05 1e-05"/>
                    <joint name="hip_roll_l" pos="0 0 0" axis="0 0 1" range="-3.1415 3.1415"/>
                    <geom type="mesh" contype="0" conaffinity="0" group="1" density="0"
                          rgba="0.752941 0.752941 0.752941 1"
                          mesh="hip_roll_link_l"/>
                    <geom type="mesh" rgba="0.752941 0.752941 0.752941 1" mesh="hip_roll_link_l"/>
                    <body name="hip_pitch_link_l" pos="0 0 0" quat="0.707107 0.707107 0 0">
                        <inertial pos="0.142447 -0.00832054 0.00049317" quat="-0.002203 0.702817 0.024599 0.710942"
                                  mass="0.720628" diaginertia="0.018195 0.0179541 0.000461885"/>
                        <joint name="hip_pitch_l" pos="0 0 0" axis="0 0 1" range="-3.1415 3.1415"/>
                        <geom type="mesh" contype="0" conaffinity="0" group="1" density="0"
                              rgba="0.752941 0.752941 0.752941 1" mesh="hip_pitch_link_l"/>
                        <geom type="mesh" rgba="0.752941 0.752941 0.752941 1" mesh="hip_pitch_link_l"/>
                        <body name="knee_pitch_link_l" pos="0.204949 0 0">
                            <inertial pos="0.0730996 0.0178102 -0.00219767" quat="0.0505999 0.70058 0.00930476 0.711716"
                                      mass="0.0952654" diaginertia="0.00107995 0.00101966 0.000104635"/>
                            <joint name="knee_pitch_l" pos="0 0 0" axis="0 0 1" range="-3.1415 3.1415"/>
                            <geom type="mesh" contype="0" conaffinity="0" group="1" density="0"
                                  rgba="0.752941 0.752941 0.752941 1" mesh="knee_pitch_link_l"/>
                            <geom type="mesh" rgba="0.752941 0.752941 0.752941 1" mesh="knee_pitch_link_l"/>
                            <body name="ankle_pitch_link_l" pos="0.199881 0 0">
                                <inertial pos="0.0123398 0.00253004 -0.00030441"
                                          quat="0.455603 0.546571 -0.442281 0.545962"
                                          mass="0.0274829" diaginertia="2.60237e-05 2.09939e-05 5.69233e-06"/>
                                <joint name="ankle_pitch_l" pos="0 0 0" axis="0 0 1" range="-3.1415 3.1415"/>
                                <geom type="mesh" contype="0" conaffinity="0" group="1" density="0"
                                      rgba="0.792157 0.819608 0.933333 1" mesh="ankle_pitch_link_l"/>
                                <geom type="mesh" rgba="0.792157 0.819608 0.933333 1" mesh="ankle_pitch_link_l"/>
                            </body>
                        </body>
                    </body>
                </body>
            </body>
            <body name="shoulder_pitch_link_r" pos="0.029216 -0.12375 0.152985" quat="0.5 0.5 -0.5 0.5">
                <inertial pos="0 -0.00038323 -0.0141368" quat="0.999984 0.0057278 0 0" mass="0.0493169"
                          diaginertia="2.507e-05 2.40321e-05 8.31794e-06"/>
                <joint name="shoulder_pitch_r" pos="0 0 0" axis="0 0 1" range="-1.57 1.57"/>
                <geom type="mesh" contype="0" conaffinity="0" group="1" density="0" rgba="0.752941 0.752941 0.752941 1"
                      mesh="shoulder_pitch_link_r"/>
                <geom type="mesh" rgba="0.752941 0.752941 0.752941 1" mesh="shoulder_pitch_link_r"/>
                <body name="shoulder_roll_link_r" pos="0 0 0" quat="0.5 0.5 -0.5 0.5">
                    <inertial pos="0.0570939 -0.00419463 0.00093738" quat="-0.205082 0.694437 -0.169487 0.66856"
                              mass="0.024" diaginertia="0.000126403 0.000125807 7.29e-06"/>
                    <joint name="shoulder_roll_r" pos="0 0 0" axis="0 0 1" range="-1.57 1.57"/>
                    <geom type="mesh" contype="0" conaffinity="0" group="1" density="0"
                          rgba="0.752941 0.752941 0.752941 1"
                          mesh="shoulder_roll_link_r"/>
                    <geom type="mesh" rgba="0.752941 0.752941 0.752941 1" mesh="shoulder_roll_link_r"/>
                    <body name="elbow_pitch_link_r" pos="0.1146 -0.005 0.005" quat="0.707107 0.707107 0 0">
                        <inertial pos="0.0217884 0 0.0003604" quat="0.499291 0.500708 0.500708 0.499291"
                                  mass="0.0524404"
                                  diaginertia="7.261e-05 7.10305e-05 7.52949e-06"/>
                        <joint name="elbow_pitch_r" pos="0 0 0" axis="0 0 1" range="-1.57 1.57"/>
                        <geom type="mesh" contype="0" conaffinity="0" group="1" density="0"
                              rgba="0.752941 0.752941 0.752941 1" mesh="elbow_pitch_link_r"/>
                        <geom type="mesh" rgba="0.752941 0.752941 0.752941 1" mesh="elbow_pitch_link_r"/>
                        <body name="hand_r" pos="0.12 0 0" quat="0.707107 0.707107 0 0">
                            <geom type="sphere" contype="0" conaffinity="1" size="0.005" rgba="0.752941 0.752941 0.752941 1"/>
                        </body>
                    </body>
                </body>
            </body>
            <body name="shoulder_pitch_link_l" pos="0.029216 0.12375 0.152985" quat="0.5 -0.5 0.5 0.5">
                <inertial pos="0 0.00038323 -0.0141368" quat="0.999984 -0.0057278 0 0" mass="0.0493169"
                          diaginertia="2.507e-05 2.40321e-05 8.31794e-06"/>
                <joint name="shoulder_pitch_l" pos="0 0 0" axis="0 0 1" range="-3.1415 3.1415"/>
                <geom type="mesh" contype="0" conaffinity="0" group="1" density="0" rgba="0.752941 0.752941 0.752941 1"
                      mesh="shoulder_pitch_link_l"/>
                <geom type="mesh" rgba="0.752941 0.752941 0.752941 1" mesh="shoulder_pitch_link_l"/>
                <body name="shoulder_roll_link_l" pos="0 0 0" quat="0.5 0.5 -0.5 0.5">
                    <inertial pos="0.0570939 0.00419463 0.00094155" quat="0.207025 0.693936 0.171489 0.667971"
                              mass="0.0313652" diaginertia="0.000165195 0.000164406 9.52871e-06"/>
                    <joint name="shoulder_roll_l" pos="0 0 0" axis="0 0 1" range="-1.57 1.57"/>
                    <geom type="mesh" contype="0" conaffinity="0" group="1" density="0"
                          rgba="0.752941 0.752941 0.752941 1"
                          mesh="shoulder_roll_link_l"/>
                    <geom type="mesh" rgba="0.752941 0.752941 0.752941 1" mesh="shoulder_roll_link_l"/>
                    <body name="elbow_pitch_link_l" pos="0.1146 0.005 0.005" quat="0.707107 -0.707107 0 0">
                        <inertial pos="0.0217884 0 0.0003604" quat="0.499291 0.500708 0.500708 0.499291"
                                  mass="0.0524404"
                                  diaginertia="7.261e-05 7.10305e-05 7.52949e-06"/>
                        <joint name="elbow_pitch_l" pos="0 0 0" axis="0 0 1" range="-1.57 1.57"/>
                        <geom type="mesh" contype="0" conaffinity="0" group="1" density="0"
                              rgba="0.752941 0.752941 0.752941 1" mesh="elbow_pitch_link_l"/>
                        <geom type="mesh" rgba="0.752941 0.752941 0.752941 1" mesh="elbow_pitch_link_l"/>
                        <body name="hand_l" pos="0.12 0 0" quat="0.707107 0.707107 0 0">
                            <geom type="sphere" contype="0" conaffinity="1" size="0.005" rgba="0.752941 0.752941 0.752941 1"/>
                        </body>
                    </body>
                </body>
            </body>
        </body>
    </worldbody>

    <actuator>
        <motor gear="1" joint="hip_yaw_r"/>
        <motor gear="1" joint="hip_roll_r"/>
        <motor gear="1" joint="hip_pitch_r"/>
        <motor gear="1" joint="knee_pitch_r"/>
        <motor gear="1" joint="ankle_pitch_r"/>
        <motor gear="1" joint="hip_yaw_l"/>
        <motor gear="1" joint="hip_roll_l"/>
        <motor gear="1" joint="hip_pitch_l"/>
        <motor gear="1" joint="knee_pitch_l"/>
        <motor gear="1" joint="ankle_pitch_l"/>
        <motor gear="1" joint="shoulder_pitch_r"/>
        <motor gear="1" joint="shoulder_roll_r"/>
        <motor gear="1" joint="elbow_pitch_r"/>
        <motor gear="1" joint="shoulder_pitch_l"/>
        <motor gear="1" joint="shoulder_roll_l"/>
        <motor gear="1" joint="elbow_pitch_l"/>
    </actuator>
</mujoco>
