<mujoco model="h1_description">
    <compiler angle="radian" meshdir="../../urdf/unitreeH1/meshes/"/>
    <statistic meansize="0.226223" extent="2.02548" center="0.015564 2.74848e-06 -0.182867"/>
    <default>
        <motor ctrlrange="-1 1" ctrllimited="true"/>
        <default class="body">
            <geom type="capsule" condim="1" friction="1.0 0.05 0.05" solimp=".9 .99 .003" solref=".015 1"/>
            <joint type="hinge" damping="0.1" stiffness="5" armature=".007" limited="true" solimplimit="0 .99 .01"/>
            <site size=".04" group="3"/>
            <default class="force-torque">
                <site type="box" size=".01 .01 .02" rgba="1 0 0 1"/>
            </default>
            <default class="touch">
                <site type="capsule" rgba="0 0 1 .3"/>
            </default>
        </default>
    </default>
    <asset>
        <mesh name="pelvis" file="pelvis.STL"/>
        <mesh name="left_hip_yaw_link" file="left_hip_yaw_link.STL"/>
        <mesh name="left_hip_roll_link" file="left_hip_roll_link.STL"/>
        <mesh name="left_hip_pitch_link" file="left_hip_pitch_link.STL"/>
        <mesh name="left_knee_link" file="left_knee_link.STL"/>
        <mesh name="left_ankle_link" file="left_ankle_link.STL"/>
        <mesh name="right_hip_yaw_link" file="right_hip_yaw_link.STL"/>
        <mesh name="right_hip_roll_link" file="right_hip_roll_link.STL"/>
        <mesh name="right_hip_pitch_link" file="right_hip_pitch_link.STL"/>
        <mesh name="right_knee_link" file="right_knee_link.STL"/>
        <mesh name="right_ankle_link" file="right_ankle_link.STL"/>
        <mesh name="torso_link" file="torso_link.STL"/>
        <mesh name="left_shoulder_pitch_link" file="left_shoulder_pitch_link.STL"/>
        <mesh name="left_shoulder_roll_link" file="left_shoulder_roll_link.STL"/>
        <mesh name="left_shoulder_yaw_link" file="left_shoulder_yaw_link.STL"/>
        <mesh name="left_elbow_link" file="left_elbow_link.STL"/>
        <mesh name="right_shoulder_pitch_link" file="right_shoulder_pitch_link.STL"/>
        <mesh name="right_shoulder_roll_link" file="right_shoulder_roll_link.STL"/>
        <mesh name="right_shoulder_yaw_link" file="right_shoulder_yaw_link.STL"/>
        <mesh name="right_elbow_link" file="right_elbow_link.STL"/>
        <mesh name="logo_link" file="logo_link.STL"/>
    </asset>
    <worldbody>
        <light directional="true" pos="-0.5 0.5 3" dir="0 0 -1"/>
        <geom name="floor" type="plane" conaffinity="1" size="100 100 .2"/>
        <body name="pelvis" pos="0 0 1" childclass="body">
            <!--            <freejoint name="root"/>-->
            <geom type="mesh" contype="0" conaffinity="0" group="1" density="0" rgba="0.1 0.1 0.1 1" mesh="pelvis"/>

            <body name="left_hip_yaw_link" pos="0 0.0875 -0.1742">
                <inertial pos="-0.04923 0.0001 0.0072" quat="0.69699 0.219193 0.233287 0.641667" mass="2.244"
                          diaginertia="0.00304494 0.00296885 0.00189201"/>
                <joint name="left_hip_yaw_joint" pos="0 0 0" axis="0 0 1" range="-0.43 0.43"/>
                <geom type="mesh" contype="0" conaffinity="0" group="1" density="0" rgba="0.1 0.1 0.1 1"
                      mesh="left_hip_yaw_link"/>
                <geom size="0.06 0.035" pos="-0.067 0 0" quat="0.707123 0 0.70709 0" type="cylinder"
                      rgba="0.1 0.1 0.1 1"/>
                <body name="left_hip_roll_link" pos="0.039468 0 0">
                    <inertial pos="-0.0058 -0.00319 -9e-05" quat="0.0438242 0.70721 -0.0729075 0.701867" mass="2.232"
                              diaginertia="0.00243264 0.00225325 0.00205492"/>
                    <joint name="left_hip_roll_joint" pos="0 0 0" axis="1 0 0" range="-0.43 0.43"/>
                    <geom type="mesh" contype="0" conaffinity="0" group="1" density="0" rgba="0.1 0.1 0.1 1"
                          mesh="left_hip_roll_link"/>
                    <geom type="mesh" rgba="0.1 0.1 0.1 1" mesh="left_hip_roll_link"/>
                    <body name="left_hip_pitch_link" pos="0 0.11536 0">
                        <inertial pos="0.00746 -0.02346 -0.08193" quat="0.979828 0.0513522 -0.0169854 -0.192382"
                                  mass="4.152" diaginertia="0.0829503 0.0821457 0.00510909"/>
                        <joint name="left_hip_pitch_joint" pos="0 0 0" axis="0 1 0" range="-1.57 1.57"/>
                        <geom type="mesh" contype="0" conaffinity="0" group="1" density="0" rgba="0.1 0.1 0.1 1"
                              mesh="left_hip_pitch_link"/>
                        <geom type="mesh" rgba="0.1 0.1 0.1 1" mesh="left_hip_pitch_link"/>
                        <body name="left_knee_link" pos="0 0 -0.4">
                            <inertial pos="-0.00136 -0.00512 -0.1384" quat="0.626132 -0.034227 -0.0416277 0.777852"
                                      mass="1.721" diaginertia="0.0125237 0.0123104 0.0019428"/>
                            <joint name="left_knee_joint" pos="0 0 0" axis="0 1 0" range="-0.26 2.05"/>
                            <geom type="mesh" contype="0" conaffinity="0" group="1" density="0" rgba="0.1 0.1 0.1 1"
                                  mesh="left_knee_link"/>
                            <geom type="mesh" rgba="0.1 0.1 0.1 1" mesh="left_knee_link"/>
                            <body name="left_ankle_link" pos="0 0 -0.4">
                                <inertial pos="0.048568 0 -0.045609" quat="0.489385 0.510394 0.510394 0.489385"
                                          mass="0.552448" diaginertia="0.00362 0.00355701 0.000149987"/>
                                <joint name="left_ankle_joint" pos="0 0 0" axis="0 1 0" range="-0.87 0.52"/>
                                <geom type="mesh" contype="0" conaffinity="0" group="1" density="0" rgba="0.1 0.1 0.1 1"
                                      mesh="left_ankle_link"/>
                                <geom type="mesh" rgba="0.1 0.1 0.1 1" mesh="left_ankle_link"/>
                            </body>
                        </body>
                    </body>
                </body>
            </body>
            <body name="right_hip_yaw_link" pos="0 -0.0875 -0.1742">
                <inertial pos="-0.04923 -0.0001 0.0072" quat="0.641667 0.233287 0.219193 0.69699" mass="2.244"
                          diaginertia="0.00304494 0.00296885 0.00189201"/>
                <joint name="right_hip_yaw_joint" pos="0 0 0" axis="0 0 1" range="-0.43 0.43"/>
                <geom type="mesh" contype="0" conaffinity="0" group="1" density="0" rgba="0.1 0.1 0.1 1"
                      mesh="right_hip_yaw_link"/>
                <geom size="0.06 0.035" pos="-0.067 0 0" quat="0.707123 0 0.70709 0" type="cylinder"
                      rgba="0.1 0.1 0.1 1"/>
                <body name="right_hip_roll_link" pos="0.039468 0 0">
                    <inertial pos="-0.0058 0.00319 -9e-05" quat="-0.0438242 0.70721 0.0729075 0.701867" mass="2.232"
                              diaginertia="0.00243264 0.00225325 0.00205492"/>
                    <joint name="right_hip_roll_joint" pos="0 0 0" axis="1 0 0" range="-0.43 0.43"/>
                    <geom type="mesh" contype="0" conaffinity="0" group="1" density="0" rgba="0.1 0.1 0.1 1"
                          mesh="right_hip_roll_link"/>
                    <geom type="mesh" rgba="0.1 0.1 0.1 1" mesh="right_hip_roll_link"/>
                    <body name="right_hip_pitch_link" pos="0 -0.11536 0">
                        <inertial pos="0.00746 0.02346 -0.08193" quat="0.979828 -0.0513522 -0.0169854 0.192382"
                                  mass="4.152"
                                  diaginertia="0.0829503 0.0821457 0.00510909"/>
                        <joint name="right_hip_pitch_joint" pos="0 0 0" axis="0 1 0" range="-1.57 1.57"/>
                        <geom type="mesh" contype="0" conaffinity="0" group="1" density="0" rgba="0.1 0.1 0.1 1"
                              mesh="right_hip_pitch_link"/>
                        <geom type="mesh" rgba="0.1 0.1 0.1 1" mesh="right_hip_pitch_link"/>
                        <body name="right_knee_link" pos="0 0 -0.4">
                            <inertial pos="-0.00136 0.00512 -0.1384" quat="0.777852 -0.0416277 -0.034227 0.626132"
                                      mass="1.721" diaginertia="0.0125237 0.0123104 0.0019428"/>
                            <joint name="right_knee_joint" pos="0 0 0" axis="0 1 0" range="-0.26 2.05"/>
                            <geom type="mesh" contype="0" conaffinity="0" group="1" density="0" rgba="0.1 0.1 0.1 1"
                                  mesh="right_knee_link"/>
                            <geom type="mesh" rgba="0.1 0.1 0.1 1" mesh="right_knee_link"/>
                            <body name="right_ankle_link" pos="0 0 -0.4">
                                <inertial pos="0.048568 0 -0.045609" quat="0.489385 0.510394 0.510394 0.489385"
                                          mass="0.552448" diaginertia="0.00362 0.00355701 0.000149987"/>
                                <joint name="right_ankle_joint" pos="0 0 0" axis="0 1 0" range="-0.87 0.52"/>
                                <geom type="mesh" contype="0" conaffinity="0" group="1" density="0" rgba="0.1 0.1 0.1 1"
                                      mesh="right_ankle_link"/>
                                <geom type="mesh" rgba="0.1 0.1 0.1 1" mesh="right_ankle_link"/>
                            </body>
                        </body>
                    </body>
                </body>
            </body>
            <body name="torso_link">
                <inertial pos="0.000489 0.002797 0.20484" quat="0.999989 -0.00130808 -0.00282289 -0.00349105"
                          mass="17.789"
                          diaginertia="0.487315 0.409628 0.127837"/>
                <joint name="torso_joint" pos="0 0 0" axis="0 0 1" range="-2.35 2.35"/>
                <geom type="mesh" contype="0" conaffinity="0" group="1" density="0" rgba="0.1 0.1 0.1 1"
                      mesh="torso_link"/>
                <geom type="mesh" rgba="0.1 0.1 0.1 1" mesh="torso_link"/>
                <geom type="mesh" contype="0" conaffinity="0" group="1" density="0" rgba="1 1 1 1" mesh="logo_link"/>
                <body name="left_shoulder_pitch_link" pos="0.0055 0.15535 0.42999" quat="0.976296 0.216438 0 0">
                    <inertial pos="0.005045 0.053657 -0.015715" quat="0.814858 0.579236 -0.0201072 -0.00936488"
                              mass="1.033"
                              diaginertia="0.00129936 0.000987113 0.000858198"/>
                    <joint name="left_shoulder_pitch_joint" pos="0 0 0" axis="0 1 0" range="-2.87 2.87"/>
                    <geom type="mesh" contype="0" conaffinity="0" group="1" density="0" rgba="0.1 0.1 0.1 1"
                          mesh="left_shoulder_pitch_link"/>
                    <geom type="mesh" rgba="0.1 0.1 0.1 1" mesh="left_shoulder_pitch_link"/>
                    <body name="left_shoulder_roll_link" pos="-0.0055 0.0565 -0.0165" quat="0.976296 -0.216438 0 0">
                        <inertial pos="0.000679 0.00115 -0.094076" quat="0.732491 0.00917179 0.0766656 0.676384"
                                  mass="0.793" diaginertia="0.00170388 0.00158256 0.00100336"/>
                        <joint name="left_shoulder_roll_joint" pos="0 0 0" axis="1 0 0" range="-0.34 3.11"/>
                        <geom type="mesh" contype="0" conaffinity="0" group="1" density="0" rgba="0.1 0.1 0.1 1"
                              mesh="left_shoulder_roll_link"/>
                        <geom type="mesh" rgba="0.1 0.1 0.1 1" mesh="left_shoulder_roll_link"/>
                        <body name="left_shoulder_yaw_link" pos="0 0 -0.1343">
                            <inertial pos="0.01365 0.002767 -0.16266" quat="0.703042 -0.0331229 -0.0473362 0.708798"
                                      mass="0.839" diaginertia="0.00408038 0.00370367 0.000622687"/>
                            <joint name="left_shoulder_yaw_joint" pos="0 0 0" axis="0 0 1" range="-1.3 4.45"/>
                            <geom type="mesh" contype="0" conaffinity="0" group="1" density="0" rgba="0.1 0.1 0.1 1"
                                  mesh="left_shoulder_yaw_link"/>
                            <geom type="mesh" rgba="0.1 0.1 0.1 1" mesh="left_shoulder_yaw_link"/>
                            <body name="left_elbow_link" pos="0.0185 0 -0.198">
                                <inertial pos="0.15908 -0.000144 -0.015776" quat="0.0765232 0.720327 0.0853116 0.684102"
                                          mass="0.669" diaginertia="0.00601829 0.00600579 0.000408305"/>
                                <joint name="left_elbow_joint" pos="0 0 0" axis="0 1 0" range="-1.25 2.61"/>
                                <geom type="mesh" contype="0" conaffinity="0" group="1" density="0" rgba="0.1 0.1 0.1 1"
                                      mesh="left_elbow_link"/>
                                <geom type="mesh" rgba="0.1 0.1 0.1 1" mesh="left_elbow_link"/>
                            </body>
                        </body>
                    </body>
                </body>
                <body name="right_shoulder_pitch_link" pos="0.0055 -0.15535 0.42999" quat="0.976296 -0.216438 0 0">
                    <inertial pos="0.005045 -0.053657 -0.015715" quat="0.579236 0.814858 0.00936488 0.0201072"
                              mass="1.033"
                              diaginertia="0.00129936 0.000987113 0.000858198"/>
                    <joint name="right_shoulder_pitch_joint" pos="0 0 0" axis="0 1 0" range="-2.87 2.87"/>
                    <geom type="mesh" contype="0" conaffinity="0" group="1" density="0" rgba="0.1 0.1 0.1 1"
                          mesh="right_shoulder_pitch_link"/>
                    <geom type="mesh" rgba="0.1 0.1 0.1 1" mesh="right_shoulder_pitch_link"/>
                    <body name="right_shoulder_roll_link" pos="-0.0055 -0.0565 -0.0165" quat="0.976296 0.216438 0 0">
                        <inertial pos="0.000679 -0.00115 -0.094076" quat="0.676384 0.0766656 0.00917179 0.732491"
                                  mass="0.793" diaginertia="0.00170388 0.00158256 0.00100336"/>
                        <joint name="right_shoulder_roll_joint" pos="0 0 0" axis="1 0 0" range="-3.11 0.34"/>
                        <geom type="mesh" contype="0" conaffinity="0" group="1" density="0" rgba="0.1 0.1 0.1 1"
                              mesh="right_shoulder_roll_link"/>
                        <geom type="mesh" rgba="0.1 0.1 0.1 1" mesh="right_shoulder_roll_link"/>
                        <body name="right_shoulder_yaw_link" pos="0 0 -0.1343">
                            <inertial pos="0.01365 -0.002767 -0.16266" quat="0.708798 -0.0473362 -0.0331229 0.703042"
                                      mass="0.839" diaginertia="0.00408038 0.00370367 0.000622687"/>
                            <joint name="right_shoulder_yaw_joint" pos="0 0 0" axis="0 0 1" range="-4.45 1.3"/>
                            <geom type="mesh" contype="0" conaffinity="0" group="1" density="0" rgba="0.1 0.1 0.1 1"
                                  mesh="right_shoulder_yaw_link"/>
                            <geom type="mesh" rgba="0.1 0.1 0.1 1" mesh="right_shoulder_yaw_link"/>
                            <body name="right_elbow_link" pos="0.0185 0 -0.198">
                                <inertial pos="0.15908 0.000144 -0.015776"
                                          quat="-0.0765232 0.720327 -0.0853116 0.684102"
                                          mass="0.669" diaginertia="0.00601829 0.00600579 0.000408305"/>
                                <joint name="right_elbow_joint" pos="0 0 0" axis="0 1 0" range="-1.25 2.61"/>
                                <geom type="mesh" contype="0" conaffinity="0" group="1" density="0" rgba="0.1 0.1 0.1 1"
                                      mesh="right_elbow_link"/>
                                <geom type="mesh" rgba="0.1 0.1 0.1 1" mesh="right_elbow_link"/>
                            </body>
                        </body>
                    </body>
                </body>
            </body>
        </body>
    </worldbody>
</mujoco>
