<mujoco model="h1_description">
    <compiler angle="radian"/>
    <statistic meansize="0.226223" extent="2.02548" center="0.015564 2.74848e-06 -0.182867"/>
    <default>
        <motor ctrlrange="-1 1" ctrllimited="true"/>
        <default class="body">
            <geom type="capsule" condim="1" friction="1.0 0.05 0.05" solimp=".9 .99 .003" solref=".015 1"/>
            <joint type="hinge" damping="0.1" stiffness="5" armature=".007" limited="true" solimplimit="0 .99 .01"/>
            <site size=".04" group="3"/>
            <default class="force-torque">
                <site type="box" size=".01 .01 .02" rgba="1 0 0 1"/>
            </default>
            <default class="touch">
                <site type="capsule" rgba="0 0 1 .3"/>
            </default>
        </default>
    </default>
    <asset>
        <mesh name="pelvis" file="../../urdf/unitreeH1/meshes/pelvis.STL"/>
        <mesh name="left_hip_yaw_link" file="../../urdf/unitreeH1/meshes/left_hip_yaw_link.STL"/>
        <mesh name="left_hip_roll_link" file="../../urdf/unitreeH1/meshes/left_hip_roll_link.STL"/>
        <mesh name="left_hip_pitch_link" file="../../urdf/unitreeH1/meshes/left_hip_pitch_link.STL"/>
        <mesh name="left_knee_link" file="../../urdf/unitreeH1/meshes/left_knee_link.STL"/>
        <mesh name="left_ankle_link" file="../../urdf/unitreeH1/meshes/left_ankle_link.STL"/>
        <mesh name="right_hip_yaw_link" file="../../urdf/unitreeH1/meshes/right_hip_yaw_link.STL"/>
        <mesh name="right_hip_roll_link" file="../../urdf/unitreeH1/meshes/right_hip_roll_link.STL"/>
        <mesh name="right_hip_pitch_link" file="../../urdf/unitreeH1/meshes/right_hip_pitch_link.STL"/>
        <mesh name="right_knee_link" file="../../urdf/unitreeH1/meshes/right_knee_link.STL"/>
        <mesh name="right_ankle_link" file="../../urdf/unitreeH1/meshes/right_ankle_link.STL"/>
        <mesh name="torso_link" file="../../urdf/unitreeH1/meshes/torso_link.STL"/>
        <mesh name="left_shoulder_pitch_link" file="../../urdf/unitreeH1/meshes/left_shoulder_pitch_link.STL"/>
        <mesh name="left_shoulder_roll_link" file="../../urdf/unitreeH1/meshes/left_shoulder_roll_link.STL"/>
        <mesh name="left_shoulder_yaw_link" file="../../urdf/unitreeH1/meshes/left_shoulder_yaw_link.STL"/>
        <mesh name="left_elbow_link" file="../../urdf/unitreeH1/meshes/left_elbow_link.STL"/>
        <mesh name="right_shoulder_pitch_link" file="../../urdf/unitreeH1/meshes/right_shoulder_pitch_link.STL"/>
        <mesh name="right_shoulder_roll_link" file="../../urdf/unitreeH1/meshes/right_shoulder_roll_link.STL"/>
        <mesh name="right_shoulder_yaw_link" file="../../urdf/unitreeH1/meshes/right_shoulder_yaw_link.STL"/>
        <mesh name="right_elbow_link" file="../../urdf/unitreeH1/meshes/right_elbow_link.STL"/>
        <mesh name="logo_link" file="../../urdf/unitreeH1/meshes/logo_link.STL"/>

        <mesh name="flange_iso_04" file="../../urdf/curi/meshes/qbhand/flange_iso_04.stl" scale="0.001 0.001 0.001"/>
        <mesh name="palm_pinch_r" file="../../urdf/curi/meshes/qbhand/palm_pinch_r.stl" scale="0.001 0.001 0.001"/>
        <mesh name="ph_thumb_r" file="../../urdf/curi/meshes/qbhand/ph_thumb_r.stl" scale="0.001 0.001 0.001"/>
        <mesh name="ph_thumb_r_collision" file="../../urdf/curi/meshes/qbhand/ph_thumb_r_collision.stl"
              scale="0.001 0.001 0.001"/>
        <mesh name="palm_pinch_l" file="../../urdf/curi/meshes/qbhand/palm_pinch_l.stl" scale="0.001 0.001 0.001"/>
        <mesh name="ph_thumb_l" file="../../urdf/curi/meshes/qbhand/ph_thumb_l.stl" scale="0.001 0.001 0.001"/>
        <mesh name="ph_thumb_l_collision" file="../../urdf/curi/meshes/qbhand/ph_thumb_l_collision.stl"
              scale="0.001 0.001 0.001"/>
        <mesh name="ph_short" file="../../urdf/curi/meshes/qbhand/ph_short.stl" scale="0.001 0.001 0.001"/>
        <mesh name="ph_short_collision" file="../../urdf/curi/meshes/qbhand/ph_short_collision.stl"
              scale="0.001 0.001 0.001"/>
        <mesh name="ph_distal" file="../../urdf/curi/meshes/qbhand/ph_distal.stl" scale="0.001 0.001 0.001"/>
        <mesh name="ph_distal_collision" file="../../urdf/curi/meshes/qbhand/ph_distal_collision.stl"
              scale="0.001 0.001 0.001"/>
        <mesh name="ph_knuckle" file="../../urdf/curi/meshes/qbhand/ph_knuckle.stl" scale="0.001 0.001 0.001"/>
        <mesh name="ph_knuckle_collision" file="../../urdf/curi/meshes/qbhand/ph_knuckle_collision.stl"
              scale="0.001 0.001 0.001"/>
        <mesh name="ph_medium" file="../../urdf/curi/meshes/qbhand/ph_medium.stl" scale="0.001 0.001 0.001"/>
        <mesh name="ph_medium_collision" file="../../urdf/curi/meshes/qbhand/ph_medium_collision.stl"
              scale="0.001 0.001 0.001"/>
    </asset>
    <worldbody>
        <light directional="true" pos="-0.5 0.5 3" dir="0 0 -1"/>
        <geom name="floor" type="plane" conaffinity="1" size="100 100 .2"/>
        <body name="pelvis" pos="0 0 1" childclass="body">
            <freejoint name="root"/>
            <geom type="mesh" contype="0" conaffinity="0" density="0" rgba="0.1 0.1 0.1 1" mesh="pelvis"/>

            <body name="left_hip_yaw_link" pos="0 0.0875 -0.1742">
                <inertial pos="-0.04923 0.0001 0.0072" quat="0.69699 0.219193 0.233287 0.641667" mass="2.244"
                          diaginertia="0.00304494 0.00296885 0.00189201"/>
                <joint name="left_hip_yaw_joint" pos="0 0 0" axis="0 0 1" range="-0.43 0.43"/>
                <geom type="mesh" contype="0" conaffinity="0" density="0" rgba="0.1 0.1 0.1 1"
                      mesh="left_hip_yaw_link"/>
                <geom size="0.06 0.035" pos="-0.067 0 0" quat="0.707123 0 0.70709 0" type="cylinder"
                      rgba="0.1 0.1 0.1 1"/>
                <body name="left_hip_roll_link" pos="0.039468 0 0">
                    <inertial pos="-0.0058 -0.00319 -9e-05" quat="0.0438242 0.70721 -0.0729075 0.701867" mass="2.232"
                              diaginertia="0.00243264 0.00225325 0.00205492"/>
                    <joint name="left_hip_roll_joint" pos="0 0 0" axis="1 0 0" range="-0.43 0.43"/>
                    <geom type="mesh" contype="0" conaffinity="0" density="0" rgba="0.1 0.1 0.1 1"
                          mesh="left_hip_roll_link"/>
                    <geom type="mesh" rgba="0.1 0.1 0.1 1" mesh="left_hip_roll_link"/>
                    <body name="left_hip_pitch_link" pos="0 0.11536 0">
                        <inertial pos="0.00746 -0.02346 -0.08193" quat="0.979828 0.0513522 -0.0169854 -0.192382"
                                  mass="4.152" diaginertia="0.0829503 0.0821457 0.00510909"/>
                        <joint name="left_hip_pitch_joint" pos="0 0 0" axis="0 1 0" range="-1.57 1.57"/>
                        <geom type="mesh" contype="0" conaffinity="0" density="0" rgba="0.1 0.1 0.1 1"
                              mesh="left_hip_pitch_link"/>
                        <geom type="mesh" rgba="0.1 0.1 0.1 1" mesh="left_hip_pitch_link"/>
                        <body name="left_knee_link" pos="0 0 -0.4">
                            <inertial pos="-0.00136 -0.00512 -0.1384" quat="0.626132 -0.034227 -0.0416277 0.777852"
                                      mass="1.721" diaginertia="0.0125237 0.0123104 0.0019428"/>
                            <joint name="left_knee_joint" pos="0 0 0" axis="0 1 0" range="-0.26 2.05"/>
                            <geom type="mesh" contype="0" conaffinity="0" density="0" rgba="0.1 0.1 0.1 1"
                                  mesh="left_knee_link"/>
                            <geom type="mesh" rgba="0.1 0.1 0.1 1" mesh="left_knee_link"/>
                            <body name="left_ankle_link" pos="0 0 -0.4">
                                <inertial pos="0.048568 0 -0.045609" quat="0.489385 0.510394 0.510394 0.489385"
                                          mass="0.552448" diaginertia="0.00362 0.00355701 0.000149987"/>
                                <joint name="left_ankle_joint" pos="0 0 0" axis="0 1 0" range="-0.87 0.52"/>
                                <geom type="mesh" contype="0" conaffinity="0" density="0" rgba="0.1 0.1 0.1 1"
                                      mesh="left_ankle_link"/>
                                <geom type="mesh" rgba="0.1 0.1 0.1 1" mesh="left_ankle_link"/>
                            </body>
                        </body>
                    </body>
                </body>
            </body>
            <body name="right_hip_yaw_link" pos="0 -0.0875 -0.1742">
                <inertial pos="-0.04923 -0.0001 0.0072" quat="0.641667 0.233287 0.219193 0.69699" mass="2.244"
                          diaginertia="0.00304494 0.00296885 0.00189201"/>
                <joint name="right_hip_yaw_joint" pos="0 0 0" axis="0 0 1" range="-0.43 0.43"/>
                <geom type="mesh" contype="0" conaffinity="0" density="0" rgba="0.1 0.1 0.1 1"
                      mesh="right_hip_yaw_link"/>
                <geom size="0.06 0.035" pos="-0.067 0 0" quat="0.707123 0 0.70709 0" type="cylinder"
                      rgba="0.1 0.1 0.1 1"/>
                <body name="right_hip_roll_link" pos="0.039468 0 0">
                    <inertial pos="-0.0058 0.00319 -9e-05" quat="-0.0438242 0.70721 0.0729075 0.701867" mass="2.232"
                              diaginertia="0.00243264 0.00225325 0.00205492"/>
                    <joint name="right_hip_roll_joint" pos="0 0 0" axis="1 0 0" range="-0.43 0.43"/>
                    <geom type="mesh" contype="0" conaffinity="0" density="0" rgba="0.1 0.1 0.1 1"
                          mesh="right_hip_roll_link"/>
                    <geom type="mesh" rgba="0.1 0.1 0.1 1" mesh="right_hip_roll_link"/>
                    <body name="right_hip_pitch_link" pos="0 -0.11536 0">
                        <inertial pos="0.00746 0.02346 -0.08193" quat="0.979828 -0.0513522 -0.0169854 0.192382"
                                  mass="4.152"
                                  diaginertia="0.0829503 0.0821457 0.00510909"/>
                        <joint name="right_hip_pitch_joint" pos="0 0 0" axis="0 1 0" range="-1.57 1.57"/>
                        <geom type="mesh" contype="0" conaffinity="0" density="0" rgba="0.1 0.1 0.1 1"
                              mesh="right_hip_pitch_link"/>
                        <geom type="mesh" rgba="0.1 0.1 0.1 1" mesh="right_hip_pitch_link"/>
                        <body name="right_knee_link" pos="0 0 -0.4">
                            <inertial pos="-0.00136 0.00512 -0.1384" quat="0.777852 -0.0416277 -0.034227 0.626132"
                                      mass="1.721" diaginertia="0.0125237 0.0123104 0.0019428"/>
                            <joint name="right_knee_joint" pos="0 0 0" axis="0 1 0" range="-0.26 2.05"/>
                            <geom type="mesh" contype="0" conaffinity="0" density="0" rgba="0.1 0.1 0.1 1"
                                  mesh="right_knee_link"/>
                            <geom type="mesh" rgba="0.1 0.1 0.1 1" mesh="right_knee_link"/>
                            <body name="right_ankle_link" pos="0 0 -0.4">
                                <inertial pos="0.048568 0 -0.045609" quat="0.489385 0.510394 0.510394 0.489385"
                                          mass="0.552448" diaginertia="0.00362 0.00355701 0.000149987"/>
                                <joint name="right_ankle_joint" pos="0 0 0" axis="0 1 0" range="-0.87 0.52"/>
                                <geom type="mesh" contype="0" conaffinity="0" density="0" rgba="0.1 0.1 0.1 1"
                                      mesh="right_ankle_link"/>
                                <geom type="mesh" rgba="0.1 0.1 0.1 1" mesh="right_ankle_link"/>
                            </body>
                        </body>
                    </body>
                </body>
            </body>
            <body name="torso_link" pos="0 0 0">
                <inertial pos="0.000489 0.002797 0.20484" quat="0.999989 -0.00130808 -0.00282289 -0.00349105"
                          mass="17.789"
                          diaginertia="0.487315 0.409628 0.127837"/>
                <joint name="torso_joint" pos="0 0 0" axis="0 0 1" range="-2.35 2.35"/>
                <geom type="mesh" contype="0" conaffinity="0" density="0" rgba="0.1 0.1 0.1 1"
                      mesh="torso_link"/>
                <geom type="mesh" rgba="0.1 0.1 0.1 1" mesh="torso_link"/>
                <geom type="mesh" contype="0" conaffinity="0" density="0" rgba="1 1 1 1" mesh="logo_link"/>
                <body name="left_shoulder_pitch_link" pos="0.0055 0.15535 0.42999" quat="0.976296 0.216438 0 0">
                    <inertial pos="0.005045 0.053657 -0.015715" quat="0.814858 0.579236 -0.0201072 -0.00936488"
                              mass="1.033"
                              diaginertia="0.00129936 0.000987113 0.000858198"/>
                    <joint name="left_shoulder_pitch_joint" pos="0 0 0" axis="0 1 0" range="-2.87 2.87"/>
                    <geom type="mesh" contype="0" conaffinity="0" density="0" rgba="0.1 0.1 0.1 1"
                          mesh="left_shoulder_pitch_link"/>
                    <geom type="mesh" rgba="0.1 0.1 0.1 1" mesh="left_shoulder_pitch_link"/>
                    <body name="left_shoulder_roll_link" pos="-0.0055 0.0565 -0.0165" quat="0.976296 -0.216438 0 0">
                        <inertial pos="0.000679 0.00115 -0.094076" quat="0.732491 0.00917179 0.0766656 0.676384"
                                  mass="0.793" diaginertia="0.00170388 0.00158256 0.00100336"/>
                        <joint name="left_shoulder_roll_joint" pos="0 0 0" axis="1 0 0" range="-0.34 3.11"/>
                        <geom type="mesh" contype="0" conaffinity="0" density="0" rgba="0.1 0.1 0.1 1"
                              mesh="left_shoulder_roll_link"/>
                        <geom type="mesh" rgba="0.1 0.1 0.1 1" mesh="left_shoulder_roll_link"/>
                        <body name="left_shoulder_yaw_link" pos="0 0 -0.1343">
                            <inertial pos="0.01365 0.002767 -0.16266" quat="0.703042 -0.0331229 -0.0473362 0.708798"
                                      mass="0.839" diaginertia="0.00408038 0.00370367 0.000622687"/>
                            <joint name="left_shoulder_yaw_joint" pos="0 0 0" axis="0 0 1" range="-1.3 4.45"/>
                            <geom type="mesh" contype="0" conaffinity="0" density="0" rgba="0.1 0.1 0.1 1"
                                  mesh="left_shoulder_yaw_link"/>
                            <geom type="mesh" rgba="0.1 0.1 0.1 1" mesh="left_shoulder_yaw_link"/>
                            <body name="left_elbow_link" pos="0.0185 0 -0.198">
                                <inertial pos="0.15908 -0.000144 -0.015776" quat="0.0765232 0.720327 0.0853116 0.684102"
                                          mass="0.669" diaginertia="0.00601829 0.00600579 0.000408305"/>
                                <joint name="left_elbow_joint" pos="0 0 0" axis="0 1 0" range="-1.25 2.61"/>
                                <geom type="mesh" contype="0" conaffinity="0" density="0" rgba="0.1 0.1 0.1 1"
                                      mesh="left_elbow_link"/>
                                <geom type="mesh" rgba="0.1 0.1 0.1 1" mesh="left_elbow_link"/>

                                <body name="left_hand" pos="0.3 0 -0.02">
                                    <joint name="left_hand_x" axis="1 0 0" range="-1.57 1.57" stiffness="100"
                                           damping="10"
                                           armature=".01"/>
                                    <joint name="left_hand_y" axis="0 1 0" range="-1.57 1.57" stiffness="100"
                                           damping="10"
                                           armature=".003"/>
                                    <joint name="left_hand_z" axis="0 0 1" range="-1.57 1.57" stiffness="100"
                                           damping="10"
                                           armature=".003"/>
                                    <!--                                    <geom name="left_hand" type="sphere" size=".04" density="1865"/>-->
                                    <site name="left_hand" class="touch" type="sphere" size=".041"/>

                                    <body name="left_qbhand_root_link" pos="0.0 0.0 0.0" quat="0 0.707 0 0.707">
                                        <geom type="mesh" rgba="0.35 0.35 0.35 1" mesh="flange_iso_04" contype="0"
                                              conaffinity="0"/>
                                        <geom pos="0.0045 0.0145 0.144" quat="0.000563312 0.000562864 0.706825 0.707388"
                                              type="mesh"
                                              rgba="0.35 0.35 0.35 1" mesh="palm_pinch_l" contype="0" conaffinity="0"/>
                                        <geom pos="0.0045 0.0145 0.144" quat="0.000563312 0.000562864 0.706825 0.707388"
                                              type="mesh"
                                              rgba="0.35 0.35 0.35 1" mesh="palm_pinch_l" contype="0"/>

                                        <body name="left_qbhand_thumb_knuckle_link" pos="0.0485032 0.0164669 0.0975016"
                                              quat="-0.999998 -0.000796326 6.34136e-07 0.00159265">
                                            <inertial pos="0.0130716 0.00273463 0.000640905"
                                                      quat="0.531237 0.364349 0.576408 0.502783" mass="0.01"
                                                      diaginertia="1.43383e-06 1.35753e-06 3.12211e-07"/>
                                            <joint name="left_qbhand_thumb_knuckle_joint" pos="0 0 0" axis="0 0 1"
                                                   limited="true"
                                                   range="0 1.57"/>
                                            <geom type="mesh" contype="0" conaffinity="0" rgba="0.35 0.35 0.35 1"
                                                  mesh="ph_thumb_l"/>
                                            <geom type="mesh" contype="0" rgba="0.35 0.35 0.35 1"
                                                  mesh="ph_thumb_l_collision"/>
                                            <body name="left_qbhand_thumb_proximal_virtual_link"
                                                  pos="0.0255 0.0038 -0.00012"
                                                  quat="0.540302 -0.841471 0 0">
                                                <inertial pos="0 0 0" mass="0.0001" diaginertia="1e-09 1e-09 1e-09"/>
                                                <joint name="left_qbhand_thumb_proximal_joint" pos="0 0 0" axis="0 0 -1"
                                                       limited="true" range="0 0.785"/>
                                                <body name="left_qbhand_thumb_proximal_link" pos="0.013 0 0">
                                                    <inertial pos="0.00476016 -0.00137869 0"
                                                              quat="0.0365143 0.706163 -0.0365143 0.706163"
                                                              mass="0.0063"
                                                              diaginertia="2.6915e-07 2.3576e-07 1.79645e-07"/>
                                                    <joint name="left_qbhand_thumb_proximal_virtual_joint" pos="0 0 0"
                                                           axis="0 0 -1"
                                                           limited="true" range="0 0.785"/>
                                                    <geom type="mesh" contype="0" conaffinity="0"
                                                          rgba="0.35 0.35 0.35 1" mesh="ph_short"/>
                                                    <geom type="mesh" contype="0"
                                                          rgba="0.35 0.35 0.35 1"
                                                          mesh="ph_short_collision"/>
                                                    <body name="left_qbhand_thumb_distal_virtual_link" pos="0.009 0 0">
                                                        <inertial pos="0 0 0" mass="0.0001"
                                                                  diaginertia="1e-09 1e-09 1e-09"/>
                                                        <joint name="left_qbhand_thumb_distal_joint" pos="0 0 0"
                                                               axis="0 0 -1"
                                                               limited="true" range="0 0.785"/>
                                                        <body name="left_qbhand_thumb_distal_link" pos="0.013 0 0">
                                                            <inertial pos="0.00880255 -0.00172193 0"
                                                                      quat="0.0131386 0.706985 -0.0131386 0.706985"
                                                                      mass="0.009"
                                                                      diaginertia="6.6782e-07 5.99819e-07 2.654e-07"/>
                                                            <joint name="left_qbhand_thumb_distal_virtual_joint"
                                                                   pos="0 0 0"
                                                                   axis="0 0 -1" limited="true" range="0 0.785"/>
                                                            <geom type="mesh" contype="0" conaffinity="0"
                                                                  rgba="0.35 0.35 0.35 1" mesh="ph_distal"/>
                                                            <geom type="mesh" contype="0"
                                                                  rgba="0.35 0.35 0.35 1"
                                                                  mesh="ph_distal_collision"/>
                                                        </body>
                                                    </body>
                                                </body>
                                            </body>
                                        </body>
                                        <body name="left_qbhand_index_knuckle_link" pos="0.0244777 0.000473743 0.136989"
                                              quat="-0.499999 -0.500397 0.500796 -0.498805">
                                            <inertial pos="0.000427536 0 -0.00143217"
                                                      quat="0.587164 0.394003 0.394003 0.587164"
                                                      mass="0.0095"
                                                      diaginertia="1.12538e-06 7.39498e-07 6.27245e-07"/>
                                            <joint name="left_qbhand_index_knuckle_joint" pos="0 0 0" axis="0 0 -1"
                                                   limited="true"
                                                   range="-0.523 0.523"/>
                                            <geom type="mesh" contype="0" conaffinity="0" rgba="0.35 0.35 0.35 1"
                                                  mesh="ph_knuckle"/>
                                            <geom type="mesh" contype="0" rgba="0.35 0.35 0.35 1"
                                                  mesh="ph_knuckle_collision"/>
                                            <body name="left_qbhand_index_proximal_virtual_link" pos="0.009 0 0"
                                                  quat="0.707388 0.706825 0 0">
                                                <inertial pos="0 0 0" mass="0.0001" diaginertia="1e-09 1e-09 1e-09"/>
                                                <joint name="left_qbhand_index_proximal_joint" pos="0 0 0" axis="0 0 -1"
                                                       limited="true" range="0 0.785"/>
                                                <body name="left_qbhand_index_proximal_link" pos="0.013 0 0">
                                                    <inertial pos="0.00877074 -0.00178631 0"
                                                              quat="0.0123083 0.707 -0.0123083 0.707" mass="0.0082"
                                                              diaginertia="5.95622e-07 5.59876e-07 2.26817e-07"/>
                                                    <joint name="left_qbhand_index_proximal_virtual_joint" pos="0 0 0"
                                                           axis="0 0 -1"
                                                           limited="true"
                                                           range="0 0.785"/>
                                                    <geom type="mesh" contype="0" conaffinity="0"
                                                          rgba="0.35 0.35 0.35 1"
                                                          mesh="ph_medium"/>
                                                    <geom type="mesh" contype="0"
                                                          rgba="0.35 0.35 0.35 1"
                                                          mesh="ph_medium_collision"/>
                                                    <body name="left_qbhand_index_middle_virtual_link" pos="0.017 0 0">
                                                        <inertial pos="0 0 0" mass="0.0001"
                                                                  diaginertia="1e-09 1e-09 1e-09"/>
                                                        <joint name="left_qbhand_index_middle_joint" pos="0 0 0"
                                                               axis="0 0 -1"
                                                               limited="true"
                                                               range="0 0.785"/>
                                                        <body name="left_qbhand_index_middle_link" pos="0.013 0 0">
                                                            <inertial pos="0.00476016 -0.00137869 0"
                                                                      quat="0.0365143 0.706163 -0.0365143 0.706163"
                                                                      mass="0.0063"
                                                                      diaginertia="2.6915e-07 2.3576e-07 1.79645e-07"/>
                                                            <joint name="left_qbhand_index_middle_virtual_joint"
                                                                   pos="0 0 0"
                                                                   axis="0 0 -1" limited="true"
                                                                   range="0 0.785"/>
                                                            <geom type="mesh" contype="0" conaffinity="0"
                                                                  rgba="0.35 0.35 0.35 1"
                                                                  mesh="ph_short"/>
                                                            <geom type="mesh" contype="0"
                                                                  rgba="0.35 0.35 0.35 1"
                                                                  mesh="ph_short_collision"/>
                                                            <body name="left_qbhand_index_distal_virtual_link"
                                                                  pos="0.009 0 0">
                                                                <inertial pos="0 0 0" mass="0.0001"
                                                                          diaginertia="1e-09 1e-09 1e-09"/>
                                                                <joint name="left_qbhand_index_distal_joint" pos="0 0 0"
                                                                       axis="0 0 -1" limited="true"
                                                                       range="0 0.785"/>
                                                                <body name="left_qbhand_index_distal_link"
                                                                      pos="0.013 0 0">
                                                                    <inertial pos="0.00880255 -0.00172193 0"
                                                                              quat="0.0131386 0.706985 -0.0131386 0.706985"
                                                                              mass="0.009"
                                                                              diaginertia="6.6782e-07 5.99819e-07 2.654e-07"/>
                                                                    <joint name="left_qbhand_index_distal_virtual_joint"
                                                                           pos="0 0 0"
                                                                           axis="0 0 -1"
                                                                           limited="true" range="0 0.785"/>
                                                                    <geom type="mesh" contype="0" conaffinity="0"
                                                                          rgba="0.35 0.35 0.35 1"
                                                                          mesh="ph_distal"/>
                                                                    <geom type="mesh" contype="0"
                                                                          rgba="0.35 0.35 0.35 1"
                                                                          mesh="ph_distal_collision"/>
                                                                </body>
                                                            </body>
                                                        </body>
                                                    </body>
                                                </body>
                                            </body>
                                        </body>
                                        <body name="left_qbhand_middle_knuckle_link"
                                              pos="0.0044777 0.000500022 0.143989"
                                              quat="-0.499999 -0.500397 0.500796 -0.498805">
                                            <inertial pos="0.000427536 0 -0.00143217"
                                                      quat="0.587164 0.394003 0.394003 0.587164"
                                                      mass="0.0095"
                                                      diaginertia="1.12538e-06 7.39498e-07 6.27245e-07"/>
                                            <joint name="left_qbhand_middle_knuckle_joint" pos="0 0 0" axis="0 0 -1"
                                                   limited="true"
                                                   range="-0.523 0.523"/>
                                            <geom type="mesh" contype="0" conaffinity="0" rgba="0.35 0.35 0.35 1"
                                                  mesh="ph_knuckle"/>
                                            <geom type="mesh" contype="0" rgba="0.35 0.35 0.35 1"
                                                  mesh="ph_knuckle_collision"/>
                                            <body name="left_qbhand_middle_proximal_virtual_link" pos="0.009 0 0"
                                                  quat="0.707388 0.706825 0 0">
                                                <inertial pos="0 0 0" mass="0.0001" diaginertia="1e-09 1e-09 1e-09"/>
                                                <joint name="left_qbhand_middle_proximal_joint" pos="0 0 0"
                                                       axis="0 0 -1"
                                                       limited="true"
                                                       range="0 0.785"/>
                                                <body name="left_qbhand_middle_proximal_link" pos="0.013 0 0">
                                                    <inertial pos="0.00877074 -0.00178631 0"
                                                              quat="0.0123083 0.707 -0.0123083 0.707" mass="0.0082"
                                                              diaginertia="5.95622e-07 5.59876e-07 2.26817e-07"/>
                                                    <joint name="left_qbhand_middle_proximal_virtual_joint" pos="0 0 0"
                                                           axis="0 0 -1"
                                                           limited="true"
                                                           range="0 0.785"/>
                                                    <geom type="mesh" contype="0" conaffinity="0"
                                                          rgba="0.35 0.35 0.35 1"
                                                          mesh="ph_medium"/>
                                                    <geom type="mesh" contype="0"
                                                          rgba="0.35 0.35 0.35 1"
                                                          mesh="ph_medium_collision"/>
                                                    <body name="left_qbhand_middle_middle_virtual_link" pos="0.017 0 0">
                                                        <inertial pos="0 0 0" mass="0.0001"
                                                                  diaginertia="1e-09 1e-09 1e-09"/>
                                                        <joint name="left_qbhand_middle_middle_joint" pos="0 0 0"
                                                               axis="0 0 -1"
                                                               limited="true"
                                                               range="0 0.785"/>
                                                        <body name="left_qbhand_middle_middle_link" pos="0.013 0 0">
                                                            <inertial pos="0.00476016 -0.00137869 0"
                                                                      quat="0.0365143 0.706163 -0.0365143 0.706163"
                                                                      mass="0.0063"
                                                                      diaginertia="2.6915e-07 2.3576e-07 1.79645e-07"/>
                                                            <joint name="left_qbhand_middle_middle_virtual_joint"
                                                                   pos="0 0 0"
                                                                   axis="0 0 -1"
                                                                   limited="true" range="0 0.785"/>
                                                            <geom type="mesh" contype="0" conaffinity="0"
                                                                  rgba="0.35 0.35 0.35 1"
                                                                  mesh="ph_short"/>
                                                            <geom type="mesh" contype="0"
                                                                  rgba="0.35 0.35 0.35 1"
                                                                  mesh="ph_short_collision"/>
                                                            <body name="left_qbhand_middle_distal_virtual_link"
                                                                  pos="0.009 0 0">
                                                                <inertial pos="0 0 0" mass="0.0001"
                                                                          diaginertia="1e-09 1e-09 1e-09"/>
                                                                <joint name="left_qbhand_middle_distal_joint"
                                                                       pos="0 0 0"
                                                                       axis="0 0 -1" limited="true"
                                                                       range="0 0.785"/>
                                                                <body name="left_qbhand_middle_distal_link"
                                                                      pos="0.013 0 0">
                                                                    <inertial pos="0.00880255 -0.00172193 0"
                                                                              quat="0.0131386 0.706985 -0.0131386 0.706985"
                                                                              mass="0.009"
                                                                              diaginertia="6.6782e-07 5.99819e-07 2.654e-07"/>
                                                                    <joint name="left_qbhand_middle_distal_virtual_joint"
                                                                           pos="0 0 0"
                                                                           axis="0 0 -1"
                                                                           limited="true" range="0 0.785"/>
                                                                    <geom type="mesh" contype="0" conaffinity="0"
                                                                          rgba="0.35 0.35 0.35 1"
                                                                          mesh="ph_distal"/>
                                                                    <geom type="mesh" contype="0"
                                                                          rgba="0.35 0.35 0.35 1"
                                                                          mesh="ph_distal_collision"/>
                                                                </body>
                                                            </body>
                                                        </body>
                                                    </body>
                                                </body>
                                            </body>
                                        </body>
                                        <body name="left_qbhand_ring_knuckle_link" pos="-0.0155223 0.00053745 0.136989"
                                              quat="-0.499999 -0.500397 0.500796 -0.498805">
                                            <inertial pos="0.000427536 0 -0.00143217"
                                                      quat="0.587164 0.394003 0.394003 0.587164"
                                                      mass="0.0095"
                                                      diaginertia="1.12538e-06 7.39498e-07 6.27245e-07"/>
                                            <joint name="left_qbhand_ring_knuckle_joint" pos="0 0 0" axis="0 0 -1"
                                                   limited="true"
                                                   range="-0.523 0.523"/>
                                            <geom type="mesh" contype="0" conaffinity="0" rgba="0.35 0.35 0.35 1"
                                                  mesh="ph_knuckle"/>
                                            <geom type="mesh" contype="0" rgba="0.35 0.35 0.35 1"
                                                  mesh="ph_knuckle_collision"/>
                                            <body name="left_qbhand_ring_proximal_virtual_link" pos="0.009 0 0"
                                                  quat="0.707388 0.706825 0 0">
                                                <inertial pos="0 0 0" mass="0.0001" diaginertia="1e-09 1e-09 1e-09"/>
                                                <joint name="left_qbhand_ring_proximal_joint" pos="0 0 0" axis="0 0 -1"
                                                       limited="true" range="0 0.785"/>
                                                <body name="left_qbhand_ring_proximal_link" pos="0.013 0 0">
                                                    <inertial pos="0.00877074 -0.00178631 0"
                                                              quat="0.0123083 0.707 -0.0123083 0.707" mass="0.0082"
                                                              diaginertia="5.95622e-07 5.59876e-07 2.26817e-07"/>
                                                    <joint name="left_qbhand_ring_proximal_virtual_joint" pos="0 0 0"
                                                           axis="0 0 -1"
                                                           limited="true"
                                                           range="0 0.785"/>
                                                    <geom type="mesh" contype="0" conaffinity="0"
                                                          rgba="0.35 0.35 0.35 1"
                                                          mesh="ph_medium"/>
                                                    <geom type="mesh" contype="0"
                                                          rgba="0.35 0.35 0.35 1"
                                                          mesh="ph_medium_collision"/>
                                                    <body name="left_qbhand_ring_middle_virtual_link" pos="0.017 0 0">
                                                        <inertial pos="0 0 0" mass="0.0001"
                                                                  diaginertia="1e-09 1e-09 1e-09"/>
                                                        <joint name="left_qbhand_ring_middle_joint" pos="0 0 0"
                                                               axis="0 0 -1"
                                                               limited="true"
                                                               range="0 0.785"/>
                                                        <body name="left_qbhand_ring_middle_link" pos="0.013 0 0">
                                                            <inertial pos="0.00476016 -0.00137869 0"
                                                                      quat="0.0365143 0.706163 -0.0365143 0.706163"
                                                                      mass="0.0063"
                                                                      diaginertia="2.6915e-07 2.3576e-07 1.79645e-07"/>
                                                            <joint name="left_qbhand_ring_middle_virtual_joint"
                                                                   pos="0 0 0"
                                                                   axis="0 0 -1" limited="true"
                                                                   range="0 0.785"/>
                                                            <geom type="mesh" contype="0" conaffinity="0"
                                                                  rgba="0.35 0.35 0.35 1"
                                                                  mesh="ph_short"/>
                                                            <geom type="mesh" contype="0"
                                                                  rgba="0.35 0.35 0.35 1"
                                                                  mesh="ph_short_collision"/>
                                                            <body name="left_qbhand_ring_distal_virtual_link"
                                                                  pos="0.009 0 0">
                                                                <inertial pos="0 0 0" mass="0.0001"
                                                                          diaginertia="1e-09 1e-09 1e-09"/>
                                                                <joint name="left_qbhand_ring_distal_joint" pos="0 0 0"
                                                                       axis="0 0 -1"
                                                                       limited="true"
                                                                       range="0 0.785"/>
                                                                <body name="left_qbhand_ring_distal_link"
                                                                      pos="0.013 0 0">
                                                                    <inertial pos="0.00880255 -0.00172193 0"
                                                                              quat="0.0131386 0.706985 -0.0131386 0.706985"
                                                                              mass="0.009"
                                                                              diaginertia="6.6782e-07 5.99819e-07 2.654e-07"/>
                                                                    <joint name="left_qbhand_ring_distal_virtual_joint"
                                                                           pos="0 0 0"
                                                                           axis="0 0 -1"
                                                                           limited="true" range="0 0.785"/>
                                                                    <geom type="mesh" contype="0" conaffinity="0"
                                                                          rgba="0.35 0.35 0.35 1"
                                                                          mesh="ph_distal"/>
                                                                    <geom type="mesh" contype="0"
                                                                          rgba="0.35 0.35 0.35 1"
                                                                          mesh="ph_distal_collision"/>
                                                                </body>
                                                            </body>
                                                        </body>
                                                    </body>
                                                </body>
                                            </body>
                                        </body>
                                        <body name="left_qbhand_little_knuckle_link"
                                              pos="-0.0355222 0.000573284 0.131989"
                                              quat="-0.499999 -0.500397 0.500796 -0.498805">
                                            <inertial pos="0.000427536 0 -0.00143217"
                                                      quat="0.587164 0.394003 0.394003 0.587164"
                                                      mass="0.0095"
                                                      diaginertia="1.12538e-06 7.39498e-07 6.27245e-07"/>
                                            <joint name="left_qbhand_little_knuckle_joint" pos="0 0 0" axis="0 0 -1"
                                                   limited="true"
                                                   range="-0.523 0.523"/>
                                            <geom type="mesh" contype="0" conaffinity="0" rgba="0.35 0.35 0.35 1"
                                                  mesh="ph_knuckle"/>
                                            <geom type="mesh" contype="0" rgba="0.35 0.35 0.35 1"
                                                  mesh="ph_knuckle_collision"/>
                                            <body name="left_qbhand_little_proximal_virtual_link" pos="0.009 0 0"
                                                  quat="0.707388 0.706825 0 0">
                                                <inertial pos="0 0 0" mass="0.0001" diaginertia="1e-09 1e-09 1e-09"/>
                                                <joint name="left_qbhand_little_proximal_joint" pos="0 0 0"
                                                       axis="0 0 -1"
                                                       limited="true"
                                                       range="0 0.785"/>
                                                <body name="left_qbhand_little_proximal_link" pos="0.013 0 0">
                                                    <inertial pos="0.00476016 -0.00137869 0"
                                                              quat="0.0365143 0.706163 -0.0365143 0.706163"
                                                              mass="0.0063"
                                                              diaginertia="2.6915e-07 2.3576e-07 1.79645e-07"/>
                                                    <joint name="left_qbhand_little_proximal_virtual_joint" pos="0 0 0"
                                                           axis="0 0 -1"
                                                           limited="true"
                                                           range="0 0.785"/>
                                                    <geom type="mesh" contype="0" conaffinity="0"
                                                          rgba="0.35 0.35 0.35 1"
                                                          mesh="ph_short"/>
                                                    <geom type="mesh" contype="0"
                                                          rgba="0.35 0.35 0.35 1"
                                                          mesh="ph_short_collision"/>
                                                    <body name="left_qbhand_little_middle_virtual_link" pos="0.009 0 0">
                                                        <inertial pos="0 0 0" mass="0.0001"
                                                                  diaginertia="1e-09 1e-09 1e-09"/>
                                                        <joint name="left_qbhand_little_middle_joint" pos="0 0 0"
                                                               axis="0 0 -1"
                                                               limited="true"
                                                               range="0 0.785"/>
                                                        <body name="left_qbhand_little_middle_link" pos="0.013 0 0">
                                                            <inertial pos="0.00476016 -0.00137869 0"
                                                                      quat="0.0365143 0.706163 -0.0365143 0.706163"
                                                                      mass="0.0063"
                                                                      diaginertia="2.6915e-07 2.3576e-07 1.79645e-07"/>
                                                            <joint name="left_qbhand_little_middle_virtual_joint"
                                                                   pos="0 0 0"
                                                                   axis="0 0 -1"
                                                                   limited="true" range="0 0.785"/>
                                                            <geom type="mesh" contype="0" conaffinity="0"
                                                                  rgba="0.35 0.35 0.35 1"
                                                                  mesh="ph_short"/>
                                                            <geom type="mesh" contype="0"
                                                                  rgba="0.35 0.35 0.35 1"
                                                                  mesh="ph_short_collision"/>
                                                            <body name="left_qbhand_little_distal_virtual_link"
                                                                  pos="0.009 0 0">
                                                                <inertial pos="0 0 0" mass="0.0001"
                                                                          diaginertia="1e-09 1e-09 1e-09"/>
                                                                <joint name="left_qbhand_little_distal_joint"
                                                                       pos="0 0 0"
                                                                       axis="0 0 -1" limited="true"
                                                                       range="0 0.785"/>
                                                                <body name="left_qbhand_little_distal_link"
                                                                      pos="0.013 0 0">
                                                                    <inertial pos="0.00880255 -0.00172193 0"
                                                                              quat="0.0131386 0.706985 -0.0131386 0.706985"
                                                                              mass="0.009"
                                                                              diaginertia="6.6782e-07 5.99819e-07 2.654e-07"/>
                                                                    <joint name="left_qbhand_little_distal_virtual_joint"
                                                                           pos="0 0 0"
                                                                           axis="0 0 -1"
                                                                           limited="true" range="0 0.785"/>
                                                                    <geom type="mesh" contype="0" conaffinity="0"
                                                                          rgba="0.35 0.35 0.35 1"
                                                                          mesh="ph_distal"/>
                                                                    <geom type="mesh" contype="0"
                                                                          rgba="0.35 0.35 0.35 1"
                                                                          mesh="ph_distal_collision"/>
                                                                </body>
                                                            </body>
                                                        </body>
                                                    </body>
                                                </body>
                                            </body>
                                        </body>
                                    </body>
                                </body>

                            </body>
                        </body>
                    </body>
                </body>
                <body name="right_shoulder_pitch_link" pos="0.0055 -0.15535 0.42999" quat="0.976296 -0.216438 0 0">
                    <inertial pos="0.005045 -0.053657 -0.015715" quat="0.579236 0.814858 0.00936488 0.0201072"
                              mass="1.033"
                              diaginertia="0.00129936 0.000987113 0.000858198"/>
                    <joint name="right_shoulder_pitch_joint" pos="0 0 0" axis="0 1 0" range="-2.87 2.87"/>
                    <geom type="mesh" contype="0" conaffinity="0" density="0" rgba="0.1 0.1 0.1 1"
                          mesh="right_shoulder_pitch_link"/>
                    <geom type="mesh" rgba="0.1 0.1 0.1 1" mesh="right_shoulder_pitch_link"/>
                    <body name="right_shoulder_roll_link" pos="-0.0055 -0.0565 -0.0165" quat="0.976296 0.216438 0 0">
                        <inertial pos="0.000679 -0.00115 -0.094076" quat="0.676384 0.0766656 0.00917179 0.732491"
                                  mass="0.793" diaginertia="0.00170388 0.00158256 0.00100336"/>
                        <joint name="right_shoulder_roll_joint" pos="0 0 0" axis="1 0 0" range="-3.11 0.34"/>
                        <geom type="mesh" contype="0" conaffinity="0" density="0" rgba="0.1 0.1 0.1 1"
                              mesh="right_shoulder_roll_link"/>
                        <geom type="mesh" rgba="0.1 0.1 0.1 1" mesh="right_shoulder_roll_link"/>
                        <body name="right_shoulder_yaw_link" pos="0 0 -0.1343">
                            <inertial pos="0.01365 -0.002767 -0.16266" quat="0.708798 -0.0473362 -0.0331229 0.703042"
                                      mass="0.839" diaginertia="0.00408038 0.00370367 0.000622687"/>
                            <joint name="right_shoulder_yaw_joint" pos="0 0 0" axis="0 0 1" range="-4.45 1.3"/>
                            <geom type="mesh" contype="0" conaffinity="0" density="0" rgba="0.1 0.1 0.1 1"
                                  mesh="right_shoulder_yaw_link"/>
                            <geom type="mesh" rgba="0.1 0.1 0.1 1" mesh="right_shoulder_yaw_link"/>
                            <body name="right_elbow_link" pos="0.0185 0 -0.198">
                                <inertial pos="0.15908 0.000144 -0.015776"
                                          quat="-0.0765232 0.720327 -0.0853116 0.684102"
                                          mass="0.669" diaginertia="0.00601829 0.00600579 0.000408305"/>
                                <joint name="right_elbow_joint" pos="0 0 0" axis="0 1 0" range="-1.25 2.61"/>
                                <geom type="mesh" contype="0" conaffinity="0" density="0" rgba="0.1 0.1 0.1 1"
                                      mesh="right_elbow_link"/>
                                <geom type="mesh" rgba="0.1 0.1 0.1 1" mesh="right_elbow_link"/>

                                <body name="right_hand" pos="0.3 0 -0.02">
                                    <joint name="right_hand_x" axis="1 0 0" range="-1.57 1.57" stiffness="100"
                                           damping="10"
                                           armature=".01"/>
                                    <joint name="right_hand_y" axis="0 1 0" range="-1.57 1.57" stiffness="100"
                                           damping="10"
                                           armature=".003"/>
                                    <joint name="right_hand_z" axis="0 0 1" range="-1.57 1.57" stiffness="100"
                                           damping="10"
                                           armature=".003"/>
                                    <!--                                    <geom name="right_hand" type="sphere" size=".04" density="0"/>-->
                                    <site name="right_hand" class="touch" type="sphere" size=".041"/>

                                    <body name="right_qbhand_root_link" pos="0.0 0.0 0.0" quat="0.707 0 0.707 0">
                                        <geom type="mesh" rgba="0.35 0.35 0.35 1" mesh="flange_iso_04" contype="0"
                                              conaffinity="0"/>
                                        <geom pos="-0.0045 0.0145 0.144" quat="0.707388 0.706825 0 0" type="mesh"
                                              rgba="0.35 0.35 0.35 1" mesh="palm_pinch_r" contype="0" conaffinity="0"/>
                                        <geom pos="-0.0045 0.0145 0.144" quat="0.707388 0.706825 0 0" type="mesh"
                                              rgba="0.35 0.35 0.35 1" mesh="palm_pinch_r" contype="0"/>

                                        <body name="right_qbhand_thumb_knuckle_link" pos="-0.0485 0.016463 0.0974984"
                                              quat="0.000796327 0 0.000796326 0.999999">
                                            <inertial pos="0.0130716 -0.00273578 0.000643478"
                                                      quat="0.502681 0.576479 0.364062 0.531453" mass="0.01"
                                                      diaginertia="1.4342e-06 1.35762e-06 3.12515e-07"/>
                                            <joint name="right_qbhand_thumb_knuckle_joint" pos="0 0 0" axis="0 0 -1"
                                                   limited="true"
                                                   range="0 1.57"/>
                                            <geom type="mesh" contype="0" conaffinity="0" rgba="0.35 0.35 0.35 1"
                                                  mesh="ph_thumb_r"/>
                                            <geom type="mesh" contype="0" rgba="0.35 0.35 0.35 1"
                                                  mesh="ph_thumb_r_collision"/>
                                            <body name="right_qbhand_thumb_proximal_virtual_link"
                                                  pos="0.0255 -0.0038 -0.00012"
                                                  quat="0.841496 -0.540263 0 0">
                                                <inertial pos="0 0 0" mass="0.0001" diaginertia="1e-09 1e-09 1e-09"/>
                                                <joint name="right_qbhand_thumb_proximal_joint" pos="0 0 0"
                                                       axis="0 0 -1"
                                                       limited="true" range="0 0.785"/>
                                                <body name="right_qbhand_thumb_proximal_link" pos="0.013 0 0">
                                                    <inertial pos="0.00476016 -0.00137869 0"
                                                              quat="0.0365143 0.706163 -0.0365143 0.706163"
                                                              mass="0.0063"
                                                              diaginertia="2.6915e-07 2.3576e-07 1.79645e-07"/>
                                                    <joint name="right_qbhand_thumb_proximal_virtual_joint" pos="0 0 0"
                                                           axis="0 0 -1"
                                                           limited="true" range="0 0.785"/>
                                                    <geom type="mesh" contype="0" conaffinity="0"
                                                          rgba="0.35 0.35 0.35 1" mesh="ph_short"/>
                                                    <geom type="mesh" contype="0" rgba="0.35 0.35 0.35 1"
                                                          mesh="ph_short_collision"/>
                                                    <body name="right_qbhand_thumb_distal_virtual_link" pos="0.009 0 0">
                                                        <inertial pos="0 0 0" mass="0.0001"
                                                                  diaginertia="1e-09 1e-09 1e-09"/>
                                                        <joint name="right_qbhand_thumb_distal_joint" pos="0 0 0"
                                                               axis="0 0 -1"
                                                               limited="true" range="0 0.785"/>
                                                        <body name="right_qbhand_thumb_distal_link" pos="0.013 0 0">
                                                            <inertial pos="0.00880255 -0.00172193 0"
                                                                      quat="0.0131386 0.706985 -0.0131386 0.706985"
                                                                      mass="0.009"
                                                                      diaginertia="6.6782e-07 5.99819e-07 2.654e-07"/>
                                                            <joint name="right_qbhand_thumb_distal_virtual_joint"
                                                                   pos="0 0 0"
                                                                   axis="0 0 -1" limited="true" range="0 0.785"/>
                                                            <geom type="mesh" contype="0" conaffinity="0"
                                                                  rgba="0.35 0.35 0.35 1" mesh="ph_distal"/>
                                                            <geom type="mesh" contype="0" rgba="0.35 0.35 0.35 1"
                                                                  mesh="ph_distal_collision"/>
                                                        </body>
                                                    </body>
                                                </body>
                                            </body>
                                        </body>
                                        <body name="right_qbhand_index_knuckle_link" pos="-0.0245 0.00049443 0.137011"
                                              quat="0.500398 0.5 -0.499602 0.5">
                                            <inertial pos="0.000427536 0 -0.00143217"
                                                      quat="0.587164 0.394003 0.394003 0.587164"
                                                      mass="0.0095"
                                                      diaginertia="1.12538e-06 7.39498e-07 6.27245e-07"/>
                                            <joint name="right_qbhand_index_knuckle_joint" pos="0 0 0" axis="0 0 -1"
                                                   limited="true"
                                                   range="-0.523 0.523"/>
                                            <geom type="mesh" contype="0" conaffinity="0" rgba="0.35 0.35 0.35 1"
                                                  mesh="ph_knuckle"/>
                                            <geom type="mesh" contype="0" rgba="0.35 0.35 0.35 1"
                                                  mesh="ph_knuckle_collision"/>
                                            <body name="right_qbhand_index_proximal_virtual_link" pos="0.009 0 0"
                                                  quat="0.707388 0.706825 0 0">
                                                <inertial pos="0 0 0" mass="0.0001" diaginertia="1e-09 1e-09 1e-09"/>
                                                <joint name="right_qbhand_index_proximal_joint" pos="0 0 0"
                                                       axis="0 0 -1"
                                                       limited="true" range="0 0.785"/>
                                                <body name="right_qbhand_index_proximal_link" pos="0.013 0 0">
                                                    <inertial pos="0.00877074 -0.00178631 0"
                                                              quat="0.0123083 0.707 -0.0123083 0.707" mass="0.0082"
                                                              diaginertia="5.95622e-07 5.59876e-07 2.26817e-07"/>
                                                    <joint name="right_qbhand_index_proximal_virtual_joint" pos="0 0 0"
                                                           axis="0 0 -1"
                                                           limited="true"
                                                           range="0 0.785"/>
                                                    <geom type="mesh" contype="0" conaffinity="0"
                                                          rgba="0.35 0.35 0.35 1"
                                                          mesh="ph_medium"/>
                                                    <geom type="mesh" contype="0" rgba="0.35 0.35 0.35 1"
                                                          mesh="ph_medium_collision"/>
                                                    <body name="right_qbhand_index_middle_virtual_link" pos="0.017 0 0">
                                                        <inertial pos="0 0 0" mass="0.0001"
                                                                  diaginertia="1e-09 1e-09 1e-09"/>
                                                        <joint name="right_qbhand_index_middle_joint" pos="0 0 0"
                                                               axis="0 0 -1"
                                                               limited="true"
                                                               range="0 0.785"/>
                                                        <body name="right_qbhand_index_middle_link" pos="0.013 0 0">
                                                            <inertial pos="0.00476016 -0.00137869 0"
                                                                      quat="0.0365143 0.706163 -0.0365143 0.706163"
                                                                      mass="0.0063"
                                                                      diaginertia="2.6915e-07 2.3576e-07 1.79645e-07"/>
                                                            <joint name="right_qbhand_index_middle_virtual_joint"
                                                                   pos="0 0 0"
                                                                   axis="0 0 -1" limited="true"
                                                                   range="0 0.785"/>
                                                            <geom type="mesh" contype="0" conaffinity="0"
                                                                  rgba="0.35 0.35 0.35 1"
                                                                  mesh="ph_short"/>
                                                            <geom type="mesh" contype="0" rgba="0.35 0.35 0.35 1"
                                                                  mesh="ph_short_collision"/>
                                                            <body name="right_qbhand_index_distal_virtual_link"
                                                                  pos="0.009 0 0">
                                                                <inertial pos="0 0 0" mass="0.0001"
                                                                          diaginertia="1e-09 1e-09 1e-09"/>
                                                                <joint name="right_qbhand_index_distal_joint"
                                                                       pos="0 0 0"
                                                                       axis="0 0 -1" limited="true"
                                                                       range="0 0.785"/>
                                                                <body name="right_qbhand_index_distal_link"
                                                                      pos="0.013 0 0">
                                                                    <inertial pos="0.00880255 -0.00172193 0"
                                                                              quat="0.0131386 0.706985 -0.0131386 0.706985"
                                                                              mass="0.009"
                                                                              diaginertia="6.6782e-07 5.99819e-07 2.654e-07"/>
                                                                    <joint name="right_qbhand_index_distal_virtual_joint"
                                                                           pos="0 0 0"
                                                                           axis="0 0 -1"
                                                                           limited="true" range="0 0.785"/>
                                                                    <geom type="mesh" contype="0" conaffinity="0"
                                                                          rgba="0.35 0.35 0.35 1"
                                                                          mesh="ph_distal"/>
                                                                    <geom type="mesh" contype="0"
                                                                          rgba="0.35 0.35 0.35 1"
                                                                          mesh="ph_distal_collision"/>
                                                                </body>
                                                            </body>
                                                        </body>
                                                    </body>
                                                </body>
                                            </body>
                                        </body>
                                        <body name="right_qbhand_middle_knuckle_link" pos="-0.0045 0.000500004 0.144011"
                                              quat="0.500398 0.5 -0.499602 0.5">
                                            <inertial pos="0.000427536 0 -0.00143217"
                                                      quat="0.587164 0.394003 0.394003 0.587164"
                                                      mass="0.0095"
                                                      diaginertia="1.12538e-06 7.39498e-07 6.27245e-07"/>
                                            <joint name="right_qbhand_middle_knuckle_joint" pos="0 0 0" axis="0 0 -1"
                                                   limited="true"
                                                   range="-0.523 0.523"/>
                                            <geom type="mesh" contype="0" conaffinity="0" rgba="0.35 0.35 0.35 1"
                                                  mesh="ph_knuckle"/>
                                            <geom type="mesh" contype="0" rgba="0.35 0.35 0.35 1"
                                                  mesh="ph_knuckle_collision"/>
                                            <body name="right_qbhand_middle_proximal_virtual_link" pos="0.009 0 0"
                                                  quat="0.707388 0.706825 0 0">
                                                <inertial pos="0 0 0" mass="0.0001" diaginertia="1e-09 1e-09 1e-09"/>
                                                <joint name="right_qbhand_middle_proximal_joint" pos="0 0 0"
                                                       axis="0 0 -1"
                                                       limited="true"
                                                       range="0 0.785"/>
                                                <body name="right_qbhand_middle_proximal_link" pos="0.013 0 0">
                                                    <inertial pos="0.00877074 -0.00178631 0"
                                                              quat="0.0123083 0.707 -0.0123083 0.707" mass="0.0082"
                                                              diaginertia="5.95622e-07 5.59876e-07 2.26817e-07"/>
                                                    <joint name="right_qbhand_middle_proximal_virtual_joint" pos="0 0 0"
                                                           axis="0 0 -1"
                                                           limited="true"
                                                           range="0 0.785"/>
                                                    <geom type="mesh" contype="0" conaffinity="0"
                                                          rgba="0.35 0.35 0.35 1"
                                                          mesh="ph_medium"/>
                                                    <geom type="mesh" contype="0" rgba="0.35 0.35 0.35 1"
                                                          mesh="ph_medium_collision"/>
                                                    <body name="right_qbhand_middle_middle_virtual_link"
                                                          pos="0.017 0 0">
                                                        <inertial pos="0 0 0" mass="0.0001"
                                                                  diaginertia="1e-09 1e-09 1e-09"/>
                                                        <joint name="right_qbhand_middle_middle_joint" pos="0 0 0"
                                                               axis="0 0 -1"
                                                               limited="true"
                                                               range="0 0.785"/>
                                                        <body name="right_qbhand_middle_middle_link" pos="0.013 0 0">
                                                            <inertial pos="0.00476016 -0.00137869 0"
                                                                      quat="0.0365143 0.706163 -0.0365143 0.706163"
                                                                      mass="0.0063"
                                                                      diaginertia="2.6915e-07 2.3576e-07 1.79645e-07"/>
                                                            <joint name="right_qbhand_middle_middle_virtual_joint"
                                                                   pos="0 0 0"
                                                                   axis="0 0 -1"
                                                                   limited="true" range="0 0.785"/>
                                                            <geom type="mesh" contype="0" conaffinity="0"
                                                                  rgba="0.35 0.35 0.35 1"
                                                                  mesh="ph_short"/>
                                                            <geom type="mesh" contype="0" rgba="0.35 0.35 0.35 1"
                                                                  mesh="ph_short_collision"/>
                                                            <body name="right_qbhand_middle_distal_virtual_link"
                                                                  pos="0.009 0 0">
                                                                <inertial pos="0 0 0" mass="0.0001"
                                                                          diaginertia="1e-09 1e-09 1e-09"/>
                                                                <joint name="right_qbhand_middle_distal_joint"
                                                                       pos="0 0 0"
                                                                       axis="0 0 -1" limited="true"
                                                                       range="0 0.785"/>
                                                                <body name="right_qbhand_middle_distal_link"
                                                                      pos="0.013 0 0">
                                                                    <inertial pos="0.00880255 -0.00172193 0"
                                                                              quat="0.0131386 0.706985 -0.0131386 0.706985"
                                                                              mass="0.009"
                                                                              diaginertia="6.6782e-07 5.99819e-07 2.654e-07"/>
                                                                    <joint name="right_qbhand_middle_distal_virtual_joint"
                                                                           pos="0 0 0"
                                                                           axis="0 0 -1"
                                                                           limited="true" range="0 0.785"/>
                                                                    <geom type="mesh" contype="0" conaffinity="0"
                                                                          rgba="0.35 0.35 0.35 1"
                                                                          mesh="ph_distal"/>
                                                                    <geom type="mesh" contype="0"
                                                                          rgba="0.35 0.35 0.35 1"
                                                                          mesh="ph_distal_collision"/>
                                                                </body>
                                                            </body>
                                                        </body>
                                                    </body>
                                                </body>
                                            </body>
                                        </body>
                                        <body name="right_qbhand_ring_knuckle_link" pos="0.0155 0.00049443 0.137011"
                                              quat="0.500398 0.5 -0.499602 0.5">
                                            <inertial pos="0.000427536 0 -0.00143217"
                                                      quat="0.587164 0.394003 0.394003 0.587164"
                                                      mass="0.0095"
                                                      diaginertia="1.12538e-06 7.39498e-07 6.27245e-07"/>
                                            <joint name="right_qbhand_ring_knuckle_joint" pos="0 0 0" axis="0 0 -1"
                                                   limited="true"
                                                   range="-0.523 0.523"/>
                                            <geom type="mesh" contype="0" conaffinity="0" rgba="0.35 0.35 0.35 1"
                                                  mesh="ph_knuckle"/>
                                            <geom type="mesh" contype="0" rgba="0.35 0.35 0.35 1"
                                                  mesh="ph_knuckle_collision"/>
                                            <body name="right_qbhand_ring_proximal_virtual_link" pos="0.009 0 0"
                                                  quat="0.707388 0.706825 0 0">
                                                <inertial pos="0 0 0" mass="0.0001" diaginertia="1e-09 1e-09 1e-09"/>
                                                <joint name="right_qbhand_ring_proximal_joint" pos="0 0 0" axis="0 0 -1"
                                                       limited="true" range="0 0.785"/>
                                                <body name="right_qbhand_ring_proximal_link" pos="0.013 0 0">
                                                    <inertial pos="0.00877074 -0.00178631 0"
                                                              quat="0.0123083 0.707 -0.0123083 0.707" mass="0.0082"
                                                              diaginertia="5.95622e-07 5.59876e-07 2.26817e-07"/>
                                                    <joint name="right_qbhand_ring_proximal_virtual_joint" pos="0 0 0"
                                                           axis="0 0 -1"
                                                           limited="true"
                                                           range="0 0.785"/>
                                                    <geom type="mesh" contype="0" conaffinity="0"
                                                          rgba="0.35 0.35 0.35 1"
                                                          mesh="ph_medium"/>
                                                    <geom type="mesh" contype="0" rgba="0.35 0.35 0.35 1"
                                                          mesh="ph_medium_collision"/>
                                                    <body name="right_qbhand_ring_middle_virtual_link" pos="0.017 0 0">
                                                        <inertial pos="0 0 0" mass="0.0001"
                                                                  diaginertia="1e-09 1e-09 1e-09"/>
                                                        <joint name="right_qbhand_ring_middle_joint" pos="0 0 0"
                                                               axis="0 0 -1"
                                                               limited="true"
                                                               range="0 0.785"/>
                                                        <body name="right_qbhand_ring_middle_link" pos="0.013 0 0">
                                                            <inertial pos="0.00476016 -0.00137869 0"
                                                                      quat="0.0365143 0.706163 -0.0365143 0.706163"
                                                                      mass="0.0063"
                                                                      diaginertia="2.6915e-07 2.3576e-07 1.79645e-07"/>
                                                            <joint name="right_qbhand_ring_middle_virtual_joint"
                                                                   pos="0 0 0"
                                                                   axis="0 0 -1" limited="true"
                                                                   range="0 0.785"/>
                                                            <geom type="mesh" contype="0" conaffinity="0"
                                                                  rgba="0.35 0.35 0.35 1"
                                                                  mesh="ph_short"/>
                                                            <geom type="mesh" contype="0" rgba="0.35 0.35 0.35 1"
                                                                  mesh="ph_short_collision"/>
                                                            <body name="right_qbhand_ring_distal_virtual_link"
                                                                  pos="0.009 0 0">
                                                                <inertial pos="0 0 0" mass="0.0001"
                                                                          diaginertia="1e-09 1e-09 1e-09"/>
                                                                <joint name="right_qbhand_ring_distal_joint" pos="0 0 0"
                                                                       axis="0 0 -1"
                                                                       limited="true"
                                                                       range="0 0.785"/>
                                                                <body name="right_qbhand_ring_distal_link"
                                                                      pos="0.013 0 0">
                                                                    <inertial pos="0.00880255 -0.00172193 0"
                                                                              quat="0.0131386 0.706985 -0.0131386 0.706985"
                                                                              mass="0.009"
                                                                              diaginertia="6.6782e-07 5.99819e-07 2.654e-07"/>
                                                                    <joint name="right_qbhand_ring_distal_virtual_joint"
                                                                           pos="0 0 0"
                                                                           axis="0 0 -1"
                                                                           limited="true" range="0 0.785"/>
                                                                    <geom type="mesh" contype="0" conaffinity="0"
                                                                          rgba="0.35 0.35 0.35 1"
                                                                          mesh="ph_distal"/>
                                                                    <geom type="mesh" contype="0"
                                                                          rgba="0.35 0.35 0.35 1"
                                                                          mesh="ph_distal_collision"/>
                                                                </body>
                                                            </body>
                                                        </body>
                                                    </body>
                                                </body>
                                            </body>
                                        </body>
                                        <body name="right_qbhand_little_knuckle_link" pos="0.0355 0.000490449 0.132011"
                                              quat="0.500398 0.5 -0.499602 0.5">
                                            <inertial pos="0.000427536 0 -0.00143217"
                                                      quat="0.587164 0.394003 0.394003 0.587164"
                                                      mass="0.0095"
                                                      diaginertia="1.12538e-06 7.39498e-07 6.27245e-07"/>
                                            <joint name="right_qbhand_little_knuckle_joint" pos="0 0 0" axis="0 0 -1"
                                                   limited="true"
                                                   range="-0.523 0.523"/>
                                            <geom type="mesh" contype="0" conaffinity="0" rgba="0.35 0.35 0.35 1"
                                                  mesh="ph_knuckle"/>
                                            <geom type="mesh" contype="0" rgba="0.35 0.35 0.35 1"
                                                  mesh="ph_knuckle_collision"/>
                                            <body name="right_qbhand_little_proximal_virtual_link" pos="0.009 0 0"
                                                  quat="0.707388 0.706825 0 0">
                                                <inertial pos="0 0 0" mass="0.0001" diaginertia="1e-09 1e-09 1e-09"/>
                                                <joint name="right_qbhand_little_proximal_joint" pos="0 0 0"
                                                       axis="0 0 -1"
                                                       limited="true"
                                                       range="0 0.785"/>
                                                <body name="right_qbhand_little_proximal_link" pos="0.013 0 0">
                                                    <inertial pos="0.00476016 -0.00137869 0"
                                                              quat="0.0365143 0.706163 -0.0365143 0.706163"
                                                              mass="0.0063"
                                                              diaginertia="2.6915e-07 2.3576e-07 1.79645e-07"/>
                                                    <joint name="right_qbhand_little_proximal_virtual_joint" pos="0 0 0"
                                                           axis="0 0 -1"
                                                           limited="true"
                                                           range="0 0.785"/>
                                                    <geom type="mesh" contype="0" conaffinity="0"
                                                          rgba="0.35 0.35 0.35 1"
                                                          mesh="ph_short"/>
                                                    <geom type="mesh" contype="0" rgba="0.35 0.35 0.35 1"
                                                          mesh="ph_short_collision"/>
                                                    <body name="right_qbhand_little_middle_virtual_link"
                                                          pos="0.009 0 0">
                                                        <inertial pos="0 0 0" mass="0.0001"
                                                                  diaginertia="1e-09 1e-09 1e-09"/>
                                                        <joint name="right_qbhand_little_middle_joint" pos="0 0 0"
                                                               axis="0 0 -1"
                                                               limited="true"
                                                               range="0 0.785"/>
                                                        <body name="right_qbhand_little_middle_link" pos="0.013 0 0">
                                                            <inertial pos="0.00476016 -0.00137869 0"
                                                                      quat="0.0365143 0.706163 -0.0365143 0.706163"
                                                                      mass="0.0063"
                                                                      diaginertia="2.6915e-07 2.3576e-07 1.79645e-07"/>
                                                            <joint name="right_qbhand_little_middle_virtual_joint"
                                                                   pos="0 0 0"
                                                                   axis="0 0 -1"
                                                                   limited="true" range="0 0.785"/>
                                                            <geom type="mesh" contype="0" conaffinity="0"
                                                                  rgba="0.35 0.35 0.35 1"
                                                                  mesh="ph_short"/>
                                                            <geom type="mesh" contype="0" rgba="0.35 0.35 0.35 1"
                                                                  mesh="ph_short_collision"/>
                                                            <body name="right_qbhand_little_distal_virtual_link"
                                                                  pos="0.009 0 0">
                                                                <inertial pos="0 0 0" mass="0.0001"
                                                                          diaginertia="1e-09 1e-09 1e-09"/>
                                                                <joint name="right_qbhand_little_distal_joint"
                                                                       pos="0 0 0"
                                                                       axis="0 0 -1" limited="true"
                                                                       range="0 0.785"/>
                                                                <body name="right_qbhand_little_distal_link"
                                                                      pos="0.013 0 0">
                                                                    <inertial pos="0.00880255 -0.00172193 0"
                                                                              quat="0.0131386 0.706985 -0.0131386 0.706985"
                                                                              mass="0.009"
                                                                              diaginertia="6.6782e-07 5.99819e-07 2.654e-07"/>
                                                                    <joint name="right_qbhand_little_distal_virtual_joint"
                                                                           pos="0 0 0"
                                                                           axis="0 0 -1"
                                                                           limited="true" range="0 0.785"/>
                                                                    <geom type="mesh"
                                                                          contype="0"
                                                                          conaffinity="0"
                                                                          rgba="0.35 0.35 0.35 1"
                                                                          mesh="ph_distal"/>
                                                                    <geom type="mesh" contype="0"
                                                                          rgba="0.35 0.35 0.35 1"
                                                                          mesh="ph_distal_collision"/>
                                                                </body>
                                                            </body>
                                                        </body>
                                                    </body>
                                                </body>
                                            </body>
                                        </body>
                                    </body>
                                </body>
                            </body>
                        </body>
                    </body>
                </body>
            </body>
        </body>
    </worldbody>


    <actuator>
        <motor name="left_hip_yaw_joint" gear="125" joint="left_hip_yaw_joint"/>
        <motor name="left_hip_roll_joint" gear="125" joint="left_hip_roll_joint"/>
        <motor name="left_hip_pitch_joint" gear="125" joint="left_hip_pitch_joint"/>
        <motor name="left_knee_joint" gear="125" joint="left_knee_joint"/>
        <motor name="left_ankle_joint" gear="125" joint="left_ankle_joint"/>
        <motor name="right_hip_yaw_joint" gear="125" joint="right_hip_yaw_joint"/>
        <motor name="right_hip_roll_joint" gear="125" joint="right_hip_roll_joint"/>
        <motor name="right_hip_pitch_joint" gear="125" joint="right_hip_pitch_joint"/>
        <motor name="right_knee_joint" gear="125" joint="right_knee_joint"/>
        <motor name="right_ankle_joint" gear="125" joint="right_ankle_joint"/>
        <motor name="torso_joint" gear="125" joint="torso_joint"/>
        <motor name="left_shoulder_pitch_joint" gear="125" joint="left_shoulder_pitch_joint"/>
        <motor name="left_shoulder_roll_joint" gear="125" joint="left_shoulder_roll_joint"/>
        <motor name="left_shoulder_yaw_joint" gear="125" joint="left_shoulder_yaw_joint"/>
        <motor name="left_elbow_joint" gear="125" joint="left_elbow_joint"/>
        <motor name='left_hand_x' gear='50' joint='left_hand_x'/>
        <motor name='left_hand_y' gear='50' joint='left_hand_y'/>
        <motor name='left_hand_z' gear='50' joint='left_hand_z'/>
        <motor name='left_qbhand_thumb_knuckle_joint' gear='50' joint='left_qbhand_thumb_knuckle_joint'/>
        <motor name='left_qbhand_thumb_proximal_joint' gear='50' joint='left_qbhand_thumb_proximal_joint'/>
        <motor name='left_qbhand_thumb_distal_joint' gear='50' joint='left_qbhand_thumb_distal_joint'/>
        <motor name='left_qbhand_index_proximal_joint' gear='50' joint='left_qbhand_index_proximal_joint'/>
        <motor name='left_qbhand_index_middle_joint' gear='50' joint='left_qbhand_index_middle_joint'/>
        <motor name='left_qbhand_index_distal_joint' gear='50' joint='left_qbhand_index_distal_joint'/>
        <motor name='left_qbhand_middle_proximal_joint' gear='50' joint='left_qbhand_middle_proximal_joint'/>
        <motor name='left_qbhand_middle_middle_joint' gear='50' joint='left_qbhand_middle_middle_joint'/>
        <motor name='left_qbhand_middle_distal_joint' gear='50' joint='left_qbhand_middle_distal_joint'/>
        <motor name='left_qbhand_ring_proximal_joint' gear='50' joint='left_qbhand_ring_proximal_joint'/>
        <motor name='left_qbhand_ring_middle_joint' gear='50' joint='left_qbhand_ring_middle_joint'/>
        <motor name='left_qbhand_ring_distal_joint' gear='50' joint='left_qbhand_ring_distal_joint'/>
        <motor name='left_qbhand_little_proximal_joint' gear='50' joint='left_qbhand_little_proximal_joint'/>
        <motor name='left_qbhand_little_middle_joint' gear='50' joint='left_qbhand_little_middle_joint'/>
        <motor name='left_qbhand_little_distal_joint' gear='50' joint='left_qbhand_little_distal_joint'/>
        <motor name="right_shoulder_pitch_joint" gear="125" joint="right_shoulder_pitch_joint"/>
        <motor name="right_shoulder_roll_joint" gear="125" joint="right_shoulder_roll_joint"/>
        <motor name="right_shoulder_yaw_joint" gear="125" joint="right_shoulder_yaw_joint"/>
        <motor name="right_elbow_joint" gear="125" joint="right_elbow_joint"/>
        <motor name='right_hand_x' gear='50' joint='right_hand_x'/>
        <motor name='right_hand_y' gear='50' joint='right_hand_y'/>
        <motor name='right_hand_z' gear='50' joint='right_hand_z'/>
        <motor name='right_qbhand_thumb_knuckle_joint' gear='50' joint='right_qbhand_thumb_knuckle_joint'/>
        <motor name='right_qbhand_thumb_proximal_joint' gear='50' joint='right_qbhand_thumb_proximal_joint'/>
        <motor name='right_qbhand_thumb_distal_joint' gear='50' joint='right_qbhand_thumb_distal_joint'/>
        <motor name='right_qbhand_index_proximal_joint' gear='50' joint='right_qbhand_index_proximal_joint'/>
        <motor name='right_qbhand_index_middle_joint' gear='50' joint='right_qbhand_index_middle_joint'/>
        <motor name='right_qbhand_index_distal_joint' gear='50' joint='right_qbhand_index_distal_joint'/>
        <motor name='right_qbhand_middle_proximal_joint' gear='50' joint='right_qbhand_middle_proximal_joint'/>
        <motor name='right_qbhand_middle_middle_joint' gear='50' joint='right_qbhand_middle_middle_joint'/>
        <motor name='right_qbhand_middle_distal_joint' gear='50' joint='right_qbhand_middle_distal_joint'/>
        <motor name='right_qbhand_ring_proximal_joint' gear='50' joint='right_qbhand_ring_proximal_joint'/>
        <motor name='right_qbhand_ring_middle_joint' gear='50' joint='right_qbhand_ring_middle_joint'/>
        <motor name='right_qbhand_ring_distal_joint' gear='50' joint='right_qbhand_ring_distal_joint'/>
        <motor name='right_qbhand_little_proximal_joint' gear='50' joint='right_qbhand_little_proximal_joint'/>
        <motor name='right_qbhand_little_middle_joint' gear='50' joint='right_qbhand_little_middle_joint'/>
        <motor name='right_qbhand_little_distal_joint' gear='50' joint='right_qbhand_little_distal_joint'/>
    </actuator>
</mujoco>
