<mujoco model="ZJU_Humanoid_W_Qbhand">
    <compiler angle="radian"/>
    <statistic meansize="0.514972" extent="1.83853" center="0.00045652 9.85972e-05 -0.561266"/>
    <default>
        <motor ctrlrange="-1 1" ctrllimited="true"/>
        <default class="body">
            <geom type="capsule" condim="1" friction="1.0 0.05 0.05" solimp=".9 .99 .003" solref=".015 1"/>
            <joint type="hinge" damping="0.1" stiffness="5" armature=".007" limited="true" solimplimit="0 .99 .01"/>
            <site size=".04" group="3"/>
            <default class="force-torque">
                <site type="box" size=".01 .01 .02" rgba="1 0 0 1"/>
            </default>
            <default class="touch">
                <site type="capsule" rgba="0 0 1 .3"/>
            </default>
        </default>
    </default>
    <asset>
        <mesh name="TORSO" file="../../urdf/zju_humanoid/low_meshes/TORSO.STL"/>
        <mesh name="SCAPULA_R" file="../../urdf/zju_humanoid/low_meshes/SCAPULA_R.STL"/>
        <mesh name="SHOULDER_R" file="../../urdf/zju_humanoid/low_meshes/SHOULDER_R.STL"/>
        <mesh name="UPPERARM_R" file="../../urdf/zju_humanoid/low_meshes/UPPERARM_R.STL"/>
        <mesh name="FOREARM_R" file="../../urdf/zju_humanoid/low_meshes/FOREARM_R.STL"/>
        <mesh name="WRIST_REVOLUTE_R" file="../../urdf/zju_humanoid/low_meshes/WRIST_REVOLUTE_R.STL"/>
        <mesh name="WRIST_UPDOWN_R" file="../../urdf/zju_humanoid/low_meshes/WRIST_UPDOWN_R.STL"/>
        <mesh name="HAND_R" file="../../urdf/zju_humanoid/low_meshes/HAND_R.STL"/>
        <mesh name="SCAPULA_L" file="../../urdf/zju_humanoid/low_meshes/SCAPULA_L.STL"/>
        <mesh name="SHOULDER_L" file="../../urdf/zju_humanoid/low_meshes/SHOULDER_L.STL"/>
        <mesh name="UPPERARM_L" file="../../urdf/zju_humanoid/low_meshes/UPPERARM_L.STL"/>
        <mesh name="FOREARM_L" file="../../urdf/zju_humanoid/low_meshes/FOREARM_L.STL"/>
        <mesh name="WRIST_REVOLUTE_L" file="../../urdf/zju_humanoid/low_meshes/WRIST_REVOLUTE_L.STL"/>
        <mesh name="WRIST_UPDOWN_L" file="../../urdf/zju_humanoid/low_meshes/WRIST_UPDOWN_L.STL"/>
        <mesh name="HAND_L" file="../../urdf/zju_humanoid/low_meshes/HAND_L.STL"/>
        <mesh name="SACRUM" file="../../urdf/zju_humanoid/low_meshes/SACRUM.STL"/>
        <mesh name="ILIUM_R" file="../../urdf/zju_humanoid/low_meshes/ILIUM_R.STL"/>
        <mesh name="ISCHIUM_R" file="../../urdf/zju_humanoid/low_meshes/ISCHIUM_R.STL"/>
        <mesh name="THIGH_R" file="../../urdf/zju_humanoid/low_meshes/THIGH_R.STL"/>
        <mesh name="SHANK_R" file="../../urdf/zju_humanoid/low_meshes/SHANK_R.STL"/>
        <mesh name="ASTRAGALUS_R" file="../../urdf/zju_humanoid/low_meshes/ASTRAGALUS_R.STL"/>
        <mesh name="FOOT_R" file="../../urdf/zju_humanoid/low_meshes/FOOT_R.STL"/>
        <mesh name="TIPTOE_Z_R" file="../../urdf/zju_humanoid/low_meshes/TIPTOE_Z_R.STL"/>
        <mesh name="ILIUM_L" file="../../urdf/zju_humanoid/low_meshes/ILIUM_L.STL"/>
        <mesh name="ISCHIUM_L" file="../../urdf/zju_humanoid/low_meshes/ISCHIUM_L.STL"/>
        <mesh name="THIGH_L" file="../../urdf/zju_humanoid/low_meshes/THIGH_L.STL"/>
        <mesh name="SHANK_L" file="../../urdf/zju_humanoid/low_meshes/SHANK_L.STL"/>
        <mesh name="ASTRAGALUS_L" file="../../urdf/zju_humanoid/low_meshes/ASTRAGALUS_L.STL"/>
        <mesh name="FOOT_L" file="../../urdf/zju_humanoid/low_meshes/FOOT_L.STL"/>
        <mesh name="TIPTOE_Z_L" file="../../urdf/zju_humanoid/low_meshes/TIPTOE_Z_L.STL"/>
        <mesh name="NECK" file="../../urdf/zju_humanoid/low_meshes/NECK.STL"/>
        <mesh name="HEAD" file="../../urdf/zju_humanoid/low_meshes/HEAD.STL"/>

        <mesh name="flange_iso_04" file="../../urdf/curi/meshes/qbhand/flange_iso_04.stl" scale="0.001 0.001 0.001"/>
        <mesh name="palm_pinch_r" file="../../urdf/curi/meshes/qbhand/palm_pinch_r.stl" scale="0.001 0.001 0.001"/>
        <mesh name="ph_thumb_r" file="../../urdf/curi/meshes/qbhand/ph_thumb_r.stl" scale="0.001 0.001 0.001"/>
        <mesh name="ph_thumb_r_collision" file="../../urdf/curi/meshes/qbhand/ph_thumb_r_collision.stl"
              scale="0.001 0.001 0.001"/>
        <mesh name="palm_pinch_l" file="../../urdf/curi/meshes/qbhand/palm_pinch_l.stl" scale="0.001 0.001 0.001"/>
        <mesh name="ph_thumb_l" file="../../urdf/curi/meshes/qbhand/ph_thumb_l.stl" scale="0.001 0.001 0.001"/>
        <mesh name="ph_thumb_l_collision" file="../../urdf/curi/meshes/qbhand/ph_thumb_l_collision.stl"
              scale="0.001 0.001 0.001"/>
        <mesh name="ph_short" file="../../urdf/curi/meshes/qbhand/ph_short.stl" scale="0.001 0.001 0.001"/>
        <mesh name="ph_short_collision" file="../../urdf/curi/meshes/qbhand/ph_short_collision.stl"
              scale="0.001 0.001 0.001"/>
        <mesh name="ph_distal" file="../../urdf/curi/meshes/qbhand/ph_distal.stl" scale="0.001 0.001 0.001"/>
        <mesh name="ph_distal_collision" file="../../urdf/curi/meshes/qbhand/ph_distal_collision.stl"
              scale="0.001 0.001 0.001"/>
        <mesh name="ph_knuckle" file="../../urdf/curi/meshes/qbhand/ph_knuckle.stl" scale="0.001 0.001 0.001"/>
        <mesh name="ph_knuckle_collision" file="../../urdf/curi/meshes/qbhand/ph_knuckle_collision.stl"
              scale="0.001 0.001 0.001"/>
        <mesh name="ph_medium" file="../../urdf/curi/meshes/qbhand/ph_medium.stl" scale="0.001 0.001 0.001"/>
        <mesh name="ph_medium_collision" file="../../urdf/curi/meshes/qbhand/ph_medium_collision.stl"
              scale="0.001 0.001 0.001"/>
    </asset>
    <worldbody>
        <light directional="true" pos="-0.5 0.5 3" dir="0 0 -1"/>
        <geom name="floor" type="plane" conaffinity="1" size="100 100 .2"/>
        <body name="pelvis" pos="0 0 1.4" childclass="body">
            <geom type="mesh" contype="0" conaffinity="0" group="1" density="0" rgba="1 1 1 1" mesh="TORSO"/>
            <geom type="mesh" rgba="1 1 1 1" mesh="TORSO"/>
            <body name="SCAPULA_R" pos="-0.00138723 -0.158688 -0.0466034" quat="0.173648 0.984808 0 0">
                <inertial pos="-0.00646516 -0.277778 0.312056" quat="0.984938 0.172776 0.00364574 0.00573034"
                          mass="2.59e-02" diaginertia="4.30358e-05 3.65836e-05 0.762952e-05"/>
                <joint name="Shoulder_Y_R" pos="0 0 0" axis="0 -1 0" range="-3.14 1.22"/>
                <geom type="mesh" contype="0" conaffinity="0" group="1" density="0" rgba="1 1 1 1" mesh="SCAPULA_R"/>
                <geom type="mesh" rgba="1 1 1 1" mesh="SCAPULA_R"/>
                <body name="SHOULDER_R" pos="0 0.0752023 0" quat="0.173648 -0.984808 0 0">
                    <inertial pos="-0.00646516 0.224963 -0.413963" quat="0.999977 -0.000881804 -0.00458533 -0.00501013"
                              mass="2.59e-02" diaginertia="4.30358e-05 3.65836e-05 0.762952e-05"/>
                    <joint name="Shoulder_X_R" pos="0 0 0" axis="1 0 0" range="-2.26 0"/>
                    <geom type="mesh" contype="0" conaffinity="0" group="1" density="0" rgba="1 1 1 1"
                          mesh="SHOULDER_R"/>
                    <geom type="mesh" rgba="1 1 1 1" mesh="SHOULDER_R"/>
                    <body name="UPPERARM_R" pos="-1e-05 0 -0.0845">
                        <inertial pos="-0.00645516 0.224963 -0.329463"
                                  quat="0.999977 -0.000881804 -0.00458533 -0.00501013" mass="2.59e-02"
                                  diaginertia="4.30358e-05 3.65836e-05 0.762952e-05"/>
                        <joint name="Shoulder_Z_R" pos="0 0 0" axis="0 0 1" range="-2.09 2.09"/>
                        <geom type="mesh" contype="0" conaffinity="0" group="1" density="0" rgba="1 1 1 1"
                              mesh="UPPERARM_R"/>
                        <geom type="mesh" rgba="1 1 1 1" mesh="UPPERARM_R"/>
                        <body name="FOREARM_R" pos="0 0 -0.1455">
                            <inertial pos="-0.00645516 0.224963 -0.183962"
                                      quat="0.999977 -0.000881804 -0.00458533 -0.00501013" mass="2.59e-02"
                                      diaginertia="4.30358e-05 3.65836e-05 0.762952e-05"/>
                            <joint name="Elbow_R" pos="0 0 0" axis="0 1 0" range="-1.57 0"/>
                            <geom type="mesh" contype="0" conaffinity="0" group="1" density="0" rgba="1 1 1 1"
                                  mesh="FOREARM_R"/>
                            <geom type="mesh" rgba="1 1 1 1" mesh="FOREARM_R"/>
                            <body name="WRIST_REVOLUTE_R" pos="0 0 -0.0684244">
                                <inertial pos="-0.00645516 0.224963 -0.115538"
                                          quat="0.999977 -0.000881804 -0.00458533 -0.00501013" mass="2.59e-02"
                                          diaginertia="4.30358e-05 3.65836e-05 0.762952e-05"/>
                                <joint name="Wrist_Z_R" pos="0 0 0" axis="0 0 1" range="-2.96 2.96"/>
                                <geom type="mesh" contype="0" conaffinity="0" group="1" density="0" rgba="1 1 1 1"
                                      mesh="WRIST_REVOLUTE_R"/>
                                <geom type="mesh" rgba="1 1 1 1" mesh="WRIST_REVOLUTE_R"/>
                                <body name="WRIST_UPDOWN_R" pos="0 0 -0.20158">
                                    <inertial pos="-0.00645516 0.224963 0.0860423"
                                              quat="0.999977 -0.000881804 -0.00458533 -0.00501013" mass="2.59e-02"
                                              diaginertia="4.30358e-05 3.65836e-05 0.762952e-05"/>
                                    <joint name="Wrist_Y_R" pos="0 0 0" axis="0 -1 0" range="-0.87 0.87"/>
                                    <geom type="mesh" contype="0" conaffinity="0" group="1" density="0" rgba="1 1 1 1"
                                          mesh="WRIST_UPDOWN_R"/>
                                    <geom type="mesh" rgba="1 1 1 1" mesh="WRIST_UPDOWN_R"/>
                                    <body name="HAND_R" pos="0 0 0" quat="0 0 1 0">
                                        <joint name="Wrist_X_R" pos="0 0 0" axis="1 0 0" range="-0.87 1.57"/>
                                        <geom type="mesh" rgba="0.35 0.35 0.35 1" mesh="flange_iso_04" contype="0"
                                              conaffinity="0"/>
                                        <geom pos="-0.0045 0.0145 0.144" quat="0.707388 0.706825 0 0" type="mesh"
                                              rgba="0.35 0.35 0.35 1" mesh="palm_pinch_r" contype="0" conaffinity="0"/>
                                        <geom pos="-0.0045 0.0145 0.144" quat="0.707388 0.706825 0 0" type="mesh"
                                              rgba="0.35 0.35 0.35 1" mesh="palm_pinch_r" contype="0"/>

                                        <body name="right_qbhand_thumb_knuckle_link" pos="-0.0485 0.016463 0.0974984"
                                              quat="0.000796327 0 0.000796326 0.999999">
                                            <inertial pos="0.0130716 -0.00273578 0.000643478"
                                                      quat="0.502681 0.576479 0.364062 0.531453" mass="0.01"
                                                      diaginertia="1.4342e-06 1.35762e-06 3.12515e-07"/>
                                            <joint name="right_qbhand_thumb_knuckle_joint" pos="0 0 0" axis="0 0 -1"
                                                   limited="true"
                                                   range="0 1.57"/>
                                            <geom type="mesh" contype="0" conaffinity="0" rgba="0.35 0.35 0.35 1"
                                                  mesh="ph_thumb_r"/>
                                            <geom type="mesh" contype="0" rgba="0.35 0.35 0.35 1"
                                                  mesh="ph_thumb_r_collision"/>
                                            <body name="right_qbhand_thumb_proximal_virtual_link"
                                                  pos="0.0255 -0.0038 -0.00012"
                                                  quat="0.841496 -0.540263 0 0">
                                                <inertial pos="0 0 0" mass="0.0001" diaginertia="1e-09 1e-09 1e-09"/>
                                                <joint name="right_qbhand_thumb_proximal_joint" pos="0 0 0"
                                                       axis="0 0 -1"
                                                       limited="true" range="0 0.785"/>
                                                <body name="right_qbhand_thumb_proximal_link" pos="0.013 0 0">
                                                    <inertial pos="0.00476016 -0.00137869 0"
                                                              quat="0.0365143 0.706163 -0.0365143 0.706163"
                                                              mass="0.0063"
                                                              diaginertia="2.6915e-07 2.3576e-07 1.79645e-07"/>
                                                    <joint name="right_qbhand_thumb_proximal_virtual_joint" pos="0 0 0"
                                                           axis="0 0 -1"
                                                           limited="true" range="0 0.785"/>
                                                    <geom type="mesh" contype="0" conaffinity="0"
                                                          rgba="0.35 0.35 0.35 1" mesh="ph_short"/>
                                                    <geom type="mesh" contype="0" rgba="0.35 0.35 0.35 1"
                                                          mesh="ph_short_collision"/>
                                                    <body name="right_qbhand_thumb_distal_virtual_link" pos="0.009 0 0">
                                                        <inertial pos="0 0 0" mass="0.0001"
                                                                  diaginertia="1e-09 1e-09 1e-09"/>
                                                        <joint name="right_qbhand_thumb_distal_joint" pos="0 0 0"
                                                               axis="0 0 -1"
                                                               limited="true" range="0 0.785"/>
                                                        <body name="right_qbhand_thumb_distal_link" pos="0.013 0 0">
                                                            <inertial pos="0.00880255 -0.00172193 0"
                                                                      quat="0.0131386 0.706985 -0.0131386 0.706985"
                                                                      mass="0.009"
                                                                      diaginertia="6.6782e-07 5.99819e-07 2.654e-07"/>
                                                            <joint name="right_qbhand_thumb_distal_virtual_joint"
                                                                   pos="0 0 0"
                                                                   axis="0 0 -1" limited="true" range="0 0.785"/>
                                                            <geom type="mesh" contype="0" conaffinity="0"
                                                                  rgba="0.35 0.35 0.35 1" mesh="ph_distal"/>
                                                            <geom type="mesh" contype="0" rgba="0.35 0.35 0.35 1"
                                                                  mesh="ph_distal_collision"/>
                                                        </body>
                                                    </body>
                                                </body>
                                            </body>
                                        </body>
                                        <body name="right_qbhand_index_knuckle_link" pos="-0.0245 0.00049443 0.137011"
                                              quat="0.500398 0.5 -0.499602 0.5">
                                            <inertial pos="0.000427536 0 -0.00143217"
                                                      quat="0.587164 0.394003 0.394003 0.587164"
                                                      mass="0.0095"
                                                      diaginertia="1.12538e-06 7.39498e-07 6.27245e-07"/>
                                            <joint name="right_qbhand_index_knuckle_joint" pos="0 0 0" axis="0 0 -1"
                                                   limited="true"
                                                   range="-0.523 0.523"/>
                                            <geom type="mesh" contype="0" conaffinity="0" rgba="0.35 0.35 0.35 1"
                                                  mesh="ph_knuckle"/>
                                            <geom type="mesh" contype="0" rgba="0.35 0.35 0.35 1"
                                                  mesh="ph_knuckle_collision"/>
                                            <body name="right_qbhand_index_proximal_virtual_link" pos="0.009 0 0"
                                                  quat="0.707388 0.706825 0 0">
                                                <inertial pos="0 0 0" mass="0.0001" diaginertia="1e-09 1e-09 1e-09"/>
                                                <joint name="right_qbhand_index_proximal_joint" pos="0 0 0"
                                                       axis="0 0 -1"
                                                       limited="true" range="0 0.785"/>
                                                <body name="right_qbhand_index_proximal_link" pos="0.013 0 0">
                                                    <inertial pos="0.00877074 -0.00178631 0"
                                                              quat="0.0123083 0.707 -0.0123083 0.707" mass="0.0082"
                                                              diaginertia="5.95622e-07 5.59876e-07 2.26817e-07"/>
                                                    <joint name="right_qbhand_index_proximal_virtual_joint" pos="0 0 0"
                                                           axis="0 0 -1"
                                                           limited="true"
                                                           range="0 0.785"/>
                                                    <geom type="mesh" contype="0" conaffinity="0"
                                                          rgba="0.35 0.35 0.35 1"
                                                          mesh="ph_medium"/>
                                                    <geom type="mesh" contype="0" rgba="0.35 0.35 0.35 1"
                                                          mesh="ph_medium_collision"/>
                                                    <body name="right_qbhand_index_middle_virtual_link" pos="0.017 0 0">
                                                        <inertial pos="0 0 0" mass="0.0001"
                                                                  diaginertia="1e-09 1e-09 1e-09"/>
                                                        <joint name="right_qbhand_index_middle_joint" pos="0 0 0"
                                                               axis="0 0 -1"
                                                               limited="true"
                                                               range="0 0.785"/>
                                                        <body name="right_qbhand_index_middle_link" pos="0.013 0 0">
                                                            <inertial pos="0.00476016 -0.00137869 0"
                                                                      quat="0.0365143 0.706163 -0.0365143 0.706163"
                                                                      mass="0.0063"
                                                                      diaginertia="2.6915e-07 2.3576e-07 1.79645e-07"/>
                                                            <joint name="right_qbhand_index_middle_virtual_joint"
                                                                   pos="0 0 0"
                                                                   axis="0 0 -1" limited="true"
                                                                   range="0 0.785"/>
                                                            <geom type="mesh" contype="0" conaffinity="0"
                                                                  rgba="0.35 0.35 0.35 1"
                                                                  mesh="ph_short"/>
                                                            <geom type="mesh" contype="0" rgba="0.35 0.35 0.35 1"
                                                                  mesh="ph_short_collision"/>
                                                            <body name="right_qbhand_index_distal_virtual_link"
                                                                  pos="0.009 0 0">
                                                                <inertial pos="0 0 0" mass="0.0001"
                                                                          diaginertia="1e-09 1e-09 1e-09"/>
                                                                <joint name="right_qbhand_index_distal_joint"
                                                                       pos="0 0 0"
                                                                       axis="0 0 -1" limited="true"
                                                                       range="0 0.785"/>
                                                                <body name="right_qbhand_index_distal_link"
                                                                      pos="0.013 0 0">
                                                                    <inertial pos="0.00880255 -0.00172193 0"
                                                                              quat="0.0131386 0.706985 -0.0131386 0.706985"
                                                                              mass="0.009"
                                                                              diaginertia="6.6782e-07 5.99819e-07 2.654e-07"/>
                                                                    <joint name="right_qbhand_index_distal_virtual_joint"
                                                                           pos="0 0 0"
                                                                           axis="0 0 -1"
                                                                           limited="true" range="0 0.785"/>
                                                                    <geom type="mesh" contype="0" conaffinity="0"
                                                                          rgba="0.35 0.35 0.35 1"
                                                                          mesh="ph_distal"/>
                                                                    <geom type="mesh" contype="0"
                                                                          rgba="0.35 0.35 0.35 1"
                                                                          mesh="ph_distal_collision"/>
                                                                </body>
                                                            </body>
                                                        </body>
                                                    </body>
                                                </body>
                                            </body>
                                        </body>
                                        <body name="right_qbhand_middle_knuckle_link" pos="-0.0045 0.000500004 0.144011"
                                              quat="0.500398 0.5 -0.499602 0.5">
                                            <inertial pos="0.000427536 0 -0.00143217"
                                                      quat="0.587164 0.394003 0.394003 0.587164"
                                                      mass="0.0095"
                                                      diaginertia="1.12538e-06 7.39498e-07 6.27245e-07"/>
                                            <joint name="right_qbhand_middle_knuckle_joint" pos="0 0 0" axis="0 0 -1"
                                                   limited="true"
                                                   range="-0.523 0.523"/>
                                            <geom type="mesh" contype="0" conaffinity="0" rgba="0.35 0.35 0.35 1"
                                                  mesh="ph_knuckle"/>
                                            <geom type="mesh" contype="0" rgba="0.35 0.35 0.35 1"
                                                  mesh="ph_knuckle_collision"/>
                                            <body name="right_qbhand_middle_proximal_virtual_link" pos="0.009 0 0"
                                                  quat="0.707388 0.706825 0 0">
                                                <inertial pos="0 0 0" mass="0.0001" diaginertia="1e-09 1e-09 1e-09"/>
                                                <joint name="right_qbhand_middle_proximal_joint" pos="0 0 0"
                                                       axis="0 0 -1"
                                                       limited="true"
                                                       range="0 0.785"/>
                                                <body name="right_qbhand_middle_proximal_link" pos="0.013 0 0">
                                                    <inertial pos="0.00877074 -0.00178631 0"
                                                              quat="0.0123083 0.707 -0.0123083 0.707" mass="0.0082"
                                                              diaginertia="5.95622e-07 5.59876e-07 2.26817e-07"/>
                                                    <joint name="right_qbhand_middle_proximal_virtual_joint" pos="0 0 0"
                                                           axis="0 0 -1"
                                                           limited="true"
                                                           range="0 0.785"/>
                                                    <geom type="mesh" contype="0" conaffinity="0"
                                                          rgba="0.35 0.35 0.35 1"
                                                          mesh="ph_medium"/>
                                                    <geom type="mesh" contype="0" rgba="0.35 0.35 0.35 1"
                                                          mesh="ph_medium_collision"/>
                                                    <body name="right_qbhand_middle_middle_virtual_link"
                                                          pos="0.017 0 0">
                                                        <inertial pos="0 0 0" mass="0.0001"
                                                                  diaginertia="1e-09 1e-09 1e-09"/>
                                                        <joint name="right_qbhand_middle_middle_joint" pos="0 0 0"
                                                               axis="0 0 -1"
                                                               limited="true"
                                                               range="0 0.785"/>
                                                        <body name="right_qbhand_middle_middle_link" pos="0.013 0 0">
                                                            <inertial pos="0.00476016 -0.00137869 0"
                                                                      quat="0.0365143 0.706163 -0.0365143 0.706163"
                                                                      mass="0.0063"
                                                                      diaginertia="2.6915e-07 2.3576e-07 1.79645e-07"/>
                                                            <joint name="right_qbhand_middle_middle_virtual_joint"
                                                                   pos="0 0 0"
                                                                   axis="0 0 -1"
                                                                   limited="true" range="0 0.785"/>
                                                            <geom type="mesh" contype="0" conaffinity="0"
                                                                  rgba="0.35 0.35 0.35 1"
                                                                  mesh="ph_short"/>
                                                            <geom type="mesh" contype="0" rgba="0.35 0.35 0.35 1"
                                                                  mesh="ph_short_collision"/>
                                                            <body name="right_qbhand_middle_distal_virtual_link"
                                                                  pos="0.009 0 0">
                                                                <inertial pos="0 0 0" mass="0.0001"
                                                                          diaginertia="1e-09 1e-09 1e-09"/>
                                                                <joint name="right_qbhand_middle_distal_joint"
                                                                       pos="0 0 0"
                                                                       axis="0 0 -1" limited="true"
                                                                       range="0 0.785"/>
                                                                <body name="right_qbhand_middle_distal_link"
                                                                      pos="0.013 0 0">
                                                                    <inertial pos="0.00880255 -0.00172193 0"
                                                                              quat="0.0131386 0.706985 -0.0131386 0.706985"
                                                                              mass="0.009"
                                                                              diaginertia="6.6782e-07 5.99819e-07 2.654e-07"/>
                                                                    <joint name="right_qbhand_middle_distal_virtual_joint"
                                                                           pos="0 0 0"
                                                                           axis="0 0 -1"
                                                                           limited="true" range="0 0.785"/>
                                                                    <geom type="mesh" contype="0" conaffinity="0"
                                                                          rgba="0.35 0.35 0.35 1"
                                                                          mesh="ph_distal"/>
                                                                    <geom type="mesh" contype="0"
                                                                          rgba="0.35 0.35 0.35 1"
                                                                          mesh="ph_distal_collision"/>
                                                                </body>
                                                            </body>
                                                        </body>
                                                    </body>
                                                </body>
                                            </body>
                                        </body>
                                        <body name="right_qbhand_ring_knuckle_link" pos="0.0155 0.00049443 0.137011"
                                              quat="0.500398 0.5 -0.499602 0.5">
                                            <inertial pos="0.000427536 0 -0.00143217"
                                                      quat="0.587164 0.394003 0.394003 0.587164"
                                                      mass="0.0095"
                                                      diaginertia="1.12538e-06 7.39498e-07 6.27245e-07"/>
                                            <joint name="right_qbhand_ring_knuckle_joint" pos="0 0 0" axis="0 0 -1"
                                                   limited="true"
                                                   range="-0.523 0.523"/>
                                            <geom type="mesh" contype="0" conaffinity="0" rgba="0.35 0.35 0.35 1"
                                                  mesh="ph_knuckle"/>
                                            <geom type="mesh" contype="0" rgba="0.35 0.35 0.35 1"
                                                  mesh="ph_knuckle_collision"/>
                                            <body name="right_qbhand_ring_proximal_virtual_link" pos="0.009 0 0"
                                                  quat="0.707388 0.706825 0 0">
                                                <inertial pos="0 0 0" mass="0.0001" diaginertia="1e-09 1e-09 1e-09"/>
                                                <joint name="right_qbhand_ring_proximal_joint" pos="0 0 0" axis="0 0 -1"
                                                       limited="true" range="0 0.785"/>
                                                <body name="right_qbhand_ring_proximal_link" pos="0.013 0 0">
                                                    <inertial pos="0.00877074 -0.00178631 0"
                                                              quat="0.0123083 0.707 -0.0123083 0.707" mass="0.0082"
                                                              diaginertia="5.95622e-07 5.59876e-07 2.26817e-07"/>
                                                    <joint name="right_qbhand_ring_proximal_virtual_joint" pos="0 0 0"
                                                           axis="0 0 -1"
                                                           limited="true"
                                                           range="0 0.785"/>
                                                    <geom type="mesh" contype="0" conaffinity="0"
                                                          rgba="0.35 0.35 0.35 1"
                                                          mesh="ph_medium"/>
                                                    <geom type="mesh" contype="0" rgba="0.35 0.35 0.35 1"
                                                          mesh="ph_medium_collision"/>
                                                    <body name="right_qbhand_ring_middle_virtual_link" pos="0.017 0 0">
                                                        <inertial pos="0 0 0" mass="0.0001"
                                                                  diaginertia="1e-09 1e-09 1e-09"/>
                                                        <joint name="right_qbhand_ring_middle_joint" pos="0 0 0"
                                                               axis="0 0 -1"
                                                               limited="true"
                                                               range="0 0.785"/>
                                                        <body name="right_qbhand_ring_middle_link" pos="0.013 0 0">
                                                            <inertial pos="0.00476016 -0.00137869 0"
                                                                      quat="0.0365143 0.706163 -0.0365143 0.706163"
                                                                      mass="0.0063"
                                                                      diaginertia="2.6915e-07 2.3576e-07 1.79645e-07"/>
                                                            <joint name="right_qbhand_ring_middle_virtual_joint"
                                                                   pos="0 0 0"
                                                                   axis="0 0 -1" limited="true"
                                                                   range="0 0.785"/>
                                                            <geom type="mesh" contype="0" conaffinity="0"
                                                                  rgba="0.35 0.35 0.35 1"
                                                                  mesh="ph_short"/>
                                                            <geom type="mesh" contype="0" rgba="0.35 0.35 0.35 1"
                                                                  mesh="ph_short_collision"/>
                                                            <body name="right_qbhand_ring_distal_virtual_link"
                                                                  pos="0.009 0 0">
                                                                <inertial pos="0 0 0" mass="0.0001"
                                                                          diaginertia="1e-09 1e-09 1e-09"/>
                                                                <joint name="right_qbhand_ring_distal_joint" pos="0 0 0"
                                                                       axis="0 0 -1"
                                                                       limited="true"
                                                                       range="0 0.785"/>
                                                                <body name="right_qbhand_ring_distal_link"
                                                                      pos="0.013 0 0">
                                                                    <inertial pos="0.00880255 -0.00172193 0"
                                                                              quat="0.0131386 0.706985 -0.0131386 0.706985"
                                                                              mass="0.009"
                                                                              diaginertia="6.6782e-07 5.99819e-07 2.654e-07"/>
                                                                    <joint name="right_qbhand_ring_distal_virtual_joint"
                                                                           pos="0 0 0"
                                                                           axis="0 0 -1"
                                                                           limited="true" range="0 0.785"/>
                                                                    <geom type="mesh" contype="0" conaffinity="0"
                                                                          rgba="0.35 0.35 0.35 1"
                                                                          mesh="ph_distal"/>
                                                                    <geom type="mesh" contype="0"
                                                                          rgba="0.35 0.35 0.35 1"
                                                                          mesh="ph_distal_collision"/>
                                                                </body>
                                                            </body>
                                                        </body>
                                                    </body>
                                                </body>
                                            </body>
                                        </body>
                                        <body name="right_qbhand_little_knuckle_link" pos="0.0355 0.000490449 0.132011"
                                              quat="0.500398 0.5 -0.499602 0.5">
                                            <inertial pos="0.000427536 0 -0.00143217"
                                                      quat="0.587164 0.394003 0.394003 0.587164"
                                                      mass="0.0095"
                                                      diaginertia="1.12538e-06 7.39498e-07 6.27245e-07"/>
                                            <joint name="right_qbhand_little_knuckle_joint" pos="0 0 0" axis="0 0 -1"
                                                   limited="true"
                                                   range="-0.523 0.523"/>
                                            <geom type="mesh" contype="0" conaffinity="0" rgba="0.35 0.35 0.35 1"
                                                  mesh="ph_knuckle"/>
                                            <geom type="mesh" contype="0" rgba="0.35 0.35 0.35 1"
                                                  mesh="ph_knuckle_collision"/>
                                            <body name="right_qbhand_little_proximal_virtual_link" pos="0.009 0 0"
                                                  quat="0.707388 0.706825 0 0">
                                                <inertial pos="0 0 0" mass="0.0001" diaginertia="1e-09 1e-09 1e-09"/>
                                                <joint name="right_qbhand_little_proximal_joint" pos="0 0 0"
                                                       axis="0 0 -1"
                                                       limited="true"
                                                       range="0 0.785"/>
                                                <body name="right_qbhand_little_proximal_link" pos="0.013 0 0">
                                                    <inertial pos="0.00476016 -0.00137869 0"
                                                              quat="0.0365143 0.706163 -0.0365143 0.706163"
                                                              mass="0.0063"
                                                              diaginertia="2.6915e-07 2.3576e-07 1.79645e-07"/>
                                                    <joint name="right_qbhand_little_proximal_virtual_joint" pos="0 0 0"
                                                           axis="0 0 -1"
                                                           limited="true"
                                                           range="0 0.785"/>
                                                    <geom type="mesh" contype="0" conaffinity="0"
                                                          rgba="0.35 0.35 0.35 1"
                                                          mesh="ph_short"/>
                                                    <geom type="mesh" contype="0" rgba="0.35 0.35 0.35 1"
                                                          mesh="ph_short_collision"/>
                                                    <body name="right_qbhand_little_middle_virtual_link"
                                                          pos="0.009 0 0">
                                                        <inertial pos="0 0 0" mass="0.0001"
                                                                  diaginertia="1e-09 1e-09 1e-09"/>
                                                        <joint name="right_qbhand_little_middle_joint" pos="0 0 0"
                                                               axis="0 0 -1"
                                                               limited="true"
                                                               range="0 0.785"/>
                                                        <body name="right_qbhand_little_middle_link" pos="0.013 0 0">
                                                            <inertial pos="0.00476016 -0.00137869 0"
                                                                      quat="0.0365143 0.706163 -0.0365143 0.706163"
                                                                      mass="0.0063"
                                                                      diaginertia="2.6915e-07 2.3576e-07 1.79645e-07"/>
                                                            <joint name="right_qbhand_little_middle_virtual_joint"
                                                                   pos="0 0 0"
                                                                   axis="0 0 -1"
                                                                   limited="true" range="0 0.785"/>
                                                            <geom type="mesh" contype="0" conaffinity="0"
                                                                  rgba="0.35 0.35 0.35 1"
                                                                  mesh="ph_short"/>
                                                            <geom type="mesh" contype="0" rgba="0.35 0.35 0.35 1"
                                                                  mesh="ph_short_collision"/>
                                                            <body name="right_qbhand_little_distal_virtual_link"
                                                                  pos="0.009 0 0">
                                                                <inertial pos="0 0 0" mass="0.0001"
                                                                          diaginertia="1e-09 1e-09 1e-09"/>
                                                                <joint name="right_qbhand_little_distal_joint"
                                                                       pos="0 0 0"
                                                                       axis="0 0 -1" limited="true"
                                                                       range="0 0.785"/>
                                                                <body name="right_qbhand_little_distal_link"
                                                                      pos="0.013 0 0">
                                                                    <inertial pos="0.00880255 -0.00172193 0"
                                                                              quat="0.0131386 0.706985 -0.0131386 0.706985"
                                                                              mass="0.009"
                                                                              diaginertia="6.6782e-07 5.99819e-07 2.654e-07"/>
                                                                    <joint name="right_qbhand_little_distal_virtual_joint"
                                                                           pos="0 0 0"
                                                                           axis="0 0 -1"
                                                                           limited="true" range="0 0.785"/>
                                                                    <geom type="mesh"
                                                                          contype="0"
                                                                          conaffinity="0"
                                                                          rgba="0.35 0.35 0.35 1"
                                                                          mesh="ph_distal"/>
                                                                    <geom type="mesh" contype="0"
                                                                          rgba="0.35 0.35 0.35 1"
                                                                          mesh="ph_distal_collision"/>
                                                                </body>
                                                            </body>
                                                        </body>
                                                    </body>
                                                </body>
                                            </body>
                                        </body>
                                    </body>
                                </body>
                            </body>
                        </body>
                    </body>
                </body>
            </body>
            <body name="SCAPULA_L" pos="-0.00138723 0.158688 -0.0466034" quat="0.984808 0.173648 0 0">
                <inertial pos="-0.00646516 -0.286031 -0.309051" quat="0.984632 -0.174513 -0.00538577 -0.00413784"
                          mass="2.59e-02" diaginertia="4.30358e-05 3.65836e-05 0.762952e-05"/>
                <joint name="Shoulder_Y_L" pos="0 0 0" axis="0 -1 0" range="-1.22 3.14"/>
                <geom type="mesh" contype="0" conaffinity="0" group="1" density="0" rgba="1 1 1 1" mesh="SCAPULA_L"/>
                <geom type="mesh" rgba="1 1 1 1" mesh="SCAPULA_L"/>
                <body name="SHOULDER_L" pos="0 0.0752023 0" quat="0.984808 -0.173648 0 0">
                    <inertial pos="-0.00646516 -0.233747 -0.413963" quat="0.999977 -0.000881804 -0.00458533 -0.00501013"
                              mass="2.59e-02" diaginertia="4.30358e-05 3.65836e-05 0.762952e-05"/>
                    <joint name="Shoulder_X_L" pos="0 0 0" axis="1 0 0" range="0 2.26"/>
                    <geom type="mesh" contype="0" conaffinity="0" group="1" density="0" rgba="1 1 1 1"
                          mesh="SHOULDER_L"/>
                    <geom type="mesh" rgba="1 1 1 1" mesh="SHOULDER_L"/>
                    <body name="UPPERARM_L" pos="0 0 -0.0845">
                        <inertial pos="-0.00645516 -0.233747 -0.329463"
                                  quat="0.999977 -0.000881804 -0.00458533 -0.00501013" mass="2.59e-02"
                                  diaginertia="4.30358e-05 3.65836e-05 0.762952e-05"/>
                        <joint name="Shoulder_Z_L" pos="0 0 0" axis="0 0 1" range="-2.09 2.09"/>
                        <geom type="mesh" contype="0" conaffinity="0" group="1" density="0" rgba="1 1 1 1"
                              mesh="UPPERARM_L"/>
                        <geom type="mesh" rgba="1 1 1 1" mesh="UPPERARM_L"/>
                        <body name="FOREARM_L" pos="0 0 -0.1455">
                            <inertial pos="-0.00645516 -0.233747 -0.183962"
                                      quat="0.999977 -0.000881804 -0.00458533 -0.00501013" mass="2.59e-02"
                                      diaginertia="4.30358e-05 3.65836e-05 0.762952e-05"/>
                            <joint name="Elbow_L" pos="0 0 0" axis="0 1 0" range="-1.57 0"/>
                            <geom type="mesh" contype="0" conaffinity="0" group="1" density="0" rgba="1 1 1 1"
                                  mesh="FOREARM_L"/>
                            <geom type="mesh" rgba="1 1 1 1" mesh="FOREARM_L"/>
                            <body name="WRIST_REVOLUTE_L" pos="0 0 -0.0684244">
                                <inertial pos="-0.00645516 -0.233746 -0.115538"
                                          quat="0.999977 -0.000881804 -0.00458533 -0.00501013" mass="2.59e-02"
                                          diaginertia="4.30358e-05 3.65836e-05 0.762952e-05"/>
                                <joint name="Wrist_Z_L" pos="0 0 0" axis="0 0 1" range="-2.96 2.96"/>
                                <geom type="mesh" contype="0" conaffinity="0" group="1" density="0" rgba="1 1 1 1"
                                      mesh="WRIST_REVOLUTE_L"/>
                                <geom type="mesh" rgba="1 1 1 1" mesh="WRIST_REVOLUTE_L"/>
                                <body name="WRIST_UPDOWN_L" pos="0 0 -0.20158">
                                    <inertial pos="-0.00645516 -0.233746 0.0860423"
                                              quat="0.999977 -0.000881804 -0.00458533 -0.00501013" mass="2.59e-02"
                                              diaginertia="4.30358e-05 3.65836e-05 0.762952e-05"/>
                                    <joint name="Wrist_Y_L" pos="0 0 0" axis="0 1 0" range="-0.87 0.87"/>
                                    <geom type="mesh" contype="0" conaffinity="0" group="1" density="0" rgba="1 1 1 1"
                                          mesh="WRIST_UPDOWN_L"/>
                                    <geom type="mesh" rgba="1 1 1 1" mesh="WRIST_UPDOWN_L"/>

                                    <body name="HAND_L" pos="0 0 0" quat="0 1 0 0">
                                        <joint name="Wrist_X_L" pos="0 0 0" axis="1 0 0" range="-1.57 0.87"/>
                                        <geom type="mesh" rgba="0.35 0.35 0.35 1" mesh="flange_iso_04" contype="0"
                                              conaffinity="0"/>
                                        <geom pos="0.0045 0.0145 0.144" quat="0.000563312 0.000562864 0.706825 0.707388"
                                              type="mesh"
                                              rgba="0.35 0.35 0.35 1" mesh="palm_pinch_l" contype="0" conaffinity="0"/>
                                        <geom pos="0.0045 0.0145 0.144" quat="0.000563312 0.000562864 0.706825 0.707388"
                                              type="mesh"
                                              rgba="0.35 0.35 0.35 1" mesh="palm_pinch_l" contype="0"/>
                                        <body name="left_qbhand_thumb_knuckle_link" pos="0.0485032 0.0164669 0.0975016"
                                              quat="-0.999998 -0.000796326 6.34136e-07 0.00159265">
                                            <inertial pos="0.0130716 0.00273463 0.000640905"
                                                      quat="0.531237 0.364349 0.576408 0.502783" mass="0.01"
                                                      diaginertia="1.43383e-06 1.35753e-06 3.12211e-07"/>
                                            <joint name="left_qbhand_thumb_knuckle_joint" pos="0 0 0" axis="0 0 1"
                                                   limited="true"
                                                   range="0 1.57"/>
                                            <geom type="mesh" contype="0" conaffinity="0" rgba="0.35 0.35 0.35 1"
                                                  mesh="ph_thumb_l"/>
                                            <geom type="mesh" contype="0" rgba="0.35 0.35 0.35 1"
                                                  mesh="ph_thumb_l_collision"/>
                                            <body name="left_qbhand_thumb_proximal_virtual_link"
                                                  pos="0.0255 0.0038 -0.00012"
                                                  quat="0.540302 -0.841471 0 0">
                                                <inertial pos="0 0 0" mass="0.0001" diaginertia="1e-09 1e-09 1e-09"/>
                                                <joint name="left_qbhand_thumb_proximal_joint" pos="0 0 0" axis="0 0 -1"
                                                       limited="true" range="0 0.785"/>
                                                <body name="left_qbhand_thumb_proximal_link" pos="0.013 0 0">
                                                    <inertial pos="0.00476016 -0.00137869 0"
                                                              quat="0.0365143 0.706163 -0.0365143 0.706163"
                                                              mass="0.0063"
                                                              diaginertia="2.6915e-07 2.3576e-07 1.79645e-07"/>
                                                    <joint name="left_qbhand_thumb_proximal_virtual_joint" pos="0 0 0"
                                                           axis="0 0 -1"
                                                           limited="true" range="0 0.785"/>
                                                    <geom type="mesh" contype="0" conaffinity="0"
                                                          rgba="0.35 0.35 0.35 1" mesh="ph_short"/>
                                                    <geom type="mesh" contype="0"
                                                          rgba="0.35 0.35 0.35 1"
                                                          mesh="ph_short_collision"/>
                                                    <body name="left_qbhand_thumb_distal_virtual_link" pos="0.009 0 0">
                                                        <inertial pos="0 0 0" mass="0.0001"
                                                                  diaginertia="1e-09 1e-09 1e-09"/>
                                                        <joint name="left_qbhand_thumb_distal_joint" pos="0 0 0"
                                                               axis="0 0 -1"
                                                               limited="true" range="0 0.785"/>
                                                        <body name="left_qbhand_thumb_distal_link" pos="0.013 0 0">
                                                            <inertial pos="0.00880255 -0.00172193 0"
                                                                      quat="0.0131386 0.706985 -0.0131386 0.706985"
                                                                      mass="0.009"
                                                                      diaginertia="6.6782e-07 5.99819e-07 2.654e-07"/>
                                                            <joint name="left_qbhand_thumb_distal_virtual_joint"
                                                                   pos="0 0 0"
                                                                   axis="0 0 -1" limited="true" range="0 0.785"/>
                                                            <geom type="mesh" contype="0" conaffinity="0"
                                                                  rgba="0.35 0.35 0.35 1" mesh="ph_distal"/>
                                                            <geom type="mesh" contype="0"
                                                                  rgba="0.35 0.35 0.35 1"
                                                                  mesh="ph_distal_collision"/>
                                                        </body>
                                                    </body>
                                                </body>
                                            </body>
                                        </body>
                                        <body name="left_qbhand_index_knuckle_link" pos="0.0244777 0.000473743 0.136989"
                                              quat="-0.499999 -0.500397 0.500796 -0.498805">
                                            <inertial pos="0.000427536 0 -0.00143217"
                                                      quat="0.587164 0.394003 0.394003 0.587164"
                                                      mass="0.0095"
                                                      diaginertia="1.12538e-06 7.39498e-07 6.27245e-07"/>
                                            <joint name="left_qbhand_index_knuckle_joint" pos="0 0 0" axis="0 0 -1"
                                                   limited="true"
                                                   range="-0.523 0.523"/>
                                            <geom type="mesh" contype="0" conaffinity="0" rgba="0.35 0.35 0.35 1"
                                                  mesh="ph_knuckle"/>
                                            <geom type="mesh" contype="0" rgba="0.35 0.35 0.35 1"
                                                  mesh="ph_knuckle_collision"/>
                                            <body name="left_qbhand_index_proximal_virtual_link" pos="0.009 0 0"
                                                  quat="0.707388 0.706825 0 0">
                                                <inertial pos="0 0 0" mass="0.0001" diaginertia="1e-09 1e-09 1e-09"/>
                                                <joint name="left_qbhand_index_proximal_joint" pos="0 0 0" axis="0 0 -1"
                                                       limited="true" range="0 0.785"/>
                                                <body name="left_qbhand_index_proximal_link" pos="0.013 0 0">
                                                    <inertial pos="0.00877074 -0.00178631 0"
                                                              quat="0.0123083 0.707 -0.0123083 0.707" mass="0.0082"
                                                              diaginertia="5.95622e-07 5.59876e-07 2.26817e-07"/>
                                                    <joint name="left_qbhand_index_proximal_virtual_joint" pos="0 0 0"
                                                           axis="0 0 -1"
                                                           limited="true"
                                                           range="0 0.785"/>
                                                    <geom type="mesh" contype="0" conaffinity="0"
                                                          rgba="0.35 0.35 0.35 1"
                                                          mesh="ph_medium"/>
                                                    <geom type="mesh" contype="0"
                                                          rgba="0.35 0.35 0.35 1"
                                                          mesh="ph_medium_collision"/>
                                                    <body name="left_qbhand_index_middle_virtual_link" pos="0.017 0 0">
                                                        <inertial pos="0 0 0" mass="0.0001"
                                                                  diaginertia="1e-09 1e-09 1e-09"/>
                                                        <joint name="left_qbhand_index_middle_joint" pos="0 0 0"
                                                               axis="0 0 -1"
                                                               limited="true"
                                                               range="0 0.785"/>
                                                        <body name="left_qbhand_index_middle_link" pos="0.013 0 0">
                                                            <inertial pos="0.00476016 -0.00137869 0"
                                                                      quat="0.0365143 0.706163 -0.0365143 0.706163"
                                                                      mass="0.0063"
                                                                      diaginertia="2.6915e-07 2.3576e-07 1.79645e-07"/>
                                                            <joint name="left_qbhand_index_middle_virtual_joint"
                                                                   pos="0 0 0"
                                                                   axis="0 0 -1" limited="true"
                                                                   range="0 0.785"/>
                                                            <geom type="mesh" contype="0" conaffinity="0"
                                                                  rgba="0.35 0.35 0.35 1"
                                                                  mesh="ph_short"/>
                                                            <geom type="mesh" contype="0"
                                                                  rgba="0.35 0.35 0.35 1"
                                                                  mesh="ph_short_collision"/>
                                                            <body name="left_qbhand_index_distal_virtual_link"
                                                                  pos="0.009 0 0">
                                                                <inertial pos="0 0 0" mass="0.0001"
                                                                          diaginertia="1e-09 1e-09 1e-09"/>
                                                                <joint name="left_qbhand_index_distal_joint" pos="0 0 0"
                                                                       axis="0 0 -1" limited="true"
                                                                       range="0 0.785"/>
                                                                <body name="left_qbhand_index_distal_link"
                                                                      pos="0.013 0 0">
                                                                    <inertial pos="0.00880255 -0.00172193 0"
                                                                              quat="0.0131386 0.706985 -0.0131386 0.706985"
                                                                              mass="0.009"
                                                                              diaginertia="6.6782e-07 5.99819e-07 2.654e-07"/>
                                                                    <joint name="left_qbhand_index_distal_virtual_joint"
                                                                           pos="0 0 0"
                                                                           axis="0 0 -1"
                                                                           limited="true" range="0 0.785"/>
                                                                    <geom type="mesh" contype="0" conaffinity="0"
                                                                          rgba="0.35 0.35 0.35 1"
                                                                          mesh="ph_distal"/>
                                                                    <geom type="mesh" contype="0"
                                                                          rgba="0.35 0.35 0.35 1"
                                                                          mesh="ph_distal_collision"/>
                                                                </body>
                                                            </body>
                                                        </body>
                                                    </body>
                                                </body>
                                            </body>
                                        </body>
                                        <body name="left_qbhand_middle_knuckle_link"
                                              pos="0.0044777 0.000500022 0.143989"
                                              quat="-0.499999 -0.500397 0.500796 -0.498805">
                                            <inertial pos="0.000427536 0 -0.00143217"
                                                      quat="0.587164 0.394003 0.394003 0.587164"
                                                      mass="0.0095"
                                                      diaginertia="1.12538e-06 7.39498e-07 6.27245e-07"/>
                                            <joint name="left_qbhand_middle_knuckle_joint" pos="0 0 0" axis="0 0 -1"
                                                   limited="true"
                                                   range="-0.523 0.523"/>
                                            <geom type="mesh" contype="0" conaffinity="0" rgba="0.35 0.35 0.35 1"
                                                  mesh="ph_knuckle"/>
                                            <geom type="mesh" contype="0" rgba="0.35 0.35 0.35 1"
                                                  mesh="ph_knuckle_collision"/>
                                            <body name="left_qbhand_middle_proximal_virtual_link" pos="0.009 0 0"
                                                  quat="0.707388 0.706825 0 0">
                                                <inertial pos="0 0 0" mass="0.0001" diaginertia="1e-09 1e-09 1e-09"/>
                                                <joint name="left_qbhand_middle_proximal_joint" pos="0 0 0"
                                                       axis="0 0 -1"
                                                       limited="true"
                                                       range="0 0.785"/>
                                                <body name="left_qbhand_middle_proximal_link" pos="0.013 0 0">
                                                    <inertial pos="0.00877074 -0.00178631 0"
                                                              quat="0.0123083 0.707 -0.0123083 0.707" mass="0.0082"
                                                              diaginertia="5.95622e-07 5.59876e-07 2.26817e-07"/>
                                                    <joint name="left_qbhand_middle_proximal_virtual_joint" pos="0 0 0"
                                                           axis="0 0 -1"
                                                           limited="true"
                                                           range="0 0.785"/>
                                                    <geom type="mesh" contype="0" conaffinity="0"
                                                          rgba="0.35 0.35 0.35 1"
                                                          mesh="ph_medium"/>
                                                    <geom type="mesh" contype="0"
                                                          rgba="0.35 0.35 0.35 1"
                                                          mesh="ph_medium_collision"/>
                                                    <body name="left_qbhand_middle_middle_virtual_link" pos="0.017 0 0">
                                                        <inertial pos="0 0 0" mass="0.0001"
                                                                  diaginertia="1e-09 1e-09 1e-09"/>
                                                        <joint name="left_qbhand_middle_middle_joint" pos="0 0 0"
                                                               axis="0 0 -1"
                                                               limited="true"
                                                               range="0 0.785"/>
                                                        <body name="left_qbhand_middle_middle_link" pos="0.013 0 0">
                                                            <inertial pos="0.00476016 -0.00137869 0"
                                                                      quat="0.0365143 0.706163 -0.0365143 0.706163"
                                                                      mass="0.0063"
                                                                      diaginertia="2.6915e-07 2.3576e-07 1.79645e-07"/>
                                                            <joint name="left_qbhand_middle_middle_virtual_joint"
                                                                   pos="0 0 0"
                                                                   axis="0 0 -1"
                                                                   limited="true" range="0 0.785"/>
                                                            <geom type="mesh" contype="0" conaffinity="0"
                                                                  rgba="0.35 0.35 0.35 1"
                                                                  mesh="ph_short"/>
                                                            <geom type="mesh" contype="0"
                                                                  rgba="0.35 0.35 0.35 1"
                                                                  mesh="ph_short_collision"/>
                                                            <body name="left_qbhand_middle_distal_virtual_link"
                                                                  pos="0.009 0 0">
                                                                <inertial pos="0 0 0" mass="0.0001"
                                                                          diaginertia="1e-09 1e-09 1e-09"/>
                                                                <joint name="left_qbhand_middle_distal_joint"
                                                                       pos="0 0 0"
                                                                       axis="0 0 -1" limited="true"
                                                                       range="0 0.785"/>
                                                                <body name="left_qbhand_middle_distal_link"
                                                                      pos="0.013 0 0">
                                                                    <inertial pos="0.00880255 -0.00172193 0"
                                                                              quat="0.0131386 0.706985 -0.0131386 0.706985"
                                                                              mass="0.009"
                                                                              diaginertia="6.6782e-07 5.99819e-07 2.654e-07"/>
                                                                    <joint name="left_qbhand_middle_distal_virtual_joint"
                                                                           pos="0 0 0"
                                                                           axis="0 0 -1"
                                                                           limited="true" range="0 0.785"/>
                                                                    <geom type="mesh" contype="0" conaffinity="0"
                                                                          rgba="0.35 0.35 0.35 1"
                                                                          mesh="ph_distal"/>
                                                                    <geom type="mesh" contype="0"
                                                                          rgba="0.35 0.35 0.35 1"
                                                                          mesh="ph_distal_collision"/>
                                                                </body>
                                                            </body>
                                                        </body>
                                                    </body>
                                                </body>
                                            </body>
                                        </body>
                                        <body name="left_qbhand_ring_knuckle_link" pos="-0.0155223 0.00053745 0.136989"
                                              quat="-0.499999 -0.500397 0.500796 -0.498805">
                                            <inertial pos="0.000427536 0 -0.00143217"
                                                      quat="0.587164 0.394003 0.394003 0.587164"
                                                      mass="0.0095"
                                                      diaginertia="1.12538e-06 7.39498e-07 6.27245e-07"/>
                                            <joint name="left_qbhand_ring_knuckle_joint" pos="0 0 0" axis="0 0 -1"
                                                   limited="true"
                                                   range="-0.523 0.523"/>
                                            <geom type="mesh" contype="0" conaffinity="0" rgba="0.35 0.35 0.35 1"
                                                  mesh="ph_knuckle"/>
                                            <geom type="mesh" contype="0" rgba="0.35 0.35 0.35 1"
                                                  mesh="ph_knuckle_collision"/>
                                            <body name="left_qbhand_ring_proximal_virtual_link" pos="0.009 0 0"
                                                  quat="0.707388 0.706825 0 0">
                                                <inertial pos="0 0 0" mass="0.0001" diaginertia="1e-09 1e-09 1e-09"/>
                                                <joint name="left_qbhand_ring_proximal_joint" pos="0 0 0" axis="0 0 -1"
                                                       limited="true" range="0 0.785"/>
                                                <body name="left_qbhand_ring_proximal_link" pos="0.013 0 0">
                                                    <inertial pos="0.00877074 -0.00178631 0"
                                                              quat="0.0123083 0.707 -0.0123083 0.707" mass="0.0082"
                                                              diaginertia="5.95622e-07 5.59876e-07 2.26817e-07"/>
                                                    <joint name="left_qbhand_ring_proximal_virtual_joint" pos="0 0 0"
                                                           axis="0 0 -1"
                                                           limited="true"
                                                           range="0 0.785"/>
                                                    <geom type="mesh" contype="0" conaffinity="0"
                                                          rgba="0.35 0.35 0.35 1"
                                                          mesh="ph_medium"/>
                                                    <geom type="mesh" contype="0"
                                                          rgba="0.35 0.35 0.35 1"
                                                          mesh="ph_medium_collision"/>
                                                    <body name="left_qbhand_ring_middle_virtual_link" pos="0.017 0 0">
                                                        <inertial pos="0 0 0" mass="0.0001"
                                                                  diaginertia="1e-09 1e-09 1e-09"/>
                                                        <joint name="left_qbhand_ring_middle_joint" pos="0 0 0"
                                                               axis="0 0 -1"
                                                               limited="true"
                                                               range="0 0.785"/>
                                                        <body name="left_qbhand_ring_middle_link" pos="0.013 0 0">
                                                            <inertial pos="0.00476016 -0.00137869 0"
                                                                      quat="0.0365143 0.706163 -0.0365143 0.706163"
                                                                      mass="0.0063"
                                                                      diaginertia="2.6915e-07 2.3576e-07 1.79645e-07"/>
                                                            <joint name="left_qbhand_ring_middle_virtual_joint"
                                                                   pos="0 0 0"
                                                                   axis="0 0 -1" limited="true"
                                                                   range="0 0.785"/>
                                                            <geom type="mesh" contype="0" conaffinity="0"
                                                                  rgba="0.35 0.35 0.35 1"
                                                                  mesh="ph_short"/>
                                                            <geom type="mesh" contype="0"
                                                                  rgba="0.35 0.35 0.35 1"
                                                                  mesh="ph_short_collision"/>
                                                            <body name="left_qbhand_ring_distal_virtual_link"
                                                                  pos="0.009 0 0">
                                                                <inertial pos="0 0 0" mass="0.0001"
                                                                          diaginertia="1e-09 1e-09 1e-09"/>
                                                                <joint name="left_qbhand_ring_distal_joint" pos="0 0 0"
                                                                       axis="0 0 -1"
                                                                       limited="true"
                                                                       range="0 0.785"/>
                                                                <body name="left_qbhand_ring_distal_link"
                                                                      pos="0.013 0 0">
                                                                    <inertial pos="0.00880255 -0.00172193 0"
                                                                              quat="0.0131386 0.706985 -0.0131386 0.706985"
                                                                              mass="0.009"
                                                                              diaginertia="6.6782e-07 5.99819e-07 2.654e-07"/>
                                                                    <joint name="left_qbhand_ring_distal_virtual_joint"
                                                                           pos="0 0 0"
                                                                           axis="0 0 -1"
                                                                           limited="true" range="0 0.785"/>
                                                                    <geom type="mesh" contype="0" conaffinity="0"
                                                                          rgba="0.35 0.35 0.35 1"
                                                                          mesh="ph_distal"/>
                                                                    <geom type="mesh" contype="0"
                                                                          rgba="0.35 0.35 0.35 1"
                                                                          mesh="ph_distal_collision"/>
                                                                </body>
                                                            </body>
                                                        </body>
                                                    </body>
                                                </body>
                                            </body>
                                        </body>
                                        <body name="left_qbhand_little_knuckle_link"
                                              pos="-0.0355222 0.000573284 0.131989"
                                              quat="-0.499999 -0.500397 0.500796 -0.498805">
                                            <inertial pos="0.000427536 0 -0.00143217"
                                                      quat="0.587164 0.394003 0.394003 0.587164"
                                                      mass="0.0095"
                                                      diaginertia="1.12538e-06 7.39498e-07 6.27245e-07"/>
                                            <joint name="left_qbhand_little_knuckle_joint" pos="0 0 0" axis="0 0 -1"
                                                   limited="true"
                                                   range="-0.523 0.523"/>
                                            <geom type="mesh" contype="0" conaffinity="0" rgba="0.35 0.35 0.35 1"
                                                  mesh="ph_knuckle"/>
                                            <geom type="mesh" contype="0" rgba="0.35 0.35 0.35 1"
                                                  mesh="ph_knuckle_collision"/>
                                            <body name="left_qbhand_little_proximal_virtual_link" pos="0.009 0 0"
                                                  quat="0.707388 0.706825 0 0">
                                                <inertial pos="0 0 0" mass="0.0001" diaginertia="1e-09 1e-09 1e-09"/>
                                                <joint name="left_qbhand_little_proximal_joint" pos="0 0 0"
                                                       axis="0 0 -1"
                                                       limited="true"
                                                       range="0 0.785"/>
                                                <body name="left_qbhand_little_proximal_link" pos="0.013 0 0">
                                                    <inertial pos="0.00476016 -0.00137869 0"
                                                              quat="0.0365143 0.706163 -0.0365143 0.706163"
                                                              mass="0.0063"
                                                              diaginertia="2.6915e-07 2.3576e-07 1.79645e-07"/>
                                                    <joint name="left_qbhand_little_proximal_virtual_joint" pos="0 0 0"
                                                           axis="0 0 -1"
                                                           limited="true"
                                                           range="0 0.785"/>
                                                    <geom type="mesh" contype="0" conaffinity="0"
                                                          rgba="0.35 0.35 0.35 1"
                                                          mesh="ph_short"/>
                                                    <geom type="mesh" contype="0"
                                                          rgba="0.35 0.35 0.35 1"
                                                          mesh="ph_short_collision"/>
                                                    <body name="left_qbhand_little_middle_virtual_link" pos="0.009 0 0">
                                                        <inertial pos="0 0 0" mass="0.0001"
                                                                  diaginertia="1e-09 1e-09 1e-09"/>
                                                        <joint name="left_qbhand_little_middle_joint" pos="0 0 0"
                                                               axis="0 0 -1"
                                                               limited="true"
                                                               range="0 0.785"/>
                                                        <body name="left_qbhand_little_middle_link" pos="0.013 0 0">
                                                            <inertial pos="0.00476016 -0.00137869 0"
                                                                      quat="0.0365143 0.706163 -0.0365143 0.706163"
                                                                      mass="0.0063"
                                                                      diaginertia="2.6915e-07 2.3576e-07 1.79645e-07"/>
                                                            <joint name="left_qbhand_little_middle_virtual_joint"
                                                                   pos="0 0 0"
                                                                   axis="0 0 -1"
                                                                   limited="true" range="0 0.785"/>
                                                            <geom type="mesh" contype="0" conaffinity="0"
                                                                  rgba="0.35 0.35 0.35 1"
                                                                  mesh="ph_short"/>
                                                            <geom type="mesh" contype="0"
                                                                  rgba="0.35 0.35 0.35 1"
                                                                  mesh="ph_short_collision"/>
                                                            <body name="left_qbhand_little_distal_virtual_link"
                                                                  pos="0.009 0 0">
                                                                <inertial pos="0 0 0" mass="0.0001"
                                                                          diaginertia="1e-09 1e-09 1e-09"/>
                                                                <joint name="left_qbhand_little_distal_joint"
                                                                       pos="0 0 0"
                                                                       axis="0 0 -1" limited="true"
                                                                       range="0 0.785"/>
                                                                <body name="left_qbhand_little_distal_link"
                                                                      pos="0.013 0 0">
                                                                    <inertial pos="0.00880255 -0.00172193 0"
                                                                              quat="0.0131386 0.706985 -0.0131386 0.706985"
                                                                              mass="0.009"
                                                                              diaginertia="6.6782e-07 5.99819e-07 2.654e-07"/>
                                                                    <joint name="left_qbhand_little_distal_virtual_joint"
                                                                           pos="0 0 0"
                                                                           axis="0 0 -1"
                                                                           limited="true" range="0 0.785"/>
                                                                    <geom type="mesh" contype="0" conaffinity="0"
                                                                          rgba="0.35 0.35 0.35 1"
                                                                          mesh="ph_distal"/>
                                                                    <geom type="mesh" contype="0"
                                                                          rgba="0.35 0.35 0.35 1"
                                                                          mesh="ph_distal_collision"/>
                                                                </body>
                                                            </body>
                                                        </body>
                                                    </body>
                                                </body>
                                            </body>
                                        </body>
                                    </body>
                                </body>
                            </body>
                        </body>
                    </body>
                </body>
            </body>
            <body name="SACRUM" pos="-0.00138723 0 -0.412139">
                <inertial pos="-0.00646516 -0.00439177 -0.022706" quat="0.999977 -0.000881804 -0.00458533 -0.00501013"
                          mass="2.59e-02" diaginertia="4.30358e-05 3.65836e-05 0.762952e-05"/>
                <joint name="A_Waist" pos="0 0 0" axis="0 0 -1" range="-0.785 0.785"/>
                <geom type="mesh" contype="0" conaffinity="0" group="1" density="0" rgba="1 1 1 1" mesh="SACRUM"/>
                <body name="ILIUM_R" pos="0 -0.051 -0.1698">
                    <inertial pos="-0.00646516 0.0466082 0.147094" quat="0.999977 -0.000881804 -0.00458533 -0.00501013"
                              mass="2.59e-02" diaginertia="4.30358e-05 3.65836e-05 0.762952e-05"/>
                    <joint name="Hip_Z_R" pos="0 0 0" axis="0 0 1" range="-0.209 0.209"/>
                    <geom type="mesh" contype="0" conaffinity="0" group="1" density="0" rgba="1 1 1 1" mesh="ILIUM_R"/>
                    <body name="ISCHIUM_R" pos="0 -0.0375 0">
                        <inertial pos="-0.00646516 0.0841082 0.147094"
                                  quat="0.999977 -0.000881804 -0.00458533 -0.00501013" mass="2.59e-02"
                                  diaginertia="4.30358e-05 3.65836e-05 0.762952e-05"/>
                        <joint name="Hip_X_R" pos="0 0 0" axis="-1 0 0" range="-0.436 0.436"/>
                        <geom type="mesh" contype="0" conaffinity="0" group="1" density="0" rgba="1 1 1 1"
                              mesh="ISCHIUM_R"/>
                        <body name="THIGH_R" pos="0 -0.043004 0">
                            <inertial pos="-0.00646516 0.127112 0.147094"
                                      quat="0.999977 -0.000881804 -0.00458533 -0.00501013" mass="2.59e-02"
                                      diaginertia="4.30358e-05 3.65836e-05 0.762952e-05"/>
                            <joint name="Hip_Y_R" pos="0 0 0" axis="0 1 0" range="-2.443 0.436"/>
                            <geom type="mesh" contype="0" conaffinity="0" group="1" density="0" rgba="1 1 1 1"
                                  mesh="THIGH_R"/>
                            <geom type="mesh" rgba="1 1 1 1" mesh="THIGH_R"/>
                            <body name="SHANK_R" pos="0 0 -0.34">
                                <inertial pos="-0.00646516 0.127112 0.487094"
                                          quat="0.999977 -0.000881804 -0.00458533 -0.00501013" mass="2.59e-02"
                                          diaginertia="4.30358e-05 3.65836e-05 0.762952e-05"/>
                                <joint name="Knee_R" pos="0 0 0" axis="0 1 0" range="0 2.443"/>
                                <geom type="mesh" contype="0" conaffinity="0" group="1" density="0" rgba="1 1 1 1"
                                      mesh="SHANK_R"/>
                                <body name="ASTRAGALUS_R" pos="0 0 -0.36">
                                    <inertial pos="-0.00646516 0.127112 0.847094"
                                              quat="0.999977 -0.000881804 -0.00458533 -0.00501013" mass="2.59e-02"
                                              diaginertia="4.30358e-05 3.65836e-05 0.762952e-05"/>
                                    <joint name="Ankle_Y_R" pos="0 0 0" axis="0 -1 0" range="-0.698 1.309"/>
                                    <geom type="mesh" contype="0" conaffinity="0" group="1" density="0" rgba="1 1 1 1"
                                          mesh="ASTRAGALUS_R"/>
                                    <body name="FOOT_R" pos="0 0 0">
                                        <inertial pos="-0.00323258 0.0635561 0.381062"
                                                  quat="0.999782 -0.0197712 -0.00438517 -0.00517033" mass="5.18e-02"
                                                  diaginertia="5.44958e-05 4.78971e-05 0.777604e-05"/>
                                        <joint name="Ankle_X_R" pos="0 0 0" axis="-1 0 0" range="-0.331 0.331"/>
                                        <geom type="mesh" contype="0" conaffinity="0" group="1" density="0"
                                              rgba="1 1 1 1" mesh="FOOT_R"/>
                                        <geom type="mesh" rgba="1 1 1 1" mesh="FOOT_R"/>
                                        <geom pos="0 0 -0.08497" type="mesh" contype="0" conaffinity="0" group="1"
                                              density="0" rgba="1 1 1 1" mesh="TIPTOE_Z_R"/>
                                        <geom pos="0 0 -0.08497" type="mesh" rgba="1 1 1 1" mesh="TIPTOE_Z_R"/>
                                    </body>
                                </body>
                            </body>
                        </body>
                    </body>
                </body>
                <body name="ILIUM_L" pos="0 0.051 -0.1698">
                    <inertial pos="-0.00646516 -0.0553918 0.147094" quat="0.999977 -0.000881804 -0.00458533 -0.00501013"
                              mass="2.59e-02" diaginertia="4.30358e-05 3.65836e-05 0.762952e-05"/>
                    <joint name="Hip_Z_L" pos="0 0 0" axis="0 0 1" range="-0.209 0.209"/>
                    <geom type="mesh" contype="0" conaffinity="0" group="1" density="0" rgba="1 1 1 1" mesh="ILIUM_L"/>
                    <body name="ISCHIUM_L" pos="0 0.0375 0">
                        <inertial pos="-0.00646516 -0.0928918 0.147094"
                                  quat="0.999977 -0.000881804 -0.00458533 -0.00501013" mass="2.59e-02"
                                  diaginertia="4.30358e-05 3.65836e-05 0.762952e-05"/>
                        <joint name="Hip_X_L" pos="0 0 0" axis="-1 0 0" range="-0.436 0.436"/>
                        <geom type="mesh" contype="0" conaffinity="0" group="1" density="0" rgba="1 1 1 1"
                              mesh="ISCHIUM_L"/>
                        <body name="THIGH_L" pos="0 0.043004 0">
                            <inertial pos="-0.00646516 -0.135896 0.147094"
                                      quat="0.999977 -0.000881804 -0.00458533 -0.00501013" mass="2.59e-02"
                                      diaginertia="4.30358e-05 3.65836e-05 0.762952e-05"/>
                            <joint name="Hip_Y_L" pos="0 0 0" axis="0 1 0" range="-2.443 0.436"/>
                            <geom type="mesh" contype="0" conaffinity="0" group="1" density="0" rgba="1 1 1 1"
                                  mesh="THIGH_L"/>
                            <geom type="mesh" rgba="1 1 1 1" mesh="THIGH_L"/>
                            <body name="SHANK_L" pos="0 0 -0.34">
                                <inertial pos="-0.00646516 -0.135896 0.487094"
                                          quat="0.999977 -0.000881804 -0.00458533 -0.00501013" mass="2.59e-02"
                                          diaginertia="4.30358e-05 3.65836e-05 0.762952e-05"/>
                                <joint name="Knee_L" pos="0 0 0" axis="0 1 0" range="0 2.443"/>
                                <geom type="mesh" contype="0" conaffinity="0" group="1" density="0" rgba="1 1 1 1"
                                      mesh="SHANK_L"/>
                                <body name="ASTRAGALUS_L" pos="0 0 -0.36">
                                    <inertial pos="-0.00646516 -0.135896 0.847094"
                                              quat="0.999977 -0.000881804 -0.00458533 -0.00501013" mass="2.59e-02"
                                              diaginertia="4.30358e-05 3.65836e-05 0.762952e-05"/>
                                    <joint name="Ankle_Y_L" pos="0 0 0" axis="0 1 0" range="-0.698 1.309"/>
                                    <geom type="mesh" contype="0" conaffinity="0" group="1" density="0" rgba="1 1 1 1"
                                          mesh="ASTRAGALUS_L"/>
                                    <body name="FOOT_L" pos="0 0 0">
                                        <inertial pos="-0.00323258 -0.0679479 0.381062"
                                                  quat="0.999784 0.0198425 -0.00424682 -0.004572" mass="5.18e-02"
                                                  diaginertia="5.45257e-05 4.78974e-05 0.780582e-05"/>
                                        <joint name="Ankle_X_L" pos="0 0 0" axis="-1 0 0" range="-0.331 0.331"/>
                                        <geom type="mesh" contype="0" conaffinity="0" group="1" density="0"
                                              rgba="1 1 1 1" mesh="FOOT_L"/>
                                        <geom type="mesh" rgba="1 1 1 1" mesh="FOOT_L"/>
                                        <geom pos="0 0 -0.08497" type="mesh" contype="0" conaffinity="0" group="1"
                                              density="0" rgba="1 1 1 1" mesh="TIPTOE_Z_L"/>
                                        <geom pos="0 0 -0.08497" type="mesh" rgba="1 1 1 1" mesh="TIPTOE_Z_L"/>
                                    </body>
                                </body>
                            </body>
                        </body>
                    </body>
                </body>
            </body>
            <body name="NECK" pos="-0.00138723 0 0.089">
                <inertial pos="-0.00646516 -0.00439177 -0.523845" quat="0.999977 -0.000881804 -0.00458533 -0.00501013"
                          mass="2.59e-02" diaginertia="4.30358e-05 3.65836e-05 0.762952e-05"/>
                <joint name="Neck_Z" pos="0 0 0" axis="0 0 -1" range="-0.785 0.785"/>
                <geom type="mesh" contype="0" conaffinity="0" group="1" density="0" rgba="1 1 1 1" mesh="NECK"/>
                <geom type="mesh" rgba="1 1 1 1" mesh="NECK"/>
                <body name="HEAD" pos="0 0 0.042">
                    <inertial pos="-0.00646516 -0.00439177 -0.565845"
                              quat="0.999977 -0.000881804 -0.00458533 -0.00501013" mass="2.59e-02"
                              diaginertia="4.30358e-05 3.65836e-05 0.762952e-05"/>
                    <joint name="Neck_Y" pos="0 0 0" axis="0 -1 0" range="-0.174 0.349"/>
                    <geom type="mesh" contype="0" conaffinity="0" group="1" density="0" rgba="1 1 1 1" mesh="HEAD"/>
                </body>
            </body>
        </body>
        >
    </worldbody>

    <actuator>
        <motor name="Shoulder_Y_L" gear="125" joint="Shoulder_Y_L"/>
        <motor name="Shoulder_X_L" gear="125" joint="Shoulder_X_L"/>
        <motor name="Shoulder_Z_L" gear="125" joint="Shoulder_Z_L"/>
        <motor name="Elbow_L" gear="125" joint="Elbow_L"/>
        <motor name='Wrist_Z_L' gear='50' joint='Wrist_Z_L'/>
        <motor name='Wrist_Y_L' gear='50' joint='Wrist_Y_L'/>
        <motor name='Wrist_X_L' gear='50' joint='Wrist_X_L'/>
        <motor name='left_qbhand_thumb_knuckle_joint' gear='50' joint='left_qbhand_thumb_knuckle_joint'/>
        <motor name='left_qbhand_thumb_proximal_joint' gear='50' joint='left_qbhand_thumb_proximal_joint'/>
        <motor name='left_qbhand_thumb_distal_joint' gear='50' joint='left_qbhand_thumb_distal_joint'/>
        <motor name='left_qbhand_index_proximal_joint' gear='50' joint='left_qbhand_index_proximal_joint'/>
        <motor name='left_qbhand_index_middle_joint' gear='50' joint='left_qbhand_index_middle_joint'/>
        <motor name='left_qbhand_index_distal_joint' gear='50' joint='left_qbhand_index_distal_joint'/>
        <motor name='left_qbhand_middle_proximal_joint' gear='50' joint='left_qbhand_middle_proximal_joint'/>
        <motor name='left_qbhand_middle_middle_joint' gear='50' joint='left_qbhand_middle_middle_joint'/>
        <motor name='left_qbhand_middle_distal_joint' gear='50' joint='left_qbhand_middle_distal_joint'/>
        <motor name='left_qbhand_ring_proximal_joint' gear='50' joint='left_qbhand_ring_proximal_joint'/>
        <motor name='left_qbhand_ring_middle_joint' gear='50' joint='left_qbhand_ring_middle_joint'/>
        <motor name='left_qbhand_ring_distal_joint' gear='50' joint='left_qbhand_ring_distal_joint'/>
        <motor name='left_qbhand_little_proximal_joint' gear='50' joint='left_qbhand_little_proximal_joint'/>
        <motor name='left_qbhand_little_middle_joint' gear='50' joint='left_qbhand_little_middle_joint'/>
        <motor name='left_qbhand_little_distal_joint' gear='50' joint='left_qbhand_little_distal_joint'/>
        <motor name="Shoulder_Y_R" gear="125" joint="Shoulder_Y_R"/>
        <motor name="Shoulder_X_R" gear="125" joint="Shoulder_X_R"/>
        <motor name="Shoulder_Z_R" gear="125" joint="Shoulder_Z_R"/>
        <motor name="Elbow_R" gear="125" joint="Elbow_R"/>
        <motor name='Wrist_Z_R' gear='50' joint='Wrist_Z_R'/>
        <motor name='Wrist_Y_R' gear='50' joint='Wrist_Y_R'/>
        <motor name='Wrist_X_R' gear='50' joint='Wrist_X_R'/>
        <motor name='right_qbhand_thumb_knuckle_joint' gear='50' joint='right_qbhand_thumb_knuckle_joint'/>
        <motor name='right_qbhand_thumb_proximal_joint' gear='50' joint='right_qbhand_thumb_proximal_joint'/>
        <motor name='right_qbhand_thumb_distal_joint' gear='50' joint='right_qbhand_thumb_distal_joint'/>
        <motor name='right_qbhand_index_proximal_joint' gear='50' joint='right_qbhand_index_proximal_joint'/>
        <motor name='right_qbhand_index_middle_joint' gear='50' joint='right_qbhand_index_middle_joint'/>
        <motor name='right_qbhand_index_distal_joint' gear='50' joint='right_qbhand_index_distal_joint'/>
        <motor name='right_qbhand_middle_proximal_joint' gear='50' joint='right_qbhand_middle_proximal_joint'/>
        <motor name='right_qbhand_middle_middle_joint' gear='50' joint='right_qbhand_middle_middle_joint'/>
        <motor name='right_qbhand_middle_distal_joint' gear='50' joint='right_qbhand_middle_distal_joint'/>
        <motor name='right_qbhand_ring_proximal_joint' gear='50' joint='right_qbhand_ring_proximal_joint'/>
        <motor name='right_qbhand_ring_middle_joint' gear='50' joint='right_qbhand_ring_middle_joint'/>
        <motor name='right_qbhand_ring_distal_joint' gear='50' joint='right_qbhand_ring_distal_joint'/>
        <motor name='right_qbhand_little_proximal_joint' gear='50' joint='right_qbhand_little_proximal_joint'/>
        <motor name='right_qbhand_little_middle_joint' gear='50' joint='right_qbhand_little_middle_joint'/>
        <motor name='right_qbhand_little_distal_joint' gear='50' joint='right_qbhand_little_distal_joint'/>
        <motor name="A_Waist" gear="125" joint="A_Waist"/>
        <motor name="Hip_Z_R" gear="125" joint="Hip_Z_R"/>
        <motor name="Hip_X_R" gear="125" joint="Hip_X_R"/>
        <motor name="Hip_Y_R" gear="125" joint="Hip_Y_R"/>
        <motor name="Knee_R" gear="125" joint="Knee_R"/>
        <motor name="Ankle_Y_R" gear="125" joint="Ankle_Y_R"/>
        <motor name="Ankle_X_R" gear="125" joint="Ankle_X_R"/>
        <motor name="Hip_Z_L" gear="125" joint="Hip_Z_L"/>
        <motor name="Hip_X_L" gear="125" joint="Hip_X_L"/>
        <motor name="Hip_Y_L" gear="125" joint="Hip_Y_L"/>
        <motor name="Knee_L" gear="125" joint="Knee_L"/>
        <motor name="Ankle_Y_L" gear="125" joint="Ankle_Y_L"/>
        <motor name="Ankle_X_L" gear="125" joint="Ankle_X_L"/>
        <motor name="Neck_Z" gear="125" joint="Neck_Z"/>
        <motor name="Neck_Y" gear="125" joint="Neck_Y"/>
    </actuator>
</mujoco>
