<mujoco model="qbsofthand_no_virtual_right">
    <compiler angle="degree" meshdir="../urdf/curi/meshes/qbhand/"/>

    <statistic extent="2" center="0 0 1"/>
    <option timestep="0.00555"/>
    <default>
        <motor ctrlrange="-1 1" ctrllimited="true"/>
        <default class="body">
            <geom type="capsule" condim="1" friction="1.0 0.05 0.05" solimp=".9 .99 .003" solref=".015 1"/>
            <joint type="hinge" damping="0.1" stiffness="5" armature=".007" limited="true" solimplimit="0 .99 .01"/>
            <site size=".04" group="3"/>
            <default class="force-torque">
                <site type="box" size=".01 .01 .02" rgba="1 0 0 1"/>
            </default>
            <default class="touch">
                <site type="capsule" rgba="0 0 1 .3"/>
            </default>
        </default>
    </default>
    <asset>
        <mesh name="flange_iso_04" file="flange_iso_04.stl" scale="0.001 0.001 0.001"/>
        <mesh name="palm_pinch_r" file="palm_pinch_r.stl" scale="0.001 0.001 0.001"/>
        <mesh name="ph_thumb_r" file="ph_thumb_r.stl" scale="0.001 0.001 0.001"/>
        <mesh name="ph_thumb_r_collision" file="ph_thumb_r_collision.stl" scale="0.001 0.001 0.001"/>
        <mesh name="palm_pinch_l" file="palm_pinch_l.stl" scale="0.001 0.001 0.001"/>
        <mesh name="ph_thumb_l" file="ph_thumb_l.stl" scale="0.001 0.001 0.001"/>
        <mesh name="ph_thumb_l_collision" file="ph_thumb_l_collision.stl" scale="0.001 0.001 0.001"/>
        <mesh name="ph_short" file="ph_short.stl" scale="0.001 0.001 0.001"/>
        <mesh name="ph_short_collision" file="ph_short_collision.stl" scale="0.001 0.001 0.001"/>
        <mesh name="ph_distal" file="ph_distal.stl" scale="0.001 0.001 0.001"/>
        <mesh name="ph_distal_collision" file="ph_distal_collision.stl" scale="0.001 0.001 0.001"/>
        <mesh name="ph_knuckle" file="ph_knuckle.stl" scale="0.001 0.001 0.001"/>
        <mesh name="ph_knuckle_collision" file="ph_knuckle_collision.stl" scale="0.001 0.001 0.001"/>
        <mesh name="ph_medium" file="ph_medium.stl" scale="0.001 0.001 0.001"/>
        <mesh name="ph_medium_collision" file="ph_medium_collision.stl" scale="0.001 0.001 0.001"/>
    </asset>

    <worldbody>
        <light directional="true" pos="-0.5 0.5 3" dir="0 0 -1"/>
        <geom name="floor" type="plane" conaffinity="1" size="100 100 .2"/>

        <body name="right_qbhand_root_link" pos="0.0 0.0 0.0" quat="0 0 1 0">-->
            <geom type="mesh" rgba="0.35 0.35 0.35 1" mesh="flange_iso_04"/>
            <geom pos="-0.0045 0.0145 0.144" quat="0.707388 0.706825 0 0" type="mesh"
                  rgba="0.35 0.35 0.35 1" mesh="palm_pinch_r"/>
            <inertial pos="0.001 -0.002 0.29" quat="0.982 -0.016 0 -0.188" mass="4"
                      diaginertia="0.01 0.01 0.0075"/>
            <body name="right_qbhand_thumb_knuckle_link" pos="-0.0485 0.016463 0.0974984"
                  quat="0.000796327 0 0.000796326 0.999999">
                <inertial pos="0.0130716 -0.00273578 0.000643478"
                          quat="0.502681 0.576479 0.364062 0.531453" mass="0.01"
                          diaginertia="1.4342e-06 1.35762e-06 3.12515e-07"/>
                <joint name="right_qbhand_thumb_knuckle_joint" pos="0 0 0" axis="0 0 -1"
                       limited="true" range="0 90"/>
                <geom type="mesh" rgba="0.35 0.35 0.35 1" mesh="ph_thumb_r_collision"/>
                <body name="right_qbhand_thumb_proximal_link" pos="0.038 -0.0038 -0.00012"
                      quat="0.841496 -0.540263 0 0">
                    <joint name="right_qbhand_thumb_proximal_joint" pos="0 0 0"
                           axis="0 0 -1" limited="true" range="0 45"/>
                    <inertial pos="0.00476016 -0.00137869 0"
                              quat="0.0365143 0.706163 -0.0365143 0.706163"
                              mass="0.0063" diaginertia="2.6915e-07 2.3576e-07 1.79645e-07"/>
                    <geom type="mesh" rgba="0.35 0.35 0.35 1" mesh="ph_short_collision"/>
                    <body name="right_qbhand_thumb_distal_link" pos="0.023 0 0">
                        <joint name="right_qbhand_thumb_distal_joint" pos="0 0 0" axis="0 0 -1"
                               limited="true" range="0 45"/>
                        <inertial pos="0.00880255 -0.00172193 0"
                                  quat="0.0131386 0.706985 -0.0131386 0.706985"
                                  mass="0.009"
                                  diaginertia="6.6782e-07 5.99819e-07 2.654e-07"/>
                        <geom type="mesh" rgba="0.35 0.35 0.35 1"
                              mesh="ph_distal_collision"/>
                    </body>
                </body>
            </body>
            <body name="right_qbhand_index_proximal_link" pos="-0.0245 0.00049443 0.137011"
                  quat="-1.8365000e-07 -7.0682496e-01  5.6281635e-04 -7.0738804e-01">
                <joint name="right_qbhand_index_proximal_joint" pos="0 0 0" axis="0 0 -1"
                       limited="true" range="0 45"/>
                <inertial pos="0.00877074 -0.00178631 0"
                          quat="0.0123083 0.707 -0.0123083 0.707" mass="0.0082"
                          diaginertia="5.95622e-07 5.59876e-07 2.26817e-07"/>
                <geom type="mesh" rgba="0.35 0.35 0.35 1" mesh="ph_medium_collision"/>
                <body name="right_qbhand_index_middle_link" pos="0.030 0 0">
                    <joint name="right_qbhand_index_middle_joint" pos="0 0 0" axis="0 0 -1"
                           limited="true"
                           range="0 45"/>
                    <inertial pos="0.00476016 -0.00137869 0"
                              quat="0.0365143 0.706163 -0.0365143 0.706163"
                              mass="0.0063"
                              diaginertia="2.6915e-07 2.3576e-07 1.79645e-07"/>
                    <geom type="mesh" rgba="0.35 0.35 0.35 1" mesh="ph_short_collision"/>
                    <body name="right_qbhand_index_distal_link" pos="0.022 0 0">
                        <joint name="right_qbhand_index_distal_joint" pos="0 0 0"
                               axis="0 0 -1" limited="true"
                               range="0 45"/>
                        <inertial pos="0.00880255 -0.00172193 0"
                                  quat="0.0131386 0.706985 -0.0131386 0.706985"
                                  mass="0.009"
                                  diaginertia="6.6782e-07 5.99819e-07 2.654e-07"/>
                        <geom type="mesh" rgba="0.35 0.35 0.35 1"
                              mesh="ph_distal_collision"/>
                    </body>
                </body>
            </body>
            <body name="right_qbhand_middle_proximal_link" pos="-0.0045 0.000500004 0.144011"
                  quat="-1.8365000e-07 -7.0682496e-01  5.6281635e-04 -7.0738804e-01">
                <joint name="right_qbhand_middle_proximal_joint" pos="0 0 0" axis="0 0 -1"
                       limited="true"
                       range="0 45"/>
                <inertial pos="0.00877074 -0.00178631 0"
                          quat="0.0123083 0.707 -0.0123083 0.707" mass="0.0082"
                          diaginertia="5.95622e-07 5.59876e-07 2.26817e-07"/>
                <geom type="mesh" rgba="0.35 0.35 0.35 1" mesh="ph_medium_collision"/>
                <body name="right_qbhand_middle_middle_link" pos="0.030 0 0">
                    <joint name="right_qbhand_middle_middle_joint" pos="0 0 0" axis="0 0 -1"
                           limited="true"
                           range="0 45"/>
                    <inertial pos="0.00476016 -0.00137869 0"
                              quat="0.0365143 0.706163 -0.0365143 0.706163"
                              mass="0.0063"
                              diaginertia="2.6915e-07 2.3576e-07 1.79645e-07"/>
                    <geom type="mesh" rgba="0.35 0.35 0.35 1"
                          mesh="ph_short_collision"/>
                    <body name="right_qbhand_middle_distal_link" pos="0.022 0 0">
                        <joint name="right_qbhand_middle_distal_joint" pos="0 0 0"
                               axis="0 0 -1" limited="true"
                               range="0 45"/>
                        <inertial pos="0.00880255 -0.00172193 0"
                                  quat="0.0131386 0.706985 -0.0131386 0.706985"
                                  mass="0.009"
                                  diaginertia="6.6782e-07 5.99819e-07 2.654e-07"/>
                        <geom type="mesh" rgba="0.35 0.35 0.35 1"
                              mesh="ph_distal_collision"/>
                    </body>
                </body>
            </body>
            <body name="right_qbhand_ring_proximal_link" pos="0.0155 0.00049443 0.137011"
                  quat="-1.8365000e-07 -7.0682496e-01  5.6281635e-04 -7.0738804e-01">
                <joint name="right_qbhand_ring_proximal_joint" pos="0 0 0" axis="0 0 -1"
                       limited="true" range="0 45"/>
                <inertial pos="0.00877074 -0.00178631 0"
                          quat="0.0123083 0.707 -0.0123083 0.707" mass="0.0082"
                          diaginertia="5.95622e-07 5.59876e-07 2.26817e-07"/>
                <geom type="mesh" rgba="0.35 0.35 0.35 1" mesh="ph_medium_collision"/>
                <body name="right_qbhand_ring_middle_link" pos="0.030 0 0">
                    <joint name="right_qbhand_ring_middle_joint" pos="0 0 0" axis="0 0 -1"
                           limited="true"
                           range="0 45"/>
                    <inertial pos="0.00476016 -0.00137869 0"
                              quat="0.0365143 0.706163 -0.0365143 0.706163"
                              mass="0.0063"
                              diaginertia="2.6915e-07 2.3576e-07 1.79645e-07"/>
                    <geom type="mesh" rgba="0.35 0.35 0.35 1"
                          mesh="ph_short_collision"/>
                    <body name="right_qbhand_ring_distal_link" pos="0.022 0 0">
                        <joint name="right_qbhand_ring_distal_joint" pos="0 0 0"
                               axis="0 0 -1"
                               limited="true"
                               range="0 45"/>
                        <inertial pos="0.00880255 -0.00172193 0"
                                  quat="0.0131386 0.706985 -0.0131386 0.706985"
                                  mass="0.009"
                                  diaginertia="6.6782e-07 5.99819e-07 2.654e-07"/>
                        <geom type="mesh" rgba="0.35 0.35 0.35 1"
                              mesh="ph_distal_collision"/>
                    </body>
                </body>
            </body>
            <body name="right_qbhand_little_proximal_link" pos="0.0355 0.000490449 0.132011"
                  quat="-1.8365000e-07 -7.0682496e-01  5.6281635e-04 -7.0738804e-01">
                <joint name="right_qbhand_little_proximal_joint" pos="0 0 0" axis="0 0 -1"
                       limited="true"
                       range="0 45"/>
                <inertial pos="0.00476016 -0.00137869 0"
                          quat="0.0365143 0.706163 -0.0365143 0.706163"
                          mass="0.0063" diaginertia="2.6915e-07 2.3576e-07 1.79645e-07"/>
                <geom type="mesh" rgba="0.35 0.35 0.35 1" mesh="ph_short_collision"/>
                <body name="right_qbhand_little_middle_link" pos="0.022 0 0">
                    <joint name="right_qbhand_little_middle_joint" pos="0 0 0" axis="0 0 -1"
                           limited="true"
                           range="0 45"/>
                    <inertial pos="0.00476016 -0.00137869 0"
                              quat="0.0365143 0.706163 -0.0365143 0.706163"
                              mass="0.0063"
                              diaginertia="2.6915e-07 2.3576e-07 1.79645e-07"/>
                    <geom type="mesh" rgba="0.35 0.35 0.35 1"
                          mesh="ph_short_collision"/>
                    <body name="right_qbhand_little_distal_link" pos="0.022 0 0">
                        <joint name="right_qbhand_little_distal_joint" pos="0 0 0"
                               axis="0 0 -1" limited="true"
                               range="0 45"/>

                        <inertial pos="0.00880255 -0.00172193 0"
                                  quat="0.0131386 0.706985 -0.0131386 0.706985"
                                  mass="0.009"
                                  diaginertia="6.6782e-07 5.99819e-07 2.654e-07"/>
                        <geom type="mesh" rgba="0.35 0.35 0.35 1"
                              mesh="ph_distal_collision"/>
                    </body>
                </body>
            </body>
        </body>


    </worldbody>

    <actuator>
        <motor name='right_qbhand_thumb_knuckle_joint' gear='50' joint='right_qbhand_thumb_knuckle_joint'/>
        <motor name='right_qbhand_thumb_proximal_joint' gear='50' joint='right_qbhand_thumb_proximal_joint'/>
        <motor name='right_qbhand_thumb_distal_joint' gear='50' joint='right_qbhand_thumb_distal_joint'/>
        <motor name='right_qbhand_index_proximal_joint' gear='50' joint='right_qbhand_index_proximal_joint'/>
        <motor name='right_qbhand_index_middle_joint' gear='50' joint='right_qbhand_index_middle_joint'/>
        <motor name='right_qbhand_index_distal_joint' gear='50' joint='right_qbhand_index_distal_joint'/>
        <motor name='right_qbhand_middle_proximal_joint' gear='50' joint='right_qbhand_middle_proximal_joint'/>
        <motor name='right_qbhand_middle_middle_joint' gear='50' joint='right_qbhand_middle_middle_joint'/>
        <motor name='right_qbhand_middle_distal_joint' gear='50' joint='right_qbhand_middle_distal_joint'/>
        <motor name='right_qbhand_ring_proximal_joint' gear='50' joint='right_qbhand_ring_proximal_joint'/>
        <motor name='right_qbhand_ring_middle_joint' gear='50' joint='right_qbhand_ring_middle_joint'/>
        <motor name='right_qbhand_ring_distal_joint' gear='50' joint='right_qbhand_ring_distal_joint'/>
        <motor name='right_qbhand_little_proximal_joint' gear='50' joint='right_qbhand_little_proximal_joint'/>
        <motor name='right_qbhand_little_middle_joint' gear='50' joint='right_qbhand_little_middle_joint'/>
        <motor name='right_qbhand_little_distal_joint' gear='50' joint='right_qbhand_little_distal_joint'/>
    </actuator>
</mujoco>
