<mujoco model="qbhand">
    <compiler angle="radian" meshdir="../urdf/curi/meshes/qbhand/"/>
    <size njmax="500" nconmax="100"/>
    <asset>
        <mesh name="flange_iso_04" file="flange_iso_04.stl" scale="0.001 0.001 0.001"/>
        <mesh name="palm_pinch_r" file="palm_pinch_r.stl" scale="0.001 0.001 0.001"/>
        <mesh name="ph_thumb_r" file="ph_thumb_r.stl" scale="0.001 0.001 0.001"/>
        <mesh name="ph_thumb_r_collision" file="ph_thumb_r_collision.stl" scale="0.001 0.001 0.001"/>
        <mesh name="ph_short" file="ph_short.stl" scale="0.001 0.001 0.001"/>
        <mesh name="ph_short_collision" file="ph_short_collision.stl" scale="0.001 0.001 0.001"/>
        <mesh name="ph_distal" file="ph_distal.stl" scale="0.001 0.001 0.001"/>
        <mesh name="ph_distal_collision" file="ph_distal_collision.stl" scale="0.001 0.001 0.001"/>
        <mesh name="ph_knuckle" file="ph_knuckle.stl" scale="0.001 0.001 0.001"/>
        <mesh name="ph_knuckle_collision" file="ph_knuckle_collision.stl" scale="0.001 0.001 0.001"/>
        <mesh name="ph_medium" file="ph_medium.stl" scale="0.001 0.001 0.001"/>
        <mesh name="ph_medium_collision" file="ph_medium_collision.stl" scale="0.001 0.001 0.001"/>
    </asset>
    <worldbody>
        <body name="root_link" pos="0.0030 -0.0449 0.0135">
            <freejoint name="qbhand_base_link"/>
            <geom type="mesh" contype="0" conaffinity="0" group="1" rgba="0.35 0.35 0.35 1"
                  mesh="flange_iso_04"/>
            <geom type="mesh" rgba="0.35 0.35 0.35 1" mesh="flange_iso_04"/>
            <geom pos="-0.0045 0.0145 0.144" quat="0.707388 0.706825 0 0" type="mesh" contype="0" conaffinity="0"
                  group="1" rgba="0.35 0.35 0.35 1" mesh="palm_pinch_r"/>
            <geom pos="-0.0045 0.0145 0.144" quat="0.707388 0.706825 0 0" type="mesh" rgba="0.35 0.35 0.35 1"
                  mesh="palm_pinch_r"/>
            <body name="qbhand_thumb_knuckle_link" pos="-0.0485 0.016463 0.0974984"
                  quat="0.000796327 0 0.000796326 0.999999">
                <inertial pos="0.0130716 -0.00273578 0.000643478" quat="0.502681 0.576479 0.364062 0.531453" mass="0.01"
                          diaginertia="1.4342e-06 1.35762e-06 3.12515e-07"/>
                <joint name="qbhand_thumb_knuckle_joint" pos="0 0 0" axis="0 0 -1" limited="true" range="0 1.571"/>
                <geom type="mesh" contype="0" conaffinity="0" group="1" rgba="0.35 0.35 0.35 1" mesh="ph_thumb_r"/>
                <geom type="mesh" rgba="0.35 0.35 0.35 1" mesh="ph_thumb_r_collision"/>
                <body name="qbhand_thumb_proximal_virtual_link" pos="0.0255 -0.0038 -0.00012"
                      quat="0.841496 -0.540263 0 0">
                    <inertial pos="0 0 0" mass="0.0001" diaginertia="1e-09 1e-09 1e-09"/>
                    <joint name="qbhand_thumb_proximal_joint" pos="0 0 0" axis="0 0 -1" limited="true" range="0 0.785"/>
                    <body name="qbhand_thumb_proximal_link" pos="0.013 0 0">
                        <inertial pos="0.00476016 -0.00137869 0" quat="0.0365143 0.706163 -0.0365143 0.706163"
                                  mass="0.0063" diaginertia="2.6915e-07 2.3576e-07 1.79645e-07"/>
                        <freejoint name="qbhand_thumb_proximal_virtual_joint" pos="0 0 0" axis="0 0 -1" limited="true"
                               range="0 0.785"/>
                        <geom type="mesh" contype="0" conaffinity="0" group="1" rgba="0.35 0.35 0.35 1"
                              mesh="ph_short"/>
                        <geom type="mesh" rgba="0.35 0.35 0.35 1" mesh="ph_short_collision"/>
                        <body name="qbhand_thumb_distal_virtual_link" pos="0.009 0 0">
                            <inertial pos="0 0 0" mass="0.0001" diaginertia="1e-09 1e-09 1e-09"/>
                            <joint name="qbhand_thumb_distal_joint" pos="0 0 0" axis="0 0 -1" limited="true"
                                   range="0 0.785"/>
                            <body name="qbhand_thumb_distal_link" pos="0.013 0 0">
                                <inertial pos="0.00880255 -0.00172193 0" quat="0.0131386 0.706985 -0.0131386 0.706985"
                                          mass="0.009" diaginertia="6.6782e-07 5.99819e-07 2.654e-07"/>
                                <freejoint name="qbhand_thumb_distal_virtual_joint" pos="0 0 0" axis="0 0 -1" limited="true"
                                       range="0 0.785"/>
                                <geom type="mesh" contype="0" conaffinity="0" group="1" rgba="0.35 0.35 0.35 1"
                                      mesh="ph_distal"/>
                                <geom type="mesh" rgba="0.35 0.35 0.35 1" mesh="ph_distal_collision"/>
                            </body>
                        </body>
                    </body>
                </body>
            </body>
            <body name="qbhand_index_knuckle_link" pos="-0.0245 0.00049443 0.137011" quat="0.500398 0.5 -0.499602 0.5">
                <inertial pos="0.000427536 0 -0.00143217" quat="0.587164 0.394003 0.394003 0.587164" mass="0.0095"
                          diaginertia="1.12538e-06 7.39498e-07 6.27245e-07"/>
                <freejoint name="qbhand_index_knuckle_joint" pos="0 0 0" axis="0 0 -1" limited="true" range="-0.524 0.524"/>
                <geom type="mesh" contype="0" conaffinity="0" group="1" rgba="0.35 0.35 0.35 1" mesh="ph_knuckle"/>
                <geom type="mesh" rgba="0.35 0.35 0.35 1" mesh="ph_knuckle_collision"/>
                <body name="qbhand_index_proximal_virtual_link" pos="0.009 0 0" quat="0.707388 0.706825 0 0">
                    <inertial pos="0 0 0" mass="0.0001" diaginertia="1e-09 1e-09 1e-09"/>
                    <joint name="qbhand_index_proximal_joint" pos="0 0 0" axis="0 0 -1" limited="true" range="0 0.785"/>
                    <body name="qbhand_index_proximal_link" pos="0.013 0 0">
                        <inertial pos="0.00877074 -0.00178631 0" quat="0.0123083 0.707 -0.0123083 0.707" mass="0.0082"
                                  diaginertia="5.95622e-07 5.59876e-07 2.26817e-07"/>
                        <freejoint name="qbhand_index_proximal_virtual_joint" pos="0 0 0" axis="0 0 -1" limited="true"
                               range="0 0.785"/>
                        <geom type="mesh" contype="0" conaffinity="0" group="1" rgba="0.35 0.35 0.35 1"
                              mesh="ph_medium"/>
                        <geom type="mesh" rgba="0.35 0.35 0.35 1" mesh="ph_medium_collision"/>
                        <body name="qbhand_index_middle_virtual_link" pos="0.017 0 0">
                            <inertial pos="0 0 0" mass="0.0001" diaginertia="1e-09 1e-09 1e-09"/>
                            <joint name="qbhand_index_middle_joint" pos="0 0 0" axis="0 0 -1" limited="true"
                                   range="0 0.785"/>
                            <body name="qbhand_index_middle_link" pos="0.013 0 0">
                                <inertial pos="0.00476016 -0.00137869 0" quat="0.0365143 0.706163 -0.0365143 0.706163"
                                          mass="0.0063" diaginertia="2.6915e-07 2.3576e-07 1.79645e-07"/>
                                <freejoint name="qbhand_index_middle_virtual_joint" pos="0 0 0" axis="0 0 -1" limited="true"
                                       range="0 0.785"/>
                                <geom type="mesh" contype="0" conaffinity="0" group="1" rgba="0.35 0.35 0.35 1"
                                      mesh="ph_short"/>
                                <geom type="mesh" rgba="0.35 0.35 0.35 1" mesh="ph_short_collision"/>
                                <body name="qbhand_index_distal_virtual_link" pos="0.009 0 0">
                                    <inertial pos="0 0 0" mass="0.0001" diaginertia="1e-09 1e-09 1e-09"/>
                                    <joint name="qbhand_index_distal_joint" pos="0 0 0" axis="0 0 -1" limited="true"
                                           range="0 0.785"/>
                                    <body name="qbhand_index_distal_link" pos="0.013 0 0">
                                        <inertial pos="0.00880255 -0.00172193 0"
                                                  quat="0.0131386 0.706985 -0.0131386 0.706985" mass="0.009"
                                                  diaginertia="6.6782e-07 5.99819e-07 2.654e-07"/>
                                        <freejoint name="qbhand_index_distal_virtual_joint" pos="0 0 0" axis="0 0 -1"
                                               limited="true" range="0 0.785"/>
                                        <geom type="mesh" contype="0" conaffinity="0" group="1" rgba="0.35 0.35 0.35 1"
                                              mesh="ph_distal"/>
                                        <geom type="mesh" rgba="0.35 0.35 0.35 1" mesh="ph_distal_collision"/>
                                    </body>
                                </body>
                            </body>
                        </body>
                    </body>
                </body>
            </body>
            <body name="qbhand_middle_knuckle_link" pos="-0.0045 0.000500004 0.144011"
                  quat="0.500398 0.5 -0.499602 0.5">
                <inertial pos="0.000427536 0 -0.00143217" quat="0.587164 0.394003 0.394003 0.587164" mass="0.0095"
                          diaginertia="1.12538e-06 7.39498e-07 6.27245e-07"/>
                <freejoint name="qbhand_middle_knuckle_joint" pos="0 0 0" axis="0 0 -1" limited="true"
                       range="-0.524 0.524"/>
                <geom type="mesh" contype="0" conaffinity="0" group="1" rgba="0.35 0.35 0.35 1" mesh="ph_knuckle"/>
                <geom type="mesh" rgba="0.35 0.35 0.35 1" mesh="ph_knuckle_collision"/>
                <body name="qbhand_middle_proximal_virtual_link" pos="0.009 0 0" quat="0.707388 0.706825 0 0">
                    <inertial pos="0 0 0" mass="0.0001" diaginertia="1e-09 1e-09 1e-09"/>
                    <joint name="qbhand_middle_proximal_joint" pos="0 0 0" axis="0 0 -1" limited="true"
                           range="0 0.785"/>
                    <body name="qbhand_middle_proximal_link" pos="0.013 0 0">
                        <inertial pos="0.00877074 -0.00178631 0" quat="0.0123083 0.707 -0.0123083 0.707" mass="0.0082"
                                  diaginertia="5.95622e-07 5.59876e-07 2.26817e-07"/>
                        <freejoint name="qbhand_middle_proximal_virtual_joint" pos="0 0 0" axis="0 0 -1" limited="true"
                               range="0 0.785"/>
                        <geom type="mesh" contype="0" conaffinity="0" group="1" rgba="0.35 0.35 0.35 1"
                              mesh="ph_medium"/>
                        <geom type="mesh" rgba="0.35 0.35 0.35 1" mesh="ph_medium_collision"/>
                        <body name="qbhand_middle_middle_virtual_link" pos="0.017 0 0">
                            <inertial pos="0 0 0" mass="0.0001" diaginertia="1e-09 1e-09 1e-09"/>
                            <joint name="qbhand_middle_middle_joint" pos="0 0 0" axis="0 0 -1" limited="true"
                                   range="0 0.785"/>
                            <body name="qbhand_middle_middle_link" pos="0.013 0 0">
                                <inertial pos="0.00476016 -0.00137869 0" quat="0.0365143 0.706163 -0.0365143 0.706163"
                                          mass="0.0063" diaginertia="2.6915e-07 2.3576e-07 1.79645e-07"/>
                                <freejoint name="qbhand_middle_middle_virtual_joint" pos="0 0 0" axis="0 0 -1"
                                       limited="true" range="0 0.785"/>
                                <geom type="mesh" contype="0" conaffinity="0" group="1" rgba="0.35 0.35 0.35 1"
                                      mesh="ph_short"/>
                                <geom type="mesh" rgba="0.35 0.35 0.35 1" mesh="ph_short_collision"/>
                                <body name="qbhand_middle_distal_virtual_link" pos="0.009 0 0">
                                    <inertial pos="0 0 0" mass="0.0001" diaginertia="1e-09 1e-09 1e-09"/>
                                    <joint name="qbhand_middle_distal_joint" pos="0 0 0" axis="0 0 -1" limited="true"
                                           range="0 0.785"/>
                                    <body name="qbhand_middle_distal_link" pos="0.013 0 0">
                                        <inertial pos="0.00880255 -0.00172193 0"
                                                  quat="0.0131386 0.706985 -0.0131386 0.706985" mass="0.009"
                                                  diaginertia="6.6782e-07 5.99819e-07 2.654e-07"/>
                                        <freejoint name="qbhand_middle_distal_virtual_joint" pos="0 0 0" axis="0 0 -1"
                                               limited="true" range="0 0.785"/>
                                        <geom type="mesh" contype="0" conaffinity="0" group="1" rgba="0.35 0.35 0.35 1"
                                              mesh="ph_distal"/>
                                        <geom type="mesh" rgba="0.35 0.35 0.35 1" mesh="ph_distal_collision"/>
                                    </body>
                                </body>
                            </body>
                        </body>
                    </body>
                </body>
            </body>
            <body name="qbhand_ring_knuckle_link" pos="0.0155 0.00049443 0.137011" quat="0.500398 0.5 -0.499602 0.5">
                <inertial pos="0.000427536 0 -0.00143217" quat="0.587164 0.394003 0.394003 0.587164" mass="0.0095"
                          diaginertia="1.12538e-06 7.39498e-07 6.27245e-07"/>
                <freejoint name="qbhand_ring_knuckle_joint" pos="0 0 0" axis="0 0 -1" limited="true" range="-0.524 0.524"/>
                <geom type="mesh" contype="0" conaffinity="0" group="1" rgba="0.35 0.35 0.35 1" mesh="ph_knuckle"/>
                <geom type="mesh" rgba="0.35 0.35 0.35 1" mesh="ph_knuckle_collision"/>
                <body name="qbhand_ring_proximal_virtual_link" pos="0.009 0 0" quat="0.707388 0.706825 0 0">
                    <inertial pos="0 0 0" mass="0.0001" diaginertia="1e-09 1e-09 1e-09"/>
                    <joint name="qbhand_ring_proximal_joint" pos="0 0 0" axis="0 0 -1" limited="true" range="0 0.785"/>
                    <body name="qbhand_ring_proximal_link" pos="0.013 0 0">
                        <inertial pos="0.00877074 -0.00178631 0" quat="0.0123083 0.707 -0.0123083 0.707" mass="0.0082"
                                  diaginertia="5.95622e-07 5.59876e-07 2.26817e-07"/>
                        <freejoint name="qbhand_ring_proximal_virtual_joint" pos="0 0 0" axis="0 0 -1" limited="true"
                               range="0 0.785"/>
                        <geom type="mesh" contype="0" conaffinity="0" group="1" rgba="0.35 0.35 0.35 1"
                              mesh="ph_medium"/>
                        <geom type="mesh" rgba="0.35 0.35 0.35 1" mesh="ph_medium_collision"/>
                        <body name="qbhand_ring_middle_virtual_link" pos="0.017 0 0">
                            <inertial pos="0 0 0" mass="0.0001" diaginertia="1e-09 1e-09 1e-09"/>
                            <joint name="qbhand_ring_middle_joint" pos="0 0 0" axis="0 0 -1" limited="true"
                                   range="0 0.785"/>
                            <body name="qbhand_ring_middle_link" pos="0.013 0 0">
                                <inertial pos="0.00476016 -0.00137869 0" quat="0.0365143 0.706163 -0.0365143 0.706163"
                                          mass="0.0063" diaginertia="2.6915e-07 2.3576e-07 1.79645e-07"/>
                                <freejoint name="qbhand_ring_middle_virtual_joint" pos="0 0 0" axis="0 0 -1" limited="true"
                                       range="0 0.785"/>
                                <geom type="mesh" contype="0" conaffinity="0" group="1" rgba="0.35 0.35 0.35 1"
                                      mesh="ph_short"/>
                                <geom type="mesh" rgba="0.35 0.35 0.35 1" mesh="ph_short_collision"/>
                                <body name="qbhand_ring_distal_virtual_link" pos="0.009 0 0">
                                    <inertial pos="0 0 0" mass="0.0001" diaginertia="1e-09 1e-09 1e-09"/>
                                    <joint name="qbhand_ring_distal_joint" pos="0 0 0" axis="0 0 -1" limited="true"
                                           range="0 0.785"/>
                                    <body name="qbhand_ring_distal_link" pos="0.013 0 0">
                                        <inertial pos="0.00880255 -0.00172193 0"
                                                  quat="0.0131386 0.706985 -0.0131386 0.706985" mass="0.009"
                                                  diaginertia="6.6782e-07 5.99819e-07 2.654e-07"/>
                                        <freejoint name="qbhand_ring_distal_virtual_joint" pos="0 0 0" axis="0 0 -1"
                                               limited="true" range="0 0.785"/>
                                        <geom type="mesh" contype="0" conaffinity="0" group="1" rgba="0.35 0.35 0.35 1"
                                              mesh="ph_distal"/>
                                        <geom type="mesh" rgba="0.35 0.35 0.35 1" mesh="ph_distal_collision"/>
                                    </body>
                                </body>
                            </body>
                        </body>
                    </body>
                </body>
            </body>
            <body name="qbhand_little_knuckle_link" pos="0.0355 0.000490449 0.132011" quat="0.500398 0.5 -0.499602 0.5">
                <inertial pos="0.000427536 0 -0.00143217" quat="0.587164 0.394003 0.394003 0.587164" mass="0.0095"
                          diaginertia="1.12538e-06 7.39498e-07 6.27245e-07"/>
                <freejoint name="qbhand_little_knuckle_joint" pos="0 0 0" axis="0 0 -1" limited="true"
                       range="-0.524 0.524"/>
                <geom type="mesh" contype="0" conaffinity="0" group="1" rgba="0.35 0.35 0.35 1" mesh="ph_knuckle"/>
                <geom type="mesh" rgba="0.35 0.35 0.35 1" mesh="ph_knuckle_collision"/>
                <body name="qbhand_little_proximal_virtual_link" pos="0.009 0 0" quat="0.707388 0.706825 0 0">
                    <inertial pos="0 0 0" mass="0.0001" diaginertia="1e-09 1e-09 1e-09"/>
                    <joint name="qbhand_little_proximal_joint" pos="0 0 0" axis="0 0 -1" limited="true"
                           range="0 0.785"/>
                    <body name="qbhand_little_proximal_link" pos="0.013 0 0">
                        <inertial pos="0.00476016 -0.00137869 0" quat="0.0365143 0.706163 -0.0365143 0.706163"
                                  mass="0.0063" diaginertia="2.6915e-07 2.3576e-07 1.79645e-07"/>
                        <freejoint name="qbhand_little_proximal_virtual_joint" pos="0 0 0" axis="0 0 -1" limited="true"
                               range="0 0.785"/>
                        <geom type="mesh" contype="0" conaffinity="0" group="1" rgba="0.35 0.35 0.35 1"
                              mesh="ph_short"/>
                        <geom type="mesh" rgba="0.35 0.35 0.35 1" mesh="ph_short_collision"/>
                        <body name="qbhand_little_middle_virtual_link" pos="0.009 0 0">
                            <inertial pos="0 0 0" mass="0.0001" diaginertia="1e-09 1e-09 1e-09"/>
                            <joint name="qbhand_little_middle_joint" pos="0 0 0" axis="0 0 -1" limited="true"
                                   range="0 0.785"/>
                            <body name="qbhand_little_middle_link" pos="0.013 0 0">
                                <inertial pos="0.00476016 -0.00137869 0" quat="0.0365143 0.706163 -0.0365143 0.706163"
                                          mass="0.0063" diaginertia="2.6915e-07 2.3576e-07 1.79645e-07"/>
                                <freejoint name="qbhand_little_middle_virtual_joint" pos="0 0 0" axis="0 0 -1"
                                       limited="true" range="0 0.785"/>
                                <geom type="mesh" contype="0" conaffinity="0" group="1" rgba="0.35 0.35 0.35 1"
                                      mesh="ph_short"/>
                                <geom type="mesh" rgba="0.35 0.35 0.35 1" mesh="ph_short_collision"/>
                                <body name="qbhand_little_distal_virtual_link" pos="0.009 0 0">
                                    <inertial pos="0 0 0" mass="0.0001" diaginertia="1e-09 1e-09 1e-09"/>
                                    <joint name="qbhand_little_distal_joint" pos="0 0 0" axis="0 0 -1" limited="true"
                                           range="0 0.785"/>
                                    <body name="qbhand_little_distal_link" pos="0.013 0 0">
                                        <inertial pos="0.00880255 -0.00172193 0"
                                                  quat="0.0131386 0.706985 -0.0131386 0.706985" mass="0.009"
                                                  diaginertia="6.6782e-07 5.99819e-07 2.654e-07"/>
                                        <freejoint name="qbhand_little_distal_virtual_joint" pos="0 0 0" axis="0 0 -1"
                                               limited="true" range="0 0.785"/>
                                        <geom type="mesh" contype="0" conaffinity="0" group="1" rgba="0.35 0.35 0.35 1"
                                              mesh="ph_distal"/>
                                        <geom type="mesh" rgba="0.35 0.35 0.35 1" mesh="ph_distal_collision"/>
                                    </body>
                                </body>
                            </body>
                        </body>
                    </body>
                </body>
            </body>
        </body>

        <!--        <body name="qbhand_synergy_tendon_virtual_link" pos="-0.0045 0.0145 0.144" quat="0.707388 0.706825 0 0">-->
        <!--            <inertial pos="0 0 0" mass="0.0001" diaginertia="1e-09 1e-09 1e-09" />-->
        <!--            <joint name="qbhand_synergy_joint" pos="0 0 0" axis="0 0 1" limited="true" range="0 1" />-->
        <!--        </body>-->

    </worldbody>
    <actuator>
        <motor name='qbhand_thumb_knuckle_joint' gear='50' joint='qbhand_thumb_knuckle_joint'/>
        <motor name='qbhand_thumb_proximal_joint' gear='50' joint='qbhand_thumb_proximal_joint'/>
        <motor name='qbhand_thumb_distal_joint' gear='50' joint='qbhand_thumb_distal_joint'/>
        <motor name='qbhand_index_proximal_joint' gear='50' joint='qbhand_index_proximal_joint'/>
        <motor name='qbhand_index_middle_joint' gear='50' joint='qbhand_index_middle_joint'/>
        <motor name='qbhand_index_distal_joint' gear='50' joint='qbhand_index_distal_joint'/>
        <motor name='qbhand_middle_proximal_joint' gear='50' joint='qbhand_middle_proximal_joint'/>
        <motor name='qbhand_middle_middle_joint' gear='50' joint='qbhand_middle_middle_joint'/>
        <motor name='qbhand_middle_distal_joint' gear='50' joint='qbhand_middle_distal_joint'/>
        <motor name='qbhand_ring_proximal_joint' gear='50' joint='qbhand_ring_proximal_joint'/>
        <motor name='qbhand_ring_middle_joint' gear='50' joint='qbhand_ring_middle_joint'/>
        <motor name='qbhand_ring_distal_joint' gear='50' joint='qbhand_ring_distal_joint'/>
        <motor name='qbhand_little_proximal_joint' gear='50' joint='qbhand_little_proximal_joint'/>
        <motor name='qbhand_little_middle_joint' gear='50' joint='qbhand_little_middle_joint'/>
        <motor name='qbhand_little_distal_joint' gear='50' joint='qbhand_little_distal_joint'/>
    </actuator>
</mujoco>
