<mujoco model="humanoid">
    <compiler angle="degree" meshdir="../../urdf/curi/meshes/qbhand/"/>
    <statistic extent="2" center="0 0 1"/>
    <option timestep="0.00555"/>
    <default>
        <motor ctrlrange="-1 1" ctrllimited="true"/>
        <default class="body">
            <geom type="capsule" condim="1" friction="1.0 0.05 0.05" solimp=".9 .99 .003" solref=".015 1"/>
            <joint type="hinge" damping="0.1" stiffness="5" armature=".007" limited="true" solimplimit="0 .99 .01"/>
            <site size=".04" group="3"/>
            <default class="force-torque">
                <site type="box" size=".01 .01 .02" rgba="1 0 0 1"/>
            </default>
            <default class="touch">
                <site type="capsule" rgba="0 0 1 .3"/>
            </default>
        </default>
    </default>
    <asset>
        <mesh name="flange_iso_04" file="flange_iso_04.stl" scale="0.0007 0.0007 0.0007"/>
        <mesh name="palm_pinch_r" file="palm_pinch_r.stl" scale="0.0007 0.0007 0.0007"/>
        <mesh name="palm_pinch_r_collision" file="palm_pinch_r.stl" scale="0.0005 0.0005 0.0005"/>
        <mesh name="ph_thumb_r" file="ph_thumb_r.stl" scale="0.0007 0.0007 0.0007"/>
        <mesh name="ph_thumb_r_collision" file="ph_thumb_r_collision.stl" scale="0.0007 0.0007 0.0007"/>
        <mesh name="palm_pinch_l" file="palm_pinch_l.stl" scale="0.0007 0.0007 0.0007"/>
        <mesh name="palm_pinch_l_collision" file="palm_pinch_l.stl" scale="0.0005 0.0005 0.0005"/>
        <mesh name="ph_thumb_l" file="ph_thumb_l.stl" scale="0.0007 0.0007 0.0007"/>
        <mesh name="ph_thumb_l_collision" file="ph_thumb_l_collision.stl" scale="0.0007 0.0007 0.0007"/>
        <mesh name="ph_short" file="ph_short.stl" scale="0.0007 0.0007 0.0007"/>
        <mesh name="ph_short_collision" file="ph_short_collision.stl" scale="0.0007 0.0007 0.0007"/>
        <mesh name="ph_distal" file="ph_distal.stl" scale="0.0007 0.0007 0.0007"/>
        <mesh name="ph_distal_collision" file="ph_distal_collision.stl" scale="0.0007 0.0007 0.0007"/>
        <mesh name="ph_knuckle" file="ph_knuckle.stl" scale="0.0007 0.0007 0.0007"/>
        <mesh name="ph_knuckle_collision" file="ph_knuckle_collision.stl" scale="0.0007 0.0007 0.0007"/>
        <mesh name="ph_medium" file="ph_medium.stl" scale="0.0007 0.0007 0.0007"/>
        <mesh name="ph_medium_collision" file="ph_medium_collision.stl" scale="0.0007 0.0007 0.0007"/>
    </asset>
    <worldbody>
        <light directional="true" pos="-0.5 0.5 3" dir="0 0 -1"/>
        <geom name="floor" type="plane" conaffinity="1" size="100 100 .2"/>
        <body name="pelvis" pos="0 0 1" childclass="body">
            <freejoint name="root"/>
            <site name="root" class="force-torque"/>
            <geom name="pelvis" type="sphere" pos="0 0 0.07" size=".09" density="2226" contype="0" conaffinity="1"/>
            <geom name="upper_waist" type="sphere" pos="0 0 0.205" size="0.07" density="2226" contype="0"
                  conaffinity="1"/>
            <site name="pelvis" class="touch" type="sphere" pos="0 0 0.07" size="0.091"/>
            <site name="upper_waist" class="touch" type="sphere" pos="0 0 0.205" size="0.071"/>

            <body name="torso" pos="0 0 0.236151">
                <light name="top" pos="0 0 2" mode="trackcom"/>
                <camera name="back" pos="-3 0 1" xyaxes="0 -1 0 1 0 2" mode="trackcom"/>
                <camera name="side" pos="0 -3 1" xyaxes="1 0 0 0 1 2" mode="trackcom"/>
                <joint name="abdomen_x" pos="0 0 0" axis="1 0 0" range="-60 60" stiffness="600" damping="60"
                       armature=".025"/>
                <joint name="abdomen_y" pos="0 0 0" axis="0 1 0" range="-60 90" stiffness="600" damping="60"
                       armature=".025"/>
                <joint name="abdomen_z" pos="0 0 0" axis="0 0 1" range="-50 50" stiffness="600" damping="60"
                       armature=".025"/>
                <geom name="torso" type="sphere" pos="0 0 0.12" size="0.11" density="1794" contype="0" conaffinity="1"/>
                <site name="torso" class="touch" type="sphere" pos="0 0 0.12" size="0.111"/>

                <geom name="right_clavicle" fromto="-0.0060125 -0.0457775 0.2287955 -0.016835 -0.128177 0.2376182"
                      size=".045" density="1100"/>
                <geom name="left_clavicle" fromto="-0.0060125 0.0457775 0.2287955 -0.016835 0.128177 0.2376182"
                      size=".045" density="1100"/>

                <body name="head" pos="0 0 0.223894">
                    <joint name="neck_x" axis="1 0 0" range="-50 50" stiffness="50" damping="5" armature=".017"/>
                    <joint name="neck_y" axis="0 1 0" range="-40 60" stiffness="50" damping="5" armature=".017"/>
                    <joint name="neck_z" axis="0 0 1" range="-45 45" stiffness="50" damping="5" armature=".017"/>
                    <geom name="head" type="sphere" pos="0 0 0.175" size="0.095" density="1081"/>
                    <site name="head" class="touch" pos="0 0 0.175" type="sphere" size="0.103"/>
                    <camera name="egocentric" pos=".103 0 0.175" xyaxes="0 -1 0 .1 0 1" fovy="80"/>
                </body>

                <body name="right_upper_arm" pos="-0.02405 -0.18311 0.24350">
                    <joint name="right_shoulder_x" axis="1 0 0" range="-180 45" stiffness="200" damping="20"
                           armature=".02"/>
                    <joint name="right_shoulder_y" axis="0 1 0" range="-180 60" stiffness="200" damping="20"
                           armature=".02"/>
                    <joint name="right_shoulder_z" axis="0 0 1" range="-90 90" stiffness="200" damping="20"
                           armature=".02"/>
                    <geom name="right_upper_arm" fromto="0 0 -0.05 0 0 -0.23" size=".045" density="982"/>
                    <site name="right_upper_arm" class="touch" pos="0 0 -0.14" size="0.046 0.1" zaxis="0 0 1"/>

                    <body name="right_lower_arm" pos="0 0 -0.274788">
                        <joint name="right_elbow" axis="0 1 0" range="-160 0" stiffness="150" damping="15"
                               armature=".015"/>
                        <geom name="right_lower_arm" fromto="0 0 -0.0525 0 0 -0.1875" size="0.04" density="1056"
                              contype="0" conaffinity="1"/>
                        <site name="right_lower_arm" class="touch" pos="0 0 -0.12" size="0.041 0.0685" zaxis="0 1 0"/>

                        <!-- <body name="right_hand" pos="0 0 -0.288947" quat="0 0 1 0"> -->
                        <body name="right_hand" pos="0 0 -0.288947">
                            <joint name="right_hand_x" axis="1 0 0" range="-90 90" stiffness="100" damping="10"
                                   armature=".01"/>
                            <joint name="right_hand_y" axis="0 1 0" range="-90 90" stiffness="100" damping="10"
                                   armature=".003"/>
                            <joint name="right_hand_z" axis="0 0 1" range="-90 90" stiffness="100" damping="10"
                                   armature=".003"/>
                            <geom name="right_hand" type="sphere" size=".04" density="1865"/>
                            <site name="right_hand" class="touch" type="sphere" size=".041"/>

                            <body name="right_qbhand_root_link" pos="0.0 0.0 0.0" quat="0 0 1 0">
<!--                                <geom type="mesh" rgba="0.35 0.35 0.35 1" mesh="flange_iso_04" contype="0"-->
<!--                                      conaffinity="1"-->

<!--                                />-->
                                <geom pos="-0.0045 0.0145 0.12" quat="0.707388 0.706825 0 0" type="mesh"
                                      rgba="0.35 0.35 0.35 1" mesh="palm_pinch_r" contype="0" conaffinity="1"

                                />
                                <geom pos="-0.0045 0.0145 0.12" quat="0.707388 0.706825 0 0" type="mesh"
                                      rgba="0.35 0.35 0.35 1" mesh="palm_pinch_r_collision" contype="0"/>

                                <body name="right_qbhand_thumb_knuckle_link" pos="-0.0485 0.016463 0.0974984"
                                      quat="0.000796327 0 0.000796326 0.999999">
                                    <inertial pos="0.0130716 -0.00273578 0.000643478"
                                              quat="0.502681 0.576479 0.364062 0.531453" mass="0.01"
                                              diaginertia="1.4342e-06 1.35762e-06 3.12515e-07"/>
                                    <joint name="right_qbhand_thumb_knuckle_joint" pos="0 0 0" axis="0 0 -1"
                                           limited="true"
                                           range="0 90"/>
                                    <geom type="mesh" contype="0" conaffinity="1"


                                          rgba="0.35 0.35 0.35 1"
                                          mesh="ph_thumb_r"/>
                                    <geom type="mesh" contype="0" rgba="0.35 0.35 0.35 1" mesh="ph_thumb_r_collision"/>
                                    <body name="right_qbhand_thumb_proximal_virtual_link" pos="0.0255 -0.0038 -0.00012"
                                          quat="0.841496 -0.540263 0 0">
                                        <inertial pos="0 0 0" mass="0.0001" diaginertia="1e-09 1e-09 1e-09"/>
                                        <joint name="right_qbhand_thumb_proximal_joint" pos="0 0 0" axis="0 0 -1"
                                               limited="true" range="0 45"/>
                                        <body name="right_qbhand_thumb_proximal_link" pos="0.013 0 0">
                                            <inertial pos="0.00476016 -0.00137869 0"
                                                      quat="0.0365143 0.706163 -0.0365143 0.706163"
                                                      mass="0.0063" diaginertia="2.6915e-07 2.3576e-07 1.79645e-07"/>
                                            <joint name="right_qbhand_thumb_proximal_virtual_joint" pos="0 0 0"
                                                   axis="0 0 -1"
                                                   limited="true" range="0 45"/>
                                            <geom type="mesh" contype="0" conaffinity="1"


                                                  rgba="0.35 0.35 0.35 1" mesh="ph_short"/>
                                            <geom type="mesh" contype="0" rgba="0.35 0.35 0.35 1"
                                                  mesh="ph_short_collision"/>
                                            <body name="right_qbhand_thumb_distal_virtual_link" pos="0.009 0 0">
                                                <inertial pos="0 0 0" mass="0.0001" diaginertia="1e-09 1e-09 1e-09"/>
                                                <joint name="right_qbhand_thumb_distal_joint" pos="0 0 0" axis="0 0 -1"
                                                       limited="true" range="0 45"/>
                                                <body name="right_qbhand_thumb_distal_link" pos="0.013 0 0">
                                                    <inertial pos="0.00880255 -0.00172193 0"
                                                              quat="0.0131386 0.706985 -0.0131386 0.706985"
                                                              mass="0.009"
                                                              diaginertia="6.6782e-07 5.99819e-07 2.654e-07"/>
                                                    <joint name="right_qbhand_thumb_distal_virtual_joint" pos="0 0 0"
                                                           axis="0 0 -1" limited="true" range="0 45"/>
                                                    <geom type="mesh" contype="0" conaffinity="1"


                                                          rgba="0.35 0.35 0.35 1" mesh="ph_distal"/>
                                                    <geom type="mesh" contype="0" rgba="0.35 0.35 0.35 1"
                                                          mesh="ph_distal_collision"/>
                                                </body>
                                            </body>
                                        </body>
                                    </body>
                                </body>
                                <body name="right_qbhand_index_knuckle_link" pos="-0.0245 0.00049443 0.137011"
                                      quat="0.500398 0.5 -0.499602 0.5">
                                    <inertial pos="0.000427536 0 -0.00143217"
                                              quat="0.587164 0.394003 0.394003 0.587164"
                                              mass="0.0095"
                                              diaginertia="1.12538e-06 7.39498e-07 6.27245e-07"/>
                                    <!--                                    <joint name="right_qbhand_index_knuckle_joint" pos="0 0 0" axis="0 0 -1"-->
                                    <!--                                           limited="true"-->
                                    <!--                                           range="-30 30"/>-->
                                    <geom type="mesh" contype="0" conaffinity="1"


                                          rgba="0.35 0.35 0.35 1"
                                          mesh="ph_knuckle"/>
                                    <geom type="mesh" contype="0" rgba="0.35 0.35 0.35 1" mesh="ph_knuckle_collision"/>
                                    <body name="right_qbhand_index_proximal_virtual_link" pos="0.009 0 0"
                                          quat="0.707388 0.706825 0 0">
                                        <inertial pos="0 0 0" mass="0.0001" diaginertia="1e-09 1e-09 1e-09"/>
                                        <joint name="right_qbhand_index_proximal_joint" pos="0 0 0" axis="0 0 -1"
                                               limited="true" range="0 45"/>
                                        <body name="right_qbhand_index_proximal_link" pos="0.013 0 0">
                                            <inertial pos="0.00877074 -0.00178631 0"
                                                      quat="0.0123083 0.707 -0.0123083 0.707" mass="0.0082"
                                                      diaginertia="5.95622e-07 5.59876e-07 2.26817e-07"/>
                                            <joint name="right_qbhand_index_proximal_virtual_joint" pos="0 0 0"
                                                   axis="0 0 -1"
                                                   limited="true"
                                                   range="0 45"/>
                                            <geom type="mesh" contype="0" conaffinity="1"


                                                  rgba="0.35 0.35 0.35 1"
                                                  mesh="ph_medium"/>
                                            <geom type="mesh" contype="0" rgba="0.35 0.35 0.35 1"
                                                  mesh="ph_medium_collision"/>
                                            <body name="right_qbhand_index_middle_virtual_link" pos="0.017 0 0">
                                                <inertial pos="0 0 0" mass="0.0001" diaginertia="1e-09 1e-09 1e-09"/>
                                                <joint name="right_qbhand_index_middle_joint" pos="0 0 0" axis="0 0 -1"
                                                       limited="true"
                                                       range="0 45"/>
                                                <body name="right_qbhand_index_middle_link" pos="0.013 0 0">
                                                    <inertial pos="0.00476016 -0.00137869 0"
                                                              quat="0.0365143 0.706163 -0.0365143 0.706163"
                                                              mass="0.0063"
                                                              diaginertia="2.6915e-07 2.3576e-07 1.79645e-07"/>
                                                    <joint name="right_qbhand_index_middle_virtual_joint" pos="0 0 0"
                                                           axis="0 0 -1" limited="true"
                                                           range="0 45"/>
                                                    <geom type="mesh" contype="0" conaffinity="1"


                                                          rgba="0.35 0.35 0.35 1" mesh="ph_short"/>
                                                    <geom type="mesh" contype="0" rgba="0.35 0.35 0.35 1"
                                                          mesh="ph_short_collision"/>
                                                    <body name="right_qbhand_index_distal_virtual_link" pos="0.009 0 0">
                                                        <inertial pos="0 0 0" mass="0.0001"
                                                                  diaginertia="1e-09 1e-09 1e-09"/>
                                                        <joint name="right_qbhand_index_distal_joint" pos="0 0 0"
                                                               axis="0 0 -1" limited="true"
                                                               range="0 45"/>
                                                        <body name="right_qbhand_index_distal_link" pos="0.013 0 0">
                                                            <inertial pos="0.00880255 -0.00172193 0"
                                                                      quat="0.0131386 0.706985 -0.0131386 0.706985"
                                                                      mass="0.009"
                                                                      diaginertia="6.6782e-07 5.99819e-07 2.654e-07"/>
                                                            <joint name="right_qbhand_index_distal_virtual_joint"
                                                                   pos="0 0 0"
                                                                   axis="0 0 -1"
                                                                   limited="true" range="0 45"/>
                                                            <geom type="mesh" contype="0" conaffinity="1"


                                                                  rgba="0.35 0.35 0.35 1"
                                                                  mesh="ph_distal"/>
                                                            <geom type="mesh" contype="0" rgba="0.35 0.35 0.35 1"
                                                                  mesh="ph_distal_collision"/>
                                                        </body>
                                                    </body>
                                                </body>
                                            </body>
                                        </body>
                                    </body>
                                </body>
                                <body name="right_qbhand_middle_knuckle_link" pos="-0.0045 0.000500004 0.144011"
                                      quat="0.500398 0.5 -0.499602 0.5">
                                    <inertial pos="0.000427536 0 -0.00143217" quat="0.587164 0.394003 0.394003 0.587164"
                                              mass="0.0095"
                                              diaginertia="1.12538e-06 7.39498e-07 6.27245e-07"/>
                                    <!--                                    <joint name="right_qbhand_middle_knuckle_joint" pos="0 0 0" axis="0 0 -1"-->
                                    <!--                                           limited="true"-->
                                    <!--                                           range="-30 30"/>-->
                                    <geom type="mesh" contype="0" conaffinity="1"


                                          rgba="0.35 0.35 0.35 1"
                                          mesh="ph_knuckle"/>
                                    <geom type="mesh" contype="0" rgba="0.35 0.35 0.35 1" mesh="ph_knuckle_collision"/>
                                    <body name="right_qbhand_middle_proximal_virtual_link" pos="0.009 0 0"
                                          quat="0.707388 0.706825 0 0">
                                        <inertial pos="0 0 0" mass="0.0001" diaginertia="1e-09 1e-09 1e-09"/>
                                        <joint name="right_qbhand_middle_proximal_joint" pos="0 0 0" axis="0 0 -1"
                                               limited="true"
                                               range="0 45"/>
                                        <body name="right_qbhand_middle_proximal_link" pos="0.013 0 0">
                                            <inertial pos="0.00877074 -0.00178631 0"
                                                      quat="0.0123083 0.707 -0.0123083 0.707" mass="0.0082"
                                                      diaginertia="5.95622e-07 5.59876e-07 2.26817e-07"/>
                                            <joint name="right_qbhand_middle_proximal_virtual_joint" pos="0 0 0"
                                                   axis="0 0 -1"
                                                   limited="true"
                                                   range="0 45"/>
                                            <geom type="mesh" contype="0" conaffinity="1"


                                                  rgba="0.35 0.35 0.35 1"
                                                  mesh="ph_medium"/>
                                            <geom type="mesh" contype="0" rgba="0.35 0.35 0.35 1"
                                                  mesh="ph_medium_collision"/>
                                            <body name="right_qbhand_middle_middle_virtual_link" pos="0.017 0 0">
                                                <inertial pos="0 0 0" mass="0.0001" diaginertia="1e-09 1e-09 1e-09"/>
                                                <joint name="right_qbhand_middle_middle_joint" pos="0 0 0" axis="0 0 -1"
                                                       limited="true"
                                                       range="0 45"/>
                                                <body name="right_qbhand_middle_middle_link" pos="0.013 0 0">
                                                    <inertial pos="0.00476016 -0.00137869 0"
                                                              quat="0.0365143 0.706163 -0.0365143 0.706163"
                                                              mass="0.0063"
                                                              diaginertia="2.6915e-07 2.3576e-07 1.79645e-07"/>
                                                    <joint name="right_qbhand_middle_middle_virtual_joint" pos="0 0 0"
                                                           axis="0 0 -1"
                                                           limited="true" range="0 45"/>
                                                    <geom type="mesh" contype="0" conaffinity="1"


                                                          rgba="0.35 0.35 0.35 1"
                                                          mesh="ph_short"/>
                                                    <geom type="mesh" contype="0" rgba="0.35 0.35 0.35 1"
                                                          mesh="ph_short_collision"/>
                                                    <body name="right_qbhand_middle_distal_virtual_link"
                                                          pos="0.009 0 0">
                                                        <inertial pos="0 0 0" mass="0.0001"
                                                                  diaginertia="1e-09 1e-09 1e-09"/>
                                                        <joint name="right_qbhand_middle_distal_joint" pos="0 0 0"
                                                               axis="0 0 -1" limited="true"
                                                               range="0 45"/>
                                                        <body name="right_qbhand_middle_distal_link" pos="0.013 0 0">
                                                            <inertial pos="0.00880255 -0.00172193 0"
                                                                      quat="0.0131386 0.706985 -0.0131386 0.706985"
                                                                      mass="0.009"
                                                                      diaginertia="6.6782e-07 5.99819e-07 2.654e-07"/>
                                                            <joint name="right_qbhand_middle_distal_virtual_joint"
                                                                   pos="0 0 0"
                                                                   axis="0 0 -1"
                                                                   limited="true" range="0 45"/>
                                                            <geom type="mesh" contype="0" conaffinity="1"


                                                                  rgba="0.35 0.35 0.35 1"
                                                                  mesh="ph_distal"/>
                                                            <geom type="mesh" contype="0" rgba="0.35 0.35 0.35 1"
                                                                  mesh="ph_distal_collision"/>
                                                        </body>
                                                    </body>
                                                </body>
                                            </body>
                                        </body>
                                    </body>
                                </body>
                                <body name="right_qbhand_ring_knuckle_link" pos="0.0155 0.00049443 0.137011"
                                      quat="0.500398 0.5 -0.499602 0.5">
                                    <inertial pos="0.000427536 0 -0.00143217" quat="0.587164 0.394003 0.394003 0.587164"
                                              mass="0.0095"
                                              diaginertia="1.12538e-06 7.39498e-07 6.27245e-07"/>
                                    <!--                                    <joint name="right_qbhand_ring_knuckle_joint" pos="0 0 0" axis="0 0 -1"-->
                                    <!--                                           limited="true"-->
                                    <!--                                           range="-30 30"/>-->
                                    <geom type="mesh" contype="0" conaffinity="1"


                                          rgba="0.35 0.35 0.35 1"
                                          mesh="ph_knuckle"/>
                                    <geom type="mesh" contype="0" rgba="0.35 0.35 0.35 1" mesh="ph_knuckle_collision"/>
                                    <body name="right_qbhand_ring_proximal_virtual_link" pos="0.009 0 0"
                                          quat="0.707388 0.706825 0 0">
                                        <inertial pos="0 0 0" mass="0.0001" diaginertia="1e-09 1e-09 1e-09"/>
                                        <joint name="right_qbhand_ring_proximal_joint" pos="0 0 0" axis="0 0 -1"
                                               limited="true" range="0 45"/>
                                        <body name="right_qbhand_ring_proximal_link" pos="0.013 0 0">
                                            <inertial pos="0.00877074 -0.00178631 0"
                                                      quat="0.0123083 0.707 -0.0123083 0.707" mass="0.0082"
                                                      diaginertia="5.95622e-07 5.59876e-07 2.26817e-07"/>
                                            <joint name="right_qbhand_ring_proximal_virtual_joint" pos="0 0 0"
                                                   axis="0 0 -1"
                                                   limited="true"
                                                   range="0 45"/>
                                            <geom type="mesh" contype="0"
                                                  conaffinity="1"


                                                  rgba="0.35 0.35 0.35 1"
                                                  mesh="ph_medium"/>
                                            <geom type="mesh" contype="0" rgba="0.35 0.35 0.35 1"
                                                  mesh="ph_medium_collision"/>
                                            <body name="right_qbhand_ring_middle_virtual_link" pos="0.017 0 0">
                                                <inertial pos="0 0 0" mass="0.0001" diaginertia="1e-09 1e-09 1e-09"/>
                                                <joint name="right_qbhand_ring_middle_joint" pos="0 0 0" axis="0 0 -1"
                                                       limited="true"
                                                       range="0 45"/>
                                                <body name="right_qbhand_ring_middle_link" pos="0.013 0 0">
                                                    <inertial pos="0.00476016 -0.00137869 0"
                                                              quat="0.0365143 0.706163 -0.0365143 0.706163"
                                                              mass="0.0063"
                                                              diaginertia="2.6915e-07 2.3576e-07 1.79645e-07"/>
                                                    <joint name="right_qbhand_ring_middle_virtual_joint" pos="0 0 0"
                                                           axis="0 0 -1" limited="true"
                                                           range="0 45"/>
                                                    <geom type="mesh" contype="0" conaffinity="1"


                                                          rgba="0.35 0.35 0.35 1"
                                                          mesh="ph_short"/>
                                                    <geom type="mesh" contype="0" rgba="0.35 0.35 0.35 1"
                                                          mesh="ph_short_collision"/>
                                                    <body name="right_qbhand_ring_distal_virtual_link" pos="0.009 0 0">
                                                        <inertial pos="0 0 0" mass="0.0001"
                                                                  diaginertia="1e-09 1e-09 1e-09"/>
                                                        <joint name="right_qbhand_ring_distal_joint" pos="0 0 0"
                                                               axis="0 0 -1"
                                                               limited="true"
                                                               range="0 45"/>
                                                        <body name="right_qbhand_ring_distal_link" pos="0.013 0 0">
                                                            <inertial pos="0.00880255 -0.00172193 0"
                                                                      quat="0.0131386 0.706985 -0.0131386 0.706985"
                                                                      mass="0.009"
                                                                      diaginertia="6.6782e-07 5.99819e-07 2.654e-07"/>
                                                            <joint name="right_qbhand_ring_distal_virtual_joint"
                                                                   pos="0 0 0"
                                                                   axis="0 0 -1"
                                                                   limited="true" range="0 45"/>
                                                            <geom type="mesh" contype="0" conaffinity="1"


                                                                  rgba="0.35 0.35 0.35 1"
                                                                  mesh="ph_distal"/>
                                                            <geom type="mesh" contype="0" rgba="0.35 0.35 0.35 1"
                                                                  mesh="ph_distal_collision"/>
                                                        </body>
                                                    </body>
                                                </body>
                                            </body>
                                        </body>
                                    </body>
                                </body>
                                <body name="right_qbhand_little_knuckle_link" pos="0.0355 0.000490449 0.132011"
                                      quat="0.500398 0.5 -0.499602 0.5">
                                    <inertial pos="0.000427536 0 -0.00143217" quat="0.587164 0.394003 0.394003 0.587164"
                                              mass="0.0095"
                                              diaginertia="1.12538e-06 7.39498e-07 6.27245e-07"/>
                                    <!--                                    <joint name="right_qbhand_little_knuckle_joint" pos="0 0 0" axis="0 0 -1"-->
                                    <!--                                           limited="true"-->
                                    <!--                                           range="-30 30"/>-->
                                    <geom type="mesh" contype="0" conaffinity="1"


                                          rgba="0.35 0.35 0.35 1"
                                          mesh="ph_knuckle"/>
                                    <geom type="mesh" contype="0" rgba="0.35 0.35 0.35 1" mesh="ph_knuckle_collision"/>
                                    <body name="right_qbhand_little_proximal_virtual_link" pos="0.009 0 0"
                                          quat="0.707388 0.706825 0 0">
                                        <inertial pos="0 0 0" mass="0.0001" diaginertia="1e-09 1e-09 1e-09"/>
                                        <joint name="right_qbhand_little_proximal_joint" pos="0 0 0" axis="0 0 -1"
                                               limited="true"
                                               range="0 45"/>
                                        <body name="right_qbhand_little_proximal_link" pos="0.013 0 0">
                                            <inertial pos="0.00476016 -0.00137869 0"
                                                      quat="0.0365143 0.706163 -0.0365143 0.706163"
                                                      mass="0.0063" diaginertia="2.6915e-07 2.3576e-07 1.79645e-07"/>
                                            <joint name="right_qbhand_little_proximal_virtual_joint" pos="0 0 0"
                                                   axis="0 0 -1"
                                                   limited="true"
                                                   range="0 45"/>
                                            <geom type="mesh" contype="0" conaffinity="1"


                                                  rgba="0.35 0.35 0.35 1"
                                                  mesh="ph_short"/>
                                            <geom type="mesh" contype="0" rgba="0.35 0.35 0.35 1"
                                                  mesh="ph_short_collision"/>
                                            <body name="right_qbhand_little_middle_virtual_link" pos="0.009 0 0">
                                                <inertial pos="0 0 0" mass="0.0001" diaginertia="1e-09 1e-09 1e-09"/>
                                                <joint name="right_qbhand_little_middle_joint" pos="0 0 0" axis="0 0 -1"
                                                       limited="true"
                                                       range="0 45"/>
                                                <body name="right_qbhand_little_middle_link" pos="0.013 0 0">
                                                    <inertial pos="0.00476016 -0.00137869 0"
                                                              quat="0.0365143 0.706163 -0.0365143 0.706163"
                                                              mass="0.0063"
                                                              diaginertia="2.6915e-07 2.3576e-07 1.79645e-07"/>
                                                    <joint name="right_qbhand_little_middle_virtual_joint" pos="0 0 0"
                                                           axis="0 0 -1"
                                                           limited="true" range="0 45"/>
                                                    <geom type="mesh" contype="0" conaffinity="1"


                                                          rgba="0.35 0.35 0.35 1"
                                                          mesh="ph_short"/>
                                                    <geom type="mesh" contype="0" rgba="0.35 0.35 0.35 1"
                                                          mesh="ph_short_collision"/>
                                                    <body name="right_qbhand_little_distal_virtual_link"
                                                          pos="0.009 0 0">
                                                        <inertial pos="0 0 0" mass="0.0001"
                                                                  diaginertia="1e-09 1e-09 1e-09"/>
                                                        <joint name="right_qbhand_little_distal_joint" pos="0 0 0"
                                                               axis="0 0 -1" limited="true"
                                                               range="0 45"/>
                                                        <body name="right_qbhand_little_distal_link" pos="0.013 0 0">
                                                            <inertial pos="0.00880255 -0.00172193 0"
                                                                      quat="0.0131386 0.706985 -0.0131386 0.706985"
                                                                      mass="0.009"
                                                                      diaginertia="6.6782e-07 5.99819e-07 2.654e-07"/>
                                                            <joint name="right_qbhand_little_distal_virtual_joint"
                                                                   pos="0 0 0"
                                                                   axis="0 0 -1"
                                                                   limited="true" range="0 45"/>
                                                            <geom type="mesh" contype="0" conaffinity="1"


                                                                  rgba="0.35 0.35 0.35 1"
                                                                  mesh="ph_distal"/>
                                                            <geom type="mesh" contype="0" rgba="0.35 0.35 0.35 1"
                                                                  mesh="ph_distal_collision"/>
                                                        </body>
                                                    </body>
                                                </body>
                                            </body>
                                        </body>
                                    </body>
                                </body>
                            </body>
                        </body>
                    </body>
                </body>

                <body name="left_upper_arm" pos="-0.02405 0.18311 0.24350">
                    <joint name="left_shoulder_x" axis="1 0 0" range="-45 180" stiffness="200" damping="20"
                           armature=".02"/>
                    <joint name="left_shoulder_y" axis="0 1 0" range="-180 60" stiffness="200" damping="20"
                           armature=".02"/>
                    <joint name="left_shoulder_z" axis="0 0 1" range="-90 90" stiffness="200" damping="20"
                           armature=".02"/>
                    <geom name="left_upper_arm" fromto="0 0 -0.05 0 0 -0.23" size="0.045" density="982"/>
                    <site name="left_upper_arm" class="touch" pos="0 0 -0.14" size="0.046 0.1" zaxis="0 0 1"/>

                    <body name="left_lower_arm" pos="0 0 -0.274788">
                        <joint name="left_elbow" axis="0 1 0" range="-160 0" stiffness="150" damping="15"
                               armature=".015"/>
                        <geom name="left_lower_arm" fromto="0 0 -0.0525 0 0 -0.1875" size="0.04" density="1056"
                              contype="0" conaffinity="1"


                        />
                        <site name="left_lower_arm" class="touch" pos="0 0 -0.1" size="0.041 0.0685" zaxis="0 0 1"/>

                        <!-- <body name="left_hand" pos="0 0 -0.288947"  quat="0 1 0 0"> -->
                        <body name="left_hand" pos="0 0 -0.288947">
                            <joint name="left_hand_x" axis="1 0 0" range="-90 90" stiffness="100" damping="10"
                                   armature=".01"/>
                            <joint name="left_hand_y" axis="0 1 0" range="-90 90" stiffness="100" damping="10"
                                   armature=".003"/>
                            <joint name="left_hand_z" axis="0 0 1" range="-90 90" stiffness="100" damping="10"
                                   armature=".003"/>
                            <geom name="left_hand" type="sphere" size=".04" density="1865"/>
                            <site name="left_hand" class="touch" type="sphere" size=".041"/>

                            <body name="left_qbhand_root_link" pos="0.0 0.0 0.0" quat="0 1 0 0">
<!--                                <geom type="mesh" rgba="0.35 0.35 0.35 1" mesh="flange_iso_04" contype="0"-->
<!--                                      conaffinity="1"-->

<!--                                />-->
                                <geom pos="0.0045 0.0145 0.12" quat="0.000563312 0.000562864 0.706825 0.707388"
                                      type="mesh"
                                      rgba="0.35 0.35 0.35 1" mesh="palm_pinch_l" contype="0" conaffinity="1"/>
                                <geom pos="0.0045 0.0145 0.12" quat="0.000563312 0.000562864 0.706825 0.707388"
                                      type="mesh"
                                      rgba="0.35 0.35 0.35 1" mesh="palm_pinch_l_collision" contype="0"/>

                                <body name="left_qbhand_thumb_knuckle_link" pos="0.0485032 0.0164669 0.0975016"
                                      quat="-0.999998 -0.000796326 6.34136e-07 0.00159265">
                                    <inertial pos="0.0130716 0.00273463 0.000640905"
                                              quat="0.531237 0.364349 0.576408 0.502783" mass="0.01"
                                              diaginertia="1.43383e-06 1.35753e-06 3.12211e-07"/>
                                    <joint name="left_qbhand_thumb_knuckle_joint" pos="0 0 0" axis="0 0 1"
                                           limited="true"
                                           range="0 90"/>
                                    <geom type="mesh" contype="0" conaffinity="1"


                                          rgba="0.35 0.35 0.35 1"
                                          mesh="ph_thumb_l"/>
                                    <geom type="mesh" contype="0" rgba="0.35 0.35 0.35 1" mesh="ph_thumb_l_collision"/>
                                    <body name="left_qbhand_thumb_proximal_virtual_link" pos="0.0255 0.0038 -0.00012"
                                          quat="0.540302 -0.841471 0 0">
                                        <inertial pos="0 0 0" mass="0.0001" diaginertia="1e-09 1e-09 1e-09"/>
                                        <joint name="left_qbhand_thumb_proximal_joint" pos="0 0 0" axis="0 0 -1"
                                               limited="true" range="0 45"/>
                                        <body name="left_qbhand_thumb_proximal_link" pos="0.013 0 0">
                                            <inertial pos="0.00476016 -0.00137869 0"
                                                      quat="0.0365143 0.706163 -0.0365143 0.706163"
                                                      mass="0.0063" diaginertia="2.6915e-07 2.3576e-07 1.79645e-07"/>
                                            <joint name="left_qbhand_thumb_proximal_virtual_joint" pos="0 0 0"
                                                   axis="0 0 -1"
                                                   limited="true" range="0 45"/>
                                            <geom type="mesh" contype="0" conaffinity="1"


                                                  rgba="0.35 0.35 0.35 1" mesh="ph_short"/>
                                            <geom type="mesh" contype="0" rgba="0.35 0.35 0.35 1"
                                                  mesh="ph_short_collision"/>
                                            <body name="left_qbhand_thumb_distal_virtual_link" pos="0.009 0 0">
                                                <inertial pos="0 0 0" mass="0.0001" diaginertia="1e-09 1e-09 1e-09"/>
                                                <joint name="left_qbhand_thumb_distal_joint" pos="0 0 0" axis="0 0 -1"
                                                       limited="true" range="0 45"/>
                                                <body name="left_qbhand_thumb_distal_link" pos="0.013 0 0">
                                                    <inertial pos="0.00880255 -0.00172193 0"
                                                              quat="0.0131386 0.706985 -0.0131386 0.706985"
                                                              mass="0.009"
                                                              diaginertia="6.6782e-07 5.99819e-07 2.654e-07"/>
                                                    <joint name="left_qbhand_thumb_distal_virtual_joint" pos="0 0 0"
                                                           axis="0 0 -1" limited="true" range="0 45"/>
                                                    <geom type="mesh" contype="0" conaffinity="1"


                                                          rgba="0.35 0.35 0.35 1" mesh="ph_distal"/>
                                                    <geom type="mesh" contype="0" rgba="0.35 0.35 0.35 1"
                                                          mesh="ph_distal_collision"/>
                                                </body>
                                            </body>
                                        </body>
                                    </body>
                                </body>
                                <body name="left_qbhand_index_knuckle_link" pos="0.0244777 0.000473743 0.136989"
                                      quat="-0.499999 -0.500397 0.500796 -0.498805">
                                    <inertial pos="0.000427536 0 -0.00143217"
                                              quat="0.587164 0.394003 0.394003 0.587164"
                                              mass="0.0095"
                                              diaginertia="1.12538e-06 7.39498e-07 6.27245e-07"/>
                                    <!--                                    <joint name="left_qbhand_index_knuckle_joint" pos="0 0 0" axis="0 0 -1"-->
                                    <!--                                           limited="true"-->
                                    <!--                                           range="-30 30"/>-->
                                    <geom type="mesh" contype="0" conaffinity="1"


                                          rgba="0.35 0.35 0.35 1"
                                          mesh="ph_knuckle"/>
                                    <geom type="mesh" contype="0" rgba="0.35 0.35 0.35 1" mesh="ph_knuckle_collision"/>
                                    <body name="left_qbhand_index_proximal_virtual_link" pos="0.009 0 0"
                                          quat="0.707388 0.706825 0 0">
                                        <inertial pos="0 0 0" mass="0.0001" diaginertia="1e-09 1e-09 1e-09"/>
                                        <joint name="left_qbhand_index_proximal_joint" pos="0 0 0" axis="0 0 -1"
                                               limited="true" range="0 45"/>
                                        <body name="left_qbhand_index_proximal_link" pos="0.013 0 0">
                                            <inertial pos="0.00877074 -0.00178631 0"
                                                      quat="0.0123083 0.707 -0.0123083 0.707" mass="0.0082"
                                                      diaginertia="5.95622e-07 5.59876e-07 2.26817e-07"/>
                                            <joint name="left_qbhand_index_proximal_virtual_joint" pos="0 0 0"
                                                   axis="0 0 -1"
                                                   limited="true"
                                                   range="0 45"/>
                                            <geom type="mesh" contype="0" conaffinity="1"


                                                  rgba="0.35 0.35 0.35 1"
                                                  mesh="ph_medium"/>
                                            <geom type="mesh" contype="0" rgba="0.35 0.35 0.35 1"
                                                  mesh="ph_medium_collision"/>
                                            <body name="left_qbhand_index_middle_virtual_link" pos="0.017 0 0">
                                                <inertial pos="0 0 0" mass="0.0001" diaginertia="1e-09 1e-09 1e-09"/>
                                                <joint name="left_qbhand_index_middle_joint" pos="0 0 0" axis="0 0 -1"
                                                       limited="true"
                                                       range="0 45"/>
                                                <body name="left_qbhand_index_middle_link" pos="0.013 0 0">
                                                    <inertial pos="0.00476016 -0.00137869 0"
                                                              quat="0.0365143 0.706163 -0.0365143 0.706163"
                                                              mass="0.0063"
                                                              diaginertia="2.6915e-07 2.3576e-07 1.79645e-07"/>
                                                    <joint name="left_qbhand_index_middle_virtual_joint" pos="0 0 0"
                                                           axis="0 0 -1" limited="true"
                                                           range="0 45"/>
                                                    <geom type="mesh" contype="0" conaffinity="1"


                                                          rgba="0.35 0.35 0.35 1"
                                                          mesh="ph_short"/>
                                                    <geom type="mesh" contype="0" rgba="0.35 0.35 0.35 1"
                                                          mesh="ph_short_collision"/>
                                                    <body name="left_qbhand_index_distal_virtual_link" pos="0.009 0 0">
                                                        <inertial pos="0 0 0" mass="0.0001"
                                                                  diaginertia="1e-09 1e-09 1e-09"/>
                                                        <joint name="left_qbhand_index_distal_joint" pos="0 0 0"
                                                               axis="0 0 -1" limited="true"
                                                               range="0 45"/>
                                                        <body name="left_qbhand_index_distal_link" pos="0.013 0 0">
                                                            <inertial pos="0.00880255 -0.00172193 0"
                                                                      quat="0.0131386 0.706985 -0.0131386 0.706985"
                                                                      mass="0.009"
                                                                      diaginertia="6.6782e-07 5.99819e-07 2.654e-07"/>
                                                            <joint name="left_qbhand_index_distal_virtual_joint"
                                                                   pos="0 0 0"
                                                                   axis="0 0 -1"
                                                                   limited="true" range="0 45"/>
                                                            <geom type="mesh" contype="0" conaffinity="1"


                                                                  rgba="0.35 0.35 0.35 1"
                                                                  mesh="ph_distal"/>
                                                            <geom type="mesh" contype="0" rgba="0.35 0.35 0.35 1"
                                                                  mesh="ph_distal_collision"/>
                                                        </body>
                                                    </body>
                                                </body>
                                            </body>
                                        </body>
                                    </body>
                                </body>
                                <body name="left_qbhand_middle_knuckle_link" pos="0.0044777 0.000500022 0.143989"
                                      quat="-0.499999 -0.500397 0.500796 -0.498805">
                                    <inertial pos="0.000427536 0 -0.00143217" quat="0.587164 0.394003 0.394003 0.587164"
                                              mass="0.0095"
                                              diaginertia="1.12538e-06 7.39498e-07 6.27245e-07"/>
                                    <!--                                    <joint name="left_qbhand_middle_knuckle_joint" pos="0 0 0" axis="0 0 -1"-->
                                    <!--                                           limited="true"-->
                                    <!--                                           range="-30 30"/>-->
                                    <geom type="mesh" contype="0" conaffinity="1"


                                          rgba="0.35 0.35 0.35 1"
                                          mesh="ph_knuckle"/>
                                    <geom type="mesh" contype="0" rgba="0.35 0.35 0.35 1" mesh="ph_knuckle_collision"/>
                                    <body name="left_qbhand_middle_proximal_virtual_link" pos="0.009 0 0"
                                          quat="0.707388 0.706825 0 0">
                                        <inertial pos="0 0 0" mass="0.0001" diaginertia="1e-09 1e-09 1e-09"/>
                                        <joint name="left_qbhand_middle_proximal_joint" pos="0 0 0" axis="0 0 -1"
                                               limited="true"
                                               range="0 45"/>
                                        <body name="left_qbhand_middle_proximal_link" pos="0.013 0 0">
                                            <inertial pos="0.00877074 -0.00178631 0"
                                                      quat="0.0123083 0.707 -0.0123083 0.707" mass="0.0082"
                                                      diaginertia="5.95622e-07 5.59876e-07 2.26817e-07"/>
                                            <joint name="left_qbhand_middle_proximal_virtual_joint" pos="0 0 0"
                                                   axis="0 0 -1"
                                                   limited="true"
                                                   range="0 45"/>
                                            <geom type="mesh" contype="0" conaffinity="1"


                                                  rgba="0.35 0.35 0.35 1"
                                                  mesh="ph_medium"/>
                                            <geom type="mesh" contype="0" rgba="0.35 0.35 0.35 1"
                                                  mesh="ph_medium_collision"/>
                                            <body name="left_qbhand_middle_middle_virtual_link" pos="0.017 0 0">
                                                <inertial pos="0 0 0" mass="0.0001" diaginertia="1e-09 1e-09 1e-09"/>
                                                <joint name="left_qbhand_middle_middle_joint" pos="0 0 0" axis="0 0 -1"
                                                       limited="true"
                                                       range="0 45"/>
                                                <body name="left_qbhand_middle_middle_link" pos="0.013 0 0">
                                                    <inertial pos="0.00476016 -0.00137869 0"
                                                              quat="0.0365143 0.706163 -0.0365143 0.706163"
                                                              mass="0.0063"
                                                              diaginertia="2.6915e-07 2.3576e-07 1.79645e-07"/>
                                                    <joint name="left_qbhand_middle_middle_virtual_joint" pos="0 0 0"
                                                           axis="0 0 -1"
                                                           limited="true" range="0 45"/>
                                                    <geom type="mesh" contype="0" conaffinity="1"


                                                          rgba="0.35 0.35 0.35 1"
                                                          mesh="ph_short"/>
                                                    <geom type="mesh" contype="0" rgba="0.35 0.35 0.35 1"
                                                          mesh="ph_short_collision"/>
                                                    <body name="left_qbhand_middle_distal_virtual_link" pos="0.009 0 0">
                                                        <inertial pos="0 0 0" mass="0.0001"
                                                                  diaginertia="1e-09 1e-09 1e-09"/>
                                                        <joint name="left_qbhand_middle_distal_joint" pos="0 0 0"
                                                               axis="0 0 -1" limited="true"
                                                               range="0 45"/>
                                                        <body name="left_qbhand_middle_distal_link" pos="0.013 0 0">
                                                            <inertial pos="0.00880255 -0.00172193 0"
                                                                      quat="0.0131386 0.706985 -0.0131386 0.706985"
                                                                      mass="0.009"
                                                                      diaginertia="6.6782e-07 5.99819e-07 2.654e-07"/>
                                                            <joint name="left_qbhand_middle_distal_virtual_joint"
                                                                   pos="0 0 0"
                                                                   axis="0 0 -1"
                                                                   limited="true" range="0 45"/>
                                                            <geom type="mesh" contype="0" conaffinity="1"


                                                                  rgba="0.35 0.35 0.35 1"
                                                                  mesh="ph_distal"/>
                                                            <geom type="mesh" contype="0" rgba="0.35 0.35 0.35 1"
                                                                  mesh="ph_distal_collision"/>
                                                        </body>
                                                    </body>
                                                </body>
                                            </body>
                                        </body>
                                    </body>
                                </body>
                                <body name="left_qbhand_ring_knuckle_link" pos="-0.0155223 0.00053745 0.136989"
                                      quat="-0.499999 -0.500397 0.500796 -0.498805">
                                    <inertial pos="0.000427536 0 -0.00143217" quat="0.587164 0.394003 0.394003 0.587164"
                                              mass="0.0095"
                                              diaginertia="1.12538e-06 7.39498e-07 6.27245e-07"/>
                                    <!--                                    <joint name="left_qbhand_ring_knuckle_joint" pos="0 0 0" axis="0 0 -1"-->
                                    <!--                                           limited="true"-->
                                    <!--                                           range="-30 30"/>-->
                                    <geom type="mesh" contype="0" conaffinity="1"


                                          rgba="0.35 0.35 0.35 1"
                                          mesh="ph_knuckle"/>
                                    <geom type="mesh" contype="0" rgba="0.35 0.35 0.35 1" mesh="ph_knuckle_collision"/>
                                    <body name="left_qbhand_ring_proximal_virtual_link" pos="0.009 0 0"
                                          quat="0.707388 0.706825 0 0">
                                        <inertial pos="0 0 0" mass="0.0001" diaginertia="1e-09 1e-09 1e-09"/>
                                        <joint name="left_qbhand_ring_proximal_joint" pos="0 0 0" axis="0 0 -1"
                                               limited="true" range="0 45"/>
                                        <body name="left_qbhand_ring_proximal_link" pos="0.013 0 0">
                                            <inertial pos="0.00877074 -0.00178631 0"
                                                      quat="0.0123083 0.707 -0.0123083 0.707" mass="0.0082"
                                                      diaginertia="5.95622e-07 5.59876e-07 2.26817e-07"/>
                                            <joint name="left_qbhand_ring_proximal_virtual_joint" pos="0 0 0"
                                                   axis="0 0 -1"
                                                   limited="true"
                                                   range="0 45"/>
                                            <geom type="mesh" contype="0" conaffinity="1"


                                                  rgba="0.35 0.35 0.35 1"
                                                  mesh="ph_medium"/>
                                            <geom type="mesh" contype="0" rgba="0.35 0.35 0.35 1"
                                                  mesh="ph_medium_collision"/>
                                            <body name="left_qbhand_ring_middle_virtual_link" pos="0.017 0 0">
                                                <inertial pos="0 0 0" mass="0.0001" diaginertia="1e-09 1e-09 1e-09"/>
                                                <joint name="left_qbhand_ring_middle_joint" pos="0 0 0" axis="0 0 -1"
                                                       limited="true"
                                                       range="0 45"/>
                                                <body name="left_qbhand_ring_middle_link" pos="0.013 0 0">
                                                    <inertial pos="0.00476016 -0.00137869 0"
                                                              quat="0.0365143 0.706163 -0.0365143 0.706163"
                                                              mass="0.0063"
                                                              diaginertia="2.6915e-07 2.3576e-07 1.79645e-07"/>
                                                    <joint name="left_qbhand_ring_middle_virtual_joint" pos="0 0 0"
                                                           axis="0 0 -1" limited="true"
                                                           range="0 45"/>
                                                    <geom type="mesh" contype="0" conaffinity="1"


                                                          rgba="0.35 0.35 0.35 1"
                                                          mesh="ph_short"/>
                                                    <geom type="mesh" contype="0" rgba="0.35 0.35 0.35 1"
                                                          mesh="ph_short_collision"/>
                                                    <body name="left_qbhand_ring_distal_virtual_link" pos="0.009 0 0">
                                                        <inertial pos="0 0 0" mass="0.0001"
                                                                  diaginertia="1e-09 1e-09 1e-09"/>
                                                        <joint name="left_qbhand_ring_distal_joint" pos="0 0 0"
                                                               axis="0 0 -1"
                                                               limited="true"
                                                               range="0 45"/>
                                                        <body name="left_qbhand_ring_distal_link" pos="0.013 0 0">
                                                            <inertial pos="0.00880255 -0.00172193 0"
                                                                      quat="0.0131386 0.706985 -0.0131386 0.706985"
                                                                      mass="0.009"
                                                                      diaginertia="6.6782e-07 5.99819e-07 2.654e-07"/>
                                                            <joint name="left_qbhand_ring_distal_virtual_joint"
                                                                   pos="0 0 0"
                                                                   axis="0 0 -1"
                                                                   limited="true" range="0 45"/>
                                                            <geom type="mesh" contype="0" conaffinity="1"


                                                                  rgba="0.35 0.35 0.35 1"
                                                                  mesh="ph_distal"/>
                                                            <geom type="mesh" contype="0" rgba="0.35 0.35 0.35 1"
                                                                  mesh="ph_distal_collision"/>
                                                        </body>
                                                    </body>
                                                </body>
                                            </body>
                                        </body>
                                    </body>
                                </body>
                                <body name="left_qbhand_little_knuckle_link" pos="-0.0355222 0.000573284 0.131989"
                                      quat="-0.499999 -0.500397 0.500796 -0.498805">
                                    <inertial pos="0.000427536 0 -0.00143217" quat="0.587164 0.394003 0.394003 0.587164"
                                              mass="0.0095"
                                              diaginertia="1.12538e-06 7.39498e-07 6.27245e-07"/>
                                    <!--                                    <joint name="left_qbhand_little_knuckle_joint" pos="0 0 0" axis="0 0 -1"-->
                                    <!--                                           limited="true"-->
                                    <!--                                           range="-30 30"/>-->
                                    <geom type="mesh" contype="0" conaffinity="1"


                                          rgba="0.35 0.35 0.35 1"
                                          mesh="ph_knuckle"/>
                                    <geom type="mesh" contype="0" rgba="0.35 0.35 0.35 1" mesh="ph_knuckle_collision"/>
                                    <body name="left_qbhand_little_proximal_virtual_link" pos="0.009 0 0"
                                          quat="0.707388 0.706825 0 0">
                                        <inertial pos="0 0 0" mass="0.0001" diaginertia="1e-09 1e-09 1e-09"/>
                                        <joint name="left_qbhand_little_proximal_joint" pos="0 0 0" axis="0 0 -1"
                                               limited="true"
                                               range="0 45"/>
                                        <body name="left_qbhand_little_proximal_link" pos="0.013 0 0">
                                            <inertial pos="0.00476016 -0.00137869 0"
                                                      quat="0.0365143 0.706163 -0.0365143 0.706163"
                                                      mass="0.0063" diaginertia="2.6915e-07 2.3576e-07 1.79645e-07"/>
                                            <joint name="left_qbhand_little_proximal_virtual_joint" pos="0 0 0"
                                                   axis="0 0 -1"
                                                   limited="true"
                                                   range="0 45"/>
                                            <geom type="mesh" contype="0" conaffinity="1"


                                                  rgba="0.35 0.35 0.35 1"
                                                  mesh="ph_short"/>
                                            <geom type="mesh" contype="0" rgba="0.35 0.35 0.35 1"
                                                  mesh="ph_short_collision"/>
                                            <body name="left_qbhand_little_middle_virtual_link" pos="0.009 0 0">
                                                <inertial pos="0 0 0" mass="0.0001" diaginertia="1e-09 1e-09 1e-09"/>
                                                <joint name="left_qbhand_little_middle_joint" pos="0 0 0" axis="0 0 -1"
                                                       limited="true"
                                                       range="0 45"/>
                                                <body name="left_qbhand_little_middle_link" pos="0.013 0 0">
                                                    <inertial pos="0.00476016 -0.00137869 0"
                                                              quat="0.0365143 0.706163 -0.0365143 0.706163"
                                                              mass="0.0063"
                                                              diaginertia="2.6915e-07 2.3576e-07 1.79645e-07"/>
                                                    <joint name="left_qbhand_little_middle_virtual_joint" pos="0 0 0"
                                                           axis="0 0 -1"
                                                           limited="true" range="0 45"/>
                                                    <geom type="mesh" contype="0" conaffinity="1"


                                                          rgba="0.35 0.35 0.35 1"
                                                          mesh="ph_short"/>
                                                    <geom type="mesh" contype="0" rgba="0.35 0.35 0.35 1"
                                                          mesh="ph_short_collision"/>
                                                    <body name="left_qbhand_little_distal_virtual_link" pos="0.009 0 0">
                                                        <inertial pos="0 0 0" mass="0.0001"
                                                                  diaginertia="1e-09 1e-09 1e-09"/>
                                                        <joint name="left_qbhand_little_distal_joint" pos="0 0 0"
                                                               axis="0 0 -1" limited="true"
                                                               range="0 45"/>
                                                        <body name="left_qbhand_little_distal_link" pos="0.013 0 0">
                                                            <inertial pos="0.00880255 -0.00172193 0"
                                                                      quat="0.0131386 0.706985 -0.0131386 0.706985"
                                                                      mass="0.009"
                                                                      diaginertia="6.6782e-07 5.99819e-07 2.654e-07"/>
                                                            <joint name="left_qbhand_little_distal_virtual_joint"
                                                                   pos="0 0 0"
                                                                   axis="0 0 -1"
                                                                   limited="true" range="0 45"/>
                                                            <geom type="mesh" contype="0" conaffinity="1"


                                                                  rgba="0.35 0.35 0.35 1"
                                                                  mesh="ph_distal"/>
                                                            <geom type="mesh" contype="0" rgba="0.35 0.35 0.35 1"
                                                                  mesh="ph_distal_collision"/>
                                                        </body>
                                                    </body>
                                                </body>
                                            </body>
                                        </body>
                                    </body>
                                </body>
                            </body>
                        </body>
                    </body>
                </body>
            </body>

            <body name="right_thigh" pos="0 -0.084887 0">
                <site name="right_hip" class="force-torque"/>
                <joint name="right_hip_x" axis="1 0 0" range="-60 15" stiffness="300" damping="30" armature=".02"/>
                <joint name="right_hip_y" axis="0 1 0" range="-140 60" stiffness="300" damping="30" armature=".02"/>
                <joint name="right_hip_z" axis="0 0 1" range="-60 35" stiffness="300" damping="30" armature=".02"/>
                <geom name="right_thigh" fromto="0 0 -0.06 0 0 -0.36" size="0.055" density="1269"/>
                <site name="right_thigh" class="touch" pos="0 0 -0.21" size="0.056 0.301" zaxis="0 0 -1"/>

                <body name="right_shin" pos="0 0 -0.421546">
                    <site name="right_knee" class="force-torque" pos="0 0 0"/>
                    <joint name="right_knee" pos="0 0 0" axis="0 1 0" range="0 160" stiffness="300" damping="30"
                           armature=".02"/>
                    <geom name="right_shin" fromto="0 0 -0.045 0 0 -0.355" size=".05" density="1014"/>
                    <site name="right_shin" class="touch" pos="0 0 -0.2" size="0.051 0.156" zaxis="0 0 -1"/>

                    <body name="right_foot" pos="0 0 -0.409870">
                        <site name="right_ankle" class="force-torque"/>
                        <joint name="right_ankle_x" pos="0 0 0" axis="1 0 0" range="-30 30" stiffness="200"
                               damping="20"
                               armature=".01"/>
                        <joint name="right_ankle_y" pos="0 0 0" axis="0 1 0" range="-55 55" stiffness="200"
                               damping="20"
                               armature=".01"/>
                        <joint name="right_ankle_z" pos="0 0 0" axis="0 0 1" range="-40 40" stiffness="200"
                               damping="20"
                               armature=".01"/>
                        <geom name="right_foot" type="box" pos="0.045 0 -0.0225" size="0.0885 0.045 0.0275"
                              density="1141"/>
                        <site name="right_foot" class="touch" type="box" pos="0.045 0 -0.0225"
                              size="0.0895 0.055 0.0285"/>
                    </body>
                </body>
            </body>

            <body name="left_thigh" pos="0 0.084887 0">
                <site name="left_hip" class="force-torque"/>
                <joint name="left_hip_x" axis="1 0 0" range="-15 60" stiffness="300" damping="30" armature=".02"/>
                <joint name="left_hip_y" axis="0 1 0" range="-140 60" stiffness="300" damping="30" armature=".02"/>
                <joint name="left_hip_z" axis="0 0 1" range="-35 60" stiffness="300" damping="30" armature=".02"/>
                <geom name="left_thigh" fromto="0 0 -0.06 0 0 -0.36" size=".055" density="1269"/>
                <site name="left_thigh" class="touch" pos="0 0 -0.21" size="0.056 0.301" zaxis="0 0 -1"/>

                <body name="left_shin" pos="0 0 -0.421546">
                    <site name="left_knee" class="force-torque" pos="0 0 .02"/>
                    <joint name="left_knee" pos="0 0 0" axis="0 1 0" range="0 160" stiffness="300" damping="30"
                           armature=".02"/>
                    <geom name="left_shin" fromto="0 0 -0.045 0 0 -0.355" size=".05" density="1014"/>
                    <site name="left_shin" class="touch" pos="0 0 -0.2" size="0.051 0.156" zaxis="0 0 -1"/>

                    <body name="left_foot" pos="0 0 -0.409870">
                        <site name="left_ankle" class="force-torque"/>
                        <joint name="left_ankle_x" pos="0 0 0" axis="1 0 0" range="-30 30" stiffness="200"
                               damping="20"
                               armature=".01"/>
                        <joint name="left_ankle_y" pos="0 0 0" axis="0 1 0" range="-55 55" stiffness="200"
                               damping="20"
                               armature=".01"/>
                        <joint name="left_ankle_z" pos="0 0 0" axis="0 0 1" range="-40 40" stiffness="200"
                               damping="20"
                               armature=".01"/>
                        <geom name="left_foot" type="box" pos="0.045 0 -0.0225" size="0.0885 0.045 0.0275"
                              density="1141"/>
                        <site name="left_foot" class="touch" type="box" pos="0.045 0 -0.0225"
                              size="0.0895 0.055 0.0285"/>
                    </body>
                </body>
            </body>
        </body>
    </worldbody>

    <actuator>
        <motor name='abdomen_x' gear='125' joint='abdomen_x'/>
        <motor name='abdomen_y' gear='125' joint='abdomen_y'/>
        <motor name='abdomen_z' gear='125' joint='abdomen_z'/>
        <motor name='neck_x' gear='20' joint='neck_x'/>
        <motor name='neck_y' gear='20' joint='neck_y'/>
        <motor name='neck_z' gear='20' joint='neck_z'/>
        <motor name='right_shoulder_x' gear='70' joint='right_shoulder_x'/>
        <motor name='right_shoulder_y' gear='70' joint='right_shoulder_y'/>
        <motor name='right_shoulder_z' gear='70' joint='right_shoulder_z'/>
        <motor name='right_elbow' gear='60' joint='right_elbow'/>
        <motor name='right_hand_x' gear='50' joint='right_hand_x'/>
        <motor name='right_hand_y' gear='50' joint='right_hand_y'/>
        <motor name='right_hand_z' gear='50' joint='right_hand_z'/>
        <motor name='right_qbhand_thumb_knuckle_joint' gear='125' joint='right_qbhand_thumb_knuckle_joint'/>
        <motor name='right_qbhand_thumb_proximal_joint' gear='125' joint='right_qbhand_thumb_proximal_joint'/>
        <motor name='right_qbhand_thumb_distal_joint' gear='125' joint='right_qbhand_thumb_distal_joint'/>
        <motor name='right_qbhand_index_proximal_joint' gear='125' joint='right_qbhand_index_proximal_joint'/>
        <motor name='right_qbhand_index_middle_joint' gear='125' joint='right_qbhand_index_middle_joint'/>
        <motor name='right_qbhand_index_distal_joint' gear='125' joint='right_qbhand_index_distal_joint'/>
        <motor name='right_qbhand_middle_proximal_joint' gear='125' joint='right_qbhand_middle_proximal_joint'/>
        <motor name='right_qbhand_middle_middle_joint' gear='125' joint='right_qbhand_middle_middle_joint'/>
        <motor name='right_qbhand_middle_distal_joint' gear='125' joint='right_qbhand_middle_distal_joint'/>
        <motor name='right_qbhand_ring_proximal_joint' gear='125' joint='right_qbhand_ring_proximal_joint'/>
        <motor name='right_qbhand_ring_middle_joint' gear='125' joint='right_qbhand_ring_middle_joint'/>
        <motor name='right_qbhand_ring_distal_joint' gear='125' joint='right_qbhand_ring_distal_joint'/>
        <motor name='right_qbhand_little_proximal_joint' gear='125' joint='right_qbhand_little_proximal_joint'/>
        <motor name='right_qbhand_little_middle_joint' gear='125' joint='right_qbhand_little_middle_joint'/>
        <motor name='right_qbhand_little_distal_joint' gear='125' joint='right_qbhand_little_distal_joint'/>
        <motor name='left_shoulder_x' gear='70' joint='left_shoulder_x'/>
        <motor name='left_shoulder_y' gear='70' joint='left_shoulder_y'/>
        <motor name='left_shoulder_z' gear='70' joint='left_shoulder_z'/>
        <motor name='left_elbow' gear='60' joint='left_elbow'/>
        <motor name='left_hand_x' gear='50' joint='left_hand_x'/>
        <motor name='left_hand_y' gear='50' joint='left_hand_y'/>
        <motor name='left_hand_z' gear='50' joint='left_hand_z'/>
        <motor name='left_qbhand_thumb_knuckle_joint' gear='125' joint='left_qbhand_thumb_knuckle_joint'/>
        <motor name='left_qbhand_thumb_proximal_joint' gear='125' joint='left_qbhand_thumb_proximal_joint'/>
        <motor name='left_qbhand_thumb_distal_joint' gear='125' joint='left_qbhand_thumb_distal_joint'/>
        <motor name='left_qbhand_index_proximal_joint' gear='125' joint='left_qbhand_index_proximal_joint'/>
        <motor name='left_qbhand_index_middle_joint' gear='125' joint='left_qbhand_index_middle_joint'/>
        <motor name='left_qbhand_index_distal_joint' gear='125' joint='left_qbhand_index_distal_joint'/>
        <motor name='left_qbhand_middle_proximal_joint' gear='125' joint='left_qbhand_middle_proximal_joint'/>
        <motor name='left_qbhand_middle_middle_joint' gear='125' joint='left_qbhand_middle_middle_joint'/>
        <motor name='left_qbhand_middle_distal_joint' gear='125' joint='left_qbhand_middle_distal_joint'/>
        <motor name='left_qbhand_ring_proximal_joint' gear='125' joint='left_qbhand_ring_proximal_joint'/>
        <motor name='left_qbhand_ring_middle_joint' gear='125' joint='left_qbhand_ring_middle_joint'/>
        <motor name='left_qbhand_ring_distal_joint' gear='125' joint='left_qbhand_ring_distal_joint'/>
        <motor name='left_qbhand_little_proximal_joint' gear='125' joint='left_qbhand_little_proximal_joint'/>
        <motor name='left_qbhand_little_middle_joint' gear='125' joint='left_qbhand_little_middle_joint'/>
        <motor name='left_qbhand_little_distal_joint' gear='125' joint='left_qbhand_little_distal_joint'/>
        <motor name='right_hip_x' gear='125' joint='right_hip_x'/>
        <motor name='right_hip_z' gear='125' joint='right_hip_z'/>
        <motor name='right_hip_y' gear='125' joint='right_hip_y'/>
        <motor name='right_knee' gear='100' joint='right_knee'/>
        <motor name='right_ankle_x' gear='50' joint='right_ankle_x'/>
        <motor name='right_ankle_y' gear='50' joint='right_ankle_y'/>
        <motor name='right_ankle_z' gear='50' joint='right_ankle_z'/>
        <motor name='left_hip_x' gear='125' joint='left_hip_x'/>
        <motor name='left_hip_z' gear='125' joint='left_hip_z'/>
        <motor name='left_hip_y' gear='125' joint='left_hip_y'/>
        <motor name='left_knee' gear='100' joint='left_knee'/>
        <motor name='left_ankle_x' gear='50' joint='left_ankle_x'/>
        <motor name='left_ankle_y' gear='50' joint='left_ankle_y'/>
        <motor name='left_ankle_z' gear='50' joint='left_ankle_z'/>
    </actuator>

    <sensor>
        <subtreelinvel name="pelvis_subtreelinvel" body="pelvis"/>
        <accelerometer name="root_accel" site="root"/>
        <velocimeter name="root_vel" site="root"/>
        <gyro name="root_gyro" site="root"/>

        <force name="left_ankle_force" site="left_ankle"/>
        <force name="right_ankle_force" site="right_ankle"/>
        <force name="left_knee_force" site="left_knee"/>
        <force name="right_knee_force" site="right_knee"/>
        <force name="left_hip_force" site="left_hip"/>
        <force name="right_hip_force" site="right_hip"/>

        <torque name="left_ankle_torque" site="left_ankle"/>
        <torque name="right_ankle_torque" site="right_ankle"/>
        <torque name="left_knee_torque" site="left_knee"/>
        <torque name="right_knee_torque" site="right_knee"/>
        <torque name="left_hip_torque" site="left_hip"/>
        <torque name="right_hip_torque" site="right_hip"/>

        <touch name="pelvis_touch" site="pelvis"/>
        <touch name="upper_waist_touch" site="upper_waist"/>
        <touch name="torso_touch" site="torso"/>
        <touch name="head_touch" site="head"/>
        <touch name="right_upper_arm_touch" site="right_upper_arm"/>
        <touch name="right_lower_arm_touch" site="right_lower_arm"/>
        <touch name="right_hand_touch" site="right_hand"/>
        <touch name="left_upper_arm_touch" site="left_upper_arm"/>
        <touch name="left_lower_arm_touch" site="left_lower_arm"/>
        <touch name="left_hand_touch" site="left_hand"/>
        <touch name="right_thigh_touch" site="right_thigh"/>
        <touch name="right_shin_touch" site="right_shin"/>
        <touch name="right_foot_touch" site="right_foot"/>
        <touch name="left_thigh_touch" site="left_thigh"/>
        <touch name="left_shin_touch" site="left_shin"/>
        <touch name="left_foot_touch" site="left_foot"/>
    </sensor>

</mujoco>
