<?xml version="1.0" ?>
<!-- =================================================================================== -->
<!-- |    This document was autogenerated by xacro from ../robots/robotnik/summit_xls.urdf.xacro | -->
<!-- |    EDITING THIS FILE BY HAND IS NOT RECOMMENDED                                 | -->
<!-- =================================================================================== -->
<robot name="summit_xls">
  <!-- in kg-->
  <link name="world"/>
  <joint name="reference" type="floating">
    <parent link="world"/>
    <child link="summit_xls_base_footprint"/>
  </joint>
  <link name="summit_xls_base_footprint">
    <visual>
      <origin rpy="0 0 0" xyz="0 0 0"/>
      <geometry>
        <box size="0.001 0.001 0.001"/>
      </geometry>
    </visual>
  </link>
  <joint name="summit_xls_base_footprint_joint" type="fixed">
    <origin rpy="0 0 0" xyz="0 0 0.127"/>
    <parent link="summit_xls_base_footprint"/>
    <child link="summit_xls_base_link"/>
  </joint>
  <!-- BASE_LINK -->
  <link name="summit_xls_base_link">
    <inertial>
      <mass value="125.0"/>
      <origin xyz="0 0 0"/>
      <inertia ixx="1.391" ixy="0.004" ixz="0.0" iyy="6.853" iyz="0.0" izz="6.125"/>
    </inertial>
    <visual>
      <origin rpy="0 0 0" xyz="0 0 0"/>
      <geometry>
        <mesh filename="package://curi_description/meshes/robotnik/bases/summit_xls_chassis.dae"/>
      </geometry>
      <material name="black">
        <color rgba="0.0 0.0 0.0 1"/>
      </material>
    </visual>
    <collision>
      <origin rpy="0 0 0 " xyz="0 0 0"/>
      <geometry>
        <mesh filename="package://curi_description/meshes/robotnik/bases/summit_xls_chassis.stl"/>
      </geometry>
    </collision>
  </link>
  <joint name="summit_xls_front_right_wheel_joint" type="continuous">
    <parent link="summit_xls_base_link"/>
    <child link="summit_xls_front_right_wheel_link"/>
    <origin rpy="0 0 0" xyz="0.2225 -0.2045 0.0"/>
    <axis rpy="0 0 0" xyz="0 1 0"/>
    <limit effort="100" velocity="100"/>
    <joint_properties damping="0.0" friction="0.0"/>
  </joint>
  <link name="summit_xls_front_right_wheel_link">
    <visual>
      <origin rpy="0 0 0" xyz="0 0 0"/>
      <geometry>
        <mesh filename="package://curi_description/meshes/robotnik/wheels/omni_wheel_2.dae"/>
      </geometry>
      <material name="darkgrey">
        <color rgba="0.2 0.2 0.2 1"/>
      </material>
    </visual>
    <collision>
      <origin rpy="1.5707963267948966 0 0" xyz="0 0 0"/>
      <geometry>
        <cylinder length="0.087" radius="0.127"/>
      </geometry>
    </collision>
    <inertial>
      <mass value="6.5"/>
      <origin xyz="0 0 0"/>
      <inertia ixx="0.0303095" ixy="0" ixz="0" iyy="0.05241925" iyz="0" izz="0.0303095"/>
    </inertial>
  </link>
  <joint name="summit_xls_front_left_wheel_joint" type="continuous">
    <parent link="summit_xls_base_link"/>
    <child link="summit_xls_front_left_wheel_link"/>
    <origin rpy="0 0 0" xyz="0.2225 0.2045 0.0"/>
    <axis rpy="0 0 0" xyz="0 1 0"/>
    <limit effort="100" velocity="100"/>
    <joint_properties damping="0.0" friction="0.0"/>
  </joint>
  <link name="summit_xls_front_left_wheel_link">
    <visual>
      <origin rpy="0 0 0" xyz="0 0 0"/>
      <geometry>
        <mesh filename="package://curi_description/meshes/robotnik/wheels/omni_wheel_1.dae"/>
      </geometry>
      <material name="darkgrey">
        <color rgba="0.2 0.2 0.2 1"/>
      </material>
    </visual>
    <collision>
      <origin rpy="1.5707963267948966 0 0" xyz="0 0 0"/>
      <geometry>
        <cylinder length="0.087" radius="0.127"/>
      </geometry>
    </collision>
    <inertial>
      <mass value="6.5"/>
      <origin xyz="0 0 0"/>
      <inertia ixx="0.0303095" ixy="0" ixz="0" iyy="0.05241925" iyz="0" izz="0.0303095"/>
    </inertial>
  </link>
  <joint name="summit_xls_back_left_wheel_joint" type="continuous">
    <parent link="summit_xls_base_link"/>
    <child link="summit_xls_back_left_wheel_link"/>
    <origin rpy="0 0 0" xyz="-0.2225 0.2045 0.0"/>
    <axis rpy="0 0 0" xyz="0 1 0"/>
    <limit effort="100" velocity="100"/>
    <joint_properties damping="0.0" friction="0.0"/>
  </joint>
  <link name="summit_xls_back_left_wheel_link">
    <visual>
      <origin rpy="0 0 0" xyz="0 0 0"/>
      <geometry>
        <mesh filename="package://curi_description/meshes/robotnik/wheels/omni_wheel_1.dae"/>
      </geometry>
      <material name="darkgrey">
        <color rgba="0.2 0.2 0.2 1"/>
      </material>
    </visual>
    <collision>
      <origin rpy="1.5707963267948966 0 0" xyz="0 0 0"/>
      <geometry>
        <cylinder length="0.087" radius="0.127"/>
      </geometry>
    </collision>
    <inertial>
      <mass value="6.5"/>
      <origin xyz="0 0 0"/>
      <inertia ixx="0.0303095" ixy="0" ixz="0" iyy="0.05241925" iyz="0" izz="0.0303095"/>
    </inertial>
  </link>
  <joint name="summit_xls_back_right_wheel_joint" type="continuous">
    <parent link="summit_xls_base_link"/>
    <child link="summit_xls_back_right_wheel_link"/>
    <origin rpy="0 0 0" xyz="-0.2225 -0.2045 0.0"/>
    <axis rpy="0 0 0" xyz="0 1 0"/>
    <limit effort="100" velocity="100"/>
    <joint_properties damping="0.0" friction="0.0"/>
  </joint>
  <link name="summit_xls_back_right_wheel_link">
    <visual>
      <origin rpy="0 0 0" xyz="0 0 0"/>
      <geometry>
        <mesh filename="package://curi_description/meshes/robotnik/wheels/omni_wheel_2.dae"/>
      </geometry>
      <material name="darkgrey">
        <color rgba="0.2 0.2 0.2 1"/>
      </material>
    </visual>
    <collision>
      <origin rpy="1.5707963267948966 0 0" xyz="0 0 0"/>
      <geometry>
        <cylinder length="0.087" radius="0.127"/>
      </geometry>
    </collision>
    <inertial>
      <mass value="6.5"/>
      <origin xyz="0 0 0"/>
      <inertia ixx="0.0303095" ixy="0" ixz="0" iyy="0.05241925" iyz="0" izz="0.0303095"/>
    </inertial>
  </link>
</robot>

